Looking in links: https://download.pytorch.org/whl/torch_stable.html
Requirement already satisfied: torch==1.5.0+cu101 in /home/jlpkort/anaconda3/lib/python3.8/site-packages (1.5.0+cu101)
Requirement already satisfied: torchvision==0.6.0+cu101 in /home/jlpkort/anaconda3/lib/python3.8/site-packages (0.6.0+cu101)
Requirement already satisfied: numpy in /home/jlpkort/anaconda3/lib/python3.8/site-packages (from torch==1.5.0+cu101) (1.17.4)
Requirement already satisfied: future in /home/jlpkort/anaconda3/lib/python3.8/site-packages (from torch==1.5.0+cu101) (0.18.2)
Requirement already satisfied: pillow>=4.1.1 in /home/jlpkort/anaconda3/lib/python3.8/site-packages (from torchvision==0.6.0+cu101) (8.2.0)
ERROR: Could not find a version that satisfies the requirement opencv_contrib_python_nonfree==4.1.1.1
ERROR: No matching distribution found for opencv_contrib_python_nonfree==4.1.1.1
wandb: Currently logged in as: tijmenk_ (use `wandb login --relogin` to force relogin)
DATASET:
  MASKS: ./datasets/masks_tv_256
  NAME: TVB
  ROOT: ./datasets/data_256
  SIZE_H: 256
  SIZE_W: 256
MODEL:
  D:
    BETAS: (0.9, 0.99)
    LR: 1e-05
    NAME: 1-ChOutputDiscriminator
    NUM_CHANNELS: 64
    NUM_CRITICS: 5
  IS_TRAIN: True
  JOINT:
    BETAS: (0.9, 0.99)
    LR: 0.0002
    NAME: JointNetwork
  MPN:
    BETAS: (0.9, 0.99)
    LOSS_COEFF: 1.0
    LR: 1e-05
    NAME: MaskPredictionNetwork
    NECK_CHANNELS: 128
    NUM_CHANNELS: 64
  NAME: VCNet
  RIN:
    BETAS: (0.9, 0.99)
    EMBRACE: True
    LOSS_COEFF: 2.0
    LR: 1e-06
    NAME: RobustInpaintingNetwork
    NECK_CHANNELS: 128
    NUM_CHANNELS: 32
OPTIM:
  ADVERSARIAL: 0.001
  GP: 10
  MASK: 1
  RECON: 1.4
  SEMANTIC: 0.01
  TEXTURE: 0.1
SYSTEM:
  NUM_GPU: 4
  NUM_WORKERS: 16
TEST:
  ABLATION: False
  BATCH_SIZE: 64
  C_IMG_ID: 38
  IMG_ID: 52
  ITER: 4
  MODE: 1
  OUTPUT_DIR: ./outputs
  WEIGHTS: ./weights/VCNet_TVB_100000step_4bs_0.0002lr_4gpu_16run/checkpoint-30000.pth
TRAIN:
  BATCH_SIZE: 4
  LOG_INTERVAL: 500
  NUM_STEPS_FOR_JOINT: 6600
  NUM_TOTAL_STEP: 15000
  RESUME: False
  SAVE_DIR: ./weights
  SAVE_INTERVAL: 5000
  SHUFFLE: True
  START_STEP: 0
  TUNE: False
  VISUALIZE_INTERVAL: 500
WANDB:
  ENTITY: tijmenk_
  LOG_DIR: 
  NUM_ROW: 0
  PROJECT_NAME: thesis_pytorch
  RUN: 16
wandb: wandb version 0.12.2 is available!  To upgrade, please run:
wandb:  $ pip install wandb --upgrade
wandb: Tracking run with wandb version 0.11.0
wandb: Syncing run classic-butterfly-162
wandb:  View project at https://wandb.ai/tijmenk_/thesis_pytorch
wandb:  View run at https://wandb.ai/tijmenk_/thesis_pytorch/runs/14udsw8v
wandb: Run data is saved locally in /home/jlpkort/vcnet-blind-image-inpainting/wandb/run-20210917_001123-14udsw8v
wandb: Run `wandb offline` to turn off syncing.
I0917 00:11:31.705118 9752 trainer.py:244] Using 4 GPUs...

Traceback (most recent call last):
  File "/home/jlpkort/anaconda3/lib/python3.8/multiprocessing/util.py", line 300, in _run_finalizers
    finalizer()
  File "/home/jlpkort/anaconda3/lib/python3.8/multiprocessing/util.py", line 224, in __call__
    res = self._callback(*self._args, **self._kwargs)
  File "/home/jlpkort/anaconda3/lib/python3.8/multiprocessing/util.py", line 133, in _remove_temp_dir
    rmtree(tempdir)
  File "/home/jlpkort/anaconda3/lib/python3.8/shutil.py", line 722, in rmtree
    onerror(os.rmdir, path, sys.exc_info())
  File "/home/jlpkort/anaconda3/lib/python3.8/shutil.py", line 720, in rmtree
    os.rmdir(path)
OSError: [Errno 39] Directory not empty: '/scratch/pymp-c154g6ln'
Traceback (most recent call last):
  File "/home/jlpkort/anaconda3/lib/python3.8/multiprocessing/util.py", line 300, in _run_finalizers
    finalizer()
  File "/home/jlpkort/anaconda3/lib/python3.8/multiprocessing/util.py", line 224, in __call__
    res = self._callback(*self._args, **self._kwargs)
  File "/home/jlpkort/anaconda3/lib/python3.8/multiprocessing/util.py", line 133, in _remove_temp_dir
    rmtree(tempdir)
  File "/home/jlpkort/anaconda3/lib/python3.8/shutil.py", line 722, in rmtree
    onerror(os.rmdir, path, sys.exc_info())
  File "/home/jlpkort/anaconda3/lib/python3.8/shutil.py", line 720, in rmtree
    os.rmdir(path)
OSError: [Errno 39] Directory not empty: '/scratch/pymp-vf8afa4h'
Traceback (most recent call last):
  File "/home/jlpkort/anaconda3/lib/python3.8/multiprocessing/util.py", line 300, in _run_finalizers
    finalizer()
  File "/home/jlpkort/anaconda3/lib/python3.8/multiprocessing/util.py", line 224, in __call__
    res = self._callback(*self._args, **self._kwargs)
  File "/home/jlpkort/anaconda3/lib/python3.8/multiprocessing/util.py", line 133, in _remove_temp_dir
    rmtree(tempdir)
  File "/home/jlpkort/anaconda3/lib/python3.8/shutil.py", line 722, in rmtree
    onerror(os.rmdir, path, sys.exc_info())
  File "/home/jlpkort/anaconda3/lib/python3.8/shutil.py", line 720, in rmtree
    os.rmdir(path)
OSError: [Errno 39] Directory not empty: '/scratch/pymp-rlznmsz8'
Traceback (most recent call last):
  File "/home/jlpkort/anaconda3/lib/python3.8/multiprocessing/util.py", line 300, in _run_finalizers
    finalizer()
  File "/home/jlpkort/anaconda3/lib/python3.8/multiprocessing/util.py", line 224, in __call__
    res = self._callback(*self._args, **self._kwargs)
  File "/home/jlpkort/anaconda3/lib/python3.8/multiprocessing/util.py", line 133, in _remove_temp_dir
    rmtree(tempdir)
  File "/home/jlpkort/anaconda3/lib/python3.8/shutil.py", line 722, in rmtree
    onerror(os.rmdir, path, sys.exc_info())
  File "/home/jlpkort/anaconda3/lib/python3.8/shutil.py", line 720, in rmtree
    os.rmdir(path)
OSError: [Errno 39] Directory not empty: '/scratch/pymp-qvlmmshw'
I0917 00:51:37.398876 9752 trainer.py:117]  [Step: 500/15000 (3.3333333333333335%)] D Loss: -139.82461547851562 M Loss: 1.3998827934265137 G Loss: -1.6179747581481934 
Traceback (most recent call last):
  File "/home/jlpkort/anaconda3/lib/python3.8/multiprocessing/util.py", line 300, in _run_finalizers
    finalizer()
  File "/home/jlpkort/anaconda3/lib/python3.8/multiprocessing/util.py", line 224, in __call__
    res = self._callback(*self._args, **self._kwargs)
  File "/home/jlpkort/anaconda3/lib/python3.8/multiprocessing/util.py", line 133, in _remove_temp_dir
    rmtree(tempdir)
  File "/home/jlpkort/anaconda3/lib/python3.8/shutil.py", line 722, in rmtree
    onerror(os.rmdir, path, sys.exc_info())
  File "/home/jlpkort/anaconda3/lib/python3.8/shutil.py", line 720, in rmtree
    os.rmdir(path)
OSError: [Errno 39] Directory not empty: '/scratch/pymp-vnciv_wq'
I0917 01:32:04.995001 9752 trainer.py:117]  [Step: 1000/15000 (6.666666666666667%)] D Loss: -264.23907470703125 M Loss: 1.378138780593872 G Loss: -0.47709769010543823 
Traceback (most recent call last):
  File "/home/jlpkort/anaconda3/lib/python3.8/multiprocessing/util.py", line 300, in _run_finalizers
    finalizer()
  File "/home/jlpkort/anaconda3/lib/python3.8/multiprocessing/util.py", line 224, in __call__
    res = self._callback(*self._args, **self._kwargs)
  File "/home/jlpkort/anaconda3/lib/python3.8/multiprocessing/util.py", line 133, in _remove_temp_dir
    rmtree(tempdir)
  File "/home/jlpkort/anaconda3/lib/python3.8/shutil.py", line 722, in rmtree
    onerror(os.rmdir, path, sys.exc_info())
  File "/home/jlpkort/anaconda3/lib/python3.8/shutil.py", line 720, in rmtree
    os.rmdir(path)
OSError: [Errno 39] Directory not empty: '/scratch/pymp-_cst8b3h'
Traceback (most recent call last):
  File "/home/jlpkort/anaconda3/lib/python3.8/multiprocessing/util.py", line 300, in _run_finalizers
    finalizer()
  File "/home/jlpkort/anaconda3/lib/python3.8/multiprocessing/util.py", line 224, in __call__
    res = self._callback(*self._args, **self._kwargs)
  File "/home/jlpkort/anaconda3/lib/python3.8/multiprocessing/util.py", line 133, in _remove_temp_dir
    rmtree(tempdir)
  File "/home/jlpkort/anaconda3/lib/python3.8/shutil.py", line 722, in rmtree
    onerror(os.rmdir, path, sys.exc_info())
  File "/home/jlpkort/anaconda3/lib/python3.8/shutil.py", line 720, in rmtree
    os.rmdir(path)
OSError: [Errno 39] Directory not empty: '/scratch/pymp-u5gad69k'
I0917 02:12:38.665561 9752 trainer.py:117]  [Step: 1500/15000 (10.0%)] D Loss: -201.15293884277344 M Loss: 1.3925142288208008 G Loss: -1.1966794729232788 
Traceback (most recent call last):
  File "/home/jlpkort/anaconda3/lib/python3.8/multiprocessing/util.py", line 300, in _run_finalizers
    finalizer()
  File "/home/jlpkort/anaconda3/lib/python3.8/multiprocessing/util.py", line 224, in __call__
    res = self._callback(*self._args, **self._kwargs)
  File "/home/jlpkort/anaconda3/lib/python3.8/multiprocessing/util.py", line 133, in _remove_temp_dir
    rmtree(tempdir)
  File "/home/jlpkort/anaconda3/lib/python3.8/shutil.py", line 722, in rmtree
    onerror(os.rmdir, path, sys.exc_info())
  File "/home/jlpkort/anaconda3/lib/python3.8/shutil.py", line 720, in rmtree
    os.rmdir(path)
OSError: [Errno 39] Directory not empty: '/scratch/pymp-7b7ejfvy'
I0917 02:53:17.427869 9752 trainer.py:117]  [Step: 2000/15000 (13.333333333333334%)] D Loss: -102.92959594726562 M Loss: 1.0559498071670532 G Loss: -2.056992292404175 
Traceback (most recent call last):
  File "/home/jlpkort/anaconda3/lib/python3.8/multiprocessing/util.py", line 300, in _run_finalizers
    finalizer()
  File "/home/jlpkort/anaconda3/lib/python3.8/multiprocessing/util.py", line 224, in __call__
    res = self._callback(*self._args, **self._kwargs)
  File "/home/jlpkort/anaconda3/lib/python3.8/multiprocessing/util.py", line 133, in _remove_temp_dir
    rmtree(tempdir)
  File "/home/jlpkort/anaconda3/lib/python3.8/shutil.py", line 722, in rmtree
    onerror(os.rmdir, path, sys.exc_info())
  File "/home/jlpkort/anaconda3/lib/python3.8/shutil.py", line 720, in rmtree
    os.rmdir(path)
OSError: [Errno 39] Directory not empty: '/scratch/pymp-100vnya3'
Traceback (most recent call last):
  File "/home/jlpkort/anaconda3/lib/python3.8/multiprocessing/util.py", line 300, in _run_finalizers
    finalizer()
  File "/home/jlpkort/anaconda3/lib/python3.8/multiprocessing/util.py", line 224, in __call__
    res = self._callback(*self._args, **self._kwargs)
  File "/home/jlpkort/anaconda3/lib/python3.8/multiprocessing/util.py", line 133, in _remove_temp_dir
    rmtree(tempdir)
  File "/home/jlpkort/anaconda3/lib/python3.8/shutil.py", line 722, in rmtree
    onerror(os.rmdir, path, sys.exc_info())
  File "/home/jlpkort/anaconda3/lib/python3.8/shutil.py", line 720, in rmtree
    os.rmdir(path)
OSError: [Errno 39] Directory not empty: '/scratch/pymp-ml8aesz2'
Traceback (most recent call last):
  File "/home/jlpkort/anaconda3/lib/python3.8/multiprocessing/util.py", line 300, in _run_finalizers
    finalizer()
  File "/home/jlpkort/anaconda3/lib/python3.8/multiprocessing/util.py", line 224, in __call__
    res = self._callback(*self._args, **self._kwargs)
  File "/home/jlpkort/anaconda3/lib/python3.8/multiprocessing/util.py", line 133, in _remove_temp_dir
    rmtree(tempdir)
  File "/home/jlpkort/anaconda3/lib/python3.8/shutil.py", line 722, in rmtree
    onerror(os.rmdir, path, sys.exc_info())
  File "/home/jlpkort/anaconda3/lib/python3.8/shutil.py", line 720, in rmtree
    os.rmdir(path)
OSError: [Errno 39] Directory not empty: '/scratch/pymp-e8jn3lqp'
Traceback (most recent call last):
  File "/home/jlpkort/anaconda3/lib/python3.8/multiprocessing/util.py", line 300, in _run_finalizers
    finalizer()
  File "/home/jlpkort/anaconda3/lib/python3.8/multiprocessing/util.py", line 224, in __call__
    res = self._callback(*self._args, **self._kwargs)
  File "/home/jlpkort/anaconda3/lib/python3.8/multiprocessing/util.py", line 133, in _remove_temp_dir
    rmtree(tempdir)
  File "/home/jlpkort/anaconda3/lib/python3.8/shutil.py", line 722, in rmtree
    onerror(os.rmdir, path, sys.exc_info())
  File "/home/jlpkort/anaconda3/lib/python3.8/shutil.py", line 720, in rmtree
    os.rmdir(path)
OSError: [Errno 39] Directory not empty: '/scratch/pymp-7s_8rjtn'
I0917 03:33:34.652478 9752 trainer.py:117]  [Step: 2500/15000 (16.666666666666668%)] D Loss: -303.3849182128906 M Loss: 1.2174031734466553 G Loss: -2.3957362174987793 
I0917 04:13:10.286832 9752 trainer.py:117]  [Step: 3000/15000 (20.0%)] D Loss: -145.32504272460938 M Loss: 1.4022328853607178 G Loss: -3.129653215408325 
Traceback (most recent call last):
  File "/home/jlpkort/anaconda3/lib/python3.8/multiprocessing/util.py", line 300, in _run_finalizers
    finalizer()
  File "/home/jlpkort/anaconda3/lib/python3.8/multiprocessing/util.py", line 224, in __call__
    res = self._callback(*self._args, **self._kwargs)
  File "/home/jlpkort/anaconda3/lib/python3.8/multiprocessing/util.py", line 133, in _remove_temp_dir
    rmtree(tempdir)
  File "/home/jlpkort/anaconda3/lib/python3.8/shutil.py", line 722, in rmtree
    onerror(os.rmdir, path, sys.exc_info())
  File "/home/jlpkort/anaconda3/lib/python3.8/shutil.py", line 720, in rmtree
    os.rmdir(path)
OSError: [Errno 39] Directory not empty: '/scratch/pymp-a98eazpe'
Traceback (most recent call last):
  File "/home/jlpkort/anaconda3/lib/python3.8/multiprocessing/util.py", line 300, in _run_finalizers
    finalizer()
  File "/home/jlpkort/anaconda3/lib/python3.8/multiprocessing/util.py", line 224, in __call__
    res = self._callback(*self._args, **self._kwargs)
  File "/home/jlpkort/anaconda3/lib/python3.8/multiprocessing/util.py", line 133, in _remove_temp_dir
    rmtree(tempdir)
  File "/home/jlpkort/anaconda3/lib/python3.8/shutil.py", line 722, in rmtree
    onerror(os.rmdir, path, sys.exc_info())
  File "/home/jlpkort/anaconda3/lib/python3.8/shutil.py", line 720, in rmtree
    os.rmdir(path)
OSError: [Errno 39] Directory not empty: '/scratch/pymp-iweb1d5j'
Traceback (most recent call last):
  File "/home/jlpkort/anaconda3/lib/python3.8/multiprocessing/util.py", line 300, in _run_finalizers
    finalizer()
  File "/home/jlpkort/anaconda3/lib/python3.8/multiprocessing/util.py", line 224, in __call__
    res = self._callback(*self._args, **self._kwargs)
  File "/home/jlpkort/anaconda3/lib/python3.8/multiprocessing/util.py", line 133, in _remove_temp_dir
    rmtree(tempdir)
  File "/home/jlpkort/anaconda3/lib/python3.8/shutil.py", line 722, in rmtree
    onerror(os.rmdir, path, sys.exc_info())
  File "/home/jlpkort/anaconda3/lib/python3.8/shutil.py", line 720, in rmtree
    os.rmdir(path)
OSError: [Errno 39] Directory not empty: '/scratch/pymp-25mh24aj'
Traceback (most recent call last):
  File "/home/jlpkort/anaconda3/lib/python3.8/multiprocessing/util.py", line 300, in _run_finalizers
    finalizer()
  File "/home/jlpkort/anaconda3/lib/python3.8/multiprocessing/util.py", line 224, in __call__
    res = self._callback(*self._args, **self._kwargs)
  File "/home/jlpkort/anaconda3/lib/python3.8/multiprocessing/util.py", line 133, in _remove_temp_dir
    rmtree(tempdir)
  File "/home/jlpkort/anaconda3/lib/python3.8/shutil.py", line 722, in rmtree
    onerror(os.rmdir, path, sys.exc_info())
  File "/home/jlpkort/anaconda3/lib/python3.8/shutil.py", line 720, in rmtree
    os.rmdir(path)
OSError: [Errno 39] Directory not empty: '/scratch/pymp-28390l7c'
I0917 04:53:46.434655 9752 trainer.py:117]  [Step: 3500/15000 (23.333333333333332%)] D Loss: -175.82583618164062 M Loss: 1.2984095811843872 G Loss: -2.7680861949920654 
Traceback (most recent call last):
  File "/home/jlpkort/anaconda3/lib/python3.8/multiprocessing/util.py", line 300, in _run_finalizers
    finalizer()
  File "/home/jlpkort/anaconda3/lib/python3.8/multiprocessing/util.py", line 224, in __call__
    res = self._callback(*self._args, **self._kwargs)
  File "/home/jlpkort/anaconda3/lib/python3.8/multiprocessing/util.py", line 133, in _remove_temp_dir
    rmtree(tempdir)
  File "/home/jlpkort/anaconda3/lib/python3.8/shutil.py", line 722, in rmtree
    onerror(os.rmdir, path, sys.exc_info())
  File "/home/jlpkort/anaconda3/lib/python3.8/shutil.py", line 720, in rmtree
    os.rmdir(path)
OSError: [Errno 39] Directory not empty: '/scratch/pymp-5f1iil6o'
Traceback (most recent call last):
  File "/home/jlpkort/anaconda3/lib/python3.8/multiprocessing/util.py", line 300, in _run_finalizers
    finalizer()
  File "/home/jlpkort/anaconda3/lib/python3.8/multiprocessing/util.py", line 224, in __call__
    res = self._callback(*self._args, **self._kwargs)
  File "/home/jlpkort/anaconda3/lib/python3.8/multiprocessing/util.py", line 133, in _remove_temp_dir
    rmtree(tempdir)
  File "/home/jlpkort/anaconda3/lib/python3.8/shutil.py", line 722, in rmtree
    onerror(os.rmdir, path, sys.exc_info())
  File "/home/jlpkort/anaconda3/lib/python3.8/shutil.py", line 720, in rmtree
    os.rmdir(path)
OSError: [Errno 39] Directory not empty: '/scratch/pymp-o5osbx24'
Traceback (most recent call last):
  File "/home/jlpkort/anaconda3/lib/python3.8/multiprocessing/util.py", line 300, in _run_finalizers
    finalizer()
  File "/home/jlpkort/anaconda3/lib/python3.8/multiprocessing/util.py", line 224, in __call__
    res = self._callback(*self._args, **self._kwargs)
  File "/home/jlpkort/anaconda3/lib/python3.8/multiprocessing/util.py", line 133, in _remove_temp_dir
    rmtree(tempdir)
  File "/home/jlpkort/anaconda3/lib/python3.8/shutil.py", line 722, in rmtree
    onerror(os.rmdir, path, sys.exc_info())
  File "/home/jlpkort/anaconda3/lib/python3.8/shutil.py", line 720, in rmtree
    os.rmdir(path)
OSError: [Errno 39] Directory not empty: '/scratch/pymp-h1b431ma'
I0917 05:34:35.631583 9752 trainer.py:117]  [Step: 4000/15000 (26.666666666666668%)] D Loss: -137.94268798828125 M Loss: 1.3877031803131104 G Loss: -2.687704563140869 
Traceback (most recent call last):
  File "/home/jlpkort/anaconda3/lib/python3.8/multiprocessing/util.py", line 300, in _run_finalizers
    finalizer()
  File "/home/jlpkort/anaconda3/lib/python3.8/multiprocessing/util.py", line 224, in __call__
    res = self._callback(*self._args, **self._kwargs)
  File "/home/jlpkort/anaconda3/lib/python3.8/multiprocessing/util.py", line 133, in _remove_temp_dir
    rmtree(tempdir)
  File "/home/jlpkort/anaconda3/lib/python3.8/shutil.py", line 722, in rmtree
    onerror(os.rmdir, path, sys.exc_info())
  File "/home/jlpkort/anaconda3/lib/python3.8/shutil.py", line 720, in rmtree
    os.rmdir(path)
OSError: [Errno 39] Directory not empty: '/scratch/pymp-fjz6grti'
Traceback (most recent call last):
  File "/home/jlpkort/anaconda3/lib/python3.8/multiprocessing/util.py", line 300, in _run_finalizers
    finalizer()
  File "/home/jlpkort/anaconda3/lib/python3.8/multiprocessing/util.py", line 224, in __call__
    res = self._callback(*self._args, **self._kwargs)
  File "/home/jlpkort/anaconda3/lib/python3.8/multiprocessing/util.py", line 133, in _remove_temp_dir
    rmtree(tempdir)
  File "/home/jlpkort/anaconda3/lib/python3.8/shutil.py", line 722, in rmtree
    onerror(os.rmdir, path, sys.exc_info())
  File "/home/jlpkort/anaconda3/lib/python3.8/shutil.py", line 720, in rmtree
    os.rmdir(path)
OSError: [Errno 39] Directory not empty: '/scratch/pymp-qwbi5opk'
Traceback (most recent call last):
  File "/home/jlpkort/anaconda3/lib/python3.8/multiprocessing/util.py", line 300, in _run_finalizers
    finalizer()
  File "/home/jlpkort/anaconda3/lib/python3.8/multiprocessing/util.py", line 224, in __call__
    res = self._callback(*self._args, **self._kwargs)
  File "/home/jlpkort/anaconda3/lib/python3.8/multiprocessing/util.py", line 133, in _remove_temp_dir
    rmtree(tempdir)
  File "/home/jlpkort/anaconda3/lib/python3.8/shutil.py", line 722, in rmtree
    onerror(os.rmdir, path, sys.exc_info())
  File "/home/jlpkort/anaconda3/lib/python3.8/shutil.py", line 720, in rmtree
    os.rmdir(path)
OSError: [Errno 39] Directory not empty: '/scratch/pymp-tzcunx_v'
I0917 06:15:27.341047 9752 trainer.py:117]  [Step: 4500/15000 (30.0%)] D Loss: -117.49921417236328 M Loss: 1.3423516750335693 G Loss: -1.939452886581421 
Traceback (most recent call last):
  File "/home/jlpkort/anaconda3/lib/python3.8/multiprocessing/util.py", line 300, in _run_finalizers
    finalizer()
  File "/home/jlpkort/anaconda3/lib/python3.8/multiprocessing/util.py", line 224, in __call__
    res = self._callback(*self._args, **self._kwargs)
  File "/home/jlpkort/anaconda3/lib/python3.8/multiprocessing/util.py", line 133, in _remove_temp_dir
    rmtree(tempdir)
  File "/home/jlpkort/anaconda3/lib/python3.8/shutil.py", line 722, in rmtree
    onerror(os.rmdir, path, sys.exc_info())
  File "/home/jlpkort/anaconda3/lib/python3.8/shutil.py", line 720, in rmtree
    os.rmdir(path)
OSError: [Errno 39] Directory not empty: '/scratch/pymp-qz_dxyez'
I0917 06:56:18.373929 9752 trainer.py:117]  [Step: 5000/15000 (33.333333333333336%)] D Loss: -123.76448822021484 M Loss: 1.0636157989501953 G Loss: -3.3962960243225098 
Traceback (most recent call last):
  File "/home/jlpkort/anaconda3/lib/python3.8/multiprocessing/util.py", line 300, in _run_finalizers
    finalizer()
  File "/home/jlpkort/anaconda3/lib/python3.8/multiprocessing/util.py", line 224, in __call__
    res = self._callback(*self._args, **self._kwargs)
  File "/home/jlpkort/anaconda3/lib/python3.8/multiprocessing/util.py", line 133, in _remove_temp_dir
    rmtree(tempdir)
  File "/home/jlpkort/anaconda3/lib/python3.8/shutil.py", line 722, in rmtree
    onerror(os.rmdir, path, sys.exc_info())
  File "/home/jlpkort/anaconda3/lib/python3.8/shutil.py", line 720, in rmtree
    os.rmdir(path)
OSError: [Errno 39] Directory not empty: '/scratch/pymp-mrrfxnt4'
Traceback (most recent call last):
  File "/home/jlpkort/anaconda3/lib/python3.8/multiprocessing/util.py", line 300, in _run_finalizers
    finalizer()
  File "/home/jlpkort/anaconda3/lib/python3.8/multiprocessing/util.py", line 224, in __call__
    res = self._callback(*self._args, **self._kwargs)
  File "/home/jlpkort/anaconda3/lib/python3.8/multiprocessing/util.py", line 133, in _remove_temp_dir
    rmtree(tempdir)
  File "/home/jlpkort/anaconda3/lib/python3.8/shutil.py", line 722, in rmtree
    onerror(os.rmdir, path, sys.exc_info())
  File "/home/jlpkort/anaconda3/lib/python3.8/shutil.py", line 720, in rmtree
    os.rmdir(path)
OSError: [Errno 39] Directory not empty: '/scratch/pymp-adui8lii'
Traceback (most recent call last):
  File "/home/jlpkort/anaconda3/lib/python3.8/multiprocessing/util.py", line 300, in _run_finalizers
    finalizer()
  File "/home/jlpkort/anaconda3/lib/python3.8/multiprocessing/util.py", line 224, in __call__
    res = self._callback(*self._args, **self._kwargs)
  File "/home/jlpkort/anaconda3/lib/python3.8/multiprocessing/util.py", line 133, in _remove_temp_dir
    rmtree(tempdir)
  File "/home/jlpkort/anaconda3/lib/python3.8/shutil.py", line 722, in rmtree
    onerror(os.rmdir, path, sys.exc_info())
  File "/home/jlpkort/anaconda3/lib/python3.8/shutil.py", line 720, in rmtree
    os.rmdir(path)
OSError: [Errno 39] Directory not empty: '/scratch/pymp-_1o5vs9z'
I0917 07:37:13.557360 9752 trainer.py:117]  [Step: 5500/15000 (36.666666666666664%)] D Loss: -143.32009887695312 M Loss: 1.3321444988250732 G Loss: -3.2297565937042236 
Traceback (most recent call last):
  File "/home/jlpkort/anaconda3/lib/python3.8/multiprocessing/util.py", line 300, in _run_finalizers
    finalizer()
  File "/home/jlpkort/anaconda3/lib/python3.8/multiprocessing/util.py", line 224, in __call__
    res = self._callback(*self._args, **self._kwargs)
  File "/home/jlpkort/anaconda3/lib/python3.8/multiprocessing/util.py", line 133, in _remove_temp_dir
    rmtree(tempdir)
  File "/home/jlpkort/anaconda3/lib/python3.8/shutil.py", line 722, in rmtree
    onerror(os.rmdir, path, sys.exc_info())
  File "/home/jlpkort/anaconda3/lib/python3.8/shutil.py", line 720, in rmtree
    os.rmdir(path)
OSError: [Errno 39] Directory not empty: '/scratch/pymp-pq816_t6'
I0917 08:18:07.073584 9752 trainer.py:117]  [Step: 6000/15000 (40.0%)] D Loss: -123.80252838134766 M Loss: 1.3387279510498047 G Loss: -2.14310622215271 
Traceback (most recent call last):
  File "/home/jlpkort/anaconda3/lib/python3.8/multiprocessing/util.py", line 300, in _run_finalizers
    finalizer()
  File "/home/jlpkort/anaconda3/lib/python3.8/multiprocessing/util.py", line 224, in __call__
    res = self._callback(*self._args, **self._kwargs)
  File "/home/jlpkort/anaconda3/lib/python3.8/multiprocessing/util.py", line 133, in _remove_temp_dir
    rmtree(tempdir)
  File "/home/jlpkort/anaconda3/lib/python3.8/shutil.py", line 722, in rmtree
    onerror(os.rmdir, path, sys.exc_info())
  File "/home/jlpkort/anaconda3/lib/python3.8/shutil.py", line 720, in rmtree
    os.rmdir(path)
OSError: [Errno 39] Directory not empty: '/scratch/pymp-awpezt2w'
Traceback (most recent call last):
  File "/home/jlpkort/anaconda3/lib/python3.8/multiprocessing/util.py", line 300, in _run_finalizers
    finalizer()
  File "/home/jlpkort/anaconda3/lib/python3.8/multiprocessing/util.py", line 224, in __call__
    res = self._callback(*self._args, **self._kwargs)
  File "/home/jlpkort/anaconda3/lib/python3.8/multiprocessing/util.py", line 133, in _remove_temp_dir
    rmtree(tempdir)
  File "/home/jlpkort/anaconda3/lib/python3.8/shutil.py", line 722, in rmtree
    onerror(os.rmdir, path, sys.exc_info())
  File "/home/jlpkort/anaconda3/lib/python3.8/shutil.py", line 720, in rmtree
    os.rmdir(path)
OSError: [Errno 39] Directory not empty: '/scratch/pymp-7_rgg2hs'
Traceback (most recent call last):
  File "/home/jlpkort/anaconda3/lib/python3.8/multiprocessing/util.py", line 300, in _run_finalizers
    finalizer()
  File "/home/jlpkort/anaconda3/lib/python3.8/multiprocessing/util.py", line 224, in __call__
    res = self._callback(*self._args, **self._kwargs)
  File "/home/jlpkort/anaconda3/lib/python3.8/multiprocessing/util.py", line 133, in _remove_temp_dir
    rmtree(tempdir)
  File "/home/jlpkort/anaconda3/lib/python3.8/shutil.py", line 722, in rmtree
    onerror(os.rmdir, path, sys.exc_info())
  File "/home/jlpkort/anaconda3/lib/python3.8/shutil.py", line 720, in rmtree
    os.rmdir(path)
OSError: [Errno 39] Directory not empty: '/scratch/pymp-n_jew2he'
Traceback (most recent call last):
  File "/home/jlpkort/anaconda3/lib/python3.8/multiprocessing/util.py", line 300, in _run_finalizers
    finalizer()
  File "/home/jlpkort/anaconda3/lib/python3.8/multiprocessing/util.py", line 224, in __call__
    res = self._callback(*self._args, **self._kwargs)
  File "/home/jlpkort/anaconda3/lib/python3.8/multiprocessing/util.py", line 133, in _remove_temp_dir
    rmtree(tempdir)
  File "/home/jlpkort/anaconda3/lib/python3.8/shutil.py", line 722, in rmtree
    onerror(os.rmdir, path, sys.exc_info())
  File "/home/jlpkort/anaconda3/lib/python3.8/shutil.py", line 720, in rmtree
    os.rmdir(path)
OSError: [Errno 39] Directory not empty: '/scratch/pymp-9rw2eivn'
I0917 08:58:56.725183 9752 trainer.py:117]  [Step: 6500/15000 (43.333333333333336%)] D Loss: -124.43122863769531 M Loss: 1.3607947826385498 G Loss: -3.5718297958374023 
Traceback (most recent call last):
  File "/home/jlpkort/anaconda3/lib/python3.8/multiprocessing/util.py", line 300, in _run_finalizers
    finalizer()
  File "/home/jlpkort/anaconda3/lib/python3.8/multiprocessing/util.py", line 224, in __call__
    res = self._callback(*self._args, **self._kwargs)
  File "/home/jlpkort/anaconda3/lib/python3.8/multiprocessing/util.py", line 133, in _remove_temp_dir
    rmtree(tempdir)
  File "/home/jlpkort/anaconda3/lib/python3.8/shutil.py", line 722, in rmtree
    onerror(os.rmdir, path, sys.exc_info())
  File "/home/jlpkort/anaconda3/lib/python3.8/shutil.py", line 720, in rmtree
    os.rmdir(path)
OSError: [Errno 39] Directory not empty: '/scratch/pymp-juy8ucip'
Traceback (most recent call last):
  File "/home/jlpkort/anaconda3/lib/python3.8/multiprocessing/util.py", line 300, in _run_finalizers
    finalizer()
  File "/home/jlpkort/anaconda3/lib/python3.8/multiprocessing/util.py", line 224, in __call__
    res = self._callback(*self._args, **self._kwargs)
  File "/home/jlpkort/anaconda3/lib/python3.8/multiprocessing/util.py", line 133, in _remove_temp_dir
    rmtree(tempdir)
  File "/home/jlpkort/anaconda3/lib/python3.8/shutil.py", line 722, in rmtree
    onerror(os.rmdir, path, sys.exc_info())
  File "/home/jlpkort/anaconda3/lib/python3.8/shutil.py", line 720, in rmtree
    os.rmdir(path)
OSError: [Errno 39] Directory not empty: '/scratch/pymp-ynwygt_5'
I0917 09:38:42.602251 9752 trainer.py:117]  [Step: 7000/15000 (46.666666666666664%)] D Loss: -48.10787582397461 M Loss: 1.36651611328125 G Loss: 4.606845855712891 
Traceback (most recent call last):
  File "/home/jlpkort/anaconda3/lib/python3.8/multiprocessing/util.py", line 300, in _run_finalizers
    finalizer()
  File "/home/jlpkort/anaconda3/lib/python3.8/multiprocessing/util.py", line 224, in __call__
    res = self._callback(*self._args, **self._kwargs)
  File "/home/jlpkort/anaconda3/lib/python3.8/multiprocessing/util.py", line 133, in _remove_temp_dir
    rmtree(tempdir)
  File "/home/jlpkort/anaconda3/lib/python3.8/shutil.py", line 722, in rmtree
    onerror(os.rmdir, path, sys.exc_info())
  File "/home/jlpkort/anaconda3/lib/python3.8/shutil.py", line 720, in rmtree
    os.rmdir(path)
OSError: [Errno 39] Directory not empty: '/scratch/pymp-5n7n6b0e'
Traceback (most recent call last):
  File "/home/jlpkort/anaconda3/lib/python3.8/multiprocessing/util.py", line 300, in _run_finalizers
    finalizer()
  File "/home/jlpkort/anaconda3/lib/python3.8/multiprocessing/util.py", line 224, in __call__
    res = self._callback(*self._args, **self._kwargs)
  File "/home/jlpkort/anaconda3/lib/python3.8/multiprocessing/util.py", line 133, in _remove_temp_dir
    rmtree(tempdir)
  File "/home/jlpkort/anaconda3/lib/python3.8/shutil.py", line 722, in rmtree
    onerror(os.rmdir, path, sys.exc_info())
  File "/home/jlpkort/anaconda3/lib/python3.8/shutil.py", line 720, in rmtree
    os.rmdir(path)
OSError: [Errno 39] Directory not empty: '/scratch/pymp-z1z_1u6c'
I0917 10:18:27.813236 9752 trainer.py:117]  [Step: 7500/15000 (50.0%)] D Loss: -38.7972297668457 M Loss: 1.3435648679733276 G Loss: 1.237724781036377 
Traceback (most recent call last):
  File "/home/jlpkort/anaconda3/lib/python3.8/multiprocessing/util.py", line 300, in _run_finalizers
    finalizer()
  File "/home/jlpkort/anaconda3/lib/python3.8/multiprocessing/util.py", line 224, in __call__
    res = self._callback(*self._args, **self._kwargs)
  File "/home/jlpkort/anaconda3/lib/python3.8/multiprocessing/util.py", line 133, in _remove_temp_dir
    rmtree(tempdir)
  File "/home/jlpkort/anaconda3/lib/python3.8/shutil.py", line 722, in rmtree
    onerror(os.rmdir, path, sys.exc_info())
  File "/home/jlpkort/anaconda3/lib/python3.8/shutil.py", line 720, in rmtree
    os.rmdir(path)
OSError: [Errno 39] Directory not empty: '/scratch/pymp-fr05okgz'
Traceback (most recent call last):
  File "/home/jlpkort/anaconda3/lib/python3.8/multiprocessing/util.py", line 300, in _run_finalizers
    finalizer()
  File "/home/jlpkort/anaconda3/lib/python3.8/multiprocessing/util.py", line 224, in __call__
    res = self._callback(*self._args, **self._kwargs)
  File "/home/jlpkort/anaconda3/lib/python3.8/multiprocessing/util.py", line 133, in _remove_temp_dir
    rmtree(tempdir)
  File "/home/jlpkort/anaconda3/lib/python3.8/shutil.py", line 722, in rmtree
    onerror(os.rmdir, path, sys.exc_info())
  File "/home/jlpkort/anaconda3/lib/python3.8/shutil.py", line 720, in rmtree
    os.rmdir(path)
OSError: [Errno 39] Directory not empty: '/scratch/pymp-lehbtjlb'
Traceback (most recent call last):
  File "/home/jlpkort/anaconda3/lib/python3.8/multiprocessing/util.py", line 300, in _run_finalizers
    finalizer()
  File "/home/jlpkort/anaconda3/lib/python3.8/multiprocessing/util.py", line 224, in __call__
    res = self._callback(*self._args, **self._kwargs)
  File "/home/jlpkort/anaconda3/lib/python3.8/multiprocessing/util.py", line 133, in _remove_temp_dir
    rmtree(tempdir)
  File "/home/jlpkort/anaconda3/lib/python3.8/shutil.py", line 722, in rmtree
    onerror(os.rmdir, path, sys.exc_info())
  File "/home/jlpkort/anaconda3/lib/python3.8/shutil.py", line 720, in rmtree
    os.rmdir(path)
OSError: [Errno 39] Directory not empty: '/scratch/pymp-6asco306'
I0917 10:58:13.054475 9752 trainer.py:117]  [Step: 8000/15000 (53.333333333333336%)] D Loss: -23.089946746826172 M Loss: 1.3564472198486328 G Loss: 0.5043272972106934 
Traceback (most recent call last):
  File "/home/jlpkort/anaconda3/lib/python3.8/multiprocessing/util.py", line 300, in _run_finalizers
    finalizer()
  File "/home/jlpkort/anaconda3/lib/python3.8/multiprocessing/util.py", line 224, in __call__
    res = self._callback(*self._args, **self._kwargs)
  File "/home/jlpkort/anaconda3/lib/python3.8/multiprocessing/util.py", line 133, in _remove_temp_dir
    rmtree(tempdir)
  File "/home/jlpkort/anaconda3/lib/python3.8/shutil.py", line 722, in rmtree
    onerror(os.rmdir, path, sys.exc_info())
  File "/home/jlpkort/anaconda3/lib/python3.8/shutil.py", line 720, in rmtree
    os.rmdir(path)
OSError: [Errno 39] Directory not empty: '/scratch/pymp-7thev2rp'
Traceback (most recent call last):
  File "/home/jlpkort/anaconda3/lib/python3.8/multiprocessing/util.py", line 300, in _run_finalizers
    finalizer()
  File "/home/jlpkort/anaconda3/lib/python3.8/multiprocessing/util.py", line 224, in __call__
    res = self._callback(*self._args, **self._kwargs)
  File "/home/jlpkort/anaconda3/lib/python3.8/multiprocessing/util.py", line 133, in _remove_temp_dir
    rmtree(tempdir)
  File "/home/jlpkort/anaconda3/lib/python3.8/shutil.py", line 722, in rmtree
    onerror(os.rmdir, path, sys.exc_info())
  File "/home/jlpkort/anaconda3/lib/python3.8/shutil.py", line 720, in rmtree
    os.rmdir(path)
OSError: [Errno 39] Directory not empty: '/scratch/pymp-iwab26di'
Traceback (most recent call last):
  File "/home/jlpkort/anaconda3/lib/python3.8/multiprocessing/util.py", line 300, in _run_finalizers
    finalizer()
  File "/home/jlpkort/anaconda3/lib/python3.8/multiprocessing/util.py", line 224, in __call__
    res = self._callback(*self._args, **self._kwargs)
  File "/home/jlpkort/anaconda3/lib/python3.8/multiprocessing/util.py", line 133, in _remove_temp_dir
    rmtree(tempdir)
  File "/home/jlpkort/anaconda3/lib/python3.8/shutil.py", line 722, in rmtree
    onerror(os.rmdir, path, sys.exc_info())
  File "/home/jlpkort/anaconda3/lib/python3.8/shutil.py", line 720, in rmtree
    os.rmdir(path)
OSError: [Errno 39] Directory not empty: '/scratch/pymp-9rqlg29g'
I0917 11:38:03.563050 9752 trainer.py:117]  [Step: 8500/15000 (56.666666666666664%)] D Loss: -15.373884201049805 M Loss: 1.3649930953979492 G Loss: 0.13440781831741333 
Traceback (most recent call last):
  File "/home/jlpkort/anaconda3/lib/python3.8/multiprocessing/util.py", line 300, in _run_finalizers
    finalizer()
  File "/home/jlpkort/anaconda3/lib/python3.8/multiprocessing/util.py", line 224, in __call__
    res = self._callback(*self._args, **self._kwargs)
  File "/home/jlpkort/anaconda3/lib/python3.8/multiprocessing/util.py", line 133, in _remove_temp_dir
    rmtree(tempdir)
  File "/home/jlpkort/anaconda3/lib/python3.8/shutil.py", line 722, in rmtree
    onerror(os.rmdir, path, sys.exc_info())
  File "/home/jlpkort/anaconda3/lib/python3.8/shutil.py", line 720, in rmtree
    os.rmdir(path)
OSError: [Errno 39] Directory not empty: '/scratch/pymp-1kzg8y53'
I0917 12:18:05.001420 9752 trainer.py:117]  [Step: 9000/15000 (60.0%)] D Loss: -14.6679105758667 M Loss: 1.3090641498565674 G Loss: 0.18784815073013306 
Traceback (most recent call last):
  File "/home/jlpkort/anaconda3/lib/python3.8/multiprocessing/util.py", line 300, in _run_finalizers
    finalizer()
  File "/home/jlpkort/anaconda3/lib/python3.8/multiprocessing/util.py", line 224, in __call__
    res = self._callback(*self._args, **self._kwargs)
  File "/home/jlpkort/anaconda3/lib/python3.8/multiprocessing/util.py", line 133, in _remove_temp_dir
    rmtree(tempdir)
  File "/home/jlpkort/anaconda3/lib/python3.8/shutil.py", line 722, in rmtree
    onerror(os.rmdir, path, sys.exc_info())
  File "/home/jlpkort/anaconda3/lib/python3.8/shutil.py", line 720, in rmtree
    os.rmdir(path)
OSError: [Errno 39] Directory not empty: '/scratch/pymp-8y02k90p'
Traceback (most recent call last):
  File "/home/jlpkort/anaconda3/lib/python3.8/multiprocessing/util.py", line 300, in _run_finalizers
    finalizer()
  File "/home/jlpkort/anaconda3/lib/python3.8/multiprocessing/util.py", line 224, in __call__
    res = self._callback(*self._args, **self._kwargs)
  File "/home/jlpkort/anaconda3/lib/python3.8/multiprocessing/util.py", line 133, in _remove_temp_dir
    rmtree(tempdir)
  File "/home/jlpkort/anaconda3/lib/python3.8/shutil.py", line 722, in rmtree
    onerror(os.rmdir, path, sys.exc_info())
  File "/home/jlpkort/anaconda3/lib/python3.8/shutil.py", line 720, in rmtree
    os.rmdir(path)
OSError: [Errno 39] Directory not empty: '/scratch/pymp-xddd_76r'
Traceback (most recent call last):
  File "/home/jlpkort/anaconda3/lib/python3.8/multiprocessing/util.py", line 300, in _run_finalizers
    finalizer()
  File "/home/jlpkort/anaconda3/lib/python3.8/multiprocessing/util.py", line 224, in __call__
    res = self._callback(*self._args, **self._kwargs)
  File "/home/jlpkort/anaconda3/lib/python3.8/multiprocessing/util.py", line 133, in _remove_temp_dir
    rmtree(tempdir)
  File "/home/jlpkort/anaconda3/lib/python3.8/shutil.py", line 722, in rmtree
    onerror(os.rmdir, path, sys.exc_info())
  File "/home/jlpkort/anaconda3/lib/python3.8/shutil.py", line 720, in rmtree
    os.rmdir(path)
OSError: [Errno 39] Directory not empty: '/scratch/pymp-esemgg50'
Traceback (most recent call last):
  File "/home/jlpkort/anaconda3/lib/python3.8/multiprocessing/util.py", line 300, in _run_finalizers
    finalizer()
  File "/home/jlpkort/anaconda3/lib/python3.8/multiprocessing/util.py", line 224, in __call__
    res = self._callback(*self._args, **self._kwargs)
  File "/home/jlpkort/anaconda3/lib/python3.8/multiprocessing/util.py", line 133, in _remove_temp_dir
    rmtree(tempdir)
  File "/home/jlpkort/anaconda3/lib/python3.8/shutil.py", line 722, in rmtree
    onerror(os.rmdir, path, sys.exc_info())
  File "/home/jlpkort/anaconda3/lib/python3.8/shutil.py", line 720, in rmtree
    os.rmdir(path)
OSError: [Errno 39] Directory not empty: '/scratch/pymp-2kujs3xv'
I0917 12:57:57.846255 9752 trainer.py:117]  [Step: 9500/15000 (63.333333333333336%)] D Loss: -6.229331016540527 M Loss: 1.3410054445266724 G Loss: 0.1819736361503601 
I0917 13:37:50.190863 9752 trainer.py:117]  [Step: 10000/15000 (66.66666666666667%)] D Loss: -12.455653190612793 M Loss: 1.3280808925628662 G Loss: 0.2024857997894287 
Traceback (most recent call last):
  File "/home/jlpkort/anaconda3/lib/python3.8/multiprocessing/util.py", line 300, in _run_finalizers
    finalizer()
  File "/home/jlpkort/anaconda3/lib/python3.8/multiprocessing/util.py", line 224, in __call__
    res = self._callback(*self._args, **self._kwargs)
  File "/home/jlpkort/anaconda3/lib/python3.8/multiprocessing/util.py", line 133, in _remove_temp_dir
    rmtree(tempdir)
  File "/home/jlpkort/anaconda3/lib/python3.8/shutil.py", line 722, in rmtree
    onerror(os.rmdir, path, sys.exc_info())
  File "/home/jlpkort/anaconda3/lib/python3.8/shutil.py", line 720, in rmtree
    os.rmdir(path)
OSError: [Errno 39] Directory not empty: '/scratch/pymp-l464yt2l'
Traceback (most recent call last):
  File "/home/jlpkort/anaconda3/lib/python3.8/multiprocessing/util.py", line 300, in _run_finalizers
    finalizer()
  File "/home/jlpkort/anaconda3/lib/python3.8/multiprocessing/util.py", line 224, in __call__
    res = self._callback(*self._args, **self._kwargs)
  File "/home/jlpkort/anaconda3/lib/python3.8/multiprocessing/util.py", line 133, in _remove_temp_dir
    rmtree(tempdir)
  File "/home/jlpkort/anaconda3/lib/python3.8/shutil.py", line 722, in rmtree
    onerror(os.rmdir, path, sys.exc_info())
  File "/home/jlpkort/anaconda3/lib/python3.8/shutil.py", line 720, in rmtree
    os.rmdir(path)
OSError: [Errno 39] Directory not empty: '/scratch/pymp-i402ak10'
Traceback (most recent call last):
  File "/home/jlpkort/anaconda3/lib/python3.8/multiprocessing/util.py", line 300, in _run_finalizers
    finalizer()
  File "/home/jlpkort/anaconda3/lib/python3.8/multiprocessing/util.py", line 224, in __call__
    res = self._callback(*self._args, **self._kwargs)
  File "/home/jlpkort/anaconda3/lib/python3.8/multiprocessing/util.py", line 133, in _remove_temp_dir
    rmtree(tempdir)
  File "/home/jlpkort/anaconda3/lib/python3.8/shutil.py", line 722, in rmtree
    onerror(os.rmdir, path, sys.exc_info())
  File "/home/jlpkort/anaconda3/lib/python3.8/shutil.py", line 720, in rmtree
    os.rmdir(path)
OSError: [Errno 39] Directory not empty: '/scratch/pymp-pgii5ki1'
Traceback (most recent call last):
  File "/home/jlpkort/anaconda3/lib/python3.8/multiprocessing/util.py", line 300, in _run_finalizers
    finalizer()
  File "/home/jlpkort/anaconda3/lib/python3.8/multiprocessing/util.py", line 224, in __call__
    res = self._callback(*self._args, **self._kwargs)
  File "/home/jlpkort/anaconda3/lib/python3.8/multiprocessing/util.py", line 133, in _remove_temp_dir
    rmtree(tempdir)
  File "/home/jlpkort/anaconda3/lib/python3.8/shutil.py", line 722, in rmtree
    onerror(os.rmdir, path, sys.exc_info())
  File "/home/jlpkort/anaconda3/lib/python3.8/shutil.py", line 720, in rmtree
    os.rmdir(path)
OSError: [Errno 39] Directory not empty: '/scratch/pymp-76m32mmk'
Traceback (most recent call last):
  File "/home/jlpkort/anaconda3/lib/python3.8/multiprocessing/util.py", line 300, in _run_finalizers
    finalizer()
  File "/home/jlpkort/anaconda3/lib/python3.8/multiprocessing/util.py", line 224, in __call__
    res = self._callback(*self._args, **self._kwargs)
  File "/home/jlpkort/anaconda3/lib/python3.8/multiprocessing/util.py", line 133, in _remove_temp_dir
    rmtree(tempdir)
  File "/home/jlpkort/anaconda3/lib/python3.8/shutil.py", line 722, in rmtree
    onerror(os.rmdir, path, sys.exc_info())
  File "/home/jlpkort/anaconda3/lib/python3.8/shutil.py", line 720, in rmtree
    os.rmdir(path)
OSError: [Errno 39] Directory not empty: '/scratch/pymp-ew614nj2'
Traceback (most recent call last):
  File "/home/jlpkort/anaconda3/lib/python3.8/multiprocessing/util.py", line 300, in _run_finalizers
    finalizer()
  File "/home/jlpkort/anaconda3/lib/python3.8/multiprocessing/util.py", line 224, in __call__
    res = self._callback(*self._args, **self._kwargs)
  File "/home/jlpkort/anaconda3/lib/python3.8/multiprocessing/util.py", line 133, in _remove_temp_dir
    rmtree(tempdir)
  File "/home/jlpkort/anaconda3/lib/python3.8/shutil.py", line 722, in rmtree
    onerror(os.rmdir, path, sys.exc_info())
  File "/home/jlpkort/anaconda3/lib/python3.8/shutil.py", line 720, in rmtree
    os.rmdir(path)
OSError: [Errno 39] Directory not empty: '/scratch/pymp-yswc93fd'
I0917 14:17:43.429328 9752 trainer.py:117]  [Step: 10500/15000 (70.0%)] D Loss: -2.4897336959838867 M Loss: 1.353908896446228 G Loss: 0.08193567395210266 
Traceback (most recent call last):
  File "/home/jlpkort/anaconda3/lib/python3.8/multiprocessing/util.py", line 300, in _run_finalizers
    finalizer()
  File "/home/jlpkort/anaconda3/lib/python3.8/multiprocessing/util.py", line 224, in __call__
    res = self._callback(*self._args, **self._kwargs)
  File "/home/jlpkort/anaconda3/lib/python3.8/multiprocessing/util.py", line 133, in _remove_temp_dir
    rmtree(tempdir)
  File "/home/jlpkort/anaconda3/lib/python3.8/shutil.py", line 722, in rmtree
    onerror(os.rmdir, path, sys.exc_info())
  File "/home/jlpkort/anaconda3/lib/python3.8/shutil.py", line 720, in rmtree
    os.rmdir(path)
OSError: [Errno 39] Directory not empty: '/scratch/pymp-0nalclvu'
Traceback (most recent call last):
  File "/home/jlpkort/anaconda3/lib/python3.8/multiprocessing/util.py", line 300, in _run_finalizers
    finalizer()
  File "/home/jlpkort/anaconda3/lib/python3.8/multiprocessing/util.py", line 224, in __call__
    res = self._callback(*self._args, **self._kwargs)
  File "/home/jlpkort/anaconda3/lib/python3.8/multiprocessing/util.py", line 133, in _remove_temp_dir
    rmtree(tempdir)
  File "/home/jlpkort/anaconda3/lib/python3.8/shutil.py", line 722, in rmtree
    onerror(os.rmdir, path, sys.exc_info())
  File "/home/jlpkort/anaconda3/lib/python3.8/shutil.py", line 720, in rmtree
    os.rmdir(path)
OSError: [Errno 39] Directory not empty: '/scratch/pymp-znk6_uhf'
Traceback (most recent call last):
  File "/home/jlpkort/anaconda3/lib/python3.8/multiprocessing/util.py", line 300, in _run_finalizers
    finalizer()
  File "/home/jlpkort/anaconda3/lib/python3.8/multiprocessing/util.py", line 224, in __call__
    res = self._callback(*self._args, **self._kwargs)
  File "/home/jlpkort/anaconda3/lib/python3.8/multiprocessing/util.py", line 133, in _remove_temp_dir
    rmtree(tempdir)
  File "/home/jlpkort/anaconda3/lib/python3.8/shutil.py", line 722, in rmtree
    onerror(os.rmdir, path, sys.exc_info())
  File "/home/jlpkort/anaconda3/lib/python3.8/shutil.py", line 720, in rmtree
    os.rmdir(path)
OSError: [Errno 39] Directory not empty: '/scratch/pymp-jth5kc0v'
I0917 14:57:38.733579 9752 trainer.py:117]  [Step: 11000/15000 (73.33333333333333%)] D Loss: -1.2872693538665771 M Loss: 1.3793349266052246 G Loss: -0.08252096176147461 
Traceback (most recent call last):
  File "/home/jlpkort/anaconda3/lib/python3.8/multiprocessing/util.py", line 300, in _run_finalizers
    finalizer()
  File "/home/jlpkort/anaconda3/lib/python3.8/multiprocessing/util.py", line 224, in __call__
    res = self._callback(*self._args, **self._kwargs)
  File "/home/jlpkort/anaconda3/lib/python3.8/multiprocessing/util.py", line 133, in _remove_temp_dir
    rmtree(tempdir)
  File "/home/jlpkort/anaconda3/lib/python3.8/shutil.py", line 722, in rmtree
    onerror(os.rmdir, path, sys.exc_info())
  File "/home/jlpkort/anaconda3/lib/python3.8/shutil.py", line 720, in rmtree
    os.rmdir(path)
OSError: [Errno 39] Directory not empty: '/scratch/pymp-xbhjt9da'
Traceback (most recent call last):
  File "/home/jlpkort/anaconda3/lib/python3.8/multiprocessing/util.py", line 300, in _run_finalizers
    finalizer()
  File "/home/jlpkort/anaconda3/lib/python3.8/multiprocessing/util.py", line 224, in __call__
    res = self._callback(*self._args, **self._kwargs)
  File "/home/jlpkort/anaconda3/lib/python3.8/multiprocessing/util.py", line 133, in _remove_temp_dir
    rmtree(tempdir)
  File "/home/jlpkort/anaconda3/lib/python3.8/shutil.py", line 722, in rmtree
    onerror(os.rmdir, path, sys.exc_info())
  File "/home/jlpkort/anaconda3/lib/python3.8/shutil.py", line 720, in rmtree
    os.rmdir(path)
OSError: [Errno 39] Directory not empty: '/scratch/pymp-8c8ifgrw'
I0917 15:37:45.036556 9752 trainer.py:117]  [Step: 11500/15000 (76.66666666666667%)] D Loss: -8.505838394165039 M Loss: 1.354987621307373 G Loss: 0.06221640110015869 
Traceback (most recent call last):
  File "/home/jlpkort/anaconda3/lib/python3.8/multiprocessing/util.py", line 300, in _run_finalizers
    finalizer()
  File "/home/jlpkort/anaconda3/lib/python3.8/multiprocessing/util.py", line 224, in __call__
    res = self._callback(*self._args, **self._kwargs)
  File "/home/jlpkort/anaconda3/lib/python3.8/multiprocessing/util.py", line 133, in _remove_temp_dir
    rmtree(tempdir)
  File "/home/jlpkort/anaconda3/lib/python3.8/shutil.py", line 722, in rmtree
    onerror(os.rmdir, path, sys.exc_info())
  File "/home/jlpkort/anaconda3/lib/python3.8/shutil.py", line 720, in rmtree
    os.rmdir(path)
OSError: [Errno 39] Directory not empty: '/scratch/pymp-oile4qg5'
I0917 16:17:46.726399 9752 trainer.py:117]  [Step: 12000/15000 (80.0%)] D Loss: -1.2230311632156372 M Loss: 1.344368815422058 G Loss: -0.03624087572097778 
Traceback (most recent call last):
  File "/home/jlpkort/anaconda3/lib/python3.8/multiprocessing/util.py", line 300, in _run_finalizers
    finalizer()
  File "/home/jlpkort/anaconda3/lib/python3.8/multiprocessing/util.py", line 224, in __call__
    res = self._callback(*self._args, **self._kwargs)
  File "/home/jlpkort/anaconda3/lib/python3.8/multiprocessing/util.py", line 133, in _remove_temp_dir
    rmtree(tempdir)
  File "/home/jlpkort/anaconda3/lib/python3.8/shutil.py", line 722, in rmtree
    onerror(os.rmdir, path, sys.exc_info())
  File "/home/jlpkort/anaconda3/lib/python3.8/shutil.py", line 720, in rmtree
    os.rmdir(path)
OSError: [Errno 39] Directory not empty: '/scratch/pymp-9jvg7pws'
Traceback (most recent call last):
  File "/home/jlpkort/anaconda3/lib/python3.8/multiprocessing/util.py", line 300, in _run_finalizers
    finalizer()
  File "/home/jlpkort/anaconda3/lib/python3.8/multiprocessing/util.py", line 224, in __call__
    res = self._callback(*self._args, **self._kwargs)
  File "/home/jlpkort/anaconda3/lib/python3.8/multiprocessing/util.py", line 133, in _remove_temp_dir
    rmtree(tempdir)
  File "/home/jlpkort/anaconda3/lib/python3.8/shutil.py", line 722, in rmtree
    onerror(os.rmdir, path, sys.exc_info())
  File "/home/jlpkort/anaconda3/lib/python3.8/shutil.py", line 720, in rmtree
    os.rmdir(path)
OSError: [Errno 39] Directory not empty: '/scratch/pymp-pu8h8f9k'
Traceback (most recent call last):
  File "/home/jlpkort/anaconda3/lib/python3.8/multiprocessing/util.py", line 300, in _run_finalizers
    finalizer()
  File "/home/jlpkort/anaconda3/lib/python3.8/multiprocessing/util.py", line 224, in __call__
    res = self._callback(*self._args, **self._kwargs)
  File "/home/jlpkort/anaconda3/lib/python3.8/multiprocessing/util.py", line 133, in _remove_temp_dir
    rmtree(tempdir)
  File "/home/jlpkort/anaconda3/lib/python3.8/shutil.py", line 722, in rmtree
    onerror(os.rmdir, path, sys.exc_info())
  File "/home/jlpkort/anaconda3/lib/python3.8/shutil.py", line 720, in rmtree
    os.rmdir(path)
OSError: [Errno 39] Directory not empty: '/scratch/pymp-2of7bbnx'
I0917 16:57:47.796725 9752 trainer.py:117]  [Step: 12500/15000 (83.33333333333333%)] D Loss: 0.25883305072784424 M Loss: 1.3668545484542847 G Loss: -0.041217148303985596 
Traceback (most recent call last):
  File "/home/jlpkort/anaconda3/lib/python3.8/multiprocessing/util.py", line 300, in _run_finalizers
    finalizer()
  File "/home/jlpkort/anaconda3/lib/python3.8/multiprocessing/util.py", line 224, in __call__
    res = self._callback(*self._args, **self._kwargs)
  File "/home/jlpkort/anaconda3/lib/python3.8/multiprocessing/util.py", line 133, in _remove_temp_dir
    rmtree(tempdir)
  File "/home/jlpkort/anaconda3/lib/python3.8/shutil.py", line 722, in rmtree
    onerror(os.rmdir, path, sys.exc_info())
  File "/home/jlpkort/anaconda3/lib/python3.8/shutil.py", line 720, in rmtree
    os.rmdir(path)
OSError: [Errno 39] Directory not empty: '/scratch/pymp-vqvgywa9'
I0917 17:37:51.780519 9752 trainer.py:117]  [Step: 13000/15000 (86.66666666666667%)] D Loss: -4.665205478668213 M Loss: 1.3788906335830688 G Loss: 0.022716224193572998 
Traceback (most recent call last):
  File "/home/jlpkort/anaconda3/lib/python3.8/multiprocessing/util.py", line 300, in _run_finalizers
    finalizer()
  File "/home/jlpkort/anaconda3/lib/python3.8/multiprocessing/util.py", line 224, in __call__
    res = self._callback(*self._args, **self._kwargs)
  File "/home/jlpkort/anaconda3/lib/python3.8/multiprocessing/util.py", line 133, in _remove_temp_dir
    rmtree(tempdir)
  File "/home/jlpkort/anaconda3/lib/python3.8/shutil.py", line 722, in rmtree
    onerror(os.rmdir, path, sys.exc_info())
  File "/home/jlpkort/anaconda3/lib/python3.8/shutil.py", line 720, in rmtree
    os.rmdir(path)
OSError: [Errno 39] Directory not empty: '/scratch/pymp-13ef3j0m'
Traceback (most recent call last):
  File "/home/jlpkort/anaconda3/lib/python3.8/multiprocessing/util.py", line 300, in _run_finalizers
    finalizer()
  File "/home/jlpkort/anaconda3/lib/python3.8/multiprocessing/util.py", line 224, in __call__
    res = self._callback(*self._args, **self._kwargs)
  File "/home/jlpkort/anaconda3/lib/python3.8/multiprocessing/util.py", line 133, in _remove_temp_dir
    rmtree(tempdir)
  File "/home/jlpkort/anaconda3/lib/python3.8/shutil.py", line 722, in rmtree
    onerror(os.rmdir, path, sys.exc_info())
  File "/home/jlpkort/anaconda3/lib/python3.8/shutil.py", line 720, in rmtree
    os.rmdir(path)
OSError: [Errno 39] Directory not empty: '/scratch/pymp-va42bovo'
Traceback (most recent call last):
  File "/home/jlpkort/anaconda3/lib/python3.8/multiprocessing/util.py", line 300, in _run_finalizers
    finalizer()
  File "/home/jlpkort/anaconda3/lib/python3.8/multiprocessing/util.py", line 224, in __call__
    res = self._callback(*self._args, **self._kwargs)
  File "/home/jlpkort/anaconda3/lib/python3.8/multiprocessing/util.py", line 133, in _remove_temp_dir
    rmtree(tempdir)
  File "/home/jlpkort/anaconda3/lib/python3.8/shutil.py", line 722, in rmtree
    onerror(os.rmdir, path, sys.exc_info())
  File "/home/jlpkort/anaconda3/lib/python3.8/shutil.py", line 720, in rmtree
    os.rmdir(path)
OSError: [Errno 39] Directory not empty: '/scratch/pymp-xckrw3w2'
Traceback (most recent call last):
  File "/home/jlpkort/anaconda3/lib/python3.8/multiprocessing/util.py", line 300, in _run_finalizers
    finalizer()
  File "/home/jlpkort/anaconda3/lib/python3.8/multiprocessing/util.py", line 224, in __call__
    res = self._callback(*self._args, **self._kwargs)
  File "/home/jlpkort/anaconda3/lib/python3.8/multiprocessing/util.py", line 133, in _remove_temp_dir
    rmtree(tempdir)
  File "/home/jlpkort/anaconda3/lib/python3.8/shutil.py", line 722, in rmtree
    onerror(os.rmdir, path, sys.exc_info())
  File "/home/jlpkort/anaconda3/lib/python3.8/shutil.py", line 720, in rmtree
    os.rmdir(path)
OSError: [Errno 39] Directory not empty: '/scratch/pymp-ekh0kd_m'
Traceback (most recent call last):
  File "/home/jlpkort/anaconda3/lib/python3.8/multiprocessing/util.py", line 300, in _run_finalizers
    finalizer()
  File "/home/jlpkort/anaconda3/lib/python3.8/multiprocessing/util.py", line 224, in __call__
    res = self._callback(*self._args, **self._kwargs)
  File "/home/jlpkort/anaconda3/lib/python3.8/multiprocessing/util.py", line 133, in _remove_temp_dir
    rmtree(tempdir)
  File "/home/jlpkort/anaconda3/lib/python3.8/shutil.py", line 722, in rmtree
    onerror(os.rmdir, path, sys.exc_info())
  File "/home/jlpkort/anaconda3/lib/python3.8/shutil.py", line 720, in rmtree
    os.rmdir(path)
OSError: [Errno 39] Directory not empty: '/scratch/pymp-2s6igr02'
I0917 18:18:56.804210 9752 trainer.py:117]  [Step: 13500/15000 (90.0%)] D Loss: 4.975625038146973 M Loss: 1.378319501876831 G Loss: -0.11464762687683105 
Traceback (most recent call last):
  File "/home/jlpkort/anaconda3/lib/python3.8/multiprocessing/util.py", line 300, in _run_finalizers
    finalizer()
  File "/home/jlpkort/anaconda3/lib/python3.8/multiprocessing/util.py", line 224, in __call__
    res = self._callback(*self._args, **self._kwargs)
  File "/home/jlpkort/anaconda3/lib/python3.8/multiprocessing/util.py", line 133, in _remove_temp_dir
    rmtree(tempdir)
  File "/home/jlpkort/anaconda3/lib/python3.8/shutil.py", line 722, in rmtree
    onerror(os.rmdir, path, sys.exc_info())
  File "/home/jlpkort/anaconda3/lib/python3.8/shutil.py", line 720, in rmtree
    os.rmdir(path)
OSError: [Errno 39] Directory not empty: '/scratch/pymp-k8264i97'
Traceback (most recent call last):
  File "/home/jlpkort/anaconda3/lib/python3.8/multiprocessing/util.py", line 300, in _run_finalizers
    finalizer()
  File "/home/jlpkort/anaconda3/lib/python3.8/multiprocessing/util.py", line 224, in __call__
    res = self._callback(*self._args, **self._kwargs)
  File "/home/jlpkort/anaconda3/lib/python3.8/multiprocessing/util.py", line 133, in _remove_temp_dir
    rmtree(tempdir)
  File "/home/jlpkort/anaconda3/lib/python3.8/shutil.py", line 722, in rmtree
    onerror(os.rmdir, path, sys.exc_info())
  File "/home/jlpkort/anaconda3/lib/python3.8/shutil.py", line 720, in rmtree
    os.rmdir(path)
OSError: [Errno 39] Directory not empty: '/scratch/pymp-bejgn5s9'
I0917 19:00:04.491769 9752 trainer.py:117]  [Step: 14000/15000 (93.33333333333333%)] D Loss: -4.704526901245117 M Loss: 1.3693082332611084 G Loss: 0.023889482021331787 
Traceback (most recent call last):
  File "/home/jlpkort/anaconda3/lib/python3.8/multiprocessing/util.py", line 300, in _run_finalizers
    finalizer()
  File "/home/jlpkort/anaconda3/lib/python3.8/multiprocessing/util.py", line 224, in __call__
    res = self._callback(*self._args, **self._kwargs)
  File "/home/jlpkort/anaconda3/lib/python3.8/multiprocessing/util.py", line 133, in _remove_temp_dir
    rmtree(tempdir)
  File "/home/jlpkort/anaconda3/lib/python3.8/shutil.py", line 722, in rmtree
    onerror(os.rmdir, path, sys.exc_info())
  File "/home/jlpkort/anaconda3/lib/python3.8/shutil.py", line 720, in rmtree
    os.rmdir(path)
OSError: [Errno 39] Directory not empty: '/scratch/pymp-qfhwh9u_'
Traceback (most recent call last):
  File "/home/jlpkort/anaconda3/lib/python3.8/multiprocessing/util.py", line 300, in _run_finalizers
    finalizer()
  File "/home/jlpkort/anaconda3/lib/python3.8/multiprocessing/util.py", line 224, in __call__
    res = self._callback(*self._args, **self._kwargs)
  File "/home/jlpkort/anaconda3/lib/python3.8/multiprocessing/util.py", line 133, in _remove_temp_dir
    rmtree(tempdir)
  File "/home/jlpkort/anaconda3/lib/python3.8/shutil.py", line 722, in rmtree
    onerror(os.rmdir, path, sys.exc_info())
  File "/home/jlpkort/anaconda3/lib/python3.8/shutil.py", line 720, in rmtree
    os.rmdir(path)
OSError: [Errno 39] Directory not empty: '/scratch/pymp-8y3g12jg'
Traceback (most recent call last):
  File "/home/jlpkort/anaconda3/lib/python3.8/multiprocessing/util.py", line 300, in _run_finalizers
    finalizer()
  File "/home/jlpkort/anaconda3/lib/python3.8/multiprocessing/util.py", line 224, in __call__
    res = self._callback(*self._args, **self._kwargs)
  File "/home/jlpkort/anaconda3/lib/python3.8/multiprocessing/util.py", line 133, in _remove_temp_dir
    rmtree(tempdir)
  File "/home/jlpkort/anaconda3/lib/python3.8/shutil.py", line 722, in rmtree
    onerror(os.rmdir, path, sys.exc_info())
  File "/home/jlpkort/anaconda3/lib/python3.8/shutil.py", line 720, in rmtree
    os.rmdir(path)
OSError: [Errno 39] Directory not empty: '/scratch/pymp-zuobs0qy'
I0917 19:41:11.560081 9752 trainer.py:117]  [Step: 14500/15000 (96.66666666666667%)] D Loss: -3.847076892852783 M Loss: 1.3819791078567505 G Loss: -0.013775378465652466 
Traceback (most recent call last):
  File "/home/jlpkort/anaconda3/lib/python3.8/multiprocessing/util.py", line 300, in _run_finalizers
    finalizer()
  File "/home/jlpkort/anaconda3/lib/python3.8/multiprocessing/util.py", line 224, in __call__
    res = self._callback(*self._args, **self._kwargs)
  File "/home/jlpkort/anaconda3/lib/python3.8/multiprocessing/util.py", line 133, in _remove_temp_dir
    rmtree(tempdir)
  File "/home/jlpkort/anaconda3/lib/python3.8/shutil.py", line 722, in rmtree
    onerror(os.rmdir, path, sys.exc_info())
  File "/home/jlpkort/anaconda3/lib/python3.8/shutil.py", line 720, in rmtree
    os.rmdir(path)
OSError: [Errno 39] Directory not empty: '/scratch/pymp-n2houywj'
Traceback (most recent call last):
  File "/home/jlpkort/anaconda3/lib/python3.8/multiprocessing/util.py", line 300, in _run_finalizers
    finalizer()
  File "/home/jlpkort/anaconda3/lib/python3.8/multiprocessing/util.py", line 224, in __call__
    res = self._callback(*self._args, **self._kwargs)
  File "/home/jlpkort/anaconda3/lib/python3.8/multiprocessing/util.py", line 133, in _remove_temp_dir
    rmtree(tempdir)
  File "/home/jlpkort/anaconda3/lib/python3.8/shutil.py", line 722, in rmtree
    onerror(os.rmdir, path, sys.exc_info())
  File "/home/jlpkort/anaconda3/lib/python3.8/shutil.py", line 720, in rmtree
    os.rmdir(path)
OSError: [Errno 39] Directory not empty: '/scratch/pymp-hnft_wxa'
Traceback (most recent call last):
  File "/home/jlpkort/anaconda3/lib/python3.8/multiprocessing/util.py", line 300, in _run_finalizers
    finalizer()
  File "/home/jlpkort/anaconda3/lib/python3.8/multiprocessing/util.py", line 224, in __call__
    res = self._callback(*self._args, **self._kwargs)
  File "/home/jlpkort/anaconda3/lib/python3.8/multiprocessing/util.py", line 133, in _remove_temp_dir
    rmtree(tempdir)
  File "/home/jlpkort/anaconda3/lib/python3.8/shutil.py", line 722, in rmtree
    onerror(os.rmdir, path, sys.exc_info())
  File "/home/jlpkort/anaconda3/lib/python3.8/shutil.py", line 720, in rmtree
    os.rmdir(path)
OSError: [Errno 39] Directory not empty: '/scratch/pymp-vadch72p'
Traceback (most recent call last):
  File "/home/jlpkort/anaconda3/lib/python3.8/multiprocessing/util.py", line 300, in _run_finalizers
    finalizer()
  File "/home/jlpkort/anaconda3/lib/python3.8/multiprocessing/util.py", line 224, in __call__
    res = self._callback(*self._args, **self._kwargs)
  File "/home/jlpkort/anaconda3/lib/python3.8/multiprocessing/util.py", line 133, in _remove_temp_dir
    rmtree(tempdir)
  File "/home/jlpkort/anaconda3/lib/python3.8/shutil.py", line 722, in rmtree
    onerror(os.rmdir, path, sys.exc_info())
  File "/home/jlpkort/anaconda3/lib/python3.8/shutil.py", line 720, in rmtree
    os.rmdir(path)
OSError: [Errno 39] Directory not empty: '/scratch/pymp-u2qonn_v'
Traceback (most recent call last):
  File "/home/jlpkort/anaconda3/lib/python3.8/multiprocessing/util.py", line 300, in _run_finalizers
    finalizer()
  File "/home/jlpkort/anaconda3/lib/python3.8/multiprocessing/util.py", line 224, in __call__
    res = self._callback(*self._args, **self._kwargs)
  File "/home/jlpkort/anaconda3/lib/python3.8/multiprocessing/util.py", line 133, in _remove_temp_dir
    rmtree(tempdir)
  File "/home/jlpkort/anaconda3/lib/python3.8/shutil.py", line 722, in rmtree
    onerror(os.rmdir, path, sys.exc_info())
  File "/home/jlpkort/anaconda3/lib/python3.8/shutil.py", line 720, in rmtree
    os.rmdir(path)
OSError: [Errno 39] Directory not empty: '/scratch/pymp-bjrs94na'
I0917 20:22:14.599617 9752 trainer.py:117]  [Step: 15000/15000 (100.0%)] D Loss: -1.510546088218689 M Loss: 1.3215022087097168 G Loss: 0.04307365417480469 
wandb: Waiting for W&B process to finish, PID 9785
wandb: Program ended successfully.
wandb: - 6.86MB of 6.86MB uploaded (0.00MB deduped)wandb: \ 6.86MB of 6.86MB uploaded (0.00MB deduped)wandb: | 6.86MB of 6.86MB uploaded (0.00MB deduped)wandb: / 6.86MB of 6.94MB uploaded (0.00MB deduped)wandb: - 6.86MB of 6.94MB uploaded (0.00MB deduped)wandb: \ 6.94MB of 6.94MB uploaded (0.00MB deduped)wandb: | 6.94MB of 6.94MB uploaded (0.00MB deduped)wandb: / 6.94MB of 6.94MB uploaded (0.00MB deduped)wandb: - 6.94MB of 6.94MB uploaded (0.00MB deduped)wandb: \ 6.94MB of 6.94MB uploaded (0.00MB deduped)wandb: | 6.94MB of 6.94MB uploaded (0.00MB deduped)wandb: / 6.94MB of 6.94MB uploaded (0.00MB deduped)wandb: - 6.94MB of 6.94MB uploaded (0.00MB deduped)wandb:                                                                                
wandb: Find user logs for this run at: /home/jlpkort/vcnet-blind-image-inpainting/wandb/run-20210917_001123-14udsw8v/logs/debug.log
wandb: Find internal logs for this run at: /home/jlpkort/vcnet-blind-image-inpainting/wandb/run-20210917_001123-14udsw8v/logs/debug-internal.log
wandb: Run summary:
wandb:   real_global_validity -223.73451
wandb:   fake_global_validity 221.79794
wandb:    real_patch_validity -120.55215
wandb:    fake_patch_validity 120.23272
wandb:              gp_global 0.04851
wandb:                gp_fake 0.02604
wandb:          real_validity -344.28668
wandb:          fake_validity 342.03067
wandb:                     gp 0.07455
wandb:                 m_loss 1.3215
wandb:             recon_loss 0.02711
wandb:         sem_const_loss 0.20026
wandb:         tex_const_loss 3.45252
wandb:        adv_global_loss -221.56732
wandb:         adv_patch_loss -120.56915
wandb:               adv_loss -342.13647
wandb:               _runtime 72651
wandb:             _timestamp 1631902934
wandb:                  _step 14999
wandb: Synced 6 W&B file(s), 180 media file(s), 0 artifact file(s) and 0 other file(s)
wandb: 
wandb: Synced classic-butterfly-162: https://wandb.ai/tijmenk_/thesis_pytorch/runs/14udsw8v

