Looking in links: https://download.pytorch.org/whl/torch_stable.html
Requirement already satisfied: torch==1.5.0+cu101 in /home/jlpkort/anaconda3/lib/python3.8/site-packages (1.5.0+cu101)
Requirement already satisfied: torchvision==0.6.0+cu101 in /home/jlpkort/anaconda3/lib/python3.8/site-packages (0.6.0+cu101)
Requirement already satisfied: numpy in /home/jlpkort/anaconda3/lib/python3.8/site-packages (from torch==1.5.0+cu101) (1.17.4)
Requirement already satisfied: future in /home/jlpkort/anaconda3/lib/python3.8/site-packages (from torch==1.5.0+cu101) (0.18.2)
Requirement already satisfied: pillow>=4.1.1 in /home/jlpkort/anaconda3/lib/python3.8/site-packages (from torchvision==0.6.0+cu101) (8.2.0)
ERROR: Could not find a version that satisfies the requirement opencv_contrib_python_nonfree==4.1.1.1
ERROR: No matching distribution found for opencv_contrib_python_nonfree==4.1.1.1
wandb: Currently logged in as: tijmenk_ (use `wandb login --relogin` to force relogin)
DATASET:
  MASKS: ./datasets/masks_tv_256
  NAME: TVB
  ROOT: ./datasets/data_256
  SIZE_H: 256
  SIZE_W: 256
MODEL:
  D:
    BETAS: (0.9, 0.99)
    LR: 1e-05
    NAME: 1-ChOutputDiscriminator
    NUM_CHANNELS: 64
    NUM_CRITICS: 5
  IS_TRAIN: True
  JOINT:
    BETAS: (0.9, 0.99)
    LR: 0.0002
    NAME: JointNetwork
  MPN:
    BETAS: (0.9, 0.99)
    LOSS_COEFF: 1.0
    LR: 1e-05
    NAME: MaskPredictionNetwork
    NECK_CHANNELS: 128
    NUM_CHANNELS: 64
  NAME: VCNet
  RIN:
    BETAS: (0.9, 0.99)
    EMBRACE: True
    LOSS_COEFF: 2.0
    LR: 1e-06
    NAME: RobustInpaintingNetwork
    NECK_CHANNELS: 128
    NUM_CHANNELS: 32
OPTIM:
  ADVERSARIAL: 0.001
  GP: 10
  MASK: 1
  RECON: 1.4
  SEMANTIC: 0.01
  TEXTURE: 0.1
SYSTEM:
  NUM_GPU: 4
  NUM_WORKERS: 16
TEST:
  ABLATION: False
  BATCH_SIZE: 64
  C_IMG_ID: 38
  IMG_ID: 52
  ITER: 4
  MODE: 1
  OUTPUT_DIR: ./outputs
  WEIGHTS: ./weights/VCNet_TVB_100000step_4bs_0.0002lr_4gpu_16run/checkpoint-30000.pth
TRAIN:
  BATCH_SIZE: 4
  LOG_INTERVAL: 500
  NUM_STEPS_FOR_JOINT: 6600
  NUM_TOTAL_STEP: 15000
  RESUME: False
  SAVE_DIR: ./weights
  SAVE_INTERVAL: 5000
  SHUFFLE: True
  START_STEP: 0
  TUNE: False
  VISUALIZE_INTERVAL: 500
WANDB:
  ENTITY: tijmenk_
  LOG_DIR: 
  NUM_ROW: 0
  PROJECT_NAME: thesis_pytorch
  RUN: 16
wandb: wandb version 0.12.2 is available!  To upgrade, please run:
wandb:  $ pip install wandb --upgrade
wandb: Tracking run with wandb version 0.11.0
wandb: Syncing run unique-sun-159
wandb:  View project at https://wandb.ai/tijmenk_/thesis_pytorch
wandb:  View run at https://wandb.ai/tijmenk_/thesis_pytorch/runs/1kibe3op
wandb: Run data is saved locally in /home/jlpkort/vcnet-blind-image-inpainting/wandb/run-20210916_171908-1kibe3op
wandb: Run `wandb offline` to turn off syncing.
I0916 17:19:16.110530 3306 trainer.py:244] Using 4 GPUs...

Traceback (most recent call last):
  File "/home/jlpkort/anaconda3/lib/python3.8/multiprocessing/util.py", line 300, in _run_finalizers
    finalizer()
  File "/home/jlpkort/anaconda3/lib/python3.8/multiprocessing/util.py", line 224, in __call__
    res = self._callback(*self._args, **self._kwargs)
  File "/home/jlpkort/anaconda3/lib/python3.8/multiprocessing/util.py", line 133, in _remove_temp_dir
    rmtree(tempdir)
  File "/home/jlpkort/anaconda3/lib/python3.8/shutil.py", line 722, in rmtree
    onerror(os.rmdir, path, sys.exc_info())
  File "/home/jlpkort/anaconda3/lib/python3.8/shutil.py", line 720, in rmtree
    os.rmdir(path)
OSError: [Errno 39] Directory not empty: '/scratch/pymp-_7mvvdcj'
Traceback (most recent call last):
  File "/home/jlpkort/anaconda3/lib/python3.8/multiprocessing/util.py", line 300, in _run_finalizers
    finalizer()
  File "/home/jlpkort/anaconda3/lib/python3.8/multiprocessing/util.py", line 224, in __call__
    res = self._callback(*self._args, **self._kwargs)
  File "/home/jlpkort/anaconda3/lib/python3.8/multiprocessing/util.py", line 133, in _remove_temp_dir
    rmtree(tempdir)
  File "/home/jlpkort/anaconda3/lib/python3.8/shutil.py", line 722, in rmtree
    onerror(os.rmdir, path, sys.exc_info())
  File "/home/jlpkort/anaconda3/lib/python3.8/shutil.py", line 720, in rmtree
    os.rmdir(path)
OSError: [Errno 39] Directory not empty: '/scratch/pymp-g2zcvymt'
I0916 17:58:48.611813 3306 trainer.py:117]  [Step: 500/15000 (3.3333333333333335%)] D Loss: -480.8902282714844 M Loss: 1.342363715171814 G Loss: -1.1067883968353271 
Traceback (most recent call last):
  File "/home/jlpkort/anaconda3/lib/python3.8/multiprocessing/util.py", line 300, in _run_finalizers
    finalizer()
  File "/home/jlpkort/anaconda3/lib/python3.8/multiprocessing/util.py", line 224, in __call__
    res = self._callback(*self._args, **self._kwargs)
  File "/home/jlpkort/anaconda3/lib/python3.8/multiprocessing/util.py", line 133, in _remove_temp_dir
    rmtree(tempdir)
  File "/home/jlpkort/anaconda3/lib/python3.8/shutil.py", line 722, in rmtree
    onerror(os.rmdir, path, sys.exc_info())
  File "/home/jlpkort/anaconda3/lib/python3.8/shutil.py", line 720, in rmtree
    os.rmdir(path)
OSError: [Errno 39] Directory not empty: '/scratch/pymp-w1fmicep'
Traceback (most recent call last):
  File "/home/jlpkort/anaconda3/lib/python3.8/multiprocessing/util.py", line 300, in _run_finalizers
    finalizer()
  File "/home/jlpkort/anaconda3/lib/python3.8/multiprocessing/util.py", line 224, in __call__
    res = self._callback(*self._args, **self._kwargs)
  File "/home/jlpkort/anaconda3/lib/python3.8/multiprocessing/util.py", line 133, in _remove_temp_dir
    rmtree(tempdir)
  File "/home/jlpkort/anaconda3/lib/python3.8/shutil.py", line 722, in rmtree
    onerror(os.rmdir, path, sys.exc_info())
  File "/home/jlpkort/anaconda3/lib/python3.8/shutil.py", line 720, in rmtree
    os.rmdir(path)
OSError: [Errno 39] Directory not empty: '/scratch/pymp-dn8k1fb7'
Traceback (most recent call last):
  File "/home/jlpkort/anaconda3/lib/python3.8/multiprocessing/util.py", line 300, in _run_finalizers
    finalizer()
  File "/home/jlpkort/anaconda3/lib/python3.8/multiprocessing/util.py", line 224, in __call__
    res = self._callback(*self._args, **self._kwargs)
  File "/home/jlpkort/anaconda3/lib/python3.8/multiprocessing/util.py", line 133, in _remove_temp_dir
    rmtree(tempdir)
  File "/home/jlpkort/anaconda3/lib/python3.8/shutil.py", line 722, in rmtree
    onerror(os.rmdir, path, sys.exc_info())
  File "/home/jlpkort/anaconda3/lib/python3.8/shutil.py", line 720, in rmtree
    os.rmdir(path)
OSError: [Errno 39] Directory not empty: '/scratch/pymp-5hpl300q'
I0916 18:38:50.078142 3306 trainer.py:117]  [Step: 1000/15000 (6.666666666666667%)] D Loss: -123.51685333251953 M Loss: 1.390870213508606 G Loss: 0.9930223226547241 
Traceback (most recent call last):
  File "/home/jlpkort/anaconda3/lib/python3.8/multiprocessing/util.py", line 300, in _run_finalizers
    finalizer()
  File "/home/jlpkort/anaconda3/lib/python3.8/multiprocessing/util.py", line 224, in __call__
    res = self._callback(*self._args, **self._kwargs)
  File "/home/jlpkort/anaconda3/lib/python3.8/multiprocessing/util.py", line 133, in _remove_temp_dir
    rmtree(tempdir)
  File "/home/jlpkort/anaconda3/lib/python3.8/shutil.py", line 722, in rmtree
    onerror(os.rmdir, path, sys.exc_info())
  File "/home/jlpkort/anaconda3/lib/python3.8/shutil.py", line 720, in rmtree
    os.rmdir(path)
OSError: [Errno 39] Directory not empty: '/scratch/pymp-gwvocv1x'
Traceback (most recent call last):
  File "/home/jlpkort/anaconda3/lib/python3.8/multiprocessing/util.py", line 300, in _run_finalizers
    finalizer()
  File "/home/jlpkort/anaconda3/lib/python3.8/multiprocessing/util.py", line 224, in __call__
    res = self._callback(*self._args, **self._kwargs)
  File "/home/jlpkort/anaconda3/lib/python3.8/multiprocessing/util.py", line 133, in _remove_temp_dir
    rmtree(tempdir)
  File "/home/jlpkort/anaconda3/lib/python3.8/shutil.py", line 722, in rmtree
    onerror(os.rmdir, path, sys.exc_info())
  File "/home/jlpkort/anaconda3/lib/python3.8/shutil.py", line 720, in rmtree
    os.rmdir(path)
OSError: [Errno 39] Directory not empty: '/scratch/pymp-3mb6nvfn'
I0916 19:19:13.811976 3306 trainer.py:117]  [Step: 1500/15000 (10.0%)] D Loss: -156.4262237548828 M Loss: 1.3109360933303833 G Loss: 0.32728302478790283 
Traceback (most recent call last):
  File "/home/jlpkort/anaconda3/lib/python3.8/multiprocessing/util.py", line 300, in _run_finalizers
    finalizer()
  File "/home/jlpkort/anaconda3/lib/python3.8/multiprocessing/util.py", line 224, in __call__
    res = self._callback(*self._args, **self._kwargs)
  File "/home/jlpkort/anaconda3/lib/python3.8/multiprocessing/util.py", line 133, in _remove_temp_dir
    rmtree(tempdir)
  File "/home/jlpkort/anaconda3/lib/python3.8/shutil.py", line 722, in rmtree
    onerror(os.rmdir, path, sys.exc_info())
  File "/home/jlpkort/anaconda3/lib/python3.8/shutil.py", line 720, in rmtree
    os.rmdir(path)
OSError: [Errno 39] Directory not empty: '/scratch/pymp-f0dsiq6e'
Traceback (most recent call last):
  File "/home/jlpkort/anaconda3/lib/python3.8/multiprocessing/util.py", line 300, in _run_finalizers
    finalizer()
  File "/home/jlpkort/anaconda3/lib/python3.8/multiprocessing/util.py", line 224, in __call__
    res = self._callback(*self._args, **self._kwargs)
  File "/home/jlpkort/anaconda3/lib/python3.8/multiprocessing/util.py", line 133, in _remove_temp_dir
    rmtree(tempdir)
  File "/home/jlpkort/anaconda3/lib/python3.8/shutil.py", line 722, in rmtree
    onerror(os.rmdir, path, sys.exc_info())
  File "/home/jlpkort/anaconda3/lib/python3.8/shutil.py", line 720, in rmtree
    os.rmdir(path)
OSError: [Errno 39] Directory not empty: '/scratch/pymp-xh_63_xg'
Traceback (most recent call last):
  File "/home/jlpkort/anaconda3/lib/python3.8/multiprocessing/util.py", line 300, in _run_finalizers
    finalizer()
  File "/home/jlpkort/anaconda3/lib/python3.8/multiprocessing/util.py", line 224, in __call__
    res = self._callback(*self._args, **self._kwargs)
  File "/home/jlpkort/anaconda3/lib/python3.8/multiprocessing/util.py", line 133, in _remove_temp_dir
    rmtree(tempdir)
  File "/home/jlpkort/anaconda3/lib/python3.8/shutil.py", line 722, in rmtree
    onerror(os.rmdir, path, sys.exc_info())
  File "/home/jlpkort/anaconda3/lib/python3.8/shutil.py", line 720, in rmtree
    os.rmdir(path)
OSError: [Errno 39] Directory not empty: '/scratch/pymp-4b5li9c2'
I0916 19:59:17.040017 3306 trainer.py:117]  [Step: 2000/15000 (13.333333333333334%)] D Loss: -274.8333740234375 M Loss: 1.3451653718948364 G Loss: -2.250317096710205 
Traceback (most recent call last):
  File "/home/jlpkort/anaconda3/lib/python3.8/multiprocessing/util.py", line 300, in _run_finalizers
    finalizer()
  File "/home/jlpkort/anaconda3/lib/python3.8/multiprocessing/util.py", line 224, in __call__
    res = self._callback(*self._args, **self._kwargs)
  File "/home/jlpkort/anaconda3/lib/python3.8/multiprocessing/util.py", line 133, in _remove_temp_dir
    rmtree(tempdir)
  File "/home/jlpkort/anaconda3/lib/python3.8/shutil.py", line 722, in rmtree
    onerror(os.rmdir, path, sys.exc_info())
  File "/home/jlpkort/anaconda3/lib/python3.8/shutil.py", line 720, in rmtree
    os.rmdir(path)
OSError: [Errno 39] Directory not empty: '/scratch/pymp-_u5o5ug7'
Traceback (most recent call last):
  File "/home/jlpkort/anaconda3/lib/python3.8/multiprocessing/util.py", line 300, in _run_finalizers
    finalizer()
  File "/home/jlpkort/anaconda3/lib/python3.8/multiprocessing/util.py", line 224, in __call__
    res = self._callback(*self._args, **self._kwargs)
  File "/home/jlpkort/anaconda3/lib/python3.8/multiprocessing/util.py", line 133, in _remove_temp_dir
    rmtree(tempdir)
  File "/home/jlpkort/anaconda3/lib/python3.8/shutil.py", line 722, in rmtree
    onerror(os.rmdir, path, sys.exc_info())
  File "/home/jlpkort/anaconda3/lib/python3.8/shutil.py", line 720, in rmtree
    os.rmdir(path)
OSError: [Errno 39] Directory not empty: '/scratch/pymp-kuk6628_'
Traceback (most recent call last):
  File "/home/jlpkort/anaconda3/lib/python3.8/multiprocessing/util.py", line 300, in _run_finalizers
    finalizer()
  File "/home/jlpkort/anaconda3/lib/python3.8/multiprocessing/util.py", line 224, in __call__
    res = self._callback(*self._args, **self._kwargs)
  File "/home/jlpkort/anaconda3/lib/python3.8/multiprocessing/util.py", line 133, in _remove_temp_dir
    rmtree(tempdir)
  File "/home/jlpkort/anaconda3/lib/python3.8/shutil.py", line 722, in rmtree
    onerror(os.rmdir, path, sys.exc_info())
  File "/home/jlpkort/anaconda3/lib/python3.8/shutil.py", line 720, in rmtree
    os.rmdir(path)
OSError: [Errno 39] Directory not empty: '/scratch/pymp-3s6mxq9x'
Traceback (most recent call last):
  File "/home/jlpkort/anaconda3/lib/python3.8/multiprocessing/util.py", line 300, in _run_finalizers
    finalizer()
  File "/home/jlpkort/anaconda3/lib/python3.8/multiprocessing/util.py", line 224, in __call__
    res = self._callback(*self._args, **self._kwargs)
  File "/home/jlpkort/anaconda3/lib/python3.8/multiprocessing/util.py", line 133, in _remove_temp_dir
    rmtree(tempdir)
  File "/home/jlpkort/anaconda3/lib/python3.8/shutil.py", line 722, in rmtree
    onerror(os.rmdir, path, sys.exc_info())
  File "/home/jlpkort/anaconda3/lib/python3.8/shutil.py", line 720, in rmtree
    os.rmdir(path)
OSError: [Errno 39] Directory not empty: '/scratch/pymp-vyacbu5j'
I0916 20:39:29.633703 3306 trainer.py:117]  [Step: 2500/15000 (16.666666666666668%)] D Loss: -142.23101806640625 M Loss: 1.3927621841430664 G Loss: -8.534263610839844 
I0916 21:19:38.460132 3306 trainer.py:117]  [Step: 3000/15000 (20.0%)] D Loss: 3.0522918701171875 M Loss: 1.036960482597351 G Loss: -4.826018810272217 
Traceback (most recent call last):
  File "/home/jlpkort/anaconda3/lib/python3.8/multiprocessing/util.py", line 300, in _run_finalizers
    finalizer()
  File "/home/jlpkort/anaconda3/lib/python3.8/multiprocessing/util.py", line 224, in __call__
    res = self._callback(*self._args, **self._kwargs)
  File "/home/jlpkort/anaconda3/lib/python3.8/multiprocessing/util.py", line 133, in _remove_temp_dir
    rmtree(tempdir)
  File "/home/jlpkort/anaconda3/lib/python3.8/shutil.py", line 722, in rmtree
    onerror(os.rmdir, path, sys.exc_info())
  File "/home/jlpkort/anaconda3/lib/python3.8/shutil.py", line 720, in rmtree
    os.rmdir(path)
OSError: [Errno 39] Directory not empty: '/scratch/pymp-ejk58bxw'
Traceback (most recent call last):
  File "/home/jlpkort/anaconda3/lib/python3.8/multiprocessing/util.py", line 300, in _run_finalizers
    finalizer()
  File "/home/jlpkort/anaconda3/lib/python3.8/multiprocessing/util.py", line 224, in __call__
    res = self._callback(*self._args, **self._kwargs)
  File "/home/jlpkort/anaconda3/lib/python3.8/multiprocessing/util.py", line 133, in _remove_temp_dir
    rmtree(tempdir)
  File "/home/jlpkort/anaconda3/lib/python3.8/shutil.py", line 722, in rmtree
    onerror(os.rmdir, path, sys.exc_info())
  File "/home/jlpkort/anaconda3/lib/python3.8/shutil.py", line 720, in rmtree
    os.rmdir(path)
OSError: [Errno 39] Directory not empty: '/scratch/pymp-r64p8pno'
Traceback (most recent call last):
  File "/home/jlpkort/anaconda3/lib/python3.8/multiprocessing/util.py", line 300, in _run_finalizers
    finalizer()
  File "/home/jlpkort/anaconda3/lib/python3.8/multiprocessing/util.py", line 224, in __call__
    res = self._callback(*self._args, **self._kwargs)
  File "/home/jlpkort/anaconda3/lib/python3.8/multiprocessing/util.py", line 133, in _remove_temp_dir
    rmtree(tempdir)
  File "/home/jlpkort/anaconda3/lib/python3.8/shutil.py", line 722, in rmtree
    onerror(os.rmdir, path, sys.exc_info())
  File "/home/jlpkort/anaconda3/lib/python3.8/shutil.py", line 720, in rmtree
    os.rmdir(path)
OSError: [Errno 39] Directory not empty: '/scratch/pymp-oc54avm1'
I0916 21:59:47.174931 3306 trainer.py:117]  [Step: 3500/15000 (23.333333333333332%)] D Loss: -78.2701644897461 M Loss: 1.3257660865783691 G Loss: -5.6324238777160645 
Traceback (most recent call last):
  File "/home/jlpkort/anaconda3/lib/python3.8/multiprocessing/util.py", line 300, in _run_finalizers
    finalizer()
  File "/home/jlpkort/anaconda3/lib/python3.8/multiprocessing/util.py", line 224, in __call__
    res = self._callback(*self._args, **self._kwargs)
  File "/home/jlpkort/anaconda3/lib/python3.8/multiprocessing/util.py", line 133, in _remove_temp_dir
    rmtree(tempdir)
  File "/home/jlpkort/anaconda3/lib/python3.8/shutil.py", line 722, in rmtree
    onerror(os.rmdir, path, sys.exc_info())
  File "/home/jlpkort/anaconda3/lib/python3.8/shutil.py", line 720, in rmtree
    os.rmdir(path)
OSError: [Errno 39] Directory not empty: '/scratch/pymp-7n6v2yl9'
I0916 22:40:02.074804 3306 trainer.py:117]  [Step: 4000/15000 (26.666666666666668%)] D Loss: -59.530738830566406 M Loss: 1.299700379371643 G Loss: -6.033832550048828 
Traceback (most recent call last):
  File "/home/jlpkort/anaconda3/lib/python3.8/multiprocessing/util.py", line 300, in _run_finalizers
    finalizer()
  File "/home/jlpkort/anaconda3/lib/python3.8/multiprocessing/util.py", line 224, in __call__
    res = self._callback(*self._args, **self._kwargs)
  File "/home/jlpkort/anaconda3/lib/python3.8/multiprocessing/util.py", line 133, in _remove_temp_dir
    rmtree(tempdir)
  File "/home/jlpkort/anaconda3/lib/python3.8/shutil.py", line 722, in rmtree
    onerror(os.rmdir, path, sys.exc_info())
  File "/home/jlpkort/anaconda3/lib/python3.8/shutil.py", line 720, in rmtree
    os.rmdir(path)
OSError: [Errno 39] Directory not empty: '/scratch/pymp-vb1gxlzw'
I0917 00:24:04.950608 3306 trainer.py:117]  [Step: 4500/15000 (30.0%)] D Loss: -82.67106628417969 M Loss: 1.3920061588287354 G Loss: -3.964912176132202 
Traceback (most recent call last):
  File "/home/jlpkort/anaconda3/lib/python3.8/multiprocessing/util.py", line 300, in _run_finalizers
    finalizer()
  File "/home/jlpkort/anaconda3/lib/python3.8/multiprocessing/util.py", line 224, in __call__
    res = self._callback(*self._args, **self._kwargs)
  File "/home/jlpkort/anaconda3/lib/python3.8/multiprocessing/util.py", line 133, in _remove_temp_dir
    rmtree(tempdir)
  File "/home/jlpkort/anaconda3/lib/python3.8/shutil.py", line 722, in rmtree
    onerror(os.rmdir, path, sys.exc_info())
  File "/home/jlpkort/anaconda3/lib/python3.8/shutil.py", line 720, in rmtree
    os.rmdir(path)
OSError: [Errno 39] Directory not empty: '/scratch/pymp-3q60vyel'
Traceback (most recent call last):
  File "/home/jlpkort/anaconda3/lib/python3.8/multiprocessing/util.py", line 300, in _run_finalizers
    finalizer()
  File "/home/jlpkort/anaconda3/lib/python3.8/multiprocessing/util.py", line 224, in __call__
    res = self._callback(*self._args, **self._kwargs)
  File "/home/jlpkort/anaconda3/lib/python3.8/multiprocessing/util.py", line 133, in _remove_temp_dir
    rmtree(tempdir)
  File "/home/jlpkort/anaconda3/lib/python3.8/shutil.py", line 722, in rmtree
    onerror(os.rmdir, path, sys.exc_info())
  File "/home/jlpkort/anaconda3/lib/python3.8/shutil.py", line 720, in rmtree
    os.rmdir(path)
OSError: [Errno 39] Directory not empty: '/scratch/pymp-twrp97cw'
Traceback (most recent call last):
  File "/home/jlpkort/anaconda3/lib/python3.8/multiprocessing/util.py", line 300, in _run_finalizers
    finalizer()
  File "/home/jlpkort/anaconda3/lib/python3.8/multiprocessing/util.py", line 224, in __call__
    res = self._callback(*self._args, **self._kwargs)
  File "/home/jlpkort/anaconda3/lib/python3.8/multiprocessing/util.py", line 133, in _remove_temp_dir
    rmtree(tempdir)
  File "/home/jlpkort/anaconda3/lib/python3.8/shutil.py", line 722, in rmtree
    onerror(os.rmdir, path, sys.exc_info())
  File "/home/jlpkort/anaconda3/lib/python3.8/shutil.py", line 720, in rmtree
    os.rmdir(path)
OSError: [Errno 39] Directory not empty: '/scratch/pymp-pvgasyrt'
Traceback (most recent call last):
  File "/home/jlpkort/anaconda3/lib/python3.8/multiprocessing/util.py", line 300, in _run_finalizers
    finalizer()
  File "/home/jlpkort/anaconda3/lib/python3.8/multiprocessing/util.py", line 224, in __call__
    res = self._callback(*self._args, **self._kwargs)
  File "/home/jlpkort/anaconda3/lib/python3.8/multiprocessing/util.py", line 133, in _remove_temp_dir
    rmtree(tempdir)
  File "/home/jlpkort/anaconda3/lib/python3.8/shutil.py", line 722, in rmtree
    onerror(os.rmdir, path, sys.exc_info())
  File "/home/jlpkort/anaconda3/lib/python3.8/shutil.py", line 720, in rmtree
    os.rmdir(path)
OSError: [Errno 39] Directory not empty: '/scratch/pymp-uqggptg3'
Traceback (most recent call last):
  File "/home/jlpkort/anaconda3/lib/python3.8/multiprocessing/util.py", line 300, in _run_finalizers
    finalizer()
  File "/home/jlpkort/anaconda3/lib/python3.8/multiprocessing/util.py", line 224, in __call__
    res = self._callback(*self._args, **self._kwargs)
  File "/home/jlpkort/anaconda3/lib/python3.8/multiprocessing/util.py", line 133, in _remove_temp_dir
    rmtree(tempdir)
  File "/home/jlpkort/anaconda3/lib/python3.8/shutil.py", line 722, in rmtree
    onerror(os.rmdir, path, sys.exc_info())
  File "/home/jlpkort/anaconda3/lib/python3.8/shutil.py", line 720, in rmtree
    os.rmdir(path)
OSError: [Errno 39] Directory not empty: '/scratch/pymp-8avqrs1l'
Traceback (most recent call last):
  File "/home/jlpkort/anaconda3/lib/python3.8/multiprocessing/util.py", line 300, in _run_finalizers
    finalizer()
  File "/home/jlpkort/anaconda3/lib/python3.8/multiprocessing/util.py", line 224, in __call__
    res = self._callback(*self._args, **self._kwargs)
  File "/home/jlpkort/anaconda3/lib/python3.8/multiprocessing/util.py", line 133, in _remove_temp_dir
    rmtree(tempdir)
  File "/home/jlpkort/anaconda3/lib/python3.8/shutil.py", line 722, in rmtree
    onerror(os.rmdir, path, sys.exc_info())
  File "/home/jlpkort/anaconda3/lib/python3.8/shutil.py", line 720, in rmtree
    os.rmdir(path)
OSError: [Errno 39] Directory not empty: '/scratch/pymp-xgt40y9l'
I0917 01:04:12.357485 3306 trainer.py:117]  [Step: 5000/15000 (33.333333333333336%)] D Loss: -121.50082397460938 M Loss: 1.3166723251342773 G Loss: -3.194556713104248 
Traceback (most recent call last):
  File "/home/jlpkort/anaconda3/lib/python3.8/multiprocessing/util.py", line 300, in _run_finalizers
    finalizer()
  File "/home/jlpkort/anaconda3/lib/python3.8/multiprocessing/util.py", line 224, in __call__
    res = self._callback(*self._args, **self._kwargs)
  File "/home/jlpkort/anaconda3/lib/python3.8/multiprocessing/util.py", line 133, in _remove_temp_dir
    rmtree(tempdir)
  File "/home/jlpkort/anaconda3/lib/python3.8/shutil.py", line 722, in rmtree
    onerror(os.rmdir, path, sys.exc_info())
  File "/home/jlpkort/anaconda3/lib/python3.8/shutil.py", line 720, in rmtree
    os.rmdir(path)
OSError: [Errno 39] Directory not empty: '/scratch/pymp-t5d4ehtt'
Traceback (most recent call last):
  File "/home/jlpkort/anaconda3/lib/python3.8/multiprocessing/util.py", line 300, in _run_finalizers
    finalizer()
  File "/home/jlpkort/anaconda3/lib/python3.8/multiprocessing/util.py", line 224, in __call__
    res = self._callback(*self._args, **self._kwargs)
  File "/home/jlpkort/anaconda3/lib/python3.8/multiprocessing/util.py", line 133, in _remove_temp_dir
    rmtree(tempdir)
  File "/home/jlpkort/anaconda3/lib/python3.8/shutil.py", line 722, in rmtree
    onerror(os.rmdir, path, sys.exc_info())
  File "/home/jlpkort/anaconda3/lib/python3.8/shutil.py", line 720, in rmtree
    os.rmdir(path)
OSError: [Errno 39] Directory not empty: '/scratch/pymp-j7u_ypry'
Traceback (most recent call last):
  File "/home/jlpkort/anaconda3/lib/python3.8/multiprocessing/util.py", line 300, in _run_finalizers
    finalizer()
  File "/home/jlpkort/anaconda3/lib/python3.8/multiprocessing/util.py", line 224, in __call__
    res = self._callback(*self._args, **self._kwargs)
  File "/home/jlpkort/anaconda3/lib/python3.8/multiprocessing/util.py", line 133, in _remove_temp_dir
    rmtree(tempdir)
  File "/home/jlpkort/anaconda3/lib/python3.8/shutil.py", line 722, in rmtree
    onerror(os.rmdir, path, sys.exc_info())
  File "/home/jlpkort/anaconda3/lib/python3.8/shutil.py", line 720, in rmtree
    os.rmdir(path)
OSError: [Errno 39] Directory not empty: '/scratch/pymp-7v7k_iqk'
I0917 01:44:28.245142 3306 trainer.py:117]  [Step: 5500/15000 (36.666666666666664%)] D Loss: -109.19096374511719 M Loss: 1.3214881420135498 G Loss: -4.123291015625 
I0917 02:24:48.975717 3306 trainer.py:117]  [Step: 6000/15000 (40.0%)] D Loss: -47.997406005859375 M Loss: 1.3930113315582275 G Loss: -4.233524322509766 
Traceback (most recent call last):
  File "/home/jlpkort/anaconda3/lib/python3.8/multiprocessing/util.py", line 300, in _run_finalizers
    finalizer()
  File "/home/jlpkort/anaconda3/lib/python3.8/multiprocessing/util.py", line 224, in __call__
    res = self._callback(*self._args, **self._kwargs)
  File "/home/jlpkort/anaconda3/lib/python3.8/multiprocessing/util.py", line 133, in _remove_temp_dir
    rmtree(tempdir)
  File "/home/jlpkort/anaconda3/lib/python3.8/shutil.py", line 722, in rmtree
    onerror(os.rmdir, path, sys.exc_info())
  File "/home/jlpkort/anaconda3/lib/python3.8/shutil.py", line 720, in rmtree
    os.rmdir(path)
OSError: [Errno 39] Directory not empty: '/scratch/pymp-pasgybi9'
Traceback (most recent call last):
  File "/home/jlpkort/anaconda3/lib/python3.8/multiprocessing/util.py", line 300, in _run_finalizers
    finalizer()
  File "/home/jlpkort/anaconda3/lib/python3.8/multiprocessing/util.py", line 224, in __call__
    res = self._callback(*self._args, **self._kwargs)
  File "/home/jlpkort/anaconda3/lib/python3.8/multiprocessing/util.py", line 133, in _remove_temp_dir
    rmtree(tempdir)
  File "/home/jlpkort/anaconda3/lib/python3.8/shutil.py", line 722, in rmtree
    onerror(os.rmdir, path, sys.exc_info())
  File "/home/jlpkort/anaconda3/lib/python3.8/shutil.py", line 720, in rmtree
    os.rmdir(path)
OSError: [Errno 39] Directory not empty: '/scratch/pymp-9c0n9gbi'
Traceback (most recent call last):
  File "/home/jlpkort/anaconda3/lib/python3.8/multiprocessing/util.py", line 300, in _run_finalizers
    finalizer()
  File "/home/jlpkort/anaconda3/lib/python3.8/multiprocessing/util.py", line 224, in __call__
    res = self._callback(*self._args, **self._kwargs)
  File "/home/jlpkort/anaconda3/lib/python3.8/multiprocessing/util.py", line 133, in _remove_temp_dir
    rmtree(tempdir)
  File "/home/jlpkort/anaconda3/lib/python3.8/shutil.py", line 722, in rmtree
    onerror(os.rmdir, path, sys.exc_info())
  File "/home/jlpkort/anaconda3/lib/python3.8/shutil.py", line 720, in rmtree
    os.rmdir(path)
OSError: [Errno 39] Directory not empty: '/scratch/pymp-t_vhuyib'
I0917 03:05:11.864169 3306 trainer.py:117]  [Step: 6500/15000 (43.333333333333336%)] D Loss: -125.27299499511719 M Loss: 1.2921725511550903 G Loss: -1.9195878505706787 
Traceback (most recent call last):
  File "/home/jlpkort/anaconda3/lib/python3.8/multiprocessing/util.py", line 300, in _run_finalizers
    finalizer()
  File "/home/jlpkort/anaconda3/lib/python3.8/multiprocessing/util.py", line 224, in __call__
    res = self._callback(*self._args, **self._kwargs)
  File "/home/jlpkort/anaconda3/lib/python3.8/multiprocessing/util.py", line 133, in _remove_temp_dir
    rmtree(tempdir)
  File "/home/jlpkort/anaconda3/lib/python3.8/shutil.py", line 722, in rmtree
    onerror(os.rmdir, path, sys.exc_info())
  File "/home/jlpkort/anaconda3/lib/python3.8/shutil.py", line 720, in rmtree
    os.rmdir(path)
OSError: [Errno 39] Directory not empty: '/scratch/pymp-fpiabobs'
Traceback (most recent call last):
  File "/home/jlpkort/anaconda3/lib/python3.8/multiprocessing/util.py", line 300, in _run_finalizers
    finalizer()
  File "/home/jlpkort/anaconda3/lib/python3.8/multiprocessing/util.py", line 224, in __call__
    res = self._callback(*self._args, **self._kwargs)
  File "/home/jlpkort/anaconda3/lib/python3.8/multiprocessing/util.py", line 133, in _remove_temp_dir
    rmtree(tempdir)
  File "/home/jlpkort/anaconda3/lib/python3.8/shutil.py", line 722, in rmtree
    onerror(os.rmdir, path, sys.exc_info())
  File "/home/jlpkort/anaconda3/lib/python3.8/shutil.py", line 720, in rmtree
    os.rmdir(path)
OSError: [Errno 39] Directory not empty: '/scratch/pymp-ogkyimda'
Traceback (most recent call last):
  File "/home/jlpkort/anaconda3/lib/python3.8/multiprocessing/util.py", line 300, in _run_finalizers
    finalizer()
  File "/home/jlpkort/anaconda3/lib/python3.8/multiprocessing/util.py", line 224, in __call__
    res = self._callback(*self._args, **self._kwargs)
  File "/home/jlpkort/anaconda3/lib/python3.8/multiprocessing/util.py", line 133, in _remove_temp_dir
    rmtree(tempdir)
  File "/home/jlpkort/anaconda3/lib/python3.8/shutil.py", line 722, in rmtree
    onerror(os.rmdir, path, sys.exc_info())
  File "/home/jlpkort/anaconda3/lib/python3.8/shutil.py", line 720, in rmtree
    os.rmdir(path)
OSError: [Errno 39] Directory not empty: '/scratch/pymp-gxloz8ey'
Traceback (most recent call last):
  File "/home/jlpkort/anaconda3/lib/python3.8/multiprocessing/util.py", line 300, in _run_finalizers
    finalizer()
  File "/home/jlpkort/anaconda3/lib/python3.8/multiprocessing/util.py", line 224, in __call__
    res = self._callback(*self._args, **self._kwargs)
  File "/home/jlpkort/anaconda3/lib/python3.8/multiprocessing/util.py", line 133, in _remove_temp_dir
    rmtree(tempdir)
  File "/home/jlpkort/anaconda3/lib/python3.8/shutil.py", line 722, in rmtree
    onerror(os.rmdir, path, sys.exc_info())
  File "/home/jlpkort/anaconda3/lib/python3.8/shutil.py", line 720, in rmtree
    os.rmdir(path)
OSError: [Errno 39] Directory not empty: '/scratch/pymp-oa52w2n8'
I0917 03:45:24.438624 3306 trainer.py:117]  [Step: 7000/15000 (46.666666666666664%)] D Loss: -221.66140747070312 M Loss: 1.385793924331665 G Loss: 5.430520057678223 
I0917 04:25:41.862204 3306 trainer.py:117]  [Step: 7500/15000 (50.0%)] D Loss: -182.92257690429688 M Loss: 1.009432077407837 G Loss: 5.717026710510254 
Traceback (most recent call last):
  File "/home/jlpkort/anaconda3/lib/python3.8/multiprocessing/util.py", line 300, in _run_finalizers
    finalizer()
  File "/home/jlpkort/anaconda3/lib/python3.8/multiprocessing/util.py", line 224, in __call__
    res = self._callback(*self._args, **self._kwargs)
  File "/home/jlpkort/anaconda3/lib/python3.8/multiprocessing/util.py", line 133, in _remove_temp_dir
    rmtree(tempdir)
  File "/home/jlpkort/anaconda3/lib/python3.8/shutil.py", line 722, in rmtree
    onerror(os.rmdir, path, sys.exc_info())
  File "/home/jlpkort/anaconda3/lib/python3.8/shutil.py", line 720, in rmtree
    os.rmdir(path)
OSError: [Errno 39] Directory not empty: '/scratch/pymp-mm21c7ss'
Traceback (most recent call last):
  File "/home/jlpkort/anaconda3/lib/python3.8/multiprocessing/util.py", line 300, in _run_finalizers
    finalizer()
  File "/home/jlpkort/anaconda3/lib/python3.8/multiprocessing/util.py", line 224, in __call__
    res = self._callback(*self._args, **self._kwargs)
  File "/home/jlpkort/anaconda3/lib/python3.8/multiprocessing/util.py", line 133, in _remove_temp_dir
    rmtree(tempdir)
  File "/home/jlpkort/anaconda3/lib/python3.8/shutil.py", line 722, in rmtree
    onerror(os.rmdir, path, sys.exc_info())
  File "/home/jlpkort/anaconda3/lib/python3.8/shutil.py", line 720, in rmtree
    os.rmdir(path)
OSError: [Errno 39] Directory not empty: '/scratch/pymp-tko6bkha'
Traceback (most recent call last):
  File "/home/jlpkort/anaconda3/lib/python3.8/multiprocessing/util.py", line 300, in _run_finalizers
    finalizer()
  File "/home/jlpkort/anaconda3/lib/python3.8/multiprocessing/util.py", line 224, in __call__
    res = self._callback(*self._args, **self._kwargs)
  File "/home/jlpkort/anaconda3/lib/python3.8/multiprocessing/util.py", line 133, in _remove_temp_dir
    rmtree(tempdir)
  File "/home/jlpkort/anaconda3/lib/python3.8/shutil.py", line 722, in rmtree
    onerror(os.rmdir, path, sys.exc_info())
  File "/home/jlpkort/anaconda3/lib/python3.8/shutil.py", line 720, in rmtree
    os.rmdir(path)
OSError: [Errno 39] Directory not empty: '/scratch/pymp-tnt0ny7o'
I0917 05:06:01.120688 3306 trainer.py:117]  [Step: 8000/15000 (53.333333333333336%)] D Loss: -4.981534957885742 M Loss: 1.0116770267486572 G Loss: 2.5993528366088867 
Traceback (most recent call last):
  File "/home/jlpkort/anaconda3/lib/python3.8/multiprocessing/util.py", line 300, in _run_finalizers
    finalizer()
  File "/home/jlpkort/anaconda3/lib/python3.8/multiprocessing/util.py", line 224, in __call__
    res = self._callback(*self._args, **self._kwargs)
  File "/home/jlpkort/anaconda3/lib/python3.8/multiprocessing/util.py", line 133, in _remove_temp_dir
    rmtree(tempdir)
  File "/home/jlpkort/anaconda3/lib/python3.8/shutil.py", line 722, in rmtree
    onerror(os.rmdir, path, sys.exc_info())
  File "/home/jlpkort/anaconda3/lib/python3.8/shutil.py", line 720, in rmtree
    os.rmdir(path)
OSError: [Errno 39] Directory not empty: '/scratch/pymp-ulgu3j2o'
Traceback (most recent call last):
  File "/home/jlpkort/anaconda3/lib/python3.8/multiprocessing/util.py", line 300, in _run_finalizers
    finalizer()
  File "/home/jlpkort/anaconda3/lib/python3.8/multiprocessing/util.py", line 224, in __call__
    res = self._callback(*self._args, **self._kwargs)
  File "/home/jlpkort/anaconda3/lib/python3.8/multiprocessing/util.py", line 133, in _remove_temp_dir
    rmtree(tempdir)
  File "/home/jlpkort/anaconda3/lib/python3.8/shutil.py", line 722, in rmtree
    onerror(os.rmdir, path, sys.exc_info())
  File "/home/jlpkort/anaconda3/lib/python3.8/shutil.py", line 720, in rmtree
    os.rmdir(path)
OSError: [Errno 39] Directory not empty: '/scratch/pymp-by83_gna'
Traceback (most recent call last):
  File "/home/jlpkort/anaconda3/lib/python3.8/multiprocessing/util.py", line 300, in _run_finalizers
    finalizer()
  File "/home/jlpkort/anaconda3/lib/python3.8/multiprocessing/util.py", line 224, in __call__
    res = self._callback(*self._args, **self._kwargs)
  File "/home/jlpkort/anaconda3/lib/python3.8/multiprocessing/util.py", line 133, in _remove_temp_dir
    rmtree(tempdir)
  File "/home/jlpkort/anaconda3/lib/python3.8/shutil.py", line 722, in rmtree
    onerror(os.rmdir, path, sys.exc_info())
  File "/home/jlpkort/anaconda3/lib/python3.8/shutil.py", line 720, in rmtree
    os.rmdir(path)
OSError: [Errno 39] Directory not empty: '/scratch/pymp-3e_feyzn'
I0917 05:46:28.164100 3306 trainer.py:117]  [Step: 8500/15000 (56.666666666666664%)] D Loss: -0.7075262069702148 M Loss: 1.1085654497146606 G Loss: 1.129576325416565 
Traceback (most recent call last):
  File "/home/jlpkort/anaconda3/lib/python3.8/multiprocessing/util.py", line 300, in _run_finalizers
    finalizer()
  File "/home/jlpkort/anaconda3/lib/python3.8/multiprocessing/util.py", line 224, in __call__
    res = self._callback(*self._args, **self._kwargs)
  File "/home/jlpkort/anaconda3/lib/python3.8/multiprocessing/util.py", line 133, in _remove_temp_dir
    rmtree(tempdir)
  File "/home/jlpkort/anaconda3/lib/python3.8/shutil.py", line 722, in rmtree
    onerror(os.rmdir, path, sys.exc_info())
  File "/home/jlpkort/anaconda3/lib/python3.8/shutil.py", line 720, in rmtree
    os.rmdir(path)
OSError: [Errno 39] Directory not empty: '/scratch/pymp-ail8bc0u'
I0917 06:26:54.087352 3306 trainer.py:117]  [Step: 9000/15000 (60.0%)] D Loss: -12.963890075683594 M Loss: 1.0151128768920898 G Loss: 0.656356692314148 
Traceback (most recent call last):
  File "/home/jlpkort/anaconda3/lib/python3.8/multiprocessing/util.py", line 300, in _run_finalizers
    finalizer()
  File "/home/jlpkort/anaconda3/lib/python3.8/multiprocessing/util.py", line 224, in __call__
    res = self._callback(*self._args, **self._kwargs)
  File "/home/jlpkort/anaconda3/lib/python3.8/multiprocessing/util.py", line 133, in _remove_temp_dir
    rmtree(tempdir)
  File "/home/jlpkort/anaconda3/lib/python3.8/shutil.py", line 722, in rmtree
    onerror(os.rmdir, path, sys.exc_info())
  File "/home/jlpkort/anaconda3/lib/python3.8/shutil.py", line 720, in rmtree
    os.rmdir(path)
OSError: [Errno 39] Directory not empty: '/scratch/pymp-5imqe_7v'
Traceback (most recent call last):
  File "/home/jlpkort/anaconda3/lib/python3.8/multiprocessing/util.py", line 300, in _run_finalizers
    finalizer()
  File "/home/jlpkort/anaconda3/lib/python3.8/multiprocessing/util.py", line 224, in __call__
    res = self._callback(*self._args, **self._kwargs)
  File "/home/jlpkort/anaconda3/lib/python3.8/multiprocessing/util.py", line 133, in _remove_temp_dir
    rmtree(tempdir)
  File "/home/jlpkort/anaconda3/lib/python3.8/shutil.py", line 722, in rmtree
    onerror(os.rmdir, path, sys.exc_info())
  File "/home/jlpkort/anaconda3/lib/python3.8/shutil.py", line 720, in rmtree
    os.rmdir(path)
OSError: [Errno 39] Directory not empty: '/scratch/pymp-8pxp5uaf'
I0917 07:07:17.648699 3306 trainer.py:117]  [Step: 9500/15000 (63.333333333333336%)] D Loss: -4.2882490158081055 M Loss: 1.0209507942199707 G Loss: 0.5230278968811035 
Traceback (most recent call last):
  File "/home/jlpkort/anaconda3/lib/python3.8/multiprocessing/util.py", line 300, in _run_finalizers
    finalizer()
  File "/home/jlpkort/anaconda3/lib/python3.8/multiprocessing/util.py", line 224, in __call__
    res = self._callback(*self._args, **self._kwargs)
  File "/home/jlpkort/anaconda3/lib/python3.8/multiprocessing/util.py", line 133, in _remove_temp_dir
    rmtree(tempdir)
  File "/home/jlpkort/anaconda3/lib/python3.8/shutil.py", line 722, in rmtree
    onerror(os.rmdir, path, sys.exc_info())
  File "/home/jlpkort/anaconda3/lib/python3.8/shutil.py", line 720, in rmtree
    os.rmdir(path)
OSError: [Errno 39] Directory not empty: '/scratch/pymp-_34taspq'
Traceback (most recent call last):
  File "/home/jlpkort/anaconda3/lib/python3.8/multiprocessing/util.py", line 300, in _run_finalizers
    finalizer()
  File "/home/jlpkort/anaconda3/lib/python3.8/multiprocessing/util.py", line 224, in __call__
    res = self._callback(*self._args, **self._kwargs)
  File "/home/jlpkort/anaconda3/lib/python3.8/multiprocessing/util.py", line 133, in _remove_temp_dir
    rmtree(tempdir)
  File "/home/jlpkort/anaconda3/lib/python3.8/shutil.py", line 722, in rmtree
    onerror(os.rmdir, path, sys.exc_info())
  File "/home/jlpkort/anaconda3/lib/python3.8/shutil.py", line 720, in rmtree
    os.rmdir(path)
OSError: [Errno 39] Directory not empty: '/scratch/pymp-2lhiphdb'
Traceback (most recent call last):
  File "/home/jlpkort/anaconda3/lib/python3.8/multiprocessing/util.py", line 300, in _run_finalizers
    finalizer()
  File "/home/jlpkort/anaconda3/lib/python3.8/multiprocessing/util.py", line 224, in __call__
    res = self._callback(*self._args, **self._kwargs)
  File "/home/jlpkort/anaconda3/lib/python3.8/multiprocessing/util.py", line 133, in _remove_temp_dir
    rmtree(tempdir)
  File "/home/jlpkort/anaconda3/lib/python3.8/shutil.py", line 722, in rmtree
    onerror(os.rmdir, path, sys.exc_info())
  File "/home/jlpkort/anaconda3/lib/python3.8/shutil.py", line 720, in rmtree
    os.rmdir(path)
OSError: [Errno 39] Directory not empty: '/scratch/pymp-_schc8c0'
Traceback (most recent call last):
  File "/home/jlpkort/anaconda3/lib/python3.8/multiprocessing/util.py", line 300, in _run_finalizers
    finalizer()
  File "/home/jlpkort/anaconda3/lib/python3.8/multiprocessing/util.py", line 224, in __call__
    res = self._callback(*self._args, **self._kwargs)
  File "/home/jlpkort/anaconda3/lib/python3.8/multiprocessing/util.py", line 133, in _remove_temp_dir
    rmtree(tempdir)
  File "/home/jlpkort/anaconda3/lib/python3.8/shutil.py", line 722, in rmtree
    onerror(os.rmdir, path, sys.exc_info())
  File "/home/jlpkort/anaconda3/lib/python3.8/shutil.py", line 720, in rmtree
    os.rmdir(path)
OSError: [Errno 39] Directory not empty: '/scratch/pymp-9tc92dav'
Traceback (most recent call last):
  File "/home/jlpkort/anaconda3/lib/python3.8/multiprocessing/util.py", line 300, in _run_finalizers
    finalizer()
  File "/home/jlpkort/anaconda3/lib/python3.8/multiprocessing/util.py", line 224, in __call__
    res = self._callback(*self._args, **self._kwargs)
  File "/home/jlpkort/anaconda3/lib/python3.8/multiprocessing/util.py", line 133, in _remove_temp_dir
    rmtree(tempdir)
  File "/home/jlpkort/anaconda3/lib/python3.8/shutil.py", line 722, in rmtree
    onerror(os.rmdir, path, sys.exc_info())
  File "/home/jlpkort/anaconda3/lib/python3.8/shutil.py", line 720, in rmtree
    os.rmdir(path)
OSError: [Errno 39] Directory not empty: '/scratch/pymp-m_eov135'
Traceback (most recent call last):
  File "/home/jlpkort/anaconda3/lib/python3.8/multiprocessing/util.py", line 300, in _run_finalizers
    finalizer()
  File "/home/jlpkort/anaconda3/lib/python3.8/multiprocessing/util.py", line 224, in __call__
    res = self._callback(*self._args, **self._kwargs)
  File "/home/jlpkort/anaconda3/lib/python3.8/multiprocessing/util.py", line 133, in _remove_temp_dir
    rmtree(tempdir)
  File "/home/jlpkort/anaconda3/lib/python3.8/shutil.py", line 722, in rmtree
    onerror(os.rmdir, path, sys.exc_info())
  File "/home/jlpkort/anaconda3/lib/python3.8/shutil.py", line 720, in rmtree
    os.rmdir(path)
OSError: [Errno 39] Directory not empty: '/scratch/pymp-6sh_j71w'
Traceback (most recent call last):
  File "/home/jlpkort/anaconda3/lib/python3.8/multiprocessing/util.py", line 300, in _run_finalizers
    finalizer()
  File "/home/jlpkort/anaconda3/lib/python3.8/multiprocessing/util.py", line 224, in __call__
    res = self._callback(*self._args, **self._kwargs)
  File "/home/jlpkort/anaconda3/lib/python3.8/multiprocessing/util.py", line 133, in _remove_temp_dir
    rmtree(tempdir)
  File "/home/jlpkort/anaconda3/lib/python3.8/shutil.py", line 722, in rmtree
    onerror(os.rmdir, path, sys.exc_info())
  File "/home/jlpkort/anaconda3/lib/python3.8/shutil.py", line 720, in rmtree
    os.rmdir(path)
OSError: [Errno 39] Directory not empty: '/scratch/pymp-hbmdj5fn'
Traceback (most recent call last):
  File "/home/jlpkort/anaconda3/lib/python3.8/multiprocessing/util.py", line 300, in _run_finalizers
    finalizer()
  File "/home/jlpkort/anaconda3/lib/python3.8/multiprocessing/util.py", line 224, in __call__
    res = self._callback(*self._args, **self._kwargs)
  File "/home/jlpkort/anaconda3/lib/python3.8/multiprocessing/util.py", line 133, in _remove_temp_dir
    rmtree(tempdir)
  File "/home/jlpkort/anaconda3/lib/python3.8/shutil.py", line 722, in rmtree
    onerror(os.rmdir, path, sys.exc_info())
  File "/home/jlpkort/anaconda3/lib/python3.8/shutil.py", line 720, in rmtree
    os.rmdir(path)
OSError: [Errno 39] Directory not empty: '/scratch/pymp-2x2uyudu'
I0917 07:47:45.047039 3306 trainer.py:117]  [Step: 10000/15000 (66.66666666666667%)] D Loss: -8.257312774658203 M Loss: 1.0174412727355957 G Loss: 0.4105129539966583 
Traceback (most recent call last):
  File "/home/jlpkort/anaconda3/lib/python3.8/multiprocessing/util.py", line 300, in _run_finalizers
    finalizer()
  File "/home/jlpkort/anaconda3/lib/python3.8/multiprocessing/util.py", line 224, in __call__
    res = self._callback(*self._args, **self._kwargs)
  File "/home/jlpkort/anaconda3/lib/python3.8/multiprocessing/util.py", line 133, in _remove_temp_dir
    rmtree(tempdir)
  File "/home/jlpkort/anaconda3/lib/python3.8/shutil.py", line 722, in rmtree
    onerror(os.rmdir, path, sys.exc_info())
  File "/home/jlpkort/anaconda3/lib/python3.8/shutil.py", line 720, in rmtree
    os.rmdir(path)
OSError: [Errno 39] Directory not empty: '/scratch/pymp-fno4qpsq'
Traceback (most recent call last):
  File "/home/jlpkort/anaconda3/lib/python3.8/multiprocessing/util.py", line 300, in _run_finalizers
    finalizer()
  File "/home/jlpkort/anaconda3/lib/python3.8/multiprocessing/util.py", line 224, in __call__
    res = self._callback(*self._args, **self._kwargs)
  File "/home/jlpkort/anaconda3/lib/python3.8/multiprocessing/util.py", line 133, in _remove_temp_dir
    rmtree(tempdir)
  File "/home/jlpkort/anaconda3/lib/python3.8/shutil.py", line 722, in rmtree
    onerror(os.rmdir, path, sys.exc_info())
  File "/home/jlpkort/anaconda3/lib/python3.8/shutil.py", line 720, in rmtree
    os.rmdir(path)
OSError: [Errno 39] Directory not empty: '/scratch/pymp-n3nsy9l0'
I0917 08:28:21.072986 3306 trainer.py:117]  [Step: 10500/15000 (70.0%)] D Loss: -11.954573631286621 M Loss: 1.0142028331756592 G Loss: 0.34815558791160583 
Traceback (most recent call last):
  File "/home/jlpkort/anaconda3/lib/python3.8/multiprocessing/util.py", line 300, in _run_finalizers
    finalizer()
  File "/home/jlpkort/anaconda3/lib/python3.8/multiprocessing/util.py", line 224, in __call__
    res = self._callback(*self._args, **self._kwargs)
  File "/home/jlpkort/anaconda3/lib/python3.8/multiprocessing/util.py", line 133, in _remove_temp_dir
    rmtree(tempdir)
  File "/home/jlpkort/anaconda3/lib/python3.8/shutil.py", line 722, in rmtree
    onerror(os.rmdir, path, sys.exc_info())
  File "/home/jlpkort/anaconda3/lib/python3.8/shutil.py", line 720, in rmtree
    os.rmdir(path)
OSError: [Errno 39] Directory not empty: '/scratch/pymp-nzij67hu'
Traceback (most recent call last):
  File "/home/jlpkort/anaconda3/lib/python3.8/multiprocessing/util.py", line 300, in _run_finalizers
    finalizer()
  File "/home/jlpkort/anaconda3/lib/python3.8/multiprocessing/util.py", line 224, in __call__
    res = self._callback(*self._args, **self._kwargs)
  File "/home/jlpkort/anaconda3/lib/python3.8/multiprocessing/util.py", line 133, in _remove_temp_dir
    rmtree(tempdir)
  File "/home/jlpkort/anaconda3/lib/python3.8/shutil.py", line 722, in rmtree
    onerror(os.rmdir, path, sys.exc_info())
  File "/home/jlpkort/anaconda3/lib/python3.8/shutil.py", line 720, in rmtree
    os.rmdir(path)
OSError: [Errno 39] Directory not empty: '/scratch/pymp-gc3usms8'
Traceback (most recent call last):
  File "/home/jlpkort/anaconda3/lib/python3.8/multiprocessing/util.py", line 300, in _run_finalizers
    finalizer()
  File "/home/jlpkort/anaconda3/lib/python3.8/multiprocessing/util.py", line 224, in __call__
    res = self._callback(*self._args, **self._kwargs)
  File "/home/jlpkort/anaconda3/lib/python3.8/multiprocessing/util.py", line 133, in _remove_temp_dir
    rmtree(tempdir)
  File "/home/jlpkort/anaconda3/lib/python3.8/shutil.py", line 722, in rmtree
    onerror(os.rmdir, path, sys.exc_info())
  File "/home/jlpkort/anaconda3/lib/python3.8/shutil.py", line 720, in rmtree
    os.rmdir(path)
OSError: [Errno 39] Directory not empty: '/scratch/pymp-14cwp3db'
I0917 09:08:52.014765 3306 trainer.py:117]  [Step: 11000/15000 (73.33333333333333%)] D Loss: -7.004867076873779 M Loss: 1.009511947631836 G Loss: -0.040593236684799194 
Traceback (most recent call last):
  File "/home/jlpkort/anaconda3/lib/python3.8/multiprocessing/util.py", line 300, in _run_finalizers
    finalizer()
  File "/home/jlpkort/anaconda3/lib/python3.8/multiprocessing/util.py", line 224, in __call__
    res = self._callback(*self._args, **self._kwargs)
  File "/home/jlpkort/anaconda3/lib/python3.8/multiprocessing/util.py", line 133, in _remove_temp_dir
    rmtree(tempdir)
  File "/home/jlpkort/anaconda3/lib/python3.8/shutil.py", line 722, in rmtree
    onerror(os.rmdir, path, sys.exc_info())
  File "/home/jlpkort/anaconda3/lib/python3.8/shutil.py", line 720, in rmtree
    os.rmdir(path)
OSError: [Errno 39] Directory not empty: '/scratch/pymp-cecmiuqp'
I0917 09:49:23.388391 3306 trainer.py:117]  [Step: 11500/15000 (76.66666666666667%)] D Loss: -5.44914436340332 M Loss: 1.0211350917816162 G Loss: 0.10213372111320496 
I0917 10:30:03.426561 3306 trainer.py:117]  [Step: 12000/15000 (80.0%)] D Loss: -10.14648151397705 M Loss: 1.000580906867981 G Loss: 0.02338486909866333 
Traceback (most recent call last):
  File "/home/jlpkort/anaconda3/lib/python3.8/multiprocessing/util.py", line 300, in _run_finalizers
    finalizer()
  File "/home/jlpkort/anaconda3/lib/python3.8/multiprocessing/util.py", line 224, in __call__
    res = self._callback(*self._args, **self._kwargs)
  File "/home/jlpkort/anaconda3/lib/python3.8/multiprocessing/util.py", line 133, in _remove_temp_dir
    rmtree(tempdir)
  File "/home/jlpkort/anaconda3/lib/python3.8/shutil.py", line 722, in rmtree
    onerror(os.rmdir, path, sys.exc_info())
  File "/home/jlpkort/anaconda3/lib/python3.8/shutil.py", line 720, in rmtree
    os.rmdir(path)
OSError: [Errno 39] Directory not empty: '/scratch/pymp-gx8f0jnx'
I0917 11:10:42.971724 3306 trainer.py:117]  [Step: 12500/15000 (83.33333333333333%)] D Loss: -2.0109121799468994 M Loss: 1.017578125 G Loss: -0.035640180110931396 
Traceback (most recent call last):
  File "/home/jlpkort/anaconda3/lib/python3.8/multiprocessing/util.py", line 300, in _run_finalizers
    finalizer()
  File "/home/jlpkort/anaconda3/lib/python3.8/multiprocessing/util.py", line 224, in __call__
    res = self._callback(*self._args, **self._kwargs)
  File "/home/jlpkort/anaconda3/lib/python3.8/multiprocessing/util.py", line 133, in _remove_temp_dir
    rmtree(tempdir)
  File "/home/jlpkort/anaconda3/lib/python3.8/shutil.py", line 722, in rmtree
    onerror(os.rmdir, path, sys.exc_info())
  File "/home/jlpkort/anaconda3/lib/python3.8/shutil.py", line 720, in rmtree
    os.rmdir(path)
OSError: [Errno 39] Directory not empty: '/scratch/pymp-vnyis6t6'
I0917 11:51:20.244677 3306 trainer.py:117]  [Step: 13000/15000 (86.66666666666667%)] D Loss: -5.854978084564209 M Loss: 0.9906955361366272 G Loss: -0.07103323936462402 
Traceback (most recent call last):
  File "/home/jlpkort/anaconda3/lib/python3.8/multiprocessing/util.py", line 300, in _run_finalizers
    finalizer()
  File "/home/jlpkort/anaconda3/lib/python3.8/multiprocessing/util.py", line 224, in __call__
    res = self._callback(*self._args, **self._kwargs)
  File "/home/jlpkort/anaconda3/lib/python3.8/multiprocessing/util.py", line 133, in _remove_temp_dir
    rmtree(tempdir)
  File "/home/jlpkort/anaconda3/lib/python3.8/shutil.py", line 722, in rmtree
    onerror(os.rmdir, path, sys.exc_info())
  File "/home/jlpkort/anaconda3/lib/python3.8/shutil.py", line 720, in rmtree
    os.rmdir(path)
OSError: [Errno 39] Directory not empty: '/scratch/pymp-x8p0ywrs'
Traceback (most recent call last):
  File "/home/jlpkort/anaconda3/lib/python3.8/multiprocessing/util.py", line 300, in _run_finalizers
    finalizer()
  File "/home/jlpkort/anaconda3/lib/python3.8/multiprocessing/util.py", line 224, in __call__
    res = self._callback(*self._args, **self._kwargs)
  File "/home/jlpkort/anaconda3/lib/python3.8/multiprocessing/util.py", line 133, in _remove_temp_dir
    rmtree(tempdir)
  File "/home/jlpkort/anaconda3/lib/python3.8/shutil.py", line 722, in rmtree
    onerror(os.rmdir, path, sys.exc_info())
  File "/home/jlpkort/anaconda3/lib/python3.8/shutil.py", line 720, in rmtree
    os.rmdir(path)
OSError: [Errno 39] Directory not empty: '/scratch/pymp-xddbd7fs'
Traceback (most recent call last):
  File "/home/jlpkort/anaconda3/lib/python3.8/multiprocessing/util.py", line 300, in _run_finalizers
    finalizer()
  File "/home/jlpkort/anaconda3/lib/python3.8/multiprocessing/util.py", line 224, in __call__
    res = self._callback(*self._args, **self._kwargs)
  File "/home/jlpkort/anaconda3/lib/python3.8/multiprocessing/util.py", line 133, in _remove_temp_dir
    rmtree(tempdir)
  File "/home/jlpkort/anaconda3/lib/python3.8/shutil.py", line 722, in rmtree
    onerror(os.rmdir, path, sys.exc_info())
  File "/home/jlpkort/anaconda3/lib/python3.8/shutil.py", line 720, in rmtree
    os.rmdir(path)
OSError: [Errno 39] Directory not empty: '/scratch/pymp-ieywe5_y'
I0917 12:31:51.273956 3306 trainer.py:117]  [Step: 13500/15000 (90.0%)] D Loss: -7.85598087310791 M Loss: 1.0133070945739746 G Loss: 0.10590890049934387 
Traceback (most recent call last):
  File "/home/jlpkort/anaconda3/lib/python3.8/multiprocessing/util.py", line 300, in _run_finalizers
    finalizer()
  File "/home/jlpkort/anaconda3/lib/python3.8/multiprocessing/util.py", line 224, in __call__
    res = self._callback(*self._args, **self._kwargs)
  File "/home/jlpkort/anaconda3/lib/python3.8/multiprocessing/util.py", line 133, in _remove_temp_dir
    rmtree(tempdir)
  File "/home/jlpkort/anaconda3/lib/python3.8/shutil.py", line 722, in rmtree
    onerror(os.rmdir, path, sys.exc_info())
  File "/home/jlpkort/anaconda3/lib/python3.8/shutil.py", line 720, in rmtree
    os.rmdir(path)
OSError: [Errno 39] Directory not empty: '/scratch/pymp-wljms1_6'
Traceback (most recent call last):
  File "/home/jlpkort/anaconda3/lib/python3.8/multiprocessing/util.py", line 300, in _run_finalizers
    finalizer()
  File "/home/jlpkort/anaconda3/lib/python3.8/multiprocessing/util.py", line 224, in __call__
    res = self._callback(*self._args, **self._kwargs)
  File "/home/jlpkort/anaconda3/lib/python3.8/multiprocessing/util.py", line 133, in _remove_temp_dir
    rmtree(tempdir)
  File "/home/jlpkort/anaconda3/lib/python3.8/shutil.py", line 722, in rmtree
    onerror(os.rmdir, path, sys.exc_info())
  File "/home/jlpkort/anaconda3/lib/python3.8/shutil.py", line 720, in rmtree
    os.rmdir(path)
OSError: [Errno 39] Directory not empty: '/scratch/pymp-68vfflxe'
Traceback (most recent call last):
  File "/home/jlpkort/anaconda3/lib/python3.8/multiprocessing/util.py", line 300, in _run_finalizers
    finalizer()
  File "/home/jlpkort/anaconda3/lib/python3.8/multiprocessing/util.py", line 224, in __call__
    res = self._callback(*self._args, **self._kwargs)
  File "/home/jlpkort/anaconda3/lib/python3.8/multiprocessing/util.py", line 133, in _remove_temp_dir
    rmtree(tempdir)
  File "/home/jlpkort/anaconda3/lib/python3.8/shutil.py", line 722, in rmtree
    onerror(os.rmdir, path, sys.exc_info())
  File "/home/jlpkort/anaconda3/lib/python3.8/shutil.py", line 720, in rmtree
    os.rmdir(path)
OSError: [Errno 39] Directory not empty: '/scratch/pymp-j8tyxz83'
I0917 13:12:33.206198 3306 trainer.py:117]  [Step: 14000/15000 (93.33333333333333%)] D Loss: -4.244647979736328 M Loss: 1.0049853324890137 G Loss: -0.1437482237815857 
Traceback (most recent call last):
  File "/home/jlpkort/anaconda3/lib/python3.8/multiprocessing/util.py", line 300, in _run_finalizers
    finalizer()
  File "/home/jlpkort/anaconda3/lib/python3.8/multiprocessing/util.py", line 224, in __call__
    res = self._callback(*self._args, **self._kwargs)
  File "/home/jlpkort/anaconda3/lib/python3.8/multiprocessing/util.py", line 133, in _remove_temp_dir
    rmtree(tempdir)
  File "/home/jlpkort/anaconda3/lib/python3.8/shutil.py", line 722, in rmtree
    onerror(os.rmdir, path, sys.exc_info())
  File "/home/jlpkort/anaconda3/lib/python3.8/shutil.py", line 720, in rmtree
    os.rmdir(path)
OSError: [Errno 39] Directory not empty: '/scratch/pymp-2s40jab3'
Traceback (most recent call last):
  File "/home/jlpkort/anaconda3/lib/python3.8/multiprocessing/util.py", line 300, in _run_finalizers
    finalizer()
  File "/home/jlpkort/anaconda3/lib/python3.8/multiprocessing/util.py", line 224, in __call__
    res = self._callback(*self._args, **self._kwargs)
  File "/home/jlpkort/anaconda3/lib/python3.8/multiprocessing/util.py", line 133, in _remove_temp_dir
    rmtree(tempdir)
  File "/home/jlpkort/anaconda3/lib/python3.8/shutil.py", line 722, in rmtree
    onerror(os.rmdir, path, sys.exc_info())
  File "/home/jlpkort/anaconda3/lib/python3.8/shutil.py", line 720, in rmtree
    os.rmdir(path)
OSError: [Errno 39] Directory not empty: '/scratch/pymp-0ft43r4b'
Traceback (most recent call last):
  File "/home/jlpkort/anaconda3/lib/python3.8/multiprocessing/util.py", line 300, in _run_finalizers
    finalizer()
  File "/home/jlpkort/anaconda3/lib/python3.8/multiprocessing/util.py", line 224, in __call__
    res = self._callback(*self._args, **self._kwargs)
  File "/home/jlpkort/anaconda3/lib/python3.8/multiprocessing/util.py", line 133, in _remove_temp_dir
    rmtree(tempdir)
  File "/home/jlpkort/anaconda3/lib/python3.8/shutil.py", line 722, in rmtree
    onerror(os.rmdir, path, sys.exc_info())
  File "/home/jlpkort/anaconda3/lib/python3.8/shutil.py", line 720, in rmtree
    os.rmdir(path)
OSError: [Errno 39] Directory not empty: '/scratch/pymp-0qrgaolv'
Traceback (most recent call last):
  File "/home/jlpkort/anaconda3/lib/python3.8/multiprocessing/util.py", line 300, in _run_finalizers
    finalizer()
  File "/home/jlpkort/anaconda3/lib/python3.8/multiprocessing/util.py", line 224, in __call__
    res = self._callback(*self._args, **self._kwargs)
  File "/home/jlpkort/anaconda3/lib/python3.8/multiprocessing/util.py", line 133, in _remove_temp_dir
    rmtree(tempdir)
  File "/home/jlpkort/anaconda3/lib/python3.8/shutil.py", line 722, in rmtree
    onerror(os.rmdir, path, sys.exc_info())
  File "/home/jlpkort/anaconda3/lib/python3.8/shutil.py", line 720, in rmtree
    os.rmdir(path)
OSError: [Errno 39] Directory not empty: '/scratch/pymp-lqdx8vff'
I0917 13:53:13.391050 3306 trainer.py:117]  [Step: 14500/15000 (96.66666666666667%)] D Loss: -6.122775077819824 M Loss: 1.0113565921783447 G Loss: -0.12255102396011353 
Traceback (most recent call last):
  File "/home/jlpkort/anaconda3/lib/python3.8/multiprocessing/util.py", line 300, in _run_finalizers
    finalizer()
  File "/home/jlpkort/anaconda3/lib/python3.8/multiprocessing/util.py", line 224, in __call__
    res = self._callback(*self._args, **self._kwargs)
  File "/home/jlpkort/anaconda3/lib/python3.8/multiprocessing/util.py", line 133, in _remove_temp_dir
    rmtree(tempdir)
  File "/home/jlpkort/anaconda3/lib/python3.8/shutil.py", line 722, in rmtree
    onerror(os.rmdir, path, sys.exc_info())
  File "/home/jlpkort/anaconda3/lib/python3.8/shutil.py", line 720, in rmtree
    os.rmdir(path)
OSError: [Errno 39] Directory not empty: '/scratch/pymp-l47nd_d_'
I0917 14:33:56.309421 3306 trainer.py:117]  [Step: 15000/15000 (100.0%)] D Loss: -9.37678337097168 M Loss: 0.9959514141082764 G Loss: 0.10654473304748535 
wandb: Waiting for W&B process to finish, PID 3361
wandb: Program ended successfully.
wandb: - 7.36MB of 7.36MB uploaded (0.00MB deduped)wandb: \ 7.36MB of 7.36MB uploaded (0.00MB deduped)wandb: | 7.36MB of 7.44MB uploaded (0.00MB deduped)wandb: / 7.36MB of 7.44MB uploaded (0.00MB deduped)wandb: - 7.44MB of 7.44MB uploaded (0.00MB deduped)wandb: \ 7.44MB of 7.44MB uploaded (0.00MB deduped)wandb: | 7.44MB of 7.44MB uploaded (0.00MB deduped)wandb: / 7.44MB of 7.44MB uploaded (0.00MB deduped)wandb: - 7.44MB of 7.44MB uploaded (0.00MB deduped)wandb: \ 7.44MB of 7.44MB uploaded (0.00MB deduped)wandb: | 7.44MB of 7.44MB uploaded (0.00MB deduped)wandb: / 7.44MB of 7.44MB uploaded (0.00MB deduped)wandb:                                                                                
wandb: Find user logs for this run at: /home/jlpkort/vcnet-blind-image-inpainting/wandb/run-20210916_171908-1kibe3op/logs/debug.log
wandb: Find internal logs for this run at: /home/jlpkort/vcnet-blind-image-inpainting/wandb/run-20210916_171908-1kibe3op/logs/debug-internal.log
wandb: Run summary:
wandb:   real_global_validity -174.32068
wandb:   fake_global_validity 170.43086
wandb:    real_patch_validity -137.48111
wandb:    fake_patch_validity 131.21942
wandb:              gp_global 0.01186
wandb:                gp_fake 0.06561
wandb:          real_validity -311.80179
wandb:          fake_validity 301.65027
wandb:                     gp 0.07747
wandb:                 m_loss 0.99595
wandb:             recon_loss 0.04008
wandb:         sem_const_loss 0.20447
wandb:         tex_const_loss 3.56146
wandb:        adv_global_loss -172.16367
wandb:         adv_patch_loss -135.59616
wandb:               adv_loss -307.75983
wandb:               _runtime 76488
wandb:             _timestamp 1631882036
wandb:                  _step 14999
wandb: Synced 6 W&B file(s), 180 media file(s), 0 artifact file(s) and 0 other file(s)
wandb: 
wandb: Synced unique-sun-159: https://wandb.ai/tijmenk_/thesis_pytorch/runs/1kibe3op

