Looking in links: https://download.pytorch.org/whl/torch_stable.html
Requirement already satisfied: torch==1.5.0+cu101 in /home/jlpkort/anaconda3/lib/python3.8/site-packages (1.5.0+cu101)
Requirement already satisfied: torchvision==0.6.0+cu101 in /home/jlpkort/anaconda3/lib/python3.8/site-packages (0.6.0+cu101)
Requirement already satisfied: future in /home/jlpkort/anaconda3/lib/python3.8/site-packages (from torch==1.5.0+cu101) (0.18.2)
Requirement already satisfied: numpy in /home/jlpkort/anaconda3/lib/python3.8/site-packages (from torch==1.5.0+cu101) (1.17.4)
Requirement already satisfied: pillow>=4.1.1 in /home/jlpkort/anaconda3/lib/python3.8/site-packages (from torchvision==0.6.0+cu101) (8.2.0)
ERROR: Could not find a version that satisfies the requirement opencv_contrib_python_nonfree==4.1.1.1
ERROR: No matching distribution found for opencv_contrib_python_nonfree==4.1.1.1
wandb: Currently logged in as: tijmenk_ (use `wandb login --relogin` to force relogin)
DATASET:
  MASKS: ./datasets/masks_tv_256
  NAME: TVB
  ROOT: ./datasets/data_256
  SIZE: 256
  SIZE_H: 256
  SIZE_W: 256
MODEL:
  D:
    BETAS: (0.9, 0.99)
    DECAY_RATE: 0.5
    LR: 1e-05
    NAME: 1-ChOutputDiscriminator
    NUM_CHANNELS: 64
    NUM_CRITICS: 5
    SCHEDULER: []
  IS_TRAIN: True
  JOINT:
    BETAS: (0.9, 0.99)
    DECAY_RATE: 0.5
    LR: 0.0002
    NAME: JointNetwork
    SCHEDULER: []
  MPN:
    BETAS: (0.9, 0.99)
    DECAY_RATE: 0.0
    LOSS_COEFF: 2.0
    LR: 1e-05
    NAME: MaskPredictionNetwork
    NECK_CHANNELS: 128
    NUM_CHANNELS: 64
    SCHEDULER: []
  NAME: VCNet
  RIN:
    BETAS: (0.5, 0.9)
    DECAY_RATE: 0.0
    EMBRACE: True
    LOSS_COEFF: 1.0
    LR: 0.0001
    NAME: RobustInpaintingNetwork
    NECK_CHANNELS: 128
    NUM_CHANNELS: 32
    SCHEDULER: []
OPTIM:
  ADVERSARIAL: 0.001
  GP: 10
  MASK: 1
  RECON: 1.4
  SEMANTIC: 0.0001
  TEXTURE: 0.001
SYSTEM:
  NUM_GPU: 4
  NUM_WORKERS: 16
TEST:
  ABLATION: False
  BATCH_SIZE: 64
  C_IMG_ID: 38
  IMG_ID: 52
  ITER: 4
  MODE: 7
  OUTPUT_DIR: ./outputs
  WEIGHTS: None
TRAIN:
  BATCH_SIZE: 4
  LOG_INTERVAL: 1000
  NUM_STEPS_FOR_JOINT: 6600
  NUM_TOTAL_STEP: 100000
  RESUME: False
  SAVE_DIR: ./weights
  SAVE_INTERVAL: 10000
  SHUFFLE: True
  START_STEP: 0
  TUNE: False
  VISUALIZE_INTERVAL: 1000
WANDB:
  ENTITY: tijmenk_
  LOG_DIR: 
  NUM_ROW: 0
  PROJECT_NAME: thesis_pytorch
  RUN: 16
wandb: wandb version 0.12.1 is available!  To upgrade, please run:
wandb:  $ pip install wandb --upgrade
wandb: Tracking run with wandb version 0.11.0
wandb: Syncing run hopeful-cosmos-126
wandb:  View project at https://wandb.ai/tijmenk_/thesis_pytorch
wandb:  View run at https://wandb.ai/tijmenk_/thesis_pytorch/runs/3j7x24zc
wandb: Run data is saved locally in /home/jlpkort/vcnet-blind-image-inpainting/wandb/run-20210907_135611-3j7x24zc
wandb: Run `wandb offline` to turn off syncing.
I0907 13:56:19.305220 8380 trainer.py:244] Using 4 GPUs...

Traceback (most recent call last):
  File "/home/jlpkort/anaconda3/lib/python3.8/multiprocessing/util.py", line 300, in _run_finalizers
    finalizer()
  File "/home/jlpkort/anaconda3/lib/python3.8/multiprocessing/util.py", line 224, in __call__
    res = self._callback(*self._args, **self._kwargs)
  File "/home/jlpkort/anaconda3/lib/python3.8/multiprocessing/util.py", line 133, in _remove_temp_dir
    rmtree(tempdir)
  File "/home/jlpkort/anaconda3/lib/python3.8/shutil.py", line 722, in rmtree
    onerror(os.rmdir, path, sys.exc_info())
  File "/home/jlpkort/anaconda3/lib/python3.8/shutil.py", line 720, in rmtree
    os.rmdir(path)
OSError: [Errno 39] Directory not empty: '/scratch/pymp-gf2auizy'
Traceback (most recent call last):
  File "/home/jlpkort/anaconda3/lib/python3.8/multiprocessing/util.py", line 300, in _run_finalizers
    finalizer()
  File "/home/jlpkort/anaconda3/lib/python3.8/multiprocessing/util.py", line 224, in __call__
    res = self._callback(*self._args, **self._kwargs)
  File "/home/jlpkort/anaconda3/lib/python3.8/multiprocessing/util.py", line 133, in _remove_temp_dir
    rmtree(tempdir)
  File "/home/jlpkort/anaconda3/lib/python3.8/shutil.py", line 722, in rmtree
    onerror(os.rmdir, path, sys.exc_info())
  File "/home/jlpkort/anaconda3/lib/python3.8/shutil.py", line 720, in rmtree
    os.rmdir(path)
OSError: [Errno 39] Directory not empty: '/scratch/pymp-mf6jiup8'
Traceback (most recent call last):
  File "/home/jlpkort/anaconda3/lib/python3.8/multiprocessing/util.py", line 300, in _run_finalizers
    finalizer()
  File "/home/jlpkort/anaconda3/lib/python3.8/multiprocessing/util.py", line 224, in __call__
    res = self._callback(*self._args, **self._kwargs)
  File "/home/jlpkort/anaconda3/lib/python3.8/multiprocessing/util.py", line 133, in _remove_temp_dir
    rmtree(tempdir)
  File "/home/jlpkort/anaconda3/lib/python3.8/shutil.py", line 722, in rmtree
    onerror(os.rmdir, path, sys.exc_info())
  File "/home/jlpkort/anaconda3/lib/python3.8/shutil.py", line 720, in rmtree
    os.rmdir(path)
OSError: [Errno 39] Directory not empty: '/scratch/pymp-myj64l_9'
Traceback (most recent call last):
  File "/home/jlpkort/anaconda3/lib/python3.8/multiprocessing/util.py", line 300, in _run_finalizers
    finalizer()
  File "/home/jlpkort/anaconda3/lib/python3.8/multiprocessing/util.py", line 224, in __call__
    res = self._callback(*self._args, **self._kwargs)
  File "/home/jlpkort/anaconda3/lib/python3.8/multiprocessing/util.py", line 133, in _remove_temp_dir
    rmtree(tempdir)
  File "/home/jlpkort/anaconda3/lib/python3.8/shutil.py", line 722, in rmtree
    onerror(os.rmdir, path, sys.exc_info())
  File "/home/jlpkort/anaconda3/lib/python3.8/shutil.py", line 720, in rmtree
    os.rmdir(path)
OSError: [Errno 39] Directory not empty: '/scratch/pymp-4m7jdl3b'
Traceback (most recent call last):
  File "/home/jlpkort/anaconda3/lib/python3.8/multiprocessing/util.py", line 300, in _run_finalizers
    finalizer()
  File "/home/jlpkort/anaconda3/lib/python3.8/multiprocessing/util.py", line 224, in __call__
    res = self._callback(*self._args, **self._kwargs)
  File "/home/jlpkort/anaconda3/lib/python3.8/multiprocessing/util.py", line 133, in _remove_temp_dir
    rmtree(tempdir)
  File "/home/jlpkort/anaconda3/lib/python3.8/shutil.py", line 722, in rmtree
    onerror(os.rmdir, path, sys.exc_info())
  File "/home/jlpkort/anaconda3/lib/python3.8/shutil.py", line 720, in rmtree
    os.rmdir(path)
OSError: [Errno 39] Directory not empty: '/scratch/pymp-96qdx252'
Traceback (most recent call last):
  File "/home/jlpkort/anaconda3/lib/python3.8/multiprocessing/util.py", line 300, in _run_finalizers
    finalizer()
  File "/home/jlpkort/anaconda3/lib/python3.8/multiprocessing/util.py", line 224, in __call__
    res = self._callback(*self._args, **self._kwargs)
  File "/home/jlpkort/anaconda3/lib/python3.8/multiprocessing/util.py", line 133, in _remove_temp_dir
    rmtree(tempdir)
  File "/home/jlpkort/anaconda3/lib/python3.8/shutil.py", line 722, in rmtree
    onerror(os.rmdir, path, sys.exc_info())
  File "/home/jlpkort/anaconda3/lib/python3.8/shutil.py", line 720, in rmtree
    os.rmdir(path)
OSError: [Errno 39] Directory not empty: '/scratch/pymp-xjloku22'
Traceback (most recent call last):
  File "/home/jlpkort/anaconda3/lib/python3.8/multiprocessing/util.py", line 300, in _run_finalizers
    finalizer()
  File "/home/jlpkort/anaconda3/lib/python3.8/multiprocessing/util.py", line 224, in __call__
    res = self._callback(*self._args, **self._kwargs)
  File "/home/jlpkort/anaconda3/lib/python3.8/multiprocessing/util.py", line 133, in _remove_temp_dir
    rmtree(tempdir)
  File "/home/jlpkort/anaconda3/lib/python3.8/shutil.py", line 722, in rmtree
    onerror(os.rmdir, path, sys.exc_info())
  File "/home/jlpkort/anaconda3/lib/python3.8/shutil.py", line 720, in rmtree
    os.rmdir(path)
OSError: [Errno 39] Directory not empty: '/scratch/pymp-isvft_dj'
I0907 15:16:53.699945 8380 trainer.py:117]  [Step: 1000/100000 (1.0%)] D Loss: -15.03230094909668 M Loss: 1.3599843978881836 G Loss: 0.08086681365966797 
Traceback (most recent call last):
  File "/home/jlpkort/anaconda3/lib/python3.8/multiprocessing/util.py", line 300, in _run_finalizers
    finalizer()
  File "/home/jlpkort/anaconda3/lib/python3.8/multiprocessing/util.py", line 224, in __call__
    res = self._callback(*self._args, **self._kwargs)
  File "/home/jlpkort/anaconda3/lib/python3.8/multiprocessing/util.py", line 133, in _remove_temp_dir
    rmtree(tempdir)
  File "/home/jlpkort/anaconda3/lib/python3.8/shutil.py", line 722, in rmtree
    onerror(os.rmdir, path, sys.exc_info())
  File "/home/jlpkort/anaconda3/lib/python3.8/shutil.py", line 720, in rmtree
    os.rmdir(path)
OSError: [Errno 39] Directory not empty: '/scratch/pymp-0mouz76z'
Traceback (most recent call last):
  File "/home/jlpkort/anaconda3/lib/python3.8/multiprocessing/util.py", line 300, in _run_finalizers
    finalizer()
  File "/home/jlpkort/anaconda3/lib/python3.8/multiprocessing/util.py", line 224, in __call__
    res = self._callback(*self._args, **self._kwargs)
  File "/home/jlpkort/anaconda3/lib/python3.8/multiprocessing/util.py", line 133, in _remove_temp_dir
    rmtree(tempdir)
  File "/home/jlpkort/anaconda3/lib/python3.8/shutil.py", line 722, in rmtree
    onerror(os.rmdir, path, sys.exc_info())
  File "/home/jlpkort/anaconda3/lib/python3.8/shutil.py", line 720, in rmtree
    os.rmdir(path)
OSError: [Errno 39] Directory not empty: '/scratch/pymp-7ei1iab4'
Traceback (most recent call last):
  File "/home/jlpkort/anaconda3/lib/python3.8/multiprocessing/util.py", line 300, in _run_finalizers
    finalizer()
  File "/home/jlpkort/anaconda3/lib/python3.8/multiprocessing/util.py", line 224, in __call__
    res = self._callback(*self._args, **self._kwargs)
  File "/home/jlpkort/anaconda3/lib/python3.8/multiprocessing/util.py", line 133, in _remove_temp_dir
    rmtree(tempdir)
  File "/home/jlpkort/anaconda3/lib/python3.8/shutil.py", line 722, in rmtree
    onerror(os.rmdir, path, sys.exc_info())
  File "/home/jlpkort/anaconda3/lib/python3.8/shutil.py", line 720, in rmtree
    os.rmdir(path)
OSError: [Errno 39] Directory not empty: '/scratch/pymp-h9ryvnc6'
Traceback (most recent call last):
  File "/home/jlpkort/anaconda3/lib/python3.8/multiprocessing/util.py", line 300, in _run_finalizers
    finalizer()
  File "/home/jlpkort/anaconda3/lib/python3.8/multiprocessing/util.py", line 224, in __call__
    res = self._callback(*self._args, **self._kwargs)
  File "/home/jlpkort/anaconda3/lib/python3.8/multiprocessing/util.py", line 133, in _remove_temp_dir
    rmtree(tempdir)
  File "/home/jlpkort/anaconda3/lib/python3.8/shutil.py", line 722, in rmtree
    onerror(os.rmdir, path, sys.exc_info())
  File "/home/jlpkort/anaconda3/lib/python3.8/shutil.py", line 720, in rmtree
    os.rmdir(path)
OSError: [Errno 39] Directory not empty: '/scratch/pymp-gpqw_fxg'
Traceback (most recent call last):
  File "/home/jlpkort/anaconda3/lib/python3.8/multiprocessing/util.py", line 300, in _run_finalizers
    finalizer()
  File "/home/jlpkort/anaconda3/lib/python3.8/multiprocessing/util.py", line 224, in __call__
    res = self._callback(*self._args, **self._kwargs)
  File "/home/jlpkort/anaconda3/lib/python3.8/multiprocessing/util.py", line 133, in _remove_temp_dir
    rmtree(tempdir)
  File "/home/jlpkort/anaconda3/lib/python3.8/shutil.py", line 722, in rmtree
    onerror(os.rmdir, path, sys.exc_info())
  File "/home/jlpkort/anaconda3/lib/python3.8/shutil.py", line 720, in rmtree
    os.rmdir(path)
OSError: [Errno 39] Directory not empty: '/scratch/pymp-9mdx62gl'
Traceback (most recent call last):
  File "/home/jlpkort/anaconda3/lib/python3.8/multiprocessing/util.py", line 300, in _run_finalizers
    finalizer()
  File "/home/jlpkort/anaconda3/lib/python3.8/multiprocessing/util.py", line 224, in __call__
    res = self._callback(*self._args, **self._kwargs)
  File "/home/jlpkort/anaconda3/lib/python3.8/multiprocessing/util.py", line 133, in _remove_temp_dir
    rmtree(tempdir)
  File "/home/jlpkort/anaconda3/lib/python3.8/shutil.py", line 722, in rmtree
    onerror(os.rmdir, path, sys.exc_info())
  File "/home/jlpkort/anaconda3/lib/python3.8/shutil.py", line 720, in rmtree
    os.rmdir(path)
OSError: [Errno 39] Directory not empty: '/scratch/pymp-qv73d5to'
Traceback (most recent call last):
  File "/home/jlpkort/anaconda3/lib/python3.8/multiprocessing/util.py", line 300, in _run_finalizers
    finalizer()
  File "/home/jlpkort/anaconda3/lib/python3.8/multiprocessing/util.py", line 224, in __call__
    res = self._callback(*self._args, **self._kwargs)
  File "/home/jlpkort/anaconda3/lib/python3.8/multiprocessing/util.py", line 133, in _remove_temp_dir
    rmtree(tempdir)
  File "/home/jlpkort/anaconda3/lib/python3.8/shutil.py", line 722, in rmtree
    onerror(os.rmdir, path, sys.exc_info())
  File "/home/jlpkort/anaconda3/lib/python3.8/shutil.py", line 720, in rmtree
    os.rmdir(path)
OSError: [Errno 39] Directory not empty: '/scratch/pymp-hsd3b78a'
Traceback (most recent call last):
  File "/home/jlpkort/anaconda3/lib/python3.8/multiprocessing/util.py", line 300, in _run_finalizers
    finalizer()
  File "/home/jlpkort/anaconda3/lib/python3.8/multiprocessing/util.py", line 224, in __call__
    res = self._callback(*self._args, **self._kwargs)
  File "/home/jlpkort/anaconda3/lib/python3.8/multiprocessing/util.py", line 133, in _remove_temp_dir
    rmtree(tempdir)
  File "/home/jlpkort/anaconda3/lib/python3.8/shutil.py", line 722, in rmtree
    onerror(os.rmdir, path, sys.exc_info())
  File "/home/jlpkort/anaconda3/lib/python3.8/shutil.py", line 720, in rmtree
    os.rmdir(path)
OSError: [Errno 39] Directory not empty: '/scratch/pymp-dd0puchi'
I0907 16:37:39.276122 8380 trainer.py:117]  [Step: 2000/100000 (2.0%)] D Loss: -24.742698669433594 M Loss: 1.4130324125289917 G Loss: 0.07238538563251495 
Traceback (most recent call last):
  File "/home/jlpkort/anaconda3/lib/python3.8/multiprocessing/util.py", line 300, in _run_finalizers
    finalizer()
  File "/home/jlpkort/anaconda3/lib/python3.8/multiprocessing/util.py", line 224, in __call__
    res = self._callback(*self._args, **self._kwargs)
  File "/home/jlpkort/anaconda3/lib/python3.8/multiprocessing/util.py", line 133, in _remove_temp_dir
    rmtree(tempdir)
  File "/home/jlpkort/anaconda3/lib/python3.8/shutil.py", line 722, in rmtree
    onerror(os.rmdir, path, sys.exc_info())
  File "/home/jlpkort/anaconda3/lib/python3.8/shutil.py", line 720, in rmtree
    os.rmdir(path)
OSError: [Errno 39] Directory not empty: '/scratch/pymp-108xuxaq'
Traceback (most recent call last):
  File "/home/jlpkort/anaconda3/lib/python3.8/multiprocessing/util.py", line 300, in _run_finalizers
    finalizer()
  File "/home/jlpkort/anaconda3/lib/python3.8/multiprocessing/util.py", line 224, in __call__
    res = self._callback(*self._args, **self._kwargs)
  File "/home/jlpkort/anaconda3/lib/python3.8/multiprocessing/util.py", line 133, in _remove_temp_dir
    rmtree(tempdir)
  File "/home/jlpkort/anaconda3/lib/python3.8/shutil.py", line 722, in rmtree
    onerror(os.rmdir, path, sys.exc_info())
  File "/home/jlpkort/anaconda3/lib/python3.8/shutil.py", line 720, in rmtree
    os.rmdir(path)
OSError: [Errno 39] Directory not empty: '/scratch/pymp-zi5otajh'
Traceback (most recent call last):
  File "/home/jlpkort/anaconda3/lib/python3.8/multiprocessing/util.py", line 300, in _run_finalizers
    finalizer()
  File "/home/jlpkort/anaconda3/lib/python3.8/multiprocessing/util.py", line 224, in __call__
    res = self._callback(*self._args, **self._kwargs)
  File "/home/jlpkort/anaconda3/lib/python3.8/multiprocessing/util.py", line 133, in _remove_temp_dir
    rmtree(tempdir)
  File "/home/jlpkort/anaconda3/lib/python3.8/shutil.py", line 722, in rmtree
    onerror(os.rmdir, path, sys.exc_info())
  File "/home/jlpkort/anaconda3/lib/python3.8/shutil.py", line 720, in rmtree
    os.rmdir(path)
OSError: [Errno 39] Directory not empty: '/scratch/pymp-lcd3wycm'
I0907 17:59:28.315672 8380 trainer.py:117]  [Step: 3000/100000 (3.0%)] D Loss: -13.112390518188477 M Loss: 1.4280263185501099 G Loss: 0.05602538213133812 
Traceback (most recent call last):
  File "/home/jlpkort/anaconda3/lib/python3.8/multiprocessing/util.py", line 300, in _run_finalizers
    finalizer()
  File "/home/jlpkort/anaconda3/lib/python3.8/multiprocessing/util.py", line 224, in __call__
    res = self._callback(*self._args, **self._kwargs)
  File "/home/jlpkort/anaconda3/lib/python3.8/multiprocessing/util.py", line 133, in _remove_temp_dir
    rmtree(tempdir)
  File "/home/jlpkort/anaconda3/lib/python3.8/shutil.py", line 722, in rmtree
    onerror(os.rmdir, path, sys.exc_info())
  File "/home/jlpkort/anaconda3/lib/python3.8/shutil.py", line 720, in rmtree
    os.rmdir(path)
OSError: [Errno 39] Directory not empty: '/scratch/pymp-rh5fso2x'
Traceback (most recent call last):
  File "/home/jlpkort/anaconda3/lib/python3.8/multiprocessing/util.py", line 300, in _run_finalizers
    finalizer()
  File "/home/jlpkort/anaconda3/lib/python3.8/multiprocessing/util.py", line 224, in __call__
    res = self._callback(*self._args, **self._kwargs)
  File "/home/jlpkort/anaconda3/lib/python3.8/multiprocessing/util.py", line 133, in _remove_temp_dir
    rmtree(tempdir)
  File "/home/jlpkort/anaconda3/lib/python3.8/shutil.py", line 722, in rmtree
    onerror(os.rmdir, path, sys.exc_info())
  File "/home/jlpkort/anaconda3/lib/python3.8/shutil.py", line 720, in rmtree
    os.rmdir(path)
OSError: [Errno 39] Directory not empty: '/scratch/pymp-97k9gxhm'
I0907 19:21:33.663883 8380 trainer.py:117]  [Step: 4000/100000 (4.0%)] D Loss: -38.83182907104492 M Loss: 1.2498581409454346 G Loss: 0.07510971277952194 
Traceback (most recent call last):
  File "/home/jlpkort/anaconda3/lib/python3.8/multiprocessing/util.py", line 300, in _run_finalizers
    finalizer()
  File "/home/jlpkort/anaconda3/lib/python3.8/multiprocessing/util.py", line 224, in __call__
    res = self._callback(*self._args, **self._kwargs)
  File "/home/jlpkort/anaconda3/lib/python3.8/multiprocessing/util.py", line 133, in _remove_temp_dir
    rmtree(tempdir)
  File "/home/jlpkort/anaconda3/lib/python3.8/shutil.py", line 722, in rmtree
    onerror(os.rmdir, path, sys.exc_info())
  File "/home/jlpkort/anaconda3/lib/python3.8/shutil.py", line 720, in rmtree
    os.rmdir(path)
OSError: [Errno 39] Directory not empty: '/scratch/pymp-03z16oq5'
Traceback (most recent call last):
  File "/home/jlpkort/anaconda3/lib/python3.8/multiprocessing/util.py", line 300, in _run_finalizers
    finalizer()
  File "/home/jlpkort/anaconda3/lib/python3.8/multiprocessing/util.py", line 224, in __call__
    res = self._callback(*self._args, **self._kwargs)
  File "/home/jlpkort/anaconda3/lib/python3.8/multiprocessing/util.py", line 133, in _remove_temp_dir
    rmtree(tempdir)
  File "/home/jlpkort/anaconda3/lib/python3.8/shutil.py", line 722, in rmtree
    onerror(os.rmdir, path, sys.exc_info())
  File "/home/jlpkort/anaconda3/lib/python3.8/shutil.py", line 720, in rmtree
    os.rmdir(path)
OSError: [Errno 39] Directory not empty: '/scratch/pymp-uzsrxkmc'
Traceback (most recent call last):
  File "/home/jlpkort/anaconda3/lib/python3.8/multiprocessing/util.py", line 300, in _run_finalizers
    finalizer()
  File "/home/jlpkort/anaconda3/lib/python3.8/multiprocessing/util.py", line 224, in __call__
    res = self._callback(*self._args, **self._kwargs)
  File "/home/jlpkort/anaconda3/lib/python3.8/multiprocessing/util.py", line 133, in _remove_temp_dir
    rmtree(tempdir)
  File "/home/jlpkort/anaconda3/lib/python3.8/shutil.py", line 722, in rmtree
    onerror(os.rmdir, path, sys.exc_info())
  File "/home/jlpkort/anaconda3/lib/python3.8/shutil.py", line 720, in rmtree
    os.rmdir(path)
OSError: [Errno 39] Directory not empty: '/scratch/pymp-qwov3qko'
Traceback (most recent call last):
  File "/home/jlpkort/anaconda3/lib/python3.8/multiprocessing/util.py", line 300, in _run_finalizers
    finalizer()
  File "/home/jlpkort/anaconda3/lib/python3.8/multiprocessing/util.py", line 224, in __call__
    res = self._callback(*self._args, **self._kwargs)
  File "/home/jlpkort/anaconda3/lib/python3.8/multiprocessing/util.py", line 133, in _remove_temp_dir
    rmtree(tempdir)
  File "/home/jlpkort/anaconda3/lib/python3.8/shutil.py", line 722, in rmtree
    onerror(os.rmdir, path, sys.exc_info())
  File "/home/jlpkort/anaconda3/lib/python3.8/shutil.py", line 720, in rmtree
    os.rmdir(path)
OSError: [Errno 39] Directory not empty: '/scratch/pymp-xf5rpavb'
I0907 20:42:46.499251 8380 trainer.py:117]  [Step: 5000/100000 (5.0%)] D Loss: -7.871419906616211 M Loss: 1.3714404106140137 G Loss: 0.03831498324871063 
Traceback (most recent call last):
  File "/home/jlpkort/anaconda3/lib/python3.8/multiprocessing/util.py", line 300, in _run_finalizers
    finalizer()
  File "/home/jlpkort/anaconda3/lib/python3.8/multiprocessing/util.py", line 224, in __call__
    res = self._callback(*self._args, **self._kwargs)
  File "/home/jlpkort/anaconda3/lib/python3.8/multiprocessing/util.py", line 133, in _remove_temp_dir
    rmtree(tempdir)
  File "/home/jlpkort/anaconda3/lib/python3.8/shutil.py", line 722, in rmtree
    onerror(os.rmdir, path, sys.exc_info())
  File "/home/jlpkort/anaconda3/lib/python3.8/shutil.py", line 720, in rmtree
    os.rmdir(path)
OSError: [Errno 39] Directory not empty: '/scratch/pymp-9iha2dpx'
Traceback (most recent call last):
  File "/home/jlpkort/anaconda3/lib/python3.8/multiprocessing/util.py", line 300, in _run_finalizers
    finalizer()
  File "/home/jlpkort/anaconda3/lib/python3.8/multiprocessing/util.py", line 224, in __call__
    res = self._callback(*self._args, **self._kwargs)
  File "/home/jlpkort/anaconda3/lib/python3.8/multiprocessing/util.py", line 133, in _remove_temp_dir
    rmtree(tempdir)
  File "/home/jlpkort/anaconda3/lib/python3.8/shutil.py", line 722, in rmtree
    onerror(os.rmdir, path, sys.exc_info())
  File "/home/jlpkort/anaconda3/lib/python3.8/shutil.py", line 720, in rmtree
    os.rmdir(path)
OSError: [Errno 39] Directory not empty: '/scratch/pymp-cnftgp7z'
Traceback (most recent call last):
  File "/home/jlpkort/anaconda3/lib/python3.8/multiprocessing/util.py", line 300, in _run_finalizers
    finalizer()
  File "/home/jlpkort/anaconda3/lib/python3.8/multiprocessing/util.py", line 224, in __call__
    res = self._callback(*self._args, **self._kwargs)
  File "/home/jlpkort/anaconda3/lib/python3.8/multiprocessing/util.py", line 133, in _remove_temp_dir
    rmtree(tempdir)
  File "/home/jlpkort/anaconda3/lib/python3.8/shutil.py", line 722, in rmtree
    onerror(os.rmdir, path, sys.exc_info())
  File "/home/jlpkort/anaconda3/lib/python3.8/shutil.py", line 720, in rmtree
    os.rmdir(path)
OSError: [Errno 39] Directory not empty: '/scratch/pymp-rh6m7hms'
I0907 22:04:04.151599 8380 trainer.py:117]  [Step: 6000/100000 (6.0%)] D Loss: -6.446353912353516 M Loss: 1.3596336841583252 G Loss: 0.028548642992973328 
Traceback (most recent call last):
  File "/home/jlpkort/anaconda3/lib/python3.8/multiprocessing/util.py", line 300, in _run_finalizers
    finalizer()
  File "/home/jlpkort/anaconda3/lib/python3.8/multiprocessing/util.py", line 224, in __call__
    res = self._callback(*self._args, **self._kwargs)
  File "/home/jlpkort/anaconda3/lib/python3.8/multiprocessing/util.py", line 133, in _remove_temp_dir
    rmtree(tempdir)
  File "/home/jlpkort/anaconda3/lib/python3.8/shutil.py", line 722, in rmtree
    onerror(os.rmdir, path, sys.exc_info())
  File "/home/jlpkort/anaconda3/lib/python3.8/shutil.py", line 720, in rmtree
    os.rmdir(path)
OSError: [Errno 39] Directory not empty: '/scratch/pymp-j62nuj3o'
Traceback (most recent call last):
  File "/home/jlpkort/anaconda3/lib/python3.8/multiprocessing/util.py", line 300, in _run_finalizers
    finalizer()
  File "/home/jlpkort/anaconda3/lib/python3.8/multiprocessing/util.py", line 224, in __call__
    res = self._callback(*self._args, **self._kwargs)
  File "/home/jlpkort/anaconda3/lib/python3.8/multiprocessing/util.py", line 133, in _remove_temp_dir
    rmtree(tempdir)
  File "/home/jlpkort/anaconda3/lib/python3.8/shutil.py", line 722, in rmtree
    onerror(os.rmdir, path, sys.exc_info())
  File "/home/jlpkort/anaconda3/lib/python3.8/shutil.py", line 720, in rmtree
    os.rmdir(path)
OSError: [Errno 39] Directory not empty: '/scratch/pymp-1xof9vq_'
Traceback (most recent call last):
  File "/home/jlpkort/anaconda3/lib/python3.8/multiprocessing/util.py", line 300, in _run_finalizers
    finalizer()
  File "/home/jlpkort/anaconda3/lib/python3.8/multiprocessing/util.py", line 224, in __call__
    res = self._callback(*self._args, **self._kwargs)
  File "/home/jlpkort/anaconda3/lib/python3.8/multiprocessing/util.py", line 133, in _remove_temp_dir
    rmtree(tempdir)
  File "/home/jlpkort/anaconda3/lib/python3.8/shutil.py", line 722, in rmtree
    onerror(os.rmdir, path, sys.exc_info())
  File "/home/jlpkort/anaconda3/lib/python3.8/shutil.py", line 720, in rmtree
    os.rmdir(path)
OSError: [Errno 39] Directory not empty: '/scratch/pymp-cos36z0b'
Traceback (most recent call last):
  File "/home/jlpkort/anaconda3/lib/python3.8/multiprocessing/util.py", line 300, in _run_finalizers
    finalizer()
  File "/home/jlpkort/anaconda3/lib/python3.8/multiprocessing/util.py", line 224, in __call__
    res = self._callback(*self._args, **self._kwargs)
  File "/home/jlpkort/anaconda3/lib/python3.8/multiprocessing/util.py", line 133, in _remove_temp_dir
    rmtree(tempdir)
  File "/home/jlpkort/anaconda3/lib/python3.8/shutil.py", line 722, in rmtree
    onerror(os.rmdir, path, sys.exc_info())
  File "/home/jlpkort/anaconda3/lib/python3.8/shutil.py", line 720, in rmtree
    os.rmdir(path)
OSError: [Errno 39] Directory not empty: '/scratch/pymp-1_yz0mfw'
Traceback (most recent call last):
  File "/home/jlpkort/anaconda3/lib/python3.8/multiprocessing/util.py", line 300, in _run_finalizers
    finalizer()
  File "/home/jlpkort/anaconda3/lib/python3.8/multiprocessing/util.py", line 224, in __call__
    res = self._callback(*self._args, **self._kwargs)
  File "/home/jlpkort/anaconda3/lib/python3.8/multiprocessing/util.py", line 133, in _remove_temp_dir
    rmtree(tempdir)
  File "/home/jlpkort/anaconda3/lib/python3.8/shutil.py", line 722, in rmtree
    onerror(os.rmdir, path, sys.exc_info())
  File "/home/jlpkort/anaconda3/lib/python3.8/shutil.py", line 720, in rmtree
    os.rmdir(path)
OSError: [Errno 39] Directory not empty: '/scratch/pymp-ys2gz3nt'
Traceback (most recent call last):
  File "/home/jlpkort/anaconda3/lib/python3.8/multiprocessing/util.py", line 300, in _run_finalizers
    finalizer()
  File "/home/jlpkort/anaconda3/lib/python3.8/multiprocessing/util.py", line 224, in __call__
    res = self._callback(*self._args, **self._kwargs)
  File "/home/jlpkort/anaconda3/lib/python3.8/multiprocessing/util.py", line 133, in _remove_temp_dir
    rmtree(tempdir)
  File "/home/jlpkort/anaconda3/lib/python3.8/shutil.py", line 722, in rmtree
    onerror(os.rmdir, path, sys.exc_info())
  File "/home/jlpkort/anaconda3/lib/python3.8/shutil.py", line 720, in rmtree
    os.rmdir(path)
OSError: [Errno 39] Directory not empty: '/scratch/pymp-vzd4djil'
Traceback (most recent call last):
  File "/home/jlpkort/anaconda3/lib/python3.8/multiprocessing/util.py", line 300, in _run_finalizers
    finalizer()
  File "/home/jlpkort/anaconda3/lib/python3.8/multiprocessing/util.py", line 224, in __call__
    res = self._callback(*self._args, **self._kwargs)
  File "/home/jlpkort/anaconda3/lib/python3.8/multiprocessing/util.py", line 133, in _remove_temp_dir
    rmtree(tempdir)
  File "/home/jlpkort/anaconda3/lib/python3.8/shutil.py", line 722, in rmtree
    onerror(os.rmdir, path, sys.exc_info())
  File "/home/jlpkort/anaconda3/lib/python3.8/shutil.py", line 720, in rmtree
    os.rmdir(path)
OSError: [Errno 39] Directory not empty: '/scratch/pymp-lzz5zhva'
I0907 23:35:04.688617 8380 trainer.py:117]  [Step: 7000/100000 (7.0%)] D Loss: 0.03390044718980789 M Loss: 1.3532848358154297 G Loss: -0.06314925104379654 
Traceback (most recent call last):
  File "/home/jlpkort/anaconda3/lib/python3.8/multiprocessing/util.py", line 300, in _run_finalizers
    finalizer()
  File "/home/jlpkort/anaconda3/lib/python3.8/multiprocessing/util.py", line 224, in __call__
    res = self._callback(*self._args, **self._kwargs)
  File "/home/jlpkort/anaconda3/lib/python3.8/multiprocessing/util.py", line 133, in _remove_temp_dir
    rmtree(tempdir)
  File "/home/jlpkort/anaconda3/lib/python3.8/shutil.py", line 722, in rmtree
    onerror(os.rmdir, path, sys.exc_info())
  File "/home/jlpkort/anaconda3/lib/python3.8/shutil.py", line 720, in rmtree
    os.rmdir(path)
OSError: [Errno 39] Directory not empty: '/scratch/pymp-whg17hge'
Traceback (most recent call last):
  File "/home/jlpkort/anaconda3/lib/python3.8/multiprocessing/util.py", line 300, in _run_finalizers
    finalizer()
  File "/home/jlpkort/anaconda3/lib/python3.8/multiprocessing/util.py", line 224, in __call__
    res = self._callback(*self._args, **self._kwargs)
  File "/home/jlpkort/anaconda3/lib/python3.8/multiprocessing/util.py", line 133, in _remove_temp_dir
    rmtree(tempdir)
  File "/home/jlpkort/anaconda3/lib/python3.8/shutil.py", line 722, in rmtree
    onerror(os.rmdir, path, sys.exc_info())
  File "/home/jlpkort/anaconda3/lib/python3.8/shutil.py", line 720, in rmtree
    os.rmdir(path)
OSError: [Errno 39] Directory not empty: '/scratch/pymp-1oxkqqb7'
Traceback (most recent call last):
  File "/home/jlpkort/anaconda3/lib/python3.8/multiprocessing/util.py", line 300, in _run_finalizers
    finalizer()
  File "/home/jlpkort/anaconda3/lib/python3.8/multiprocessing/util.py", line 224, in __call__
    res = self._callback(*self._args, **self._kwargs)
  File "/home/jlpkort/anaconda3/lib/python3.8/multiprocessing/util.py", line 133, in _remove_temp_dir
    rmtree(tempdir)
  File "/home/jlpkort/anaconda3/lib/python3.8/shutil.py", line 722, in rmtree
    onerror(os.rmdir, path, sys.exc_info())
  File "/home/jlpkort/anaconda3/lib/python3.8/shutil.py", line 720, in rmtree
    os.rmdir(path)
OSError: [Errno 39] Directory not empty: '/scratch/pymp-jfpuwj0c'
Traceback (most recent call last):
  File "/home/jlpkort/anaconda3/lib/python3.8/multiprocessing/util.py", line 300, in _run_finalizers
    finalizer()
  File "/home/jlpkort/anaconda3/lib/python3.8/multiprocessing/util.py", line 224, in __call__
    res = self._callback(*self._args, **self._kwargs)
  File "/home/jlpkort/anaconda3/lib/python3.8/multiprocessing/util.py", line 133, in _remove_temp_dir
    rmtree(tempdir)
  File "/home/jlpkort/anaconda3/lib/python3.8/shutil.py", line 722, in rmtree
    onerror(os.rmdir, path, sys.exc_info())
  File "/home/jlpkort/anaconda3/lib/python3.8/shutil.py", line 720, in rmtree
    os.rmdir(path)
OSError: [Errno 39] Directory not empty: '/scratch/pymp-25io902e'
Traceback (most recent call last):
  File "/home/jlpkort/anaconda3/lib/python3.8/multiprocessing/util.py", line 300, in _run_finalizers
    finalizer()
  File "/home/jlpkort/anaconda3/lib/python3.8/multiprocessing/util.py", line 224, in __call__
    res = self._callback(*self._args, **self._kwargs)
  File "/home/jlpkort/anaconda3/lib/python3.8/multiprocessing/util.py", line 133, in _remove_temp_dir
    rmtree(tempdir)
  File "/home/jlpkort/anaconda3/lib/python3.8/shutil.py", line 722, in rmtree
    onerror(os.rmdir, path, sys.exc_info())
  File "/home/jlpkort/anaconda3/lib/python3.8/shutil.py", line 720, in rmtree
    os.rmdir(path)
OSError: [Errno 39] Directory not empty: '/scratch/pymp-6bfvkaxa'
Traceback (most recent call last):
  File "/home/jlpkort/anaconda3/lib/python3.8/multiprocessing/util.py", line 300, in _run_finalizers
    finalizer()
  File "/home/jlpkort/anaconda3/lib/python3.8/multiprocessing/util.py", line 224, in __call__
    res = self._callback(*self._args, **self._kwargs)
  File "/home/jlpkort/anaconda3/lib/python3.8/multiprocessing/util.py", line 133, in _remove_temp_dir
    rmtree(tempdir)
  File "/home/jlpkort/anaconda3/lib/python3.8/shutil.py", line 722, in rmtree
    onerror(os.rmdir, path, sys.exc_info())
  File "/home/jlpkort/anaconda3/lib/python3.8/shutil.py", line 720, in rmtree
    os.rmdir(path)
OSError: [Errno 39] Directory not empty: '/scratch/pymp-ywt7xt3s'
Traceback (most recent call last):
  File "/home/jlpkort/anaconda3/lib/python3.8/multiprocessing/util.py", line 300, in _run_finalizers
    finalizer()
  File "/home/jlpkort/anaconda3/lib/python3.8/multiprocessing/util.py", line 224, in __call__
    res = self._callback(*self._args, **self._kwargs)
  File "/home/jlpkort/anaconda3/lib/python3.8/multiprocessing/util.py", line 133, in _remove_temp_dir
    rmtree(tempdir)
  File "/home/jlpkort/anaconda3/lib/python3.8/shutil.py", line 722, in rmtree
    onerror(os.rmdir, path, sys.exc_info())
  File "/home/jlpkort/anaconda3/lib/python3.8/shutil.py", line 720, in rmtree
    os.rmdir(path)
OSError: [Errno 39] Directory not empty: '/scratch/pymp-dmbagql6'
Traceback (most recent call last):
  File "/home/jlpkort/anaconda3/lib/python3.8/multiprocessing/util.py", line 300, in _run_finalizers
    finalizer()
  File "/home/jlpkort/anaconda3/lib/python3.8/multiprocessing/util.py", line 224, in __call__
    res = self._callback(*self._args, **self._kwargs)
  File "/home/jlpkort/anaconda3/lib/python3.8/multiprocessing/util.py", line 133, in _remove_temp_dir
    rmtree(tempdir)
  File "/home/jlpkort/anaconda3/lib/python3.8/shutil.py", line 722, in rmtree
    onerror(os.rmdir, path, sys.exc_info())
  File "/home/jlpkort/anaconda3/lib/python3.8/shutil.py", line 720, in rmtree
    os.rmdir(path)
OSError: [Errno 39] Directory not empty: '/scratch/pymp-r7x8jemo'
Traceback (most recent call last):
  File "/home/jlpkort/anaconda3/lib/python3.8/multiprocessing/util.py", line 300, in _run_finalizers
    finalizer()
  File "/home/jlpkort/anaconda3/lib/python3.8/multiprocessing/util.py", line 224, in __call__
    res = self._callback(*self._args, **self._kwargs)
  File "/home/jlpkort/anaconda3/lib/python3.8/multiprocessing/util.py", line 133, in _remove_temp_dir
    rmtree(tempdir)
  File "/home/jlpkort/anaconda3/lib/python3.8/shutil.py", line 722, in rmtree
    onerror(os.rmdir, path, sys.exc_info())
  File "/home/jlpkort/anaconda3/lib/python3.8/shutil.py", line 720, in rmtree
    os.rmdir(path)
OSError: [Errno 39] Directory not empty: '/scratch/pymp-uhzg5pm3'
Traceback (most recent call last):
  File "/home/jlpkort/anaconda3/lib/python3.8/multiprocessing/util.py", line 300, in _run_finalizers
    finalizer()
  File "/home/jlpkort/anaconda3/lib/python3.8/multiprocessing/util.py", line 224, in __call__
    res = self._callback(*self._args, **self._kwargs)
  File "/home/jlpkort/anaconda3/lib/python3.8/multiprocessing/util.py", line 133, in _remove_temp_dir
    rmtree(tempdir)
  File "/home/jlpkort/anaconda3/lib/python3.8/shutil.py", line 722, in rmtree
    onerror(os.rmdir, path, sys.exc_info())
  File "/home/jlpkort/anaconda3/lib/python3.8/shutil.py", line 720, in rmtree
    os.rmdir(path)
OSError: [Errno 39] Directory not empty: '/scratch/pymp-voi2pctt'
Traceback (most recent call last):
  File "/home/jlpkort/anaconda3/lib/python3.8/multiprocessing/util.py", line 300, in _run_finalizers
    finalizer()
  File "/home/jlpkort/anaconda3/lib/python3.8/multiprocessing/util.py", line 224, in __call__
    res = self._callback(*self._args, **self._kwargs)
  File "/home/jlpkort/anaconda3/lib/python3.8/multiprocessing/util.py", line 133, in _remove_temp_dir
    rmtree(tempdir)
  File "/home/jlpkort/anaconda3/lib/python3.8/shutil.py", line 722, in rmtree
    onerror(os.rmdir, path, sys.exc_info())
  File "/home/jlpkort/anaconda3/lib/python3.8/shutil.py", line 720, in rmtree
    os.rmdir(path)
OSError: [Errno 39] Directory not empty: '/scratch/pymp-qboqmd0d'
Traceback (most recent call last):
  File "/home/jlpkort/anaconda3/lib/python3.8/multiprocessing/util.py", line 300, in _run_finalizers
    finalizer()
  File "/home/jlpkort/anaconda3/lib/python3.8/multiprocessing/util.py", line 224, in __call__
    res = self._callback(*self._args, **self._kwargs)
  File "/home/jlpkort/anaconda3/lib/python3.8/multiprocessing/util.py", line 133, in _remove_temp_dir
    rmtree(tempdir)
  File "/home/jlpkort/anaconda3/lib/python3.8/shutil.py", line 722, in rmtree
    onerror(os.rmdir, path, sys.exc_info())
  File "/home/jlpkort/anaconda3/lib/python3.8/shutil.py", line 720, in rmtree
    os.rmdir(path)
OSError: [Errno 39] Directory not empty: '/scratch/pymp-aee38z2l'
Traceback (most recent call last):
  File "/home/jlpkort/anaconda3/lib/python3.8/multiprocessing/util.py", line 300, in _run_finalizers
    finalizer()
  File "/home/jlpkort/anaconda3/lib/python3.8/multiprocessing/util.py", line 224, in __call__
    res = self._callback(*self._args, **self._kwargs)
  File "/home/jlpkort/anaconda3/lib/python3.8/multiprocessing/util.py", line 133, in _remove_temp_dir
    rmtree(tempdir)
  File "/home/jlpkort/anaconda3/lib/python3.8/shutil.py", line 722, in rmtree
    onerror(os.rmdir, path, sys.exc_info())
  File "/home/jlpkort/anaconda3/lib/python3.8/shutil.py", line 720, in rmtree
    os.rmdir(path)
OSError: [Errno 39] Directory not empty: '/scratch/pymp-fmia5bpv'
Traceback (most recent call last):
  File "/home/jlpkort/anaconda3/lib/python3.8/multiprocessing/util.py", line 300, in _run_finalizers
    finalizer()
  File "/home/jlpkort/anaconda3/lib/python3.8/multiprocessing/util.py", line 224, in __call__
    res = self._callback(*self._args, **self._kwargs)
  File "/home/jlpkort/anaconda3/lib/python3.8/multiprocessing/util.py", line 133, in _remove_temp_dir
    rmtree(tempdir)
  File "/home/jlpkort/anaconda3/lib/python3.8/shutil.py", line 722, in rmtree
    onerror(os.rmdir, path, sys.exc_info())
  File "/home/jlpkort/anaconda3/lib/python3.8/shutil.py", line 720, in rmtree
    os.rmdir(path)
OSError: [Errno 39] Directory not empty: '/scratch/pymp-z4e8t5lb'
I0908 01:04:13.550272 8380 trainer.py:117]  [Step: 8000/100000 (8.0%)] D Loss: -1.64990234375 M Loss: 1.0207061767578125 G Loss: -0.11304324865341187 
Traceback (most recent call last):
  File "/home/jlpkort/anaconda3/lib/python3.8/multiprocessing/util.py", line 300, in _run_finalizers
    finalizer()
  File "/home/jlpkort/anaconda3/lib/python3.8/multiprocessing/util.py", line 224, in __call__
    res = self._callback(*self._args, **self._kwargs)
  File "/home/jlpkort/anaconda3/lib/python3.8/multiprocessing/util.py", line 133, in _remove_temp_dir
    rmtree(tempdir)
  File "/home/jlpkort/anaconda3/lib/python3.8/shutil.py", line 722, in rmtree
    onerror(os.rmdir, path, sys.exc_info())
  File "/home/jlpkort/anaconda3/lib/python3.8/shutil.py", line 720, in rmtree
    os.rmdir(path)
OSError: [Errno 39] Directory not empty: '/scratch/pymp-mptdfz0w'
Traceback (most recent call last):
  File "/home/jlpkort/anaconda3/lib/python3.8/multiprocessing/util.py", line 300, in _run_finalizers
    finalizer()
  File "/home/jlpkort/anaconda3/lib/python3.8/multiprocessing/util.py", line 224, in __call__
    res = self._callback(*self._args, **self._kwargs)
  File "/home/jlpkort/anaconda3/lib/python3.8/multiprocessing/util.py", line 133, in _remove_temp_dir
    rmtree(tempdir)
  File "/home/jlpkort/anaconda3/lib/python3.8/shutil.py", line 722, in rmtree
    onerror(os.rmdir, path, sys.exc_info())
  File "/home/jlpkort/anaconda3/lib/python3.8/shutil.py", line 720, in rmtree
    os.rmdir(path)
OSError: [Errno 39] Directory not empty: '/scratch/pymp-njf5uknk'
Traceback (most recent call last):
  File "/home/jlpkort/anaconda3/lib/python3.8/multiprocessing/util.py", line 300, in _run_finalizers
    finalizer()
  File "/home/jlpkort/anaconda3/lib/python3.8/multiprocessing/util.py", line 224, in __call__
    res = self._callback(*self._args, **self._kwargs)
  File "/home/jlpkort/anaconda3/lib/python3.8/multiprocessing/util.py", line 133, in _remove_temp_dir
    rmtree(tempdir)
  File "/home/jlpkort/anaconda3/lib/python3.8/shutil.py", line 722, in rmtree
    onerror(os.rmdir, path, sys.exc_info())
  File "/home/jlpkort/anaconda3/lib/python3.8/shutil.py", line 720, in rmtree
    os.rmdir(path)
OSError: [Errno 39] Directory not empty: '/scratch/pymp-yt9iyb90'
Traceback (most recent call last):
  File "/home/jlpkort/anaconda3/lib/python3.8/multiprocessing/util.py", line 300, in _run_finalizers
    finalizer()
  File "/home/jlpkort/anaconda3/lib/python3.8/multiprocessing/util.py", line 224, in __call__
    res = self._callback(*self._args, **self._kwargs)
  File "/home/jlpkort/anaconda3/lib/python3.8/multiprocessing/util.py", line 133, in _remove_temp_dir
    rmtree(tempdir)
  File "/home/jlpkort/anaconda3/lib/python3.8/shutil.py", line 722, in rmtree
    onerror(os.rmdir, path, sys.exc_info())
  File "/home/jlpkort/anaconda3/lib/python3.8/shutil.py", line 720, in rmtree
    os.rmdir(path)
OSError: [Errno 39] Directory not empty: '/scratch/pymp-vfh413n8'
Traceback (most recent call last):
  File "/home/jlpkort/anaconda3/lib/python3.8/multiprocessing/util.py", line 300, in _run_finalizers
    finalizer()
  File "/home/jlpkort/anaconda3/lib/python3.8/multiprocessing/util.py", line 224, in __call__
    res = self._callback(*self._args, **self._kwargs)
  File "/home/jlpkort/anaconda3/lib/python3.8/multiprocessing/util.py", line 133, in _remove_temp_dir
    rmtree(tempdir)
  File "/home/jlpkort/anaconda3/lib/python3.8/shutil.py", line 722, in rmtree
    onerror(os.rmdir, path, sys.exc_info())
  File "/home/jlpkort/anaconda3/lib/python3.8/shutil.py", line 720, in rmtree
    os.rmdir(path)
OSError: [Errno 39] Directory not empty: '/scratch/pymp-f6p52d7c'
I0908 02:25:04.907808 8380 trainer.py:117]  [Step: 9000/100000 (9.0%)] D Loss: -5.642650127410889 M Loss: 1.0043978691101074 G Loss: -0.11702170968055725 
Traceback (most recent call last):
  File "/home/jlpkort/anaconda3/lib/python3.8/multiprocessing/util.py", line 300, in _run_finalizers
    finalizer()
  File "/home/jlpkort/anaconda3/lib/python3.8/multiprocessing/util.py", line 224, in __call__
    res = self._callback(*self._args, **self._kwargs)
  File "/home/jlpkort/anaconda3/lib/python3.8/multiprocessing/util.py", line 133, in _remove_temp_dir
    rmtree(tempdir)
  File "/home/jlpkort/anaconda3/lib/python3.8/shutil.py", line 722, in rmtree
    onerror(os.rmdir, path, sys.exc_info())
  File "/home/jlpkort/anaconda3/lib/python3.8/shutil.py", line 720, in rmtree
    os.rmdir(path)
OSError: [Errno 39] Directory not empty: '/scratch/pymp-zh4y5wst'
Traceback (most recent call last):
  File "/home/jlpkort/anaconda3/lib/python3.8/multiprocessing/util.py", line 300, in _run_finalizers
    finalizer()
  File "/home/jlpkort/anaconda3/lib/python3.8/multiprocessing/util.py", line 224, in __call__
    res = self._callback(*self._args, **self._kwargs)
  File "/home/jlpkort/anaconda3/lib/python3.8/multiprocessing/util.py", line 133, in _remove_temp_dir
    rmtree(tempdir)
  File "/home/jlpkort/anaconda3/lib/python3.8/shutil.py", line 722, in rmtree
    onerror(os.rmdir, path, sys.exc_info())
  File "/home/jlpkort/anaconda3/lib/python3.8/shutil.py", line 720, in rmtree
    os.rmdir(path)
OSError: [Errno 39] Directory not empty: '/scratch/pymp-xjn2ptu0'
Traceback (most recent call last):
  File "/home/jlpkort/anaconda3/lib/python3.8/multiprocessing/util.py", line 300, in _run_finalizers
    finalizer()
  File "/home/jlpkort/anaconda3/lib/python3.8/multiprocessing/util.py", line 224, in __call__
    res = self._callback(*self._args, **self._kwargs)
  File "/home/jlpkort/anaconda3/lib/python3.8/multiprocessing/util.py", line 133, in _remove_temp_dir
    rmtree(tempdir)
  File "/home/jlpkort/anaconda3/lib/python3.8/shutil.py", line 722, in rmtree
    onerror(os.rmdir, path, sys.exc_info())
  File "/home/jlpkort/anaconda3/lib/python3.8/shutil.py", line 720, in rmtree
    os.rmdir(path)
OSError: [Errno 39] Directory not empty: '/scratch/pymp-chmz4s5w'
Traceback (most recent call last):
  File "/home/jlpkort/anaconda3/lib/python3.8/multiprocessing/util.py", line 300, in _run_finalizers
    finalizer()
  File "/home/jlpkort/anaconda3/lib/python3.8/multiprocessing/util.py", line 224, in __call__
    res = self._callback(*self._args, **self._kwargs)
  File "/home/jlpkort/anaconda3/lib/python3.8/multiprocessing/util.py", line 133, in _remove_temp_dir
    rmtree(tempdir)
  File "/home/jlpkort/anaconda3/lib/python3.8/shutil.py", line 722, in rmtree
    onerror(os.rmdir, path, sys.exc_info())
  File "/home/jlpkort/anaconda3/lib/python3.8/shutil.py", line 720, in rmtree
    os.rmdir(path)
OSError: [Errno 39] Directory not empty: '/scratch/pymp-_ozpgp2x'
Traceback (most recent call last):
  File "/home/jlpkort/anaconda3/lib/python3.8/multiprocessing/util.py", line 300, in _run_finalizers
    finalizer()
  File "/home/jlpkort/anaconda3/lib/python3.8/multiprocessing/util.py", line 224, in __call__
    res = self._callback(*self._args, **self._kwargs)
  File "/home/jlpkort/anaconda3/lib/python3.8/multiprocessing/util.py", line 133, in _remove_temp_dir
    rmtree(tempdir)
  File "/home/jlpkort/anaconda3/lib/python3.8/shutil.py", line 722, in rmtree
    onerror(os.rmdir, path, sys.exc_info())
  File "/home/jlpkort/anaconda3/lib/python3.8/shutil.py", line 720, in rmtree
    os.rmdir(path)
OSError: [Errno 39] Directory not empty: '/scratch/pymp-jk63j4ou'
Traceback (most recent call last):
  File "/home/jlpkort/anaconda3/lib/python3.8/multiprocessing/util.py", line 300, in _run_finalizers
    finalizer()
  File "/home/jlpkort/anaconda3/lib/python3.8/multiprocessing/util.py", line 224, in __call__
    res = self._callback(*self._args, **self._kwargs)
  File "/home/jlpkort/anaconda3/lib/python3.8/multiprocessing/util.py", line 133, in _remove_temp_dir
    rmtree(tempdir)
  File "/home/jlpkort/anaconda3/lib/python3.8/shutil.py", line 722, in rmtree
    onerror(os.rmdir, path, sys.exc_info())
  File "/home/jlpkort/anaconda3/lib/python3.8/shutil.py", line 720, in rmtree
    os.rmdir(path)
OSError: [Errno 39] Directory not empty: '/scratch/pymp-rylfxxge'
Traceback (most recent call last):
  File "/home/jlpkort/anaconda3/lib/python3.8/multiprocessing/util.py", line 300, in _run_finalizers
    finalizer()
  File "/home/jlpkort/anaconda3/lib/python3.8/multiprocessing/util.py", line 224, in __call__
    res = self._callback(*self._args, **self._kwargs)
  File "/home/jlpkort/anaconda3/lib/python3.8/multiprocessing/util.py", line 133, in _remove_temp_dir
    rmtree(tempdir)
  File "/home/jlpkort/anaconda3/lib/python3.8/shutil.py", line 722, in rmtree
    onerror(os.rmdir, path, sys.exc_info())
  File "/home/jlpkort/anaconda3/lib/python3.8/shutil.py", line 720, in rmtree
    os.rmdir(path)
OSError: [Errno 39] Directory not empty: '/scratch/pymp-m97ecizn'
Traceback (most recent call last):
  File "/home/jlpkort/anaconda3/lib/python3.8/multiprocessing/util.py", line 300, in _run_finalizers
    finalizer()
  File "/home/jlpkort/anaconda3/lib/python3.8/multiprocessing/util.py", line 224, in __call__
    res = self._callback(*self._args, **self._kwargs)
  File "/home/jlpkort/anaconda3/lib/python3.8/multiprocessing/util.py", line 133, in _remove_temp_dir
    rmtree(tempdir)
  File "/home/jlpkort/anaconda3/lib/python3.8/shutil.py", line 722, in rmtree
    onerror(os.rmdir, path, sys.exc_info())
  File "/home/jlpkort/anaconda3/lib/python3.8/shutil.py", line 720, in rmtree
    os.rmdir(path)
OSError: [Errno 39] Directory not empty: '/scratch/pymp-bun1m5fq'
Traceback (most recent call last):
  File "/home/jlpkort/anaconda3/lib/python3.8/multiprocessing/util.py", line 300, in _run_finalizers
    finalizer()
  File "/home/jlpkort/anaconda3/lib/python3.8/multiprocessing/util.py", line 224, in __call__
    res = self._callback(*self._args, **self._kwargs)
  File "/home/jlpkort/anaconda3/lib/python3.8/multiprocessing/util.py", line 133, in _remove_temp_dir
    rmtree(tempdir)
  File "/home/jlpkort/anaconda3/lib/python3.8/shutil.py", line 722, in rmtree
    onerror(os.rmdir, path, sys.exc_info())
  File "/home/jlpkort/anaconda3/lib/python3.8/shutil.py", line 720, in rmtree
    os.rmdir(path)
OSError: [Errno 39] Directory not empty: '/scratch/pymp-ivkrn67w'
I0908 03:46:05.463316 8380 trainer.py:117]  [Step: 10000/100000 (10.0%)] D Loss: 0.36782097816467285 M Loss: 1.0000637769699097 G Loss: -0.09378701448440552 
Traceback (most recent call last):
  File "/home/jlpkort/anaconda3/lib/python3.8/multiprocessing/util.py", line 300, in _run_finalizers
    finalizer()
  File "/home/jlpkort/anaconda3/lib/python3.8/multiprocessing/util.py", line 224, in __call__
    res = self._callback(*self._args, **self._kwargs)
  File "/home/jlpkort/anaconda3/lib/python3.8/multiprocessing/util.py", line 133, in _remove_temp_dir
    rmtree(tempdir)
  File "/home/jlpkort/anaconda3/lib/python3.8/shutil.py", line 722, in rmtree
    onerror(os.rmdir, path, sys.exc_info())
  File "/home/jlpkort/anaconda3/lib/python3.8/shutil.py", line 720, in rmtree
    os.rmdir(path)
OSError: [Errno 39] Directory not empty: '/scratch/pymp-fmee_oij'
Traceback (most recent call last):
  File "/home/jlpkort/anaconda3/lib/python3.8/multiprocessing/util.py", line 300, in _run_finalizers
    finalizer()
  File "/home/jlpkort/anaconda3/lib/python3.8/multiprocessing/util.py", line 224, in __call__
    res = self._callback(*self._args, **self._kwargs)
  File "/home/jlpkort/anaconda3/lib/python3.8/multiprocessing/util.py", line 133, in _remove_temp_dir
    rmtree(tempdir)
  File "/home/jlpkort/anaconda3/lib/python3.8/shutil.py", line 722, in rmtree
    onerror(os.rmdir, path, sys.exc_info())
  File "/home/jlpkort/anaconda3/lib/python3.8/shutil.py", line 720, in rmtree
    os.rmdir(path)
OSError: [Errno 39] Directory not empty: '/scratch/pymp-rg7rv4e9'
Traceback (most recent call last):
  File "/home/jlpkort/anaconda3/lib/python3.8/multiprocessing/util.py", line 300, in _run_finalizers
    finalizer()
  File "/home/jlpkort/anaconda3/lib/python3.8/multiprocessing/util.py", line 224, in __call__
    res = self._callback(*self._args, **self._kwargs)
  File "/home/jlpkort/anaconda3/lib/python3.8/multiprocessing/util.py", line 133, in _remove_temp_dir
    rmtree(tempdir)
  File "/home/jlpkort/anaconda3/lib/python3.8/shutil.py", line 722, in rmtree
    onerror(os.rmdir, path, sys.exc_info())
  File "/home/jlpkort/anaconda3/lib/python3.8/shutil.py", line 720, in rmtree
    os.rmdir(path)
OSError: [Errno 39] Directory not empty: '/scratch/pymp-ykc66ojr'
Traceback (most recent call last):
  File "/home/jlpkort/anaconda3/lib/python3.8/multiprocessing/util.py", line 300, in _run_finalizers
    finalizer()
  File "/home/jlpkort/anaconda3/lib/python3.8/multiprocessing/util.py", line 224, in __call__
    res = self._callback(*self._args, **self._kwargs)
  File "/home/jlpkort/anaconda3/lib/python3.8/multiprocessing/util.py", line 133, in _remove_temp_dir
    rmtree(tempdir)
  File "/home/jlpkort/anaconda3/lib/python3.8/shutil.py", line 722, in rmtree
    onerror(os.rmdir, path, sys.exc_info())
  File "/home/jlpkort/anaconda3/lib/python3.8/shutil.py", line 720, in rmtree
    os.rmdir(path)
OSError: [Errno 39] Directory not empty: '/scratch/pymp-kcibxbi0'
Traceback (most recent call last):
  File "/home/jlpkort/anaconda3/lib/python3.8/multiprocessing/util.py", line 300, in _run_finalizers
    finalizer()
  File "/home/jlpkort/anaconda3/lib/python3.8/multiprocessing/util.py", line 224, in __call__
    res = self._callback(*self._args, **self._kwargs)
  File "/home/jlpkort/anaconda3/lib/python3.8/multiprocessing/util.py", line 133, in _remove_temp_dir
    rmtree(tempdir)
  File "/home/jlpkort/anaconda3/lib/python3.8/shutil.py", line 722, in rmtree
    onerror(os.rmdir, path, sys.exc_info())
  File "/home/jlpkort/anaconda3/lib/python3.8/shutil.py", line 720, in rmtree
    os.rmdir(path)
OSError: [Errno 39] Directory not empty: '/scratch/pymp-n_cwwybr'
Traceback (most recent call last):
  File "/home/jlpkort/anaconda3/lib/python3.8/multiprocessing/util.py", line 300, in _run_finalizers
    finalizer()
  File "/home/jlpkort/anaconda3/lib/python3.8/multiprocessing/util.py", line 224, in __call__
    res = self._callback(*self._args, **self._kwargs)
  File "/home/jlpkort/anaconda3/lib/python3.8/multiprocessing/util.py", line 133, in _remove_temp_dir
    rmtree(tempdir)
  File "/home/jlpkort/anaconda3/lib/python3.8/shutil.py", line 722, in rmtree
    onerror(os.rmdir, path, sys.exc_info())
  File "/home/jlpkort/anaconda3/lib/python3.8/shutil.py", line 720, in rmtree
    os.rmdir(path)
OSError: [Errno 39] Directory not empty: '/scratch/pymp-64zp51mr'
Traceback (most recent call last):
  File "/home/jlpkort/anaconda3/lib/python3.8/multiprocessing/util.py", line 300, in _run_finalizers
    finalizer()
  File "/home/jlpkort/anaconda3/lib/python3.8/multiprocessing/util.py", line 224, in __call__
    res = self._callback(*self._args, **self._kwargs)
  File "/home/jlpkort/anaconda3/lib/python3.8/multiprocessing/util.py", line 133, in _remove_temp_dir
    rmtree(tempdir)
  File "/home/jlpkort/anaconda3/lib/python3.8/shutil.py", line 722, in rmtree
    onerror(os.rmdir, path, sys.exc_info())
  File "/home/jlpkort/anaconda3/lib/python3.8/shutil.py", line 720, in rmtree
    os.rmdir(path)
OSError: [Errno 39] Directory not empty: '/scratch/pymp-zg9c3__9'
I0908 05:07:15.344153 8380 trainer.py:117]  [Step: 11000/100000 (11.0%)] D Loss: -3.530174732208252 M Loss: 1.0146441459655762 G Loss: -0.10303348302841187 
Traceback (most recent call last):
  File "/home/jlpkort/anaconda3/lib/python3.8/multiprocessing/util.py", line 300, in _run_finalizers
    finalizer()
  File "/home/jlpkort/anaconda3/lib/python3.8/multiprocessing/util.py", line 224, in __call__
    res = self._callback(*self._args, **self._kwargs)
  File "/home/jlpkort/anaconda3/lib/python3.8/multiprocessing/util.py", line 133, in _remove_temp_dir
    rmtree(tempdir)
  File "/home/jlpkort/anaconda3/lib/python3.8/shutil.py", line 722, in rmtree
    onerror(os.rmdir, path, sys.exc_info())
  File "/home/jlpkort/anaconda3/lib/python3.8/shutil.py", line 720, in rmtree
    os.rmdir(path)
OSError: [Errno 39] Directory not empty: '/scratch/pymp-7fenw_yq'
Traceback (most recent call last):
  File "/home/jlpkort/anaconda3/lib/python3.8/multiprocessing/util.py", line 300, in _run_finalizers
    finalizer()
  File "/home/jlpkort/anaconda3/lib/python3.8/multiprocessing/util.py", line 224, in __call__
    res = self._callback(*self._args, **self._kwargs)
  File "/home/jlpkort/anaconda3/lib/python3.8/multiprocessing/util.py", line 133, in _remove_temp_dir
    rmtree(tempdir)
  File "/home/jlpkort/anaconda3/lib/python3.8/shutil.py", line 722, in rmtree
    onerror(os.rmdir, path, sys.exc_info())
  File "/home/jlpkort/anaconda3/lib/python3.8/shutil.py", line 720, in rmtree
    os.rmdir(path)
OSError: [Errno 39] Directory not empty: '/scratch/pymp-fqj6xp6n'
Traceback (most recent call last):
  File "/home/jlpkort/anaconda3/lib/python3.8/multiprocessing/util.py", line 300, in _run_finalizers
    finalizer()
  File "/home/jlpkort/anaconda3/lib/python3.8/multiprocessing/util.py", line 224, in __call__
    res = self._callback(*self._args, **self._kwargs)
  File "/home/jlpkort/anaconda3/lib/python3.8/multiprocessing/util.py", line 133, in _remove_temp_dir
    rmtree(tempdir)
  File "/home/jlpkort/anaconda3/lib/python3.8/shutil.py", line 722, in rmtree
    onerror(os.rmdir, path, sys.exc_info())
  File "/home/jlpkort/anaconda3/lib/python3.8/shutil.py", line 720, in rmtree
    os.rmdir(path)
OSError: [Errno 39] Directory not empty: '/scratch/pymp-0s0278sp'
Traceback (most recent call last):
  File "/home/jlpkort/anaconda3/lib/python3.8/multiprocessing/util.py", line 300, in _run_finalizers
    finalizer()
  File "/home/jlpkort/anaconda3/lib/python3.8/multiprocessing/util.py", line 224, in __call__
    res = self._callback(*self._args, **self._kwargs)
  File "/home/jlpkort/anaconda3/lib/python3.8/multiprocessing/util.py", line 133, in _remove_temp_dir
    rmtree(tempdir)
  File "/home/jlpkort/anaconda3/lib/python3.8/shutil.py", line 722, in rmtree
    onerror(os.rmdir, path, sys.exc_info())
  File "/home/jlpkort/anaconda3/lib/python3.8/shutil.py", line 720, in rmtree
    os.rmdir(path)
OSError: [Errno 39] Directory not empty: '/scratch/pymp-3dwccj4v'
I0908 06:29:25.680428 8380 trainer.py:117]  [Step: 12000/100000 (12.0%)] D Loss: -7.991343021392822 M Loss: 1.0254220962524414 G Loss: -0.09355604648590088 
Traceback (most recent call last):
  File "/home/jlpkort/anaconda3/lib/python3.8/multiprocessing/util.py", line 300, in _run_finalizers
    finalizer()
  File "/home/jlpkort/anaconda3/lib/python3.8/multiprocessing/util.py", line 224, in __call__
    res = self._callback(*self._args, **self._kwargs)
  File "/home/jlpkort/anaconda3/lib/python3.8/multiprocessing/util.py", line 133, in _remove_temp_dir
    rmtree(tempdir)
  File "/home/jlpkort/anaconda3/lib/python3.8/shutil.py", line 722, in rmtree
    onerror(os.rmdir, path, sys.exc_info())
  File "/home/jlpkort/anaconda3/lib/python3.8/shutil.py", line 720, in rmtree
    os.rmdir(path)
OSError: [Errno 39] Directory not empty: '/scratch/pymp-pmwxbukc'
Traceback (most recent call last):
  File "/home/jlpkort/anaconda3/lib/python3.8/multiprocessing/util.py", line 300, in _run_finalizers
    finalizer()
  File "/home/jlpkort/anaconda3/lib/python3.8/multiprocessing/util.py", line 224, in __call__
    res = self._callback(*self._args, **self._kwargs)
  File "/home/jlpkort/anaconda3/lib/python3.8/multiprocessing/util.py", line 133, in _remove_temp_dir
    rmtree(tempdir)
  File "/home/jlpkort/anaconda3/lib/python3.8/shutil.py", line 722, in rmtree
    onerror(os.rmdir, path, sys.exc_info())
  File "/home/jlpkort/anaconda3/lib/python3.8/shutil.py", line 720, in rmtree
    os.rmdir(path)
OSError: [Errno 39] Directory not empty: '/scratch/pymp-yhj9z279'
Traceback (most recent call last):
  File "/home/jlpkort/anaconda3/lib/python3.8/multiprocessing/util.py", line 300, in _run_finalizers
    finalizer()
  File "/home/jlpkort/anaconda3/lib/python3.8/multiprocessing/util.py", line 224, in __call__
    res = self._callback(*self._args, **self._kwargs)
  File "/home/jlpkort/anaconda3/lib/python3.8/multiprocessing/util.py", line 133, in _remove_temp_dir
    rmtree(tempdir)
  File "/home/jlpkort/anaconda3/lib/python3.8/shutil.py", line 722, in rmtree
    onerror(os.rmdir, path, sys.exc_info())
  File "/home/jlpkort/anaconda3/lib/python3.8/shutil.py", line 720, in rmtree
    os.rmdir(path)
OSError: [Errno 39] Directory not empty: '/scratch/pymp-ccfmk6q6'
I0908 07:50:44.225716 8380 trainer.py:117]  [Step: 13000/100000 (13.0%)] D Loss: -2.432173013687134 M Loss: 0.9977812767028809 G Loss: -0.08025391399860382 
Traceback (most recent call last):
  File "/home/jlpkort/anaconda3/lib/python3.8/multiprocessing/util.py", line 300, in _run_finalizers
    finalizer()
  File "/home/jlpkort/anaconda3/lib/python3.8/multiprocessing/util.py", line 224, in __call__
    res = self._callback(*self._args, **self._kwargs)
  File "/home/jlpkort/anaconda3/lib/python3.8/multiprocessing/util.py", line 133, in _remove_temp_dir
    rmtree(tempdir)
  File "/home/jlpkort/anaconda3/lib/python3.8/shutil.py", line 722, in rmtree
    onerror(os.rmdir, path, sys.exc_info())
  File "/home/jlpkort/anaconda3/lib/python3.8/shutil.py", line 720, in rmtree
    os.rmdir(path)
OSError: [Errno 39] Directory not empty: '/scratch/pymp-pu4b_fhw'
Traceback (most recent call last):
  File "/home/jlpkort/anaconda3/lib/python3.8/multiprocessing/util.py", line 300, in _run_finalizers
    finalizer()
  File "/home/jlpkort/anaconda3/lib/python3.8/multiprocessing/util.py", line 224, in __call__
    res = self._callback(*self._args, **self._kwargs)
  File "/home/jlpkort/anaconda3/lib/python3.8/multiprocessing/util.py", line 133, in _remove_temp_dir
    rmtree(tempdir)
  File "/home/jlpkort/anaconda3/lib/python3.8/shutil.py", line 722, in rmtree
    onerror(os.rmdir, path, sys.exc_info())
  File "/home/jlpkort/anaconda3/lib/python3.8/shutil.py", line 720, in rmtree
    os.rmdir(path)
OSError: [Errno 39] Directory not empty: '/scratch/pymp-tdl2cs9m'
I0908 09:12:02.706087 8380 trainer.py:117]  [Step: 14000/100000 (14.0%)] D Loss: 0.9956648349761963 M Loss: 1.0040892362594604 G Loss: -0.09725619852542877 
Traceback (most recent call last):
  File "/home/jlpkort/anaconda3/lib/python3.8/multiprocessing/util.py", line 300, in _run_finalizers
    finalizer()
  File "/home/jlpkort/anaconda3/lib/python3.8/multiprocessing/util.py", line 224, in __call__
    res = self._callback(*self._args, **self._kwargs)
  File "/home/jlpkort/anaconda3/lib/python3.8/multiprocessing/util.py", line 133, in _remove_temp_dir
    rmtree(tempdir)
  File "/home/jlpkort/anaconda3/lib/python3.8/shutil.py", line 722, in rmtree
    onerror(os.rmdir, path, sys.exc_info())
  File "/home/jlpkort/anaconda3/lib/python3.8/shutil.py", line 720, in rmtree
    os.rmdir(path)
OSError: [Errno 39] Directory not empty: '/scratch/pymp-hl8k7l9l'
Traceback (most recent call last):
  File "/home/jlpkort/anaconda3/lib/python3.8/multiprocessing/util.py", line 300, in _run_finalizers
    finalizer()
  File "/home/jlpkort/anaconda3/lib/python3.8/multiprocessing/util.py", line 224, in __call__
    res = self._callback(*self._args, **self._kwargs)
  File "/home/jlpkort/anaconda3/lib/python3.8/multiprocessing/util.py", line 133, in _remove_temp_dir
    rmtree(tempdir)
  File "/home/jlpkort/anaconda3/lib/python3.8/shutil.py", line 722, in rmtree
    onerror(os.rmdir, path, sys.exc_info())
  File "/home/jlpkort/anaconda3/lib/python3.8/shutil.py", line 720, in rmtree
    os.rmdir(path)
OSError: [Errno 39] Directory not empty: '/scratch/pymp-ae314w6j'
Traceback (most recent call last):
  File "/home/jlpkort/anaconda3/lib/python3.8/multiprocessing/util.py", line 300, in _run_finalizers
    finalizer()
  File "/home/jlpkort/anaconda3/lib/python3.8/multiprocessing/util.py", line 224, in __call__
    res = self._callback(*self._args, **self._kwargs)
  File "/home/jlpkort/anaconda3/lib/python3.8/multiprocessing/util.py", line 133, in _remove_temp_dir
    rmtree(tempdir)
  File "/home/jlpkort/anaconda3/lib/python3.8/shutil.py", line 722, in rmtree
    onerror(os.rmdir, path, sys.exc_info())
  File "/home/jlpkort/anaconda3/lib/python3.8/shutil.py", line 720, in rmtree
    os.rmdir(path)
OSError: [Errno 39] Directory not empty: '/scratch/pymp-7blteoyt'
Traceback (most recent call last):
  File "/home/jlpkort/anaconda3/lib/python3.8/multiprocessing/util.py", line 300, in _run_finalizers
    finalizer()
  File "/home/jlpkort/anaconda3/lib/python3.8/multiprocessing/util.py", line 224, in __call__
    res = self._callback(*self._args, **self._kwargs)
  File "/home/jlpkort/anaconda3/lib/python3.8/multiprocessing/util.py", line 133, in _remove_temp_dir
    rmtree(tempdir)
  File "/home/jlpkort/anaconda3/lib/python3.8/shutil.py", line 722, in rmtree
    onerror(os.rmdir, path, sys.exc_info())
  File "/home/jlpkort/anaconda3/lib/python3.8/shutil.py", line 720, in rmtree
    os.rmdir(path)
OSError: [Errno 39] Directory not empty: '/scratch/pymp-e87eb4gz'
Traceback (most recent call last):
  File "/home/jlpkort/anaconda3/lib/python3.8/multiprocessing/util.py", line 300, in _run_finalizers
    finalizer()
  File "/home/jlpkort/anaconda3/lib/python3.8/multiprocessing/util.py", line 224, in __call__
    res = self._callback(*self._args, **self._kwargs)
  File "/home/jlpkort/anaconda3/lib/python3.8/multiprocessing/util.py", line 133, in _remove_temp_dir
    rmtree(tempdir)
  File "/home/jlpkort/anaconda3/lib/python3.8/shutil.py", line 722, in rmtree
    onerror(os.rmdir, path, sys.exc_info())
  File "/home/jlpkort/anaconda3/lib/python3.8/shutil.py", line 720, in rmtree
    os.rmdir(path)
OSError: [Errno 39] Directory not empty: '/scratch/pymp-3kpy23dn'
Traceback (most recent call last):
  File "/home/jlpkort/anaconda3/lib/python3.8/multiprocessing/util.py", line 300, in _run_finalizers
    finalizer()
  File "/home/jlpkort/anaconda3/lib/python3.8/multiprocessing/util.py", line 224, in __call__
    res = self._callback(*self._args, **self._kwargs)
  File "/home/jlpkort/anaconda3/lib/python3.8/multiprocessing/util.py", line 133, in _remove_temp_dir
    rmtree(tempdir)
  File "/home/jlpkort/anaconda3/lib/python3.8/shutil.py", line 722, in rmtree
    onerror(os.rmdir, path, sys.exc_info())
  File "/home/jlpkort/anaconda3/lib/python3.8/shutil.py", line 720, in rmtree
    os.rmdir(path)
OSError: [Errno 39] Directory not empty: '/scratch/pymp-tr8ryxjx'
Traceback (most recent call last):
  File "/home/jlpkort/anaconda3/lib/python3.8/multiprocessing/util.py", line 300, in _run_finalizers
    finalizer()
  File "/home/jlpkort/anaconda3/lib/python3.8/multiprocessing/util.py", line 224, in __call__
    res = self._callback(*self._args, **self._kwargs)
  File "/home/jlpkort/anaconda3/lib/python3.8/multiprocessing/util.py", line 133, in _remove_temp_dir
    rmtree(tempdir)
  File "/home/jlpkort/anaconda3/lib/python3.8/shutil.py", line 722, in rmtree
    onerror(os.rmdir, path, sys.exc_info())
  File "/home/jlpkort/anaconda3/lib/python3.8/shutil.py", line 720, in rmtree
    os.rmdir(path)
OSError: [Errno 39] Directory not empty: '/scratch/pymp-fafevu6h'
Traceback (most recent call last):
  File "/home/jlpkort/anaconda3/lib/python3.8/multiprocessing/util.py", line 300, in _run_finalizers
    finalizer()
  File "/home/jlpkort/anaconda3/lib/python3.8/multiprocessing/util.py", line 224, in __call__
    res = self._callback(*self._args, **self._kwargs)
  File "/home/jlpkort/anaconda3/lib/python3.8/multiprocessing/util.py", line 133, in _remove_temp_dir
    rmtree(tempdir)
  File "/home/jlpkort/anaconda3/lib/python3.8/shutil.py", line 722, in rmtree
    onerror(os.rmdir, path, sys.exc_info())
  File "/home/jlpkort/anaconda3/lib/python3.8/shutil.py", line 720, in rmtree
    os.rmdir(path)
OSError: [Errno 39] Directory not empty: '/scratch/pymp-ckya3ipm'
Traceback (most recent call last):
  File "/home/jlpkort/anaconda3/lib/python3.8/multiprocessing/util.py", line 300, in _run_finalizers
    finalizer()
  File "/home/jlpkort/anaconda3/lib/python3.8/multiprocessing/util.py", line 224, in __call__
    res = self._callback(*self._args, **self._kwargs)
  File "/home/jlpkort/anaconda3/lib/python3.8/multiprocessing/util.py", line 133, in _remove_temp_dir
    rmtree(tempdir)
  File "/home/jlpkort/anaconda3/lib/python3.8/shutil.py", line 722, in rmtree
    onerror(os.rmdir, path, sys.exc_info())
  File "/home/jlpkort/anaconda3/lib/python3.8/shutil.py", line 720, in rmtree
    os.rmdir(path)
OSError: [Errno 39] Directory not empty: '/scratch/pymp-qr0j9zr1'
I0908 10:33:24.801834 8380 trainer.py:117]  [Step: 15000/100000 (15.0%)] D Loss: -20.379226684570312 M Loss: 0.9705725908279419 G Loss: -0.1006888896226883 
Traceback (most recent call last):
  File "/home/jlpkort/anaconda3/lib/python3.8/multiprocessing/util.py", line 300, in _run_finalizers
    finalizer()
  File "/home/jlpkort/anaconda3/lib/python3.8/multiprocessing/util.py", line 224, in __call__
    res = self._callback(*self._args, **self._kwargs)
  File "/home/jlpkort/anaconda3/lib/python3.8/multiprocessing/util.py", line 133, in _remove_temp_dir
    rmtree(tempdir)
  File "/home/jlpkort/anaconda3/lib/python3.8/shutil.py", line 722, in rmtree
    onerror(os.rmdir, path, sys.exc_info())
  File "/home/jlpkort/anaconda3/lib/python3.8/shutil.py", line 720, in rmtree
    os.rmdir(path)
OSError: [Errno 39] Directory not empty: '/scratch/pymp-s87zj53g'
Traceback (most recent call last):
  File "/home/jlpkort/anaconda3/lib/python3.8/multiprocessing/util.py", line 300, in _run_finalizers
    finalizer()
  File "/home/jlpkort/anaconda3/lib/python3.8/multiprocessing/util.py", line 224, in __call__
    res = self._callback(*self._args, **self._kwargs)
  File "/home/jlpkort/anaconda3/lib/python3.8/multiprocessing/util.py", line 133, in _remove_temp_dir
    rmtree(tempdir)
  File "/home/jlpkort/anaconda3/lib/python3.8/shutil.py", line 722, in rmtree
    onerror(os.rmdir, path, sys.exc_info())
  File "/home/jlpkort/anaconda3/lib/python3.8/shutil.py", line 720, in rmtree
    os.rmdir(path)
OSError: [Errno 39] Directory not empty: '/scratch/pymp-4s5fi_ho'
Traceback (most recent call last):
  File "/home/jlpkort/anaconda3/lib/python3.8/multiprocessing/util.py", line 300, in _run_finalizers
    finalizer()
  File "/home/jlpkort/anaconda3/lib/python3.8/multiprocessing/util.py", line 224, in __call__
    res = self._callback(*self._args, **self._kwargs)
  File "/home/jlpkort/anaconda3/lib/python3.8/multiprocessing/util.py", line 133, in _remove_temp_dir
    rmtree(tempdir)
  File "/home/jlpkort/anaconda3/lib/python3.8/shutil.py", line 722, in rmtree
    onerror(os.rmdir, path, sys.exc_info())
  File "/home/jlpkort/anaconda3/lib/python3.8/shutil.py", line 720, in rmtree
    os.rmdir(path)
OSError: [Errno 39] Directory not empty: '/scratch/pymp-ed31uaiz'
Traceback (most recent call last):
  File "/home/jlpkort/anaconda3/lib/python3.8/multiprocessing/util.py", line 300, in _run_finalizers
    finalizer()
  File "/home/jlpkort/anaconda3/lib/python3.8/multiprocessing/util.py", line 224, in __call__
    res = self._callback(*self._args, **self._kwargs)
  File "/home/jlpkort/anaconda3/lib/python3.8/multiprocessing/util.py", line 133, in _remove_temp_dir
    rmtree(tempdir)
  File "/home/jlpkort/anaconda3/lib/python3.8/shutil.py", line 722, in rmtree
    onerror(os.rmdir, path, sys.exc_info())
  File "/home/jlpkort/anaconda3/lib/python3.8/shutil.py", line 720, in rmtree
    os.rmdir(path)
OSError: [Errno 39] Directory not empty: '/scratch/pymp-d7pz0dp_'
Traceback (most recent call last):
  File "/home/jlpkort/anaconda3/lib/python3.8/multiprocessing/util.py", line 300, in _run_finalizers
    finalizer()
  File "/home/jlpkort/anaconda3/lib/python3.8/multiprocessing/util.py", line 224, in __call__
    res = self._callback(*self._args, **self._kwargs)
  File "/home/jlpkort/anaconda3/lib/python3.8/multiprocessing/util.py", line 133, in _remove_temp_dir
    rmtree(tempdir)
  File "/home/jlpkort/anaconda3/lib/python3.8/shutil.py", line 722, in rmtree
    onerror(os.rmdir, path, sys.exc_info())
  File "/home/jlpkort/anaconda3/lib/python3.8/shutil.py", line 720, in rmtree
    os.rmdir(path)
OSError: [Errno 39] Directory not empty: '/scratch/pymp-f620ap8t'
Traceback (most recent call last):
  File "/home/jlpkort/anaconda3/lib/python3.8/multiprocessing/util.py", line 300, in _run_finalizers
    finalizer()
  File "/home/jlpkort/anaconda3/lib/python3.8/multiprocessing/util.py", line 224, in __call__
    res = self._callback(*self._args, **self._kwargs)
  File "/home/jlpkort/anaconda3/lib/python3.8/multiprocessing/util.py", line 133, in _remove_temp_dir
    rmtree(tempdir)
  File "/home/jlpkort/anaconda3/lib/python3.8/shutil.py", line 722, in rmtree
    onerror(os.rmdir, path, sys.exc_info())
  File "/home/jlpkort/anaconda3/lib/python3.8/shutil.py", line 720, in rmtree
    os.rmdir(path)
OSError: [Errno 39] Directory not empty: '/scratch/pymp-kgt0i8ry'
Traceback (most recent call last):
  File "/home/jlpkort/anaconda3/lib/python3.8/multiprocessing/util.py", line 300, in _run_finalizers
    finalizer()
  File "/home/jlpkort/anaconda3/lib/python3.8/multiprocessing/util.py", line 224, in __call__
    res = self._callback(*self._args, **self._kwargs)
  File "/home/jlpkort/anaconda3/lib/python3.8/multiprocessing/util.py", line 133, in _remove_temp_dir
    rmtree(tempdir)
  File "/home/jlpkort/anaconda3/lib/python3.8/shutil.py", line 722, in rmtree
    onerror(os.rmdir, path, sys.exc_info())
  File "/home/jlpkort/anaconda3/lib/python3.8/shutil.py", line 720, in rmtree
    os.rmdir(path)
OSError: [Errno 39] Directory not empty: '/scratch/pymp-unyhuiiz'
Traceback (most recent call last):
  File "/home/jlpkort/anaconda3/lib/python3.8/multiprocessing/util.py", line 300, in _run_finalizers
    finalizer()
  File "/home/jlpkort/anaconda3/lib/python3.8/multiprocessing/util.py", line 224, in __call__
    res = self._callback(*self._args, **self._kwargs)
  File "/home/jlpkort/anaconda3/lib/python3.8/multiprocessing/util.py", line 133, in _remove_temp_dir
    rmtree(tempdir)
  File "/home/jlpkort/anaconda3/lib/python3.8/shutil.py", line 722, in rmtree
    onerror(os.rmdir, path, sys.exc_info())
  File "/home/jlpkort/anaconda3/lib/python3.8/shutil.py", line 720, in rmtree
    os.rmdir(path)
OSError: [Errno 39] Directory not empty: '/scratch/pymp-x101yhbn'
Traceback (most recent call last):
  File "/home/jlpkort/anaconda3/lib/python3.8/multiprocessing/util.py", line 300, in _run_finalizers
    finalizer()
  File "/home/jlpkort/anaconda3/lib/python3.8/multiprocessing/util.py", line 224, in __call__
    res = self._callback(*self._args, **self._kwargs)
  File "/home/jlpkort/anaconda3/lib/python3.8/multiprocessing/util.py", line 133, in _remove_temp_dir
    rmtree(tempdir)
  File "/home/jlpkort/anaconda3/lib/python3.8/shutil.py", line 722, in rmtree
    onerror(os.rmdir, path, sys.exc_info())
  File "/home/jlpkort/anaconda3/lib/python3.8/shutil.py", line 720, in rmtree
    os.rmdir(path)
OSError: [Errno 39] Directory not empty: '/scratch/pymp-65b3shqq'
Traceback (most recent call last):
  File "/home/jlpkort/anaconda3/lib/python3.8/multiprocessing/util.py", line 300, in _run_finalizers
    finalizer()
  File "/home/jlpkort/anaconda3/lib/python3.8/multiprocessing/util.py", line 224, in __call__
    res = self._callback(*self._args, **self._kwargs)
  File "/home/jlpkort/anaconda3/lib/python3.8/multiprocessing/util.py", line 133, in _remove_temp_dir
    rmtree(tempdir)
  File "/home/jlpkort/anaconda3/lib/python3.8/shutil.py", line 722, in rmtree
    onerror(os.rmdir, path, sys.exc_info())
  File "/home/jlpkort/anaconda3/lib/python3.8/shutil.py", line 720, in rmtree
    os.rmdir(path)
OSError: [Errno 39] Directory not empty: '/scratch/pymp-8bt9fadn'
Traceback (most recent call last):
  File "/home/jlpkort/anaconda3/lib/python3.8/multiprocessing/util.py", line 300, in _run_finalizers
    finalizer()
  File "/home/jlpkort/anaconda3/lib/python3.8/multiprocessing/util.py", line 224, in __call__
    res = self._callback(*self._args, **self._kwargs)
  File "/home/jlpkort/anaconda3/lib/python3.8/multiprocessing/util.py", line 133, in _remove_temp_dir
    rmtree(tempdir)
  File "/home/jlpkort/anaconda3/lib/python3.8/shutil.py", line 722, in rmtree
    onerror(os.rmdir, path, sys.exc_info())
  File "/home/jlpkort/anaconda3/lib/python3.8/shutil.py", line 720, in rmtree
    os.rmdir(path)
OSError: [Errno 39] Directory not empty: '/scratch/pymp-m2q2j2lh'
Traceback (most recent call last):
  File "/home/jlpkort/anaconda3/lib/python3.8/multiprocessing/util.py", line 300, in _run_finalizers
    finalizer()
  File "/home/jlpkort/anaconda3/lib/python3.8/multiprocessing/util.py", line 224, in __call__
    res = self._callback(*self._args, **self._kwargs)
  File "/home/jlpkort/anaconda3/lib/python3.8/multiprocessing/util.py", line 133, in _remove_temp_dir
    rmtree(tempdir)
  File "/home/jlpkort/anaconda3/lib/python3.8/shutil.py", line 722, in rmtree
    onerror(os.rmdir, path, sys.exc_info())
  File "/home/jlpkort/anaconda3/lib/python3.8/shutil.py", line 720, in rmtree
    os.rmdir(path)
OSError: [Errno 39] Directory not empty: '/scratch/pymp-zicoq7f6'
I0908 11:54:38.643440 8380 trainer.py:117]  [Step: 16000/100000 (16.0%)] D Loss: -6.442757606506348 M Loss: 0.9899125099182129 G Loss: -0.10026055574417114 
Traceback (most recent call last):
  File "/home/jlpkort/anaconda3/lib/python3.8/multiprocessing/util.py", line 300, in _run_finalizers
    finalizer()
  File "/home/jlpkort/anaconda3/lib/python3.8/multiprocessing/util.py", line 224, in __call__
    res = self._callback(*self._args, **self._kwargs)
  File "/home/jlpkort/anaconda3/lib/python3.8/multiprocessing/util.py", line 133, in _remove_temp_dir
    rmtree(tempdir)
  File "/home/jlpkort/anaconda3/lib/python3.8/shutil.py", line 722, in rmtree
    onerror(os.rmdir, path, sys.exc_info())
  File "/home/jlpkort/anaconda3/lib/python3.8/shutil.py", line 720, in rmtree
    os.rmdir(path)
OSError: [Errno 39] Directory not empty: '/scratch/pymp-oy0hhib6'
Traceback (most recent call last):
  File "/home/jlpkort/anaconda3/lib/python3.8/multiprocessing/util.py", line 300, in _run_finalizers
    finalizer()
  File "/home/jlpkort/anaconda3/lib/python3.8/multiprocessing/util.py", line 224, in __call__
    res = self._callback(*self._args, **self._kwargs)
  File "/home/jlpkort/anaconda3/lib/python3.8/multiprocessing/util.py", line 133, in _remove_temp_dir
    rmtree(tempdir)
  File "/home/jlpkort/anaconda3/lib/python3.8/shutil.py", line 722, in rmtree
    onerror(os.rmdir, path, sys.exc_info())
  File "/home/jlpkort/anaconda3/lib/python3.8/shutil.py", line 720, in rmtree
    os.rmdir(path)
OSError: [Errno 39] Directory not empty: '/scratch/pymp-kdi5d7mm'
Traceback (most recent call last):
  File "/home/jlpkort/anaconda3/lib/python3.8/multiprocessing/util.py", line 300, in _run_finalizers
    finalizer()
  File "/home/jlpkort/anaconda3/lib/python3.8/multiprocessing/util.py", line 224, in __call__
    res = self._callback(*self._args, **self._kwargs)
  File "/home/jlpkort/anaconda3/lib/python3.8/multiprocessing/util.py", line 133, in _remove_temp_dir
    rmtree(tempdir)
  File "/home/jlpkort/anaconda3/lib/python3.8/shutil.py", line 722, in rmtree
    onerror(os.rmdir, path, sys.exc_info())
  File "/home/jlpkort/anaconda3/lib/python3.8/shutil.py", line 720, in rmtree
    os.rmdir(path)
OSError: [Errno 39] Directory not empty: '/scratch/pymp-6bn6vy3p'
Traceback (most recent call last):
  File "/home/jlpkort/anaconda3/lib/python3.8/multiprocessing/util.py", line 300, in _run_finalizers
    finalizer()
  File "/home/jlpkort/anaconda3/lib/python3.8/multiprocessing/util.py", line 224, in __call__
    res = self._callback(*self._args, **self._kwargs)
  File "/home/jlpkort/anaconda3/lib/python3.8/multiprocessing/util.py", line 133, in _remove_temp_dir
    rmtree(tempdir)
  File "/home/jlpkort/anaconda3/lib/python3.8/shutil.py", line 722, in rmtree
    onerror(os.rmdir, path, sys.exc_info())
  File "/home/jlpkort/anaconda3/lib/python3.8/shutil.py", line 720, in rmtree
    os.rmdir(path)
OSError: [Errno 39] Directory not empty: '/scratch/pymp-1dv9bpvr'
Traceback (most recent call last):
  File "/home/jlpkort/anaconda3/lib/python3.8/multiprocessing/util.py", line 300, in _run_finalizers
    finalizer()
  File "/home/jlpkort/anaconda3/lib/python3.8/multiprocessing/util.py", line 224, in __call__
    res = self._callback(*self._args, **self._kwargs)
  File "/home/jlpkort/anaconda3/lib/python3.8/multiprocessing/util.py", line 133, in _remove_temp_dir
    rmtree(tempdir)
  File "/home/jlpkort/anaconda3/lib/python3.8/shutil.py", line 722, in rmtree
    onerror(os.rmdir, path, sys.exc_info())
  File "/home/jlpkort/anaconda3/lib/python3.8/shutil.py", line 720, in rmtree
    os.rmdir(path)
OSError: [Errno 39] Directory not empty: '/scratch/pymp-ej2ze12j'
Traceback (most recent call last):
  File "/home/jlpkort/anaconda3/lib/python3.8/multiprocessing/util.py", line 300, in _run_finalizers
    finalizer()
  File "/home/jlpkort/anaconda3/lib/python3.8/multiprocessing/util.py", line 224, in __call__
    res = self._callback(*self._args, **self._kwargs)
  File "/home/jlpkort/anaconda3/lib/python3.8/multiprocessing/util.py", line 133, in _remove_temp_dir
    rmtree(tempdir)
  File "/home/jlpkort/anaconda3/lib/python3.8/shutil.py", line 722, in rmtree
    onerror(os.rmdir, path, sys.exc_info())
  File "/home/jlpkort/anaconda3/lib/python3.8/shutil.py", line 720, in rmtree
    os.rmdir(path)
OSError: [Errno 39] Directory not empty: '/scratch/pymp-rops_6x3'
I0908 13:15:59.840660 8380 trainer.py:117]  [Step: 17000/100000 (17.0%)] D Loss: -4.188471794128418 M Loss: 1.0008922815322876 G Loss: -0.12235837429761887 
Traceback (most recent call last):
  File "/home/jlpkort/anaconda3/lib/python3.8/multiprocessing/util.py", line 300, in _run_finalizers
    finalizer()
  File "/home/jlpkort/anaconda3/lib/python3.8/multiprocessing/util.py", line 224, in __call__
    res = self._callback(*self._args, **self._kwargs)
  File "/home/jlpkort/anaconda3/lib/python3.8/multiprocessing/util.py", line 133, in _remove_temp_dir
    rmtree(tempdir)
  File "/home/jlpkort/anaconda3/lib/python3.8/shutil.py", line 722, in rmtree
    onerror(os.rmdir, path, sys.exc_info())
  File "/home/jlpkort/anaconda3/lib/python3.8/shutil.py", line 720, in rmtree
    os.rmdir(path)
OSError: [Errno 39] Directory not empty: '/scratch/pymp-2vkwe2f9'
Traceback (most recent call last):
  File "/home/jlpkort/anaconda3/lib/python3.8/multiprocessing/util.py", line 300, in _run_finalizers
    finalizer()
  File "/home/jlpkort/anaconda3/lib/python3.8/multiprocessing/util.py", line 224, in __call__
    res = self._callback(*self._args, **self._kwargs)
  File "/home/jlpkort/anaconda3/lib/python3.8/multiprocessing/util.py", line 133, in _remove_temp_dir
    rmtree(tempdir)
  File "/home/jlpkort/anaconda3/lib/python3.8/shutil.py", line 722, in rmtree
    onerror(os.rmdir, path, sys.exc_info())
  File "/home/jlpkort/anaconda3/lib/python3.8/shutil.py", line 720, in rmtree
    os.rmdir(path)
OSError: [Errno 39] Directory not empty: '/scratch/pymp-qulxcnuk'
I0908 14:37:27.495831 8380 trainer.py:117]  [Step: 18000/100000 (18.0%)] D Loss: -6.29456090927124 M Loss: 1.0014442205429077 G Loss: -0.0825619250535965 
Traceback (most recent call last):
  File "/home/jlpkort/anaconda3/lib/python3.8/multiprocessing/util.py", line 300, in _run_finalizers
    finalizer()
  File "/home/jlpkort/anaconda3/lib/python3.8/multiprocessing/util.py", line 224, in __call__
    res = self._callback(*self._args, **self._kwargs)
  File "/home/jlpkort/anaconda3/lib/python3.8/multiprocessing/util.py", line 133, in _remove_temp_dir
    rmtree(tempdir)
  File "/home/jlpkort/anaconda3/lib/python3.8/shutil.py", line 722, in rmtree
    onerror(os.rmdir, path, sys.exc_info())
  File "/home/jlpkort/anaconda3/lib/python3.8/shutil.py", line 720, in rmtree
    os.rmdir(path)
OSError: [Errno 39] Directory not empty: '/scratch/pymp-jbaas0d6'
Traceback (most recent call last):
  File "/home/jlpkort/anaconda3/lib/python3.8/multiprocessing/util.py", line 300, in _run_finalizers
    finalizer()
  File "/home/jlpkort/anaconda3/lib/python3.8/multiprocessing/util.py", line 224, in __call__
    res = self._callback(*self._args, **self._kwargs)
  File "/home/jlpkort/anaconda3/lib/python3.8/multiprocessing/util.py", line 133, in _remove_temp_dir
    rmtree(tempdir)
  File "/home/jlpkort/anaconda3/lib/python3.8/shutil.py", line 722, in rmtree
    onerror(os.rmdir, path, sys.exc_info())
  File "/home/jlpkort/anaconda3/lib/python3.8/shutil.py", line 720, in rmtree
    os.rmdir(path)
OSError: [Errno 39] Directory not empty: '/scratch/pymp-ymntkfrt'
Traceback (most recent call last):
  File "/home/jlpkort/anaconda3/lib/python3.8/multiprocessing/util.py", line 300, in _run_finalizers
    finalizer()
  File "/home/jlpkort/anaconda3/lib/python3.8/multiprocessing/util.py", line 224, in __call__
    res = self._callback(*self._args, **self._kwargs)
  File "/home/jlpkort/anaconda3/lib/python3.8/multiprocessing/util.py", line 133, in _remove_temp_dir
    rmtree(tempdir)
  File "/home/jlpkort/anaconda3/lib/python3.8/shutil.py", line 722, in rmtree
    onerror(os.rmdir, path, sys.exc_info())
  File "/home/jlpkort/anaconda3/lib/python3.8/shutil.py", line 720, in rmtree
    os.rmdir(path)
OSError: [Errno 39] Directory not empty: '/scratch/pymp-wbe9m89c'
Traceback (most recent call last):
  File "/home/jlpkort/anaconda3/lib/python3.8/multiprocessing/util.py", line 300, in _run_finalizers
    finalizer()
  File "/home/jlpkort/anaconda3/lib/python3.8/multiprocessing/util.py", line 224, in __call__
    res = self._callback(*self._args, **self._kwargs)
  File "/home/jlpkort/anaconda3/lib/python3.8/multiprocessing/util.py", line 133, in _remove_temp_dir
    rmtree(tempdir)
  File "/home/jlpkort/anaconda3/lib/python3.8/shutil.py", line 722, in rmtree
    onerror(os.rmdir, path, sys.exc_info())
  File "/home/jlpkort/anaconda3/lib/python3.8/shutil.py", line 720, in rmtree
    os.rmdir(path)
OSError: [Errno 39] Directory not empty: '/scratch/pymp-mzy05iot'
Traceback (most recent call last):
  File "/home/jlpkort/anaconda3/lib/python3.8/multiprocessing/util.py", line 300, in _run_finalizers
    finalizer()
  File "/home/jlpkort/anaconda3/lib/python3.8/multiprocessing/util.py", line 224, in __call__
    res = self._callback(*self._args, **self._kwargs)
  File "/home/jlpkort/anaconda3/lib/python3.8/multiprocessing/util.py", line 133, in _remove_temp_dir
    rmtree(tempdir)
  File "/home/jlpkort/anaconda3/lib/python3.8/shutil.py", line 722, in rmtree
    onerror(os.rmdir, path, sys.exc_info())
  File "/home/jlpkort/anaconda3/lib/python3.8/shutil.py", line 720, in rmtree
    os.rmdir(path)
OSError: [Errno 39] Directory not empty: '/scratch/pymp-a5oatdp2'
I0908 15:58:52.865206 8380 trainer.py:117]  [Step: 19000/100000 (19.0%)] D Loss: -2.3245127201080322 M Loss: 0.9831238985061646 G Loss: -0.11345234513282776 
Traceback (most recent call last):
  File "/home/jlpkort/anaconda3/lib/python3.8/multiprocessing/util.py", line 300, in _run_finalizers
    finalizer()
  File "/home/jlpkort/anaconda3/lib/python3.8/multiprocessing/util.py", line 224, in __call__
    res = self._callback(*self._args, **self._kwargs)
  File "/home/jlpkort/anaconda3/lib/python3.8/multiprocessing/util.py", line 133, in _remove_temp_dir
    rmtree(tempdir)
  File "/home/jlpkort/anaconda3/lib/python3.8/shutil.py", line 722, in rmtree
    onerror(os.rmdir, path, sys.exc_info())
  File "/home/jlpkort/anaconda3/lib/python3.8/shutil.py", line 720, in rmtree
    os.rmdir(path)
OSError: [Errno 39] Directory not empty: '/scratch/pymp-_m6ugfgs'
Traceback (most recent call last):
  File "/home/jlpkort/anaconda3/lib/python3.8/multiprocessing/util.py", line 300, in _run_finalizers
    finalizer()
  File "/home/jlpkort/anaconda3/lib/python3.8/multiprocessing/util.py", line 224, in __call__
    res = self._callback(*self._args, **self._kwargs)
  File "/home/jlpkort/anaconda3/lib/python3.8/multiprocessing/util.py", line 133, in _remove_temp_dir
    rmtree(tempdir)
  File "/home/jlpkort/anaconda3/lib/python3.8/shutil.py", line 722, in rmtree
    onerror(os.rmdir, path, sys.exc_info())
  File "/home/jlpkort/anaconda3/lib/python3.8/shutil.py", line 720, in rmtree
    os.rmdir(path)
OSError: [Errno 39] Directory not empty: '/scratch/pymp-z_mz30hp'
Traceback (most recent call last):
  File "/home/jlpkort/anaconda3/lib/python3.8/multiprocessing/util.py", line 300, in _run_finalizers
    finalizer()
  File "/home/jlpkort/anaconda3/lib/python3.8/multiprocessing/util.py", line 224, in __call__
    res = self._callback(*self._args, **self._kwargs)
  File "/home/jlpkort/anaconda3/lib/python3.8/multiprocessing/util.py", line 133, in _remove_temp_dir
    rmtree(tempdir)
  File "/home/jlpkort/anaconda3/lib/python3.8/shutil.py", line 722, in rmtree
    onerror(os.rmdir, path, sys.exc_info())
  File "/home/jlpkort/anaconda3/lib/python3.8/shutil.py", line 720, in rmtree
    os.rmdir(path)
OSError: [Errno 39] Directory not empty: '/scratch/pymp-fnczga4z'
Traceback (most recent call last):
  File "/home/jlpkort/anaconda3/lib/python3.8/multiprocessing/util.py", line 300, in _run_finalizers
    finalizer()
  File "/home/jlpkort/anaconda3/lib/python3.8/multiprocessing/util.py", line 224, in __call__
    res = self._callback(*self._args, **self._kwargs)
  File "/home/jlpkort/anaconda3/lib/python3.8/multiprocessing/util.py", line 133, in _remove_temp_dir
    rmtree(tempdir)
  File "/home/jlpkort/anaconda3/lib/python3.8/shutil.py", line 722, in rmtree
    onerror(os.rmdir, path, sys.exc_info())
  File "/home/jlpkort/anaconda3/lib/python3.8/shutil.py", line 720, in rmtree
    os.rmdir(path)
OSError: [Errno 39] Directory not empty: '/scratch/pymp-q2_mgawo'
Traceback (most recent call last):
  File "/home/jlpkort/anaconda3/lib/python3.8/multiprocessing/util.py", line 300, in _run_finalizers
    finalizer()
  File "/home/jlpkort/anaconda3/lib/python3.8/multiprocessing/util.py", line 224, in __call__
    res = self._callback(*self._args, **self._kwargs)
  File "/home/jlpkort/anaconda3/lib/python3.8/multiprocessing/util.py", line 133, in _remove_temp_dir
    rmtree(tempdir)
  File "/home/jlpkort/anaconda3/lib/python3.8/shutil.py", line 722, in rmtree
    onerror(os.rmdir, path, sys.exc_info())
  File "/home/jlpkort/anaconda3/lib/python3.8/shutil.py", line 720, in rmtree
    os.rmdir(path)
OSError: [Errno 39] Directory not empty: '/scratch/pymp-ub6yzh1e'
Traceback (most recent call last):
  File "/home/jlpkort/anaconda3/lib/python3.8/multiprocessing/util.py", line 300, in _run_finalizers
    finalizer()
  File "/home/jlpkort/anaconda3/lib/python3.8/multiprocessing/util.py", line 224, in __call__
    res = self._callback(*self._args, **self._kwargs)
  File "/home/jlpkort/anaconda3/lib/python3.8/multiprocessing/util.py", line 133, in _remove_temp_dir
    rmtree(tempdir)
  File "/home/jlpkort/anaconda3/lib/python3.8/shutil.py", line 722, in rmtree
    onerror(os.rmdir, path, sys.exc_info())
  File "/home/jlpkort/anaconda3/lib/python3.8/shutil.py", line 720, in rmtree
    os.rmdir(path)
OSError: [Errno 39] Directory not empty: '/scratch/pymp-duuz4v7c'
Traceback (most recent call last):
  File "/home/jlpkort/anaconda3/lib/python3.8/multiprocessing/util.py", line 300, in _run_finalizers
    finalizer()
  File "/home/jlpkort/anaconda3/lib/python3.8/multiprocessing/util.py", line 224, in __call__
    res = self._callback(*self._args, **self._kwargs)
  File "/home/jlpkort/anaconda3/lib/python3.8/multiprocessing/util.py", line 133, in _remove_temp_dir
    rmtree(tempdir)
  File "/home/jlpkort/anaconda3/lib/python3.8/shutil.py", line 722, in rmtree
    onerror(os.rmdir, path, sys.exc_info())
  File "/home/jlpkort/anaconda3/lib/python3.8/shutil.py", line 720, in rmtree
    os.rmdir(path)
OSError: [Errno 39] Directory not empty: '/scratch/pymp-u8j7h_ml'
Traceback (most recent call last):
  File "/home/jlpkort/anaconda3/lib/python3.8/multiprocessing/util.py", line 300, in _run_finalizers
    finalizer()
  File "/home/jlpkort/anaconda3/lib/python3.8/multiprocessing/util.py", line 224, in __call__
    res = self._callback(*self._args, **self._kwargs)
  File "/home/jlpkort/anaconda3/lib/python3.8/multiprocessing/util.py", line 133, in _remove_temp_dir
    rmtree(tempdir)
  File "/home/jlpkort/anaconda3/lib/python3.8/shutil.py", line 722, in rmtree
    onerror(os.rmdir, path, sys.exc_info())
  File "/home/jlpkort/anaconda3/lib/python3.8/shutil.py", line 720, in rmtree
    os.rmdir(path)
OSError: [Errno 39] Directory not empty: '/scratch/pymp-jy53gy8q'
I0908 17:20:35.839183 8380 trainer.py:117]  [Step: 20000/100000 (20.0%)] D Loss: -8.54055118560791 M Loss: 0.9883966445922852 G Loss: -0.07803256064653397 
Traceback (most recent call last):
  File "/home/jlpkort/anaconda3/lib/python3.8/multiprocessing/util.py", line 300, in _run_finalizers
    finalizer()
  File "/home/jlpkort/anaconda3/lib/python3.8/multiprocessing/util.py", line 224, in __call__
    res = self._callback(*self._args, **self._kwargs)
  File "/home/jlpkort/anaconda3/lib/python3.8/multiprocessing/util.py", line 133, in _remove_temp_dir
    rmtree(tempdir)
  File "/home/jlpkort/anaconda3/lib/python3.8/shutil.py", line 722, in rmtree
    onerror(os.rmdir, path, sys.exc_info())
  File "/home/jlpkort/anaconda3/lib/python3.8/shutil.py", line 720, in rmtree
    os.rmdir(path)
OSError: [Errno 39] Directory not empty: '/scratch/pymp-hd7ijxr3'
Traceback (most recent call last):
  File "/home/jlpkort/anaconda3/lib/python3.8/multiprocessing/util.py", line 300, in _run_finalizers
    finalizer()
  File "/home/jlpkort/anaconda3/lib/python3.8/multiprocessing/util.py", line 224, in __call__
    res = self._callback(*self._args, **self._kwargs)
  File "/home/jlpkort/anaconda3/lib/python3.8/multiprocessing/util.py", line 133, in _remove_temp_dir
    rmtree(tempdir)
  File "/home/jlpkort/anaconda3/lib/python3.8/shutil.py", line 722, in rmtree
    onerror(os.rmdir, path, sys.exc_info())
  File "/home/jlpkort/anaconda3/lib/python3.8/shutil.py", line 720, in rmtree
    os.rmdir(path)
OSError: [Errno 39] Directory not empty: '/scratch/pymp-k4bydc4d'
Traceback (most recent call last):
  File "/home/jlpkort/anaconda3/lib/python3.8/multiprocessing/util.py", line 300, in _run_finalizers
    finalizer()
  File "/home/jlpkort/anaconda3/lib/python3.8/multiprocessing/util.py", line 224, in __call__
    res = self._callback(*self._args, **self._kwargs)
  File "/home/jlpkort/anaconda3/lib/python3.8/multiprocessing/util.py", line 133, in _remove_temp_dir
    rmtree(tempdir)
  File "/home/jlpkort/anaconda3/lib/python3.8/shutil.py", line 722, in rmtree
    onerror(os.rmdir, path, sys.exc_info())
  File "/home/jlpkort/anaconda3/lib/python3.8/shutil.py", line 720, in rmtree
    os.rmdir(path)
OSError: [Errno 39] Directory not empty: '/scratch/pymp-k73ozxsm'
Traceback (most recent call last):
  File "/home/jlpkort/anaconda3/lib/python3.8/multiprocessing/util.py", line 300, in _run_finalizers
    finalizer()
  File "/home/jlpkort/anaconda3/lib/python3.8/multiprocessing/util.py", line 224, in __call__
    res = self._callback(*self._args, **self._kwargs)
  File "/home/jlpkort/anaconda3/lib/python3.8/multiprocessing/util.py", line 133, in _remove_temp_dir
    rmtree(tempdir)
  File "/home/jlpkort/anaconda3/lib/python3.8/shutil.py", line 722, in rmtree
    onerror(os.rmdir, path, sys.exc_info())
  File "/home/jlpkort/anaconda3/lib/python3.8/shutil.py", line 720, in rmtree
    os.rmdir(path)
OSError: [Errno 39] Directory not empty: '/scratch/pymp-0ua5p7av'
Traceback (most recent call last):
  File "/home/jlpkort/anaconda3/lib/python3.8/multiprocessing/util.py", line 300, in _run_finalizers
    finalizer()
  File "/home/jlpkort/anaconda3/lib/python3.8/multiprocessing/util.py", line 224, in __call__
    res = self._callback(*self._args, **self._kwargs)
  File "/home/jlpkort/anaconda3/lib/python3.8/multiprocessing/util.py", line 133, in _remove_temp_dir
    rmtree(tempdir)
  File "/home/jlpkort/anaconda3/lib/python3.8/shutil.py", line 722, in rmtree
    onerror(os.rmdir, path, sys.exc_info())
  File "/home/jlpkort/anaconda3/lib/python3.8/shutil.py", line 720, in rmtree
    os.rmdir(path)
OSError: [Errno 39] Directory not empty: '/scratch/pymp-bdds1bzh'
Traceback (most recent call last):
  File "/home/jlpkort/anaconda3/lib/python3.8/multiprocessing/util.py", line 300, in _run_finalizers
    finalizer()
  File "/home/jlpkort/anaconda3/lib/python3.8/multiprocessing/util.py", line 224, in __call__
    res = self._callback(*self._args, **self._kwargs)
  File "/home/jlpkort/anaconda3/lib/python3.8/multiprocessing/util.py", line 133, in _remove_temp_dir
    rmtree(tempdir)
  File "/home/jlpkort/anaconda3/lib/python3.8/shutil.py", line 722, in rmtree
    onerror(os.rmdir, path, sys.exc_info())
  File "/home/jlpkort/anaconda3/lib/python3.8/shutil.py", line 720, in rmtree
    os.rmdir(path)
OSError: [Errno 39] Directory not empty: '/scratch/pymp-7p3o3uh3'
I0908 18:43:17.175810 8380 trainer.py:117]  [Step: 21000/100000 (21.0%)] D Loss: -1.0000945329666138 M Loss: 1.0162112712860107 G Loss: -0.11108943074941635 
Traceback (most recent call last):
  File "/home/jlpkort/anaconda3/lib/python3.8/multiprocessing/util.py", line 300, in _run_finalizers
    finalizer()
  File "/home/jlpkort/anaconda3/lib/python3.8/multiprocessing/util.py", line 224, in __call__
    res = self._callback(*self._args, **self._kwargs)
  File "/home/jlpkort/anaconda3/lib/python3.8/multiprocessing/util.py", line 133, in _remove_temp_dir
    rmtree(tempdir)
  File "/home/jlpkort/anaconda3/lib/python3.8/shutil.py", line 722, in rmtree
    onerror(os.rmdir, path, sys.exc_info())
  File "/home/jlpkort/anaconda3/lib/python3.8/shutil.py", line 720, in rmtree
    os.rmdir(path)
OSError: [Errno 39] Directory not empty: '/scratch/pymp-8r7hax0d'
Traceback (most recent call last):
  File "/home/jlpkort/anaconda3/lib/python3.8/multiprocessing/util.py", line 300, in _run_finalizers
    finalizer()
  File "/home/jlpkort/anaconda3/lib/python3.8/multiprocessing/util.py", line 224, in __call__
    res = self._callback(*self._args, **self._kwargs)
  File "/home/jlpkort/anaconda3/lib/python3.8/multiprocessing/util.py", line 133, in _remove_temp_dir
    rmtree(tempdir)
  File "/home/jlpkort/anaconda3/lib/python3.8/shutil.py", line 722, in rmtree
    onerror(os.rmdir, path, sys.exc_info())
  File "/home/jlpkort/anaconda3/lib/python3.8/shutil.py", line 720, in rmtree
    os.rmdir(path)
OSError: [Errno 39] Directory not empty: '/scratch/pymp-8ueosg0j'
Traceback (most recent call last):
  File "/home/jlpkort/anaconda3/lib/python3.8/multiprocessing/util.py", line 300, in _run_finalizers
    finalizer()
  File "/home/jlpkort/anaconda3/lib/python3.8/multiprocessing/util.py", line 224, in __call__
    res = self._callback(*self._args, **self._kwargs)
  File "/home/jlpkort/anaconda3/lib/python3.8/multiprocessing/util.py", line 133, in _remove_temp_dir
    rmtree(tempdir)
  File "/home/jlpkort/anaconda3/lib/python3.8/shutil.py", line 722, in rmtree
    onerror(os.rmdir, path, sys.exc_info())
  File "/home/jlpkort/anaconda3/lib/python3.8/shutil.py", line 720, in rmtree
    os.rmdir(path)
OSError: [Errno 39] Directory not empty: '/scratch/pymp-4n59gnx5'
Traceback (most recent call last):
  File "/home/jlpkort/anaconda3/lib/python3.8/multiprocessing/util.py", line 300, in _run_finalizers
    finalizer()
  File "/home/jlpkort/anaconda3/lib/python3.8/multiprocessing/util.py", line 224, in __call__
    res = self._callback(*self._args, **self._kwargs)
  File "/home/jlpkort/anaconda3/lib/python3.8/multiprocessing/util.py", line 133, in _remove_temp_dir
    rmtree(tempdir)
  File "/home/jlpkort/anaconda3/lib/python3.8/shutil.py", line 722, in rmtree
    onerror(os.rmdir, path, sys.exc_info())
  File "/home/jlpkort/anaconda3/lib/python3.8/shutil.py", line 720, in rmtree
    os.rmdir(path)
OSError: [Errno 39] Directory not empty: '/scratch/pymp-pze5apku'
Traceback (most recent call last):
  File "/home/jlpkort/anaconda3/lib/python3.8/multiprocessing/util.py", line 300, in _run_finalizers
    finalizer()
  File "/home/jlpkort/anaconda3/lib/python3.8/multiprocessing/util.py", line 224, in __call__
    res = self._callback(*self._args, **self._kwargs)
  File "/home/jlpkort/anaconda3/lib/python3.8/multiprocessing/util.py", line 133, in _remove_temp_dir
    rmtree(tempdir)
  File "/home/jlpkort/anaconda3/lib/python3.8/shutil.py", line 722, in rmtree
    onerror(os.rmdir, path, sys.exc_info())
  File "/home/jlpkort/anaconda3/lib/python3.8/shutil.py", line 720, in rmtree
    os.rmdir(path)
OSError: [Errno 39] Directory not empty: '/scratch/pymp-4xgbbdaz'
I0908 20:06:40.824600 8380 trainer.py:117]  [Step: 22000/100000 (22.0%)] D Loss: -2.3917553424835205 M Loss: 0.9906680583953857 G Loss: -0.11454320698976517 
Traceback (most recent call last):
  File "/home/jlpkort/anaconda3/lib/python3.8/multiprocessing/util.py", line 300, in _run_finalizers
    finalizer()
  File "/home/jlpkort/anaconda3/lib/python3.8/multiprocessing/util.py", line 224, in __call__
    res = self._callback(*self._args, **self._kwargs)
  File "/home/jlpkort/anaconda3/lib/python3.8/multiprocessing/util.py", line 133, in _remove_temp_dir
    rmtree(tempdir)
  File "/home/jlpkort/anaconda3/lib/python3.8/shutil.py", line 722, in rmtree
    onerror(os.rmdir, path, sys.exc_info())
  File "/home/jlpkort/anaconda3/lib/python3.8/shutil.py", line 720, in rmtree
    os.rmdir(path)
OSError: [Errno 39] Directory not empty: '/scratch/pymp-qa29q_86'
Traceback (most recent call last):
  File "/home/jlpkort/anaconda3/lib/python3.8/multiprocessing/util.py", line 300, in _run_finalizers
    finalizer()
  File "/home/jlpkort/anaconda3/lib/python3.8/multiprocessing/util.py", line 224, in __call__
    res = self._callback(*self._args, **self._kwargs)
  File "/home/jlpkort/anaconda3/lib/python3.8/multiprocessing/util.py", line 133, in _remove_temp_dir
    rmtree(tempdir)
  File "/home/jlpkort/anaconda3/lib/python3.8/shutil.py", line 722, in rmtree
    onerror(os.rmdir, path, sys.exc_info())
  File "/home/jlpkort/anaconda3/lib/python3.8/shutil.py", line 720, in rmtree
    os.rmdir(path)
OSError: [Errno 39] Directory not empty: '/scratch/pymp-mumjkg53'
Traceback (most recent call last):
  File "/home/jlpkort/anaconda3/lib/python3.8/multiprocessing/util.py", line 300, in _run_finalizers
    finalizer()
  File "/home/jlpkort/anaconda3/lib/python3.8/multiprocessing/util.py", line 224, in __call__
    res = self._callback(*self._args, **self._kwargs)
  File "/home/jlpkort/anaconda3/lib/python3.8/multiprocessing/util.py", line 133, in _remove_temp_dir
    rmtree(tempdir)
  File "/home/jlpkort/anaconda3/lib/python3.8/shutil.py", line 722, in rmtree
    onerror(os.rmdir, path, sys.exc_info())
  File "/home/jlpkort/anaconda3/lib/python3.8/shutil.py", line 720, in rmtree
    os.rmdir(path)
OSError: [Errno 39] Directory not empty: '/scratch/pymp-6p15fy5s'
Traceback (most recent call last):
  File "/home/jlpkort/anaconda3/lib/python3.8/multiprocessing/util.py", line 300, in _run_finalizers
    finalizer()
  File "/home/jlpkort/anaconda3/lib/python3.8/multiprocessing/util.py", line 224, in __call__
    res = self._callback(*self._args, **self._kwargs)
  File "/home/jlpkort/anaconda3/lib/python3.8/multiprocessing/util.py", line 133, in _remove_temp_dir
    rmtree(tempdir)
  File "/home/jlpkort/anaconda3/lib/python3.8/shutil.py", line 722, in rmtree
    onerror(os.rmdir, path, sys.exc_info())
  File "/home/jlpkort/anaconda3/lib/python3.8/shutil.py", line 720, in rmtree
    os.rmdir(path)
OSError: [Errno 39] Directory not empty: '/scratch/pymp-8tqa_yng'
I0908 21:30:06.096510 8380 trainer.py:117]  [Step: 23000/100000 (23.0%)] D Loss: -1.2901546955108643 M Loss: 1.0065503120422363 G Loss: -0.07767019420862198 
Traceback (most recent call last):
  File "/home/jlpkort/anaconda3/lib/python3.8/multiprocessing/util.py", line 300, in _run_finalizers
    finalizer()
  File "/home/jlpkort/anaconda3/lib/python3.8/multiprocessing/util.py", line 224, in __call__
    res = self._callback(*self._args, **self._kwargs)
  File "/home/jlpkort/anaconda3/lib/python3.8/multiprocessing/util.py", line 133, in _remove_temp_dir
    rmtree(tempdir)
  File "/home/jlpkort/anaconda3/lib/python3.8/shutil.py", line 722, in rmtree
    onerror(os.rmdir, path, sys.exc_info())
  File "/home/jlpkort/anaconda3/lib/python3.8/shutil.py", line 720, in rmtree
    os.rmdir(path)
OSError: [Errno 39] Directory not empty: '/scratch/pymp-dlhjxi6x'
Traceback (most recent call last):
  File "/home/jlpkort/anaconda3/lib/python3.8/multiprocessing/util.py", line 300, in _run_finalizers
    finalizer()
  File "/home/jlpkort/anaconda3/lib/python3.8/multiprocessing/util.py", line 224, in __call__
    res = self._callback(*self._args, **self._kwargs)
  File "/home/jlpkort/anaconda3/lib/python3.8/multiprocessing/util.py", line 133, in _remove_temp_dir
    rmtree(tempdir)
  File "/home/jlpkort/anaconda3/lib/python3.8/shutil.py", line 722, in rmtree
    onerror(os.rmdir, path, sys.exc_info())
  File "/home/jlpkort/anaconda3/lib/python3.8/shutil.py", line 720, in rmtree
    os.rmdir(path)
OSError: [Errno 39] Directory not empty: '/scratch/pymp-6__eydgf'
Traceback (most recent call last):
  File "/home/jlpkort/anaconda3/lib/python3.8/multiprocessing/util.py", line 300, in _run_finalizers
    finalizer()
  File "/home/jlpkort/anaconda3/lib/python3.8/multiprocessing/util.py", line 224, in __call__
    res = self._callback(*self._args, **self._kwargs)
  File "/home/jlpkort/anaconda3/lib/python3.8/multiprocessing/util.py", line 133, in _remove_temp_dir
    rmtree(tempdir)
  File "/home/jlpkort/anaconda3/lib/python3.8/shutil.py", line 722, in rmtree
    onerror(os.rmdir, path, sys.exc_info())
  File "/home/jlpkort/anaconda3/lib/python3.8/shutil.py", line 720, in rmtree
    os.rmdir(path)
OSError: [Errno 39] Directory not empty: '/scratch/pymp-xnaio6pw'
Traceback (most recent call last):
  File "/home/jlpkort/anaconda3/lib/python3.8/multiprocessing/util.py", line 300, in _run_finalizers
    finalizer()
  File "/home/jlpkort/anaconda3/lib/python3.8/multiprocessing/util.py", line 224, in __call__
    res = self._callback(*self._args, **self._kwargs)
  File "/home/jlpkort/anaconda3/lib/python3.8/multiprocessing/util.py", line 133, in _remove_temp_dir
    rmtree(tempdir)
  File "/home/jlpkort/anaconda3/lib/python3.8/shutil.py", line 722, in rmtree
    onerror(os.rmdir, path, sys.exc_info())
  File "/home/jlpkort/anaconda3/lib/python3.8/shutil.py", line 720, in rmtree
    os.rmdir(path)
OSError: [Errno 39] Directory not empty: '/scratch/pymp-50y9zd0o'
I0908 22:56:57.808681 8380 trainer.py:117]  [Step: 24000/100000 (24.0%)] D Loss: -16.972576141357422 M Loss: 0.938327968120575 G Loss: -0.0970107764005661 
Traceback (most recent call last):
  File "/home/jlpkort/anaconda3/lib/python3.8/multiprocessing/util.py", line 300, in _run_finalizers
    finalizer()
  File "/home/jlpkort/anaconda3/lib/python3.8/multiprocessing/util.py", line 224, in __call__
    res = self._callback(*self._args, **self._kwargs)
  File "/home/jlpkort/anaconda3/lib/python3.8/multiprocessing/util.py", line 133, in _remove_temp_dir
    rmtree(tempdir)
  File "/home/jlpkort/anaconda3/lib/python3.8/shutil.py", line 722, in rmtree
    onerror(os.rmdir, path, sys.exc_info())
  File "/home/jlpkort/anaconda3/lib/python3.8/shutil.py", line 720, in rmtree
    os.rmdir(path)
OSError: [Errno 39] Directory not empty: '/scratch/pymp-0ovr7pfh'
I0909 00:21:21.224606 8380 trainer.py:117]  [Step: 25000/100000 (25.0%)] D Loss: -1.6818454265594482 M Loss: 0.9800910949707031 G Loss: -0.11171240359544754 
Traceback (most recent call last):
  File "/home/jlpkort/anaconda3/lib/python3.8/multiprocessing/util.py", line 300, in _run_finalizers
    finalizer()
  File "/home/jlpkort/anaconda3/lib/python3.8/multiprocessing/util.py", line 224, in __call__
    res = self._callback(*self._args, **self._kwargs)
  File "/home/jlpkort/anaconda3/lib/python3.8/multiprocessing/util.py", line 133, in _remove_temp_dir
    rmtree(tempdir)
  File "/home/jlpkort/anaconda3/lib/python3.8/shutil.py", line 722, in rmtree
    onerror(os.rmdir, path, sys.exc_info())
  File "/home/jlpkort/anaconda3/lib/python3.8/shutil.py", line 720, in rmtree
    os.rmdir(path)
OSError: [Errno 39] Directory not empty: '/scratch/pymp-ky51jjcw'
Traceback (most recent call last):
  File "/home/jlpkort/anaconda3/lib/python3.8/multiprocessing/util.py", line 300, in _run_finalizers
    finalizer()
  File "/home/jlpkort/anaconda3/lib/python3.8/multiprocessing/util.py", line 224, in __call__
    res = self._callback(*self._args, **self._kwargs)
  File "/home/jlpkort/anaconda3/lib/python3.8/multiprocessing/util.py", line 133, in _remove_temp_dir
    rmtree(tempdir)
  File "/home/jlpkort/anaconda3/lib/python3.8/shutil.py", line 722, in rmtree
    onerror(os.rmdir, path, sys.exc_info())
  File "/home/jlpkort/anaconda3/lib/python3.8/shutil.py", line 720, in rmtree
    os.rmdir(path)
OSError: [Errno 39] Directory not empty: '/scratch/pymp-4t9_ea9l'
Traceback (most recent call last):
  File "/home/jlpkort/anaconda3/lib/python3.8/multiprocessing/util.py", line 300, in _run_finalizers
    finalizer()
  File "/home/jlpkort/anaconda3/lib/python3.8/multiprocessing/util.py", line 224, in __call__
    res = self._callback(*self._args, **self._kwargs)
  File "/home/jlpkort/anaconda3/lib/python3.8/multiprocessing/util.py", line 133, in _remove_temp_dir
    rmtree(tempdir)
  File "/home/jlpkort/anaconda3/lib/python3.8/shutil.py", line 722, in rmtree
    onerror(os.rmdir, path, sys.exc_info())
  File "/home/jlpkort/anaconda3/lib/python3.8/shutil.py", line 720, in rmtree
    os.rmdir(path)
OSError: [Errno 39] Directory not empty: '/scratch/pymp-hukusyii'
Traceback (most recent call last):
  File "/home/jlpkort/anaconda3/lib/python3.8/multiprocessing/util.py", line 300, in _run_finalizers
    finalizer()
  File "/home/jlpkort/anaconda3/lib/python3.8/multiprocessing/util.py", line 224, in __call__
    res = self._callback(*self._args, **self._kwargs)
  File "/home/jlpkort/anaconda3/lib/python3.8/multiprocessing/util.py", line 133, in _remove_temp_dir
    rmtree(tempdir)
  File "/home/jlpkort/anaconda3/lib/python3.8/shutil.py", line 722, in rmtree
    onerror(os.rmdir, path, sys.exc_info())
  File "/home/jlpkort/anaconda3/lib/python3.8/shutil.py", line 720, in rmtree
    os.rmdir(path)
OSError: [Errno 39] Directory not empty: '/scratch/pymp-_ds7nyg2'
Traceback (most recent call last):
  File "/home/jlpkort/anaconda3/lib/python3.8/multiprocessing/util.py", line 300, in _run_finalizers
    finalizer()
  File "/home/jlpkort/anaconda3/lib/python3.8/multiprocessing/util.py", line 224, in __call__
    res = self._callback(*self._args, **self._kwargs)
  File "/home/jlpkort/anaconda3/lib/python3.8/multiprocessing/util.py", line 133, in _remove_temp_dir
    rmtree(tempdir)
  File "/home/jlpkort/anaconda3/lib/python3.8/shutil.py", line 722, in rmtree
    onerror(os.rmdir, path, sys.exc_info())
  File "/home/jlpkort/anaconda3/lib/python3.8/shutil.py", line 720, in rmtree
    os.rmdir(path)
OSError: [Errno 39] Directory not empty: '/scratch/pymp-rjwnzrxp'
I0909 01:44:43.282269 8380 trainer.py:117]  [Step: 26000/100000 (26.0%)] D Loss: -6.639372825622559 M Loss: 0.99732506275177 G Loss: -0.11497798562049866 
Traceback (most recent call last):
  File "/home/jlpkort/anaconda3/lib/python3.8/multiprocessing/util.py", line 300, in _run_finalizers
    finalizer()
  File "/home/jlpkort/anaconda3/lib/python3.8/multiprocessing/util.py", line 224, in __call__
    res = self._callback(*self._args, **self._kwargs)
  File "/home/jlpkort/anaconda3/lib/python3.8/multiprocessing/util.py", line 133, in _remove_temp_dir
    rmtree(tempdir)
  File "/home/jlpkort/anaconda3/lib/python3.8/shutil.py", line 722, in rmtree
    onerror(os.rmdir, path, sys.exc_info())
  File "/home/jlpkort/anaconda3/lib/python3.8/shutil.py", line 720, in rmtree
    os.rmdir(path)
OSError: [Errno 39] Directory not empty: '/scratch/pymp-z4d0sj2n'
Traceback (most recent call last):
  File "/home/jlpkort/anaconda3/lib/python3.8/multiprocessing/util.py", line 300, in _run_finalizers
    finalizer()
  File "/home/jlpkort/anaconda3/lib/python3.8/multiprocessing/util.py", line 224, in __call__
    res = self._callback(*self._args, **self._kwargs)
  File "/home/jlpkort/anaconda3/lib/python3.8/multiprocessing/util.py", line 133, in _remove_temp_dir
    rmtree(tempdir)
  File "/home/jlpkort/anaconda3/lib/python3.8/shutil.py", line 722, in rmtree
    onerror(os.rmdir, path, sys.exc_info())
  File "/home/jlpkort/anaconda3/lib/python3.8/shutil.py", line 720, in rmtree
    os.rmdir(path)
OSError: [Errno 39] Directory not empty: '/scratch/pymp-z4swwuam'
Traceback (most recent call last):
  File "/home/jlpkort/anaconda3/lib/python3.8/multiprocessing/util.py", line 300, in _run_finalizers
    finalizer()
  File "/home/jlpkort/anaconda3/lib/python3.8/multiprocessing/util.py", line 224, in __call__
    res = self._callback(*self._args, **self._kwargs)
  File "/home/jlpkort/anaconda3/lib/python3.8/multiprocessing/util.py", line 133, in _remove_temp_dir
    rmtree(tempdir)
  File "/home/jlpkort/anaconda3/lib/python3.8/shutil.py", line 722, in rmtree
    onerror(os.rmdir, path, sys.exc_info())
  File "/home/jlpkort/anaconda3/lib/python3.8/shutil.py", line 720, in rmtree
    os.rmdir(path)
OSError: [Errno 39] Directory not empty: '/scratch/pymp-ube7ohpo'
Traceback (most recent call last):
  File "/home/jlpkort/anaconda3/lib/python3.8/multiprocessing/util.py", line 300, in _run_finalizers
    finalizer()
  File "/home/jlpkort/anaconda3/lib/python3.8/multiprocessing/util.py", line 224, in __call__
    res = self._callback(*self._args, **self._kwargs)
  File "/home/jlpkort/anaconda3/lib/python3.8/multiprocessing/util.py", line 133, in _remove_temp_dir
    rmtree(tempdir)
  File "/home/jlpkort/anaconda3/lib/python3.8/shutil.py", line 722, in rmtree
    onerror(os.rmdir, path, sys.exc_info())
  File "/home/jlpkort/anaconda3/lib/python3.8/shutil.py", line 720, in rmtree
    os.rmdir(path)
OSError: [Errno 39] Directory not empty: '/scratch/pymp-2xgpgpg0'
I0909 03:08:15.641275 8380 trainer.py:117]  [Step: 27000/100000 (27.0%)] D Loss: 1.2323952913284302 M Loss: 1.006717562675476 G Loss: -0.11522389203310013 
Traceback (most recent call last):
  File "/home/jlpkort/anaconda3/lib/python3.8/multiprocessing/util.py", line 300, in _run_finalizers
    finalizer()
  File "/home/jlpkort/anaconda3/lib/python3.8/multiprocessing/util.py", line 224, in __call__
    res = self._callback(*self._args, **self._kwargs)
  File "/home/jlpkort/anaconda3/lib/python3.8/multiprocessing/util.py", line 133, in _remove_temp_dir
    rmtree(tempdir)
  File "/home/jlpkort/anaconda3/lib/python3.8/shutil.py", line 722, in rmtree
    onerror(os.rmdir, path, sys.exc_info())
  File "/home/jlpkort/anaconda3/lib/python3.8/shutil.py", line 720, in rmtree
    os.rmdir(path)
OSError: [Errno 39] Directory not empty: '/scratch/pymp-wuk61_be'
I0909 04:31:47.330646 8380 trainer.py:117]  [Step: 28000/100000 (28.0%)] D Loss: -1.7509247064590454 M Loss: 0.9980342388153076 G Loss: -0.10647206008434296 
Traceback (most recent call last):
  File "/home/jlpkort/anaconda3/lib/python3.8/multiprocessing/util.py", line 300, in _run_finalizers
    finalizer()
  File "/home/jlpkort/anaconda3/lib/python3.8/multiprocessing/util.py", line 224, in __call__
    res = self._callback(*self._args, **self._kwargs)
  File "/home/jlpkort/anaconda3/lib/python3.8/multiprocessing/util.py", line 133, in _remove_temp_dir
    rmtree(tempdir)
  File "/home/jlpkort/anaconda3/lib/python3.8/shutil.py", line 722, in rmtree
    onerror(os.rmdir, path, sys.exc_info())
  File "/home/jlpkort/anaconda3/lib/python3.8/shutil.py", line 720, in rmtree
    os.rmdir(path)
OSError: [Errno 39] Directory not empty: '/scratch/pymp-fa7ey8cy'
Traceback (most recent call last):
  File "/home/jlpkort/anaconda3/lib/python3.8/multiprocessing/util.py", line 300, in _run_finalizers
    finalizer()
  File "/home/jlpkort/anaconda3/lib/python3.8/multiprocessing/util.py", line 224, in __call__
    res = self._callback(*self._args, **self._kwargs)
  File "/home/jlpkort/anaconda3/lib/python3.8/multiprocessing/util.py", line 133, in _remove_temp_dir
    rmtree(tempdir)
  File "/home/jlpkort/anaconda3/lib/python3.8/shutil.py", line 722, in rmtree
    onerror(os.rmdir, path, sys.exc_info())
  File "/home/jlpkort/anaconda3/lib/python3.8/shutil.py", line 720, in rmtree
    os.rmdir(path)
OSError: [Errno 39] Directory not empty: '/scratch/pymp-t0e792kp'
Traceback (most recent call last):
  File "/home/jlpkort/anaconda3/lib/python3.8/multiprocessing/util.py", line 300, in _run_finalizers
    finalizer()
  File "/home/jlpkort/anaconda3/lib/python3.8/multiprocessing/util.py", line 224, in __call__
    res = self._callback(*self._args, **self._kwargs)
  File "/home/jlpkort/anaconda3/lib/python3.8/multiprocessing/util.py", line 133, in _remove_temp_dir
    rmtree(tempdir)
  File "/home/jlpkort/anaconda3/lib/python3.8/shutil.py", line 722, in rmtree
    onerror(os.rmdir, path, sys.exc_info())
  File "/home/jlpkort/anaconda3/lib/python3.8/shutil.py", line 720, in rmtree
    os.rmdir(path)
OSError: [Errno 39] Directory not empty: '/scratch/pymp-amgw4khm'
Traceback (most recent call last):
  File "/home/jlpkort/anaconda3/lib/python3.8/multiprocessing/util.py", line 300, in _run_finalizers
    finalizer()
  File "/home/jlpkort/anaconda3/lib/python3.8/multiprocessing/util.py", line 224, in __call__
    res = self._callback(*self._args, **self._kwargs)
  File "/home/jlpkort/anaconda3/lib/python3.8/multiprocessing/util.py", line 133, in _remove_temp_dir
    rmtree(tempdir)
  File "/home/jlpkort/anaconda3/lib/python3.8/shutil.py", line 722, in rmtree
    onerror(os.rmdir, path, sys.exc_info())
  File "/home/jlpkort/anaconda3/lib/python3.8/shutil.py", line 720, in rmtree
    os.rmdir(path)
OSError: [Errno 39] Directory not empty: '/scratch/pymp-cnr31qv0'
Traceback (most recent call last):
  File "/home/jlpkort/anaconda3/lib/python3.8/multiprocessing/util.py", line 300, in _run_finalizers
    finalizer()
  File "/home/jlpkort/anaconda3/lib/python3.8/multiprocessing/util.py", line 224, in __call__
    res = self._callback(*self._args, **self._kwargs)
  File "/home/jlpkort/anaconda3/lib/python3.8/multiprocessing/util.py", line 133, in _remove_temp_dir
    rmtree(tempdir)
  File "/home/jlpkort/anaconda3/lib/python3.8/shutil.py", line 722, in rmtree
    onerror(os.rmdir, path, sys.exc_info())
  File "/home/jlpkort/anaconda3/lib/python3.8/shutil.py", line 720, in rmtree
    os.rmdir(path)
OSError: [Errno 39] Directory not empty: '/scratch/pymp-zra5_5jf'
Traceback (most recent call last):
  File "/home/jlpkort/anaconda3/lib/python3.8/multiprocessing/util.py", line 300, in _run_finalizers
    finalizer()
  File "/home/jlpkort/anaconda3/lib/python3.8/multiprocessing/util.py", line 224, in __call__
    res = self._callback(*self._args, **self._kwargs)
  File "/home/jlpkort/anaconda3/lib/python3.8/multiprocessing/util.py", line 133, in _remove_temp_dir
    rmtree(tempdir)
  File "/home/jlpkort/anaconda3/lib/python3.8/shutil.py", line 722, in rmtree
    onerror(os.rmdir, path, sys.exc_info())
  File "/home/jlpkort/anaconda3/lib/python3.8/shutil.py", line 720, in rmtree
    os.rmdir(path)
OSError: [Errno 39] Directory not empty: '/scratch/pymp-ew6stpp1'
Traceback (most recent call last):
  File "/home/jlpkort/anaconda3/lib/python3.8/multiprocessing/util.py", line 300, in _run_finalizers
    finalizer()
  File "/home/jlpkort/anaconda3/lib/python3.8/multiprocessing/util.py", line 224, in __call__
    res = self._callback(*self._args, **self._kwargs)
  File "/home/jlpkort/anaconda3/lib/python3.8/multiprocessing/util.py", line 133, in _remove_temp_dir
    rmtree(tempdir)
  File "/home/jlpkort/anaconda3/lib/python3.8/shutil.py", line 722, in rmtree
    onerror(os.rmdir, path, sys.exc_info())
  File "/home/jlpkort/anaconda3/lib/python3.8/shutil.py", line 720, in rmtree
    os.rmdir(path)
OSError: [Errno 39] Directory not empty: '/scratch/pymp-jo3vbq7a'
I0909 05:55:24.989134 8380 trainer.py:117]  [Step: 29000/100000 (29.0%)] D Loss: -1.7634899616241455 M Loss: 0.9955743551254272 G Loss: -0.11758559942245483 
Traceback (most recent call last):
  File "/home/jlpkort/anaconda3/lib/python3.8/multiprocessing/util.py", line 300, in _run_finalizers
    finalizer()
  File "/home/jlpkort/anaconda3/lib/python3.8/multiprocessing/util.py", line 224, in __call__
    res = self._callback(*self._args, **self._kwargs)
  File "/home/jlpkort/anaconda3/lib/python3.8/multiprocessing/util.py", line 133, in _remove_temp_dir
    rmtree(tempdir)
  File "/home/jlpkort/anaconda3/lib/python3.8/shutil.py", line 722, in rmtree
    onerror(os.rmdir, path, sys.exc_info())
  File "/home/jlpkort/anaconda3/lib/python3.8/shutil.py", line 720, in rmtree
    os.rmdir(path)
OSError: [Errno 39] Directory not empty: '/scratch/pymp-7u3egu1s'
Traceback (most recent call last):
  File "/home/jlpkort/anaconda3/lib/python3.8/multiprocessing/util.py", line 300, in _run_finalizers
    finalizer()
  File "/home/jlpkort/anaconda3/lib/python3.8/multiprocessing/util.py", line 224, in __call__
    res = self._callback(*self._args, **self._kwargs)
  File "/home/jlpkort/anaconda3/lib/python3.8/multiprocessing/util.py", line 133, in _remove_temp_dir
    rmtree(tempdir)
  File "/home/jlpkort/anaconda3/lib/python3.8/shutil.py", line 722, in rmtree
    onerror(os.rmdir, path, sys.exc_info())
  File "/home/jlpkort/anaconda3/lib/python3.8/shutil.py", line 720, in rmtree
    os.rmdir(path)
OSError: [Errno 39] Directory not empty: '/scratch/pymp-nchsfpbe'
I0909 07:19:10.026211 8380 trainer.py:117]  [Step: 30000/100000 (30.0%)] D Loss: -2.935810089111328 M Loss: 1.014330506324768 G Loss: -0.10797339677810669 
Traceback (most recent call last):
  File "/home/jlpkort/anaconda3/lib/python3.8/multiprocessing/util.py", line 300, in _run_finalizers
    finalizer()
  File "/home/jlpkort/anaconda3/lib/python3.8/multiprocessing/util.py", line 224, in __call__
    res = self._callback(*self._args, **self._kwargs)
  File "/home/jlpkort/anaconda3/lib/python3.8/multiprocessing/util.py", line 133, in _remove_temp_dir
    rmtree(tempdir)
  File "/home/jlpkort/anaconda3/lib/python3.8/shutil.py", line 722, in rmtree
    onerror(os.rmdir, path, sys.exc_info())
  File "/home/jlpkort/anaconda3/lib/python3.8/shutil.py", line 720, in rmtree
    os.rmdir(path)
OSError: [Errno 39] Directory not empty: '/scratch/pymp-om38c5bk'
Traceback (most recent call last):
  File "/home/jlpkort/anaconda3/lib/python3.8/multiprocessing/util.py", line 300, in _run_finalizers
    finalizer()
  File "/home/jlpkort/anaconda3/lib/python3.8/multiprocessing/util.py", line 224, in __call__
    res = self._callback(*self._args, **self._kwargs)
  File "/home/jlpkort/anaconda3/lib/python3.8/multiprocessing/util.py", line 133, in _remove_temp_dir
    rmtree(tempdir)
  File "/home/jlpkort/anaconda3/lib/python3.8/shutil.py", line 722, in rmtree
    onerror(os.rmdir, path, sys.exc_info())
  File "/home/jlpkort/anaconda3/lib/python3.8/shutil.py", line 720, in rmtree
    os.rmdir(path)
OSError: [Errno 39] Directory not empty: '/scratch/pymp-x0v95lq8'
I0909 08:42:46.880287 8380 trainer.py:117]  [Step: 31000/100000 (31.0%)] D Loss: 0.424649715423584 M Loss: 1.0064985752105713 G Loss: -0.09635193645954132 
Traceback (most recent call last):
  File "/home/jlpkort/anaconda3/lib/python3.8/multiprocessing/util.py", line 300, in _run_finalizers
    finalizer()
  File "/home/jlpkort/anaconda3/lib/python3.8/multiprocessing/util.py", line 224, in __call__
    res = self._callback(*self._args, **self._kwargs)
  File "/home/jlpkort/anaconda3/lib/python3.8/multiprocessing/util.py", line 133, in _remove_temp_dir
    rmtree(tempdir)
  File "/home/jlpkort/anaconda3/lib/python3.8/shutil.py", line 722, in rmtree
    onerror(os.rmdir, path, sys.exc_info())
  File "/home/jlpkort/anaconda3/lib/python3.8/shutil.py", line 720, in rmtree
    os.rmdir(path)
OSError: [Errno 39] Directory not empty: '/scratch/pymp-1tksd55q'
I0909 10:06:24.997279 8380 trainer.py:117]  [Step: 32000/100000 (32.0%)] D Loss: -1.8298810720443726 M Loss: 0.9912645220756531 G Loss: -0.08981387317180634 
Traceback (most recent call last):
  File "/home/jlpkort/anaconda3/lib/python3.8/multiprocessing/util.py", line 300, in _run_finalizers
    finalizer()
  File "/home/jlpkort/anaconda3/lib/python3.8/multiprocessing/util.py", line 224, in __call__
    res = self._callback(*self._args, **self._kwargs)
  File "/home/jlpkort/anaconda3/lib/python3.8/multiprocessing/util.py", line 133, in _remove_temp_dir
    rmtree(tempdir)
  File "/home/jlpkort/anaconda3/lib/python3.8/shutil.py", line 722, in rmtree
    onerror(os.rmdir, path, sys.exc_info())
  File "/home/jlpkort/anaconda3/lib/python3.8/shutil.py", line 720, in rmtree
    os.rmdir(path)
OSError: [Errno 39] Directory not empty: '/scratch/pymp-yj952lin'
Traceback (most recent call last):
  File "/home/jlpkort/anaconda3/lib/python3.8/multiprocessing/util.py", line 300, in _run_finalizers
    finalizer()
  File "/home/jlpkort/anaconda3/lib/python3.8/multiprocessing/util.py", line 224, in __call__
    res = self._callback(*self._args, **self._kwargs)
  File "/home/jlpkort/anaconda3/lib/python3.8/multiprocessing/util.py", line 133, in _remove_temp_dir
    rmtree(tempdir)
  File "/home/jlpkort/anaconda3/lib/python3.8/shutil.py", line 722, in rmtree
    onerror(os.rmdir, path, sys.exc_info())
  File "/home/jlpkort/anaconda3/lib/python3.8/shutil.py", line 720, in rmtree
    os.rmdir(path)
OSError: [Errno 39] Directory not empty: '/scratch/pymp-imr9nkqm'
Traceback (most recent call last):
  File "/home/jlpkort/anaconda3/lib/python3.8/multiprocessing/util.py", line 300, in _run_finalizers
    finalizer()
  File "/home/jlpkort/anaconda3/lib/python3.8/multiprocessing/util.py", line 224, in __call__
    res = self._callback(*self._args, **self._kwargs)
  File "/home/jlpkort/anaconda3/lib/python3.8/multiprocessing/util.py", line 133, in _remove_temp_dir
    rmtree(tempdir)
  File "/home/jlpkort/anaconda3/lib/python3.8/shutil.py", line 722, in rmtree
    onerror(os.rmdir, path, sys.exc_info())
  File "/home/jlpkort/anaconda3/lib/python3.8/shutil.py", line 720, in rmtree
    os.rmdir(path)
OSError: [Errno 39] Directory not empty: '/scratch/pymp-vzvtk5ox'
Traceback (most recent call last):
  File "/home/jlpkort/anaconda3/lib/python3.8/multiprocessing/util.py", line 300, in _run_finalizers
    finalizer()
  File "/home/jlpkort/anaconda3/lib/python3.8/multiprocessing/util.py", line 224, in __call__
    res = self._callback(*self._args, **self._kwargs)
  File "/home/jlpkort/anaconda3/lib/python3.8/multiprocessing/util.py", line 133, in _remove_temp_dir
    rmtree(tempdir)
  File "/home/jlpkort/anaconda3/lib/python3.8/shutil.py", line 722, in rmtree
    onerror(os.rmdir, path, sys.exc_info())
  File "/home/jlpkort/anaconda3/lib/python3.8/shutil.py", line 720, in rmtree
    os.rmdir(path)
OSError: [Errno 39] Directory not empty: '/scratch/pymp-b0codbzw'
Traceback (most recent call last):
  File "/home/jlpkort/anaconda3/lib/python3.8/multiprocessing/util.py", line 300, in _run_finalizers
    finalizer()
  File "/home/jlpkort/anaconda3/lib/python3.8/multiprocessing/util.py", line 224, in __call__
    res = self._callback(*self._args, **self._kwargs)
  File "/home/jlpkort/anaconda3/lib/python3.8/multiprocessing/util.py", line 133, in _remove_temp_dir
    rmtree(tempdir)
  File "/home/jlpkort/anaconda3/lib/python3.8/shutil.py", line 722, in rmtree
    onerror(os.rmdir, path, sys.exc_info())
  File "/home/jlpkort/anaconda3/lib/python3.8/shutil.py", line 720, in rmtree
    os.rmdir(path)
OSError: [Errno 39] Directory not empty: '/scratch/pymp-mcuc49nr'
I0909 11:30:02.678932 8380 trainer.py:117]  [Step: 33000/100000 (33.0%)] D Loss: -4.679335594177246 M Loss: 1.004063606262207 G Loss: -0.10007284581661224 
slurmstepd: error: *** JOB 8168189 ON r30n3 CANCELLED AT 2021-09-09T11:43:24 ***
