Looking in links: https://download.pytorch.org/whl/torch_stable.html
Requirement already satisfied: torch==1.5.0+cu101 in /home/jlpkort/anaconda3/lib/python3.8/site-packages (1.5.0+cu101)
Requirement already satisfied: torchvision==0.6.0+cu101 in /home/jlpkort/anaconda3/lib/python3.8/site-packages (0.6.0+cu101)
Requirement already satisfied: future in /home/jlpkort/anaconda3/lib/python3.8/site-packages (from torch==1.5.0+cu101) (0.18.2)
Requirement already satisfied: numpy in /home/jlpkort/anaconda3/lib/python3.8/site-packages (from torch==1.5.0+cu101) (1.17.4)
Requirement already satisfied: pillow>=4.1.1 in /home/jlpkort/anaconda3/lib/python3.8/site-packages (from torchvision==0.6.0+cu101) (8.2.0)
ERROR: Could not find a version that satisfies the requirement opencv_contrib_python_nonfree==4.1.1.1
ERROR: No matching distribution found for opencv_contrib_python_nonfree==4.1.1.1
wandb: Currently logged in as: tijmenk_ (use `wandb login --relogin` to force relogin)
DATASET:
  MASKS: ./datasets/masks_tv_256
  MEAN: [0.5, 0.5, 0.5]
  NAME: TVB
  ROOT: ./datasets/data_256
  SIZE: 256
  SIZE_H: 256
  SIZE_W: 256
  STD: [0.5, 0.5, 0.5]
MODEL:
  D:
    BETAS: (0.5, 0.9)
    DECAY_RATE: 0.5
    LR: 0.001
    NAME: 1-ChOutputDiscriminator
    NUM_CHANNELS: 64
    NUM_CRITICS: 5
    SCHEDULER: []
  IS_TRAIN: True
  JOINT:
    BETAS: (0.5, 0.9)
    DECAY_RATE: 0.5
    LR: 0.0002
    NAME: JointNetwork
    SCHEDULER: []
  MPN:
    BETAS: (0.5, 0.9)
    DECAY_RATE: 0.0
    LOSS_COEFF: 2.0
    LR: 1e-05
    NAME: MaskPredictionNetwork
    NECK_CHANNELS: 128
    NUM_CHANNELS: 64
    SCHEDULER: []
  NAME: VCNet
  RIN:
    BETAS: (0.5, 0.9)
    DECAY_RATE: 0.0
    EMBRACE: True
    LOSS_COEFF: 1.0
    LR: 0.0001
    NAME: RobustInpaintingNetwork
    NECK_CHANNELS: 128
    NUM_CHANNELS: 32
    SCHEDULER: []
OPTIM:
  ADVERSARIAL: 0.001
  GP: 10
  MASK: 1
  RECON: 1.4
  SEMANTIC: 0.0001
  TEXTURE: 0.001
SYSTEM:
  NUM_GPU: 4
  NUM_WORKERS: 16
TEST:
  ABLATION: False
  BATCH_SIZE: 64
  C_IMG_ID: 38
  IMG_ID: 52
  ITER: 4
  MODE: 7
  OUTPUT_DIR: ./outputs
  WEIGHTS: None
TRAIN:
  BATCH_SIZE: 4
  LOG_INTERVAL: 1000
  NUM_STEPS_FOR_JOINT: 6600
  NUM_TOTAL_STEP: 100000
  RESUME: False
  SAVE_DIR: ./weights
  SAVE_INTERVAL: 10000
  SHUFFLE: True
  START_STEP: 0
  TUNE: False
  VISUALIZE_INTERVAL: 1000
WANDB:
  ENTITY: tijmenk_
  LOG_DIR: 
  NUM_ROW: 0
  PROJECT_NAME: thesis_pytorch
  RUN: 16
wandb: wandb version 0.12.1 is available!  To upgrade, please run:
wandb:  $ pip install wandb --upgrade
wandb: Tracking run with wandb version 0.11.0
wandb: Syncing run generous-river-124
wandb:  View project at https://wandb.ai/tijmenk_/thesis_pytorch
wandb:  View run at https://wandb.ai/tijmenk_/thesis_pytorch/runs/14750s9s
wandb: Run data is saved locally in /home/jlpkort/vcnet-blind-image-inpainting/wandb/run-20210904_094453-14750s9s
wandb: Run `wandb offline` to turn off syncing.
I0904 09:45:01.612848 5956 trainer.py:244] Using 4 GPUs...

CHANNELS:  64
CHANNELS:  64
Traceback (most recent call last):
  File "/home/jlpkort/anaconda3/lib/python3.8/multiprocessing/util.py", line 300, in _run_finalizers
    finalizer()
  File "/home/jlpkort/anaconda3/lib/python3.8/multiprocessing/util.py", line 224, in __call__
    res = self._callback(*self._args, **self._kwargs)
  File "/home/jlpkort/anaconda3/lib/python3.8/multiprocessing/util.py", line 133, in _remove_temp_dir
    rmtree(tempdir)
  File "/home/jlpkort/anaconda3/lib/python3.8/shutil.py", line 722, in rmtree
    onerror(os.rmdir, path, sys.exc_info())
  File "/home/jlpkort/anaconda3/lib/python3.8/shutil.py", line 720, in rmtree
    os.rmdir(path)
OSError: [Errno 39] Directory not empty: '/scratch/pymp-nr0m3xm8'
Traceback (most recent call last):
  File "/home/jlpkort/anaconda3/lib/python3.8/multiprocessing/util.py", line 300, in _run_finalizers
    finalizer()
  File "/home/jlpkort/anaconda3/lib/python3.8/multiprocessing/util.py", line 224, in __call__
    res = self._callback(*self._args, **self._kwargs)
  File "/home/jlpkort/anaconda3/lib/python3.8/multiprocessing/util.py", line 133, in _remove_temp_dir
    rmtree(tempdir)
  File "/home/jlpkort/anaconda3/lib/python3.8/shutil.py", line 722, in rmtree
    onerror(os.rmdir, path, sys.exc_info())
  File "/home/jlpkort/anaconda3/lib/python3.8/shutil.py", line 720, in rmtree
    os.rmdir(path)
OSError: [Errno 39] Directory not empty: '/scratch/pymp-7udtbk1o'
Traceback (most recent call last):
  File "/home/jlpkort/anaconda3/lib/python3.8/multiprocessing/util.py", line 300, in _run_finalizers
    finalizer()
  File "/home/jlpkort/anaconda3/lib/python3.8/multiprocessing/util.py", line 224, in __call__
    res = self._callback(*self._args, **self._kwargs)
  File "/home/jlpkort/anaconda3/lib/python3.8/multiprocessing/util.py", line 133, in _remove_temp_dir
    rmtree(tempdir)
  File "/home/jlpkort/anaconda3/lib/python3.8/shutil.py", line 722, in rmtree
    onerror(os.rmdir, path, sys.exc_info())
  File "/home/jlpkort/anaconda3/lib/python3.8/shutil.py", line 720, in rmtree
    os.rmdir(path)
OSError: [Errno 39] Directory not empty: '/scratch/pymp-p1n88btf'
Traceback (most recent call last):
  File "/home/jlpkort/anaconda3/lib/python3.8/multiprocessing/util.py", line 300, in _run_finalizers
    finalizer()
  File "/home/jlpkort/anaconda3/lib/python3.8/multiprocessing/util.py", line 224, in __call__
    res = self._callback(*self._args, **self._kwargs)
  File "/home/jlpkort/anaconda3/lib/python3.8/multiprocessing/util.py", line 133, in _remove_temp_dir
    rmtree(tempdir)
  File "/home/jlpkort/anaconda3/lib/python3.8/shutil.py", line 722, in rmtree
    onerror(os.rmdir, path, sys.exc_info())
  File "/home/jlpkort/anaconda3/lib/python3.8/shutil.py", line 720, in rmtree
    os.rmdir(path)
OSError: [Errno 39] Directory not empty: '/scratch/pymp-8gpa6xo8'
Traceback (most recent call last):
  File "/home/jlpkort/anaconda3/lib/python3.8/multiprocessing/util.py", line 300, in _run_finalizers
    finalizer()
  File "/home/jlpkort/anaconda3/lib/python3.8/multiprocessing/util.py", line 224, in __call__
    res = self._callback(*self._args, **self._kwargs)
  File "/home/jlpkort/anaconda3/lib/python3.8/multiprocessing/util.py", line 133, in _remove_temp_dir
    rmtree(tempdir)
  File "/home/jlpkort/anaconda3/lib/python3.8/shutil.py", line 722, in rmtree
    onerror(os.rmdir, path, sys.exc_info())
  File "/home/jlpkort/anaconda3/lib/python3.8/shutil.py", line 720, in rmtree
    os.rmdir(path)
OSError: [Errno 39] Directory not empty: '/scratch/pymp-rjltg1x3'
I0904 11:03:21.136307 5956 trainer.py:117]  [Step: 1000/100000 (1.0%)] D Loss: -59.649208068847656 M Loss: 1.3643946647644043 G Loss: -0.6470778584480286 
Traceback (most recent call last):
  File "/home/jlpkort/anaconda3/lib/python3.8/multiprocessing/util.py", line 300, in _run_finalizers
    finalizer()
  File "/home/jlpkort/anaconda3/lib/python3.8/multiprocessing/util.py", line 224, in __call__
    res = self._callback(*self._args, **self._kwargs)
  File "/home/jlpkort/anaconda3/lib/python3.8/multiprocessing/util.py", line 133, in _remove_temp_dir
    rmtree(tempdir)
  File "/home/jlpkort/anaconda3/lib/python3.8/shutil.py", line 722, in rmtree
    onerror(os.rmdir, path, sys.exc_info())
  File "/home/jlpkort/anaconda3/lib/python3.8/shutil.py", line 720, in rmtree
    os.rmdir(path)
OSError: [Errno 39] Directory not empty: '/scratch/pymp-s01iaz87'
Traceback (most recent call last):
  File "/home/jlpkort/anaconda3/lib/python3.8/multiprocessing/util.py", line 300, in _run_finalizers
    finalizer()
  File "/home/jlpkort/anaconda3/lib/python3.8/multiprocessing/util.py", line 224, in __call__
    res = self._callback(*self._args, **self._kwargs)
  File "/home/jlpkort/anaconda3/lib/python3.8/multiprocessing/util.py", line 133, in _remove_temp_dir
    rmtree(tempdir)
  File "/home/jlpkort/anaconda3/lib/python3.8/shutil.py", line 722, in rmtree
    onerror(os.rmdir, path, sys.exc_info())
  File "/home/jlpkort/anaconda3/lib/python3.8/shutil.py", line 720, in rmtree
    os.rmdir(path)
OSError: [Errno 39] Directory not empty: '/scratch/pymp-zlu_h8d3'
Traceback (most recent call last):
  File "/home/jlpkort/anaconda3/lib/python3.8/multiprocessing/util.py", line 300, in _run_finalizers
    finalizer()
  File "/home/jlpkort/anaconda3/lib/python3.8/multiprocessing/util.py", line 224, in __call__
    res = self._callback(*self._args, **self._kwargs)
  File "/home/jlpkort/anaconda3/lib/python3.8/multiprocessing/util.py", line 133, in _remove_temp_dir
    rmtree(tempdir)
  File "/home/jlpkort/anaconda3/lib/python3.8/shutil.py", line 722, in rmtree
    onerror(os.rmdir, path, sys.exc_info())
  File "/home/jlpkort/anaconda3/lib/python3.8/shutil.py", line 720, in rmtree
    os.rmdir(path)
OSError: [Errno 39] Directory not empty: '/scratch/pymp-7o3wycyh'
Traceback (most recent call last):
  File "/home/jlpkort/anaconda3/lib/python3.8/multiprocessing/util.py", line 300, in _run_finalizers
    finalizer()
  File "/home/jlpkort/anaconda3/lib/python3.8/multiprocessing/util.py", line 224, in __call__
    res = self._callback(*self._args, **self._kwargs)
  File "/home/jlpkort/anaconda3/lib/python3.8/multiprocessing/util.py", line 133, in _remove_temp_dir
    rmtree(tempdir)
  File "/home/jlpkort/anaconda3/lib/python3.8/shutil.py", line 722, in rmtree
    onerror(os.rmdir, path, sys.exc_info())
  File "/home/jlpkort/anaconda3/lib/python3.8/shutil.py", line 720, in rmtree
    os.rmdir(path)
OSError: [Errno 39] Directory not empty: '/scratch/pymp-93hje4r5'
Traceback (most recent call last):
  File "/home/jlpkort/anaconda3/lib/python3.8/multiprocessing/util.py", line 300, in _run_finalizers
    finalizer()
  File "/home/jlpkort/anaconda3/lib/python3.8/multiprocessing/util.py", line 224, in __call__
    res = self._callback(*self._args, **self._kwargs)
  File "/home/jlpkort/anaconda3/lib/python3.8/multiprocessing/util.py", line 133, in _remove_temp_dir
    rmtree(tempdir)
  File "/home/jlpkort/anaconda3/lib/python3.8/shutil.py", line 722, in rmtree
    onerror(os.rmdir, path, sys.exc_info())
  File "/home/jlpkort/anaconda3/lib/python3.8/shutil.py", line 720, in rmtree
    os.rmdir(path)
OSError: [Errno 39] Directory not empty: '/scratch/pymp-dqcr2ocf'
Traceback (most recent call last):
  File "/home/jlpkort/anaconda3/lib/python3.8/multiprocessing/util.py", line 300, in _run_finalizers
    finalizer()
  File "/home/jlpkort/anaconda3/lib/python3.8/multiprocessing/util.py", line 224, in __call__
    res = self._callback(*self._args, **self._kwargs)
  File "/home/jlpkort/anaconda3/lib/python3.8/multiprocessing/util.py", line 133, in _remove_temp_dir
    rmtree(tempdir)
  File "/home/jlpkort/anaconda3/lib/python3.8/shutil.py", line 722, in rmtree
    onerror(os.rmdir, path, sys.exc_info())
  File "/home/jlpkort/anaconda3/lib/python3.8/shutil.py", line 720, in rmtree
    os.rmdir(path)
OSError: [Errno 39] Directory not empty: '/scratch/pymp-pay8az36'
Traceback (most recent call last):
  File "/home/jlpkort/anaconda3/lib/python3.8/multiprocessing/util.py", line 300, in _run_finalizers
    finalizer()
  File "/home/jlpkort/anaconda3/lib/python3.8/multiprocessing/util.py", line 224, in __call__
    res = self._callback(*self._args, **self._kwargs)
  File "/home/jlpkort/anaconda3/lib/python3.8/multiprocessing/util.py", line 133, in _remove_temp_dir
    rmtree(tempdir)
  File "/home/jlpkort/anaconda3/lib/python3.8/shutil.py", line 722, in rmtree
    onerror(os.rmdir, path, sys.exc_info())
  File "/home/jlpkort/anaconda3/lib/python3.8/shutil.py", line 720, in rmtree
    os.rmdir(path)
OSError: [Errno 39] Directory not empty: '/scratch/pymp-wvs_0mex'
Traceback (most recent call last):
  File "/home/jlpkort/anaconda3/lib/python3.8/multiprocessing/util.py", line 300, in _run_finalizers
    finalizer()
  File "/home/jlpkort/anaconda3/lib/python3.8/multiprocessing/util.py", line 224, in __call__
    res = self._callback(*self._args, **self._kwargs)
  File "/home/jlpkort/anaconda3/lib/python3.8/multiprocessing/util.py", line 133, in _remove_temp_dir
    rmtree(tempdir)
  File "/home/jlpkort/anaconda3/lib/python3.8/shutil.py", line 722, in rmtree
    onerror(os.rmdir, path, sys.exc_info())
  File "/home/jlpkort/anaconda3/lib/python3.8/shutil.py", line 720, in rmtree
    os.rmdir(path)
OSError: [Errno 39] Directory not empty: '/scratch/pymp-7m52xuq0'
Traceback (most recent call last):
  File "/home/jlpkort/anaconda3/lib/python3.8/multiprocessing/util.py", line 300, in _run_finalizers
    finalizer()
  File "/home/jlpkort/anaconda3/lib/python3.8/multiprocessing/util.py", line 224, in __call__
    res = self._callback(*self._args, **self._kwargs)
  File "/home/jlpkort/anaconda3/lib/python3.8/multiprocessing/util.py", line 133, in _remove_temp_dir
    rmtree(tempdir)
  File "/home/jlpkort/anaconda3/lib/python3.8/shutil.py", line 722, in rmtree
    onerror(os.rmdir, path, sys.exc_info())
  File "/home/jlpkort/anaconda3/lib/python3.8/shutil.py", line 720, in rmtree
    os.rmdir(path)
OSError: [Errno 39] Directory not empty: '/scratch/pymp-rplarzbh'
Traceback (most recent call last):
  File "/home/jlpkort/anaconda3/lib/python3.8/multiprocessing/util.py", line 300, in _run_finalizers
    finalizer()
  File "/home/jlpkort/anaconda3/lib/python3.8/multiprocessing/util.py", line 224, in __call__
    res = self._callback(*self._args, **self._kwargs)
  File "/home/jlpkort/anaconda3/lib/python3.8/multiprocessing/util.py", line 133, in _remove_temp_dir
    rmtree(tempdir)
  File "/home/jlpkort/anaconda3/lib/python3.8/shutil.py", line 722, in rmtree
    onerror(os.rmdir, path, sys.exc_info())
  File "/home/jlpkort/anaconda3/lib/python3.8/shutil.py", line 720, in rmtree
    os.rmdir(path)
OSError: [Errno 39] Directory not empty: '/scratch/pymp-8t3yodgu'
Traceback (most recent call last):
  File "/home/jlpkort/anaconda3/lib/python3.8/multiprocessing/util.py", line 300, in _run_finalizers
    finalizer()
  File "/home/jlpkort/anaconda3/lib/python3.8/multiprocessing/util.py", line 224, in __call__
    res = self._callback(*self._args, **self._kwargs)
  File "/home/jlpkort/anaconda3/lib/python3.8/multiprocessing/util.py", line 133, in _remove_temp_dir
    rmtree(tempdir)
  File "/home/jlpkort/anaconda3/lib/python3.8/shutil.py", line 722, in rmtree
    onerror(os.rmdir, path, sys.exc_info())
  File "/home/jlpkort/anaconda3/lib/python3.8/shutil.py", line 720, in rmtree
    os.rmdir(path)
OSError: [Errno 39] Directory not empty: '/scratch/pymp-qjh7a266'
Traceback (most recent call last):
  File "/home/jlpkort/anaconda3/lib/python3.8/multiprocessing/util.py", line 300, in _run_finalizers
    finalizer()
  File "/home/jlpkort/anaconda3/lib/python3.8/multiprocessing/util.py", line 224, in __call__
    res = self._callback(*self._args, **self._kwargs)
  File "/home/jlpkort/anaconda3/lib/python3.8/multiprocessing/util.py", line 133, in _remove_temp_dir
    rmtree(tempdir)
  File "/home/jlpkort/anaconda3/lib/python3.8/shutil.py", line 722, in rmtree
    onerror(os.rmdir, path, sys.exc_info())
  File "/home/jlpkort/anaconda3/lib/python3.8/shutil.py", line 720, in rmtree
    os.rmdir(path)
OSError: [Errno 39] Directory not empty: '/scratch/pymp-4kn6nosv'
Traceback (most recent call last):
  File "/home/jlpkort/anaconda3/lib/python3.8/multiprocessing/util.py", line 300, in _run_finalizers
    finalizer()
  File "/home/jlpkort/anaconda3/lib/python3.8/multiprocessing/util.py", line 224, in __call__
    res = self._callback(*self._args, **self._kwargs)
  File "/home/jlpkort/anaconda3/lib/python3.8/multiprocessing/util.py", line 133, in _remove_temp_dir
    rmtree(tempdir)
  File "/home/jlpkort/anaconda3/lib/python3.8/shutil.py", line 722, in rmtree
    onerror(os.rmdir, path, sys.exc_info())
  File "/home/jlpkort/anaconda3/lib/python3.8/shutil.py", line 720, in rmtree
    os.rmdir(path)
OSError: [Errno 39] Directory not empty: '/scratch/pymp-sf1dw907'
Traceback (most recent call last):
  File "/home/jlpkort/anaconda3/lib/python3.8/multiprocessing/util.py", line 300, in _run_finalizers
    finalizer()
  File "/home/jlpkort/anaconda3/lib/python3.8/multiprocessing/util.py", line 224, in __call__
    res = self._callback(*self._args, **self._kwargs)
  File "/home/jlpkort/anaconda3/lib/python3.8/multiprocessing/util.py", line 133, in _remove_temp_dir
    rmtree(tempdir)
  File "/home/jlpkort/anaconda3/lib/python3.8/shutil.py", line 722, in rmtree
    onerror(os.rmdir, path, sys.exc_info())
  File "/home/jlpkort/anaconda3/lib/python3.8/shutil.py", line 720, in rmtree
    os.rmdir(path)
OSError: [Errno 39] Directory not empty: '/scratch/pymp-dqpj8gk0'
I0904 12:23:36.069503 5956 trainer.py:117]  [Step: 2000/100000 (2.0%)] D Loss: -3017.0546875 M Loss: 1.0918242931365967 G Loss: -371.49639892578125 
Traceback (most recent call last):
  File "/home/jlpkort/anaconda3/lib/python3.8/multiprocessing/util.py", line 300, in _run_finalizers
    finalizer()
  File "/home/jlpkort/anaconda3/lib/python3.8/multiprocessing/util.py", line 224, in __call__
    res = self._callback(*self._args, **self._kwargs)
  File "/home/jlpkort/anaconda3/lib/python3.8/multiprocessing/util.py", line 133, in _remove_temp_dir
    rmtree(tempdir)
  File "/home/jlpkort/anaconda3/lib/python3.8/shutil.py", line 722, in rmtree
    onerror(os.rmdir, path, sys.exc_info())
  File "/home/jlpkort/anaconda3/lib/python3.8/shutil.py", line 720, in rmtree
    os.rmdir(path)
OSError: [Errno 39] Directory not empty: '/scratch/pymp-r0o9ccij'
Traceback (most recent call last):
  File "/home/jlpkort/anaconda3/lib/python3.8/multiprocessing/util.py", line 300, in _run_finalizers
    finalizer()
  File "/home/jlpkort/anaconda3/lib/python3.8/multiprocessing/util.py", line 224, in __call__
    res = self._callback(*self._args, **self._kwargs)
  File "/home/jlpkort/anaconda3/lib/python3.8/multiprocessing/util.py", line 133, in _remove_temp_dir
    rmtree(tempdir)
  File "/home/jlpkort/anaconda3/lib/python3.8/shutil.py", line 722, in rmtree
    onerror(os.rmdir, path, sys.exc_info())
  File "/home/jlpkort/anaconda3/lib/python3.8/shutil.py", line 720, in rmtree
    os.rmdir(path)
OSError: [Errno 39] Directory not empty: '/scratch/pymp-npvc5vk2'
Traceback (most recent call last):
  File "/home/jlpkort/anaconda3/lib/python3.8/multiprocessing/util.py", line 300, in _run_finalizers
    finalizer()
  File "/home/jlpkort/anaconda3/lib/python3.8/multiprocessing/util.py", line 224, in __call__
    res = self._callback(*self._args, **self._kwargs)
  File "/home/jlpkort/anaconda3/lib/python3.8/multiprocessing/util.py", line 133, in _remove_temp_dir
    rmtree(tempdir)
  File "/home/jlpkort/anaconda3/lib/python3.8/shutil.py", line 722, in rmtree
    onerror(os.rmdir, path, sys.exc_info())
  File "/home/jlpkort/anaconda3/lib/python3.8/shutil.py", line 720, in rmtree
    os.rmdir(path)
OSError: [Errno 39] Directory not empty: '/scratch/pymp-hjic1smc'
Traceback (most recent call last):
  File "/home/jlpkort/anaconda3/lib/python3.8/multiprocessing/util.py", line 300, in _run_finalizers
    finalizer()
  File "/home/jlpkort/anaconda3/lib/python3.8/multiprocessing/util.py", line 224, in __call__
    res = self._callback(*self._args, **self._kwargs)
  File "/home/jlpkort/anaconda3/lib/python3.8/multiprocessing/util.py", line 133, in _remove_temp_dir
    rmtree(tempdir)
  File "/home/jlpkort/anaconda3/lib/python3.8/shutil.py", line 722, in rmtree
    onerror(os.rmdir, path, sys.exc_info())
  File "/home/jlpkort/anaconda3/lib/python3.8/shutil.py", line 720, in rmtree
    os.rmdir(path)
OSError: [Errno 39] Directory not empty: '/scratch/pymp-pn8wemd0'
Traceback (most recent call last):
  File "/home/jlpkort/anaconda3/lib/python3.8/multiprocessing/util.py", line 300, in _run_finalizers
    finalizer()
  File "/home/jlpkort/anaconda3/lib/python3.8/multiprocessing/util.py", line 224, in __call__
    res = self._callback(*self._args, **self._kwargs)
  File "/home/jlpkort/anaconda3/lib/python3.8/multiprocessing/util.py", line 133, in _remove_temp_dir
    rmtree(tempdir)
  File "/home/jlpkort/anaconda3/lib/python3.8/shutil.py", line 722, in rmtree
    onerror(os.rmdir, path, sys.exc_info())
  File "/home/jlpkort/anaconda3/lib/python3.8/shutil.py", line 720, in rmtree
    os.rmdir(path)
OSError: [Errno 39] Directory not empty: '/scratch/pymp-m_zg5asa'
Traceback (most recent call last):
  File "/home/jlpkort/anaconda3/lib/python3.8/multiprocessing/util.py", line 300, in _run_finalizers
    finalizer()
  File "/home/jlpkort/anaconda3/lib/python3.8/multiprocessing/util.py", line 224, in __call__
    res = self._callback(*self._args, **self._kwargs)
  File "/home/jlpkort/anaconda3/lib/python3.8/multiprocessing/util.py", line 133, in _remove_temp_dir
    rmtree(tempdir)
  File "/home/jlpkort/anaconda3/lib/python3.8/shutil.py", line 722, in rmtree
    onerror(os.rmdir, path, sys.exc_info())
  File "/home/jlpkort/anaconda3/lib/python3.8/shutil.py", line 720, in rmtree
    os.rmdir(path)
OSError: [Errno 39] Directory not empty: '/scratch/pymp-6v8o_gfa'
Traceback (most recent call last):
  File "/home/jlpkort/anaconda3/lib/python3.8/multiprocessing/util.py", line 300, in _run_finalizers
    finalizer()
  File "/home/jlpkort/anaconda3/lib/python3.8/multiprocessing/util.py", line 224, in __call__
    res = self._callback(*self._args, **self._kwargs)
  File "/home/jlpkort/anaconda3/lib/python3.8/multiprocessing/util.py", line 133, in _remove_temp_dir
    rmtree(tempdir)
  File "/home/jlpkort/anaconda3/lib/python3.8/shutil.py", line 722, in rmtree
    onerror(os.rmdir, path, sys.exc_info())
  File "/home/jlpkort/anaconda3/lib/python3.8/shutil.py", line 720, in rmtree
    os.rmdir(path)
OSError: [Errno 39] Directory not empty: '/scratch/pymp-5f8cs4xt'
I0904 13:45:15.637856 5956 trainer.py:117]  [Step: 3000/100000 (3.0%)] D Loss: -8174.5244140625 M Loss: 1.0570337772369385 G Loss: -1667.106201171875 
Traceback (most recent call last):
  File "/home/jlpkort/anaconda3/lib/python3.8/multiprocessing/util.py", line 300, in _run_finalizers
    finalizer()
  File "/home/jlpkort/anaconda3/lib/python3.8/multiprocessing/util.py", line 224, in __call__
    res = self._callback(*self._args, **self._kwargs)
  File "/home/jlpkort/anaconda3/lib/python3.8/multiprocessing/util.py", line 133, in _remove_temp_dir
    rmtree(tempdir)
  File "/home/jlpkort/anaconda3/lib/python3.8/shutil.py", line 722, in rmtree
    onerror(os.rmdir, path, sys.exc_info())
  File "/home/jlpkort/anaconda3/lib/python3.8/shutil.py", line 720, in rmtree
    os.rmdir(path)
OSError: [Errno 39] Directory not empty: '/scratch/pymp-rk3deiyj'
Traceback (most recent call last):
  File "/home/jlpkort/anaconda3/lib/python3.8/multiprocessing/util.py", line 300, in _run_finalizers
    finalizer()
  File "/home/jlpkort/anaconda3/lib/python3.8/multiprocessing/util.py", line 224, in __call__
    res = self._callback(*self._args, **self._kwargs)
  File "/home/jlpkort/anaconda3/lib/python3.8/multiprocessing/util.py", line 133, in _remove_temp_dir
    rmtree(tempdir)
  File "/home/jlpkort/anaconda3/lib/python3.8/shutil.py", line 722, in rmtree
    onerror(os.rmdir, path, sys.exc_info())
  File "/home/jlpkort/anaconda3/lib/python3.8/shutil.py", line 720, in rmtree
    os.rmdir(path)
OSError: [Errno 39] Directory not empty: '/scratch/pymp-ixrs3v8d'
Traceback (most recent call last):
  File "/home/jlpkort/anaconda3/lib/python3.8/multiprocessing/util.py", line 300, in _run_finalizers
    finalizer()
  File "/home/jlpkort/anaconda3/lib/python3.8/multiprocessing/util.py", line 224, in __call__
    res = self._callback(*self._args, **self._kwargs)
  File "/home/jlpkort/anaconda3/lib/python3.8/multiprocessing/util.py", line 133, in _remove_temp_dir
    rmtree(tempdir)
  File "/home/jlpkort/anaconda3/lib/python3.8/shutil.py", line 722, in rmtree
    onerror(os.rmdir, path, sys.exc_info())
  File "/home/jlpkort/anaconda3/lib/python3.8/shutil.py", line 720, in rmtree
    os.rmdir(path)
OSError: [Errno 39] Directory not empty: '/scratch/pymp-hfrehc53'
Traceback (most recent call last):
  File "/home/jlpkort/anaconda3/lib/python3.8/multiprocessing/util.py", line 300, in _run_finalizers
    finalizer()
  File "/home/jlpkort/anaconda3/lib/python3.8/multiprocessing/util.py", line 224, in __call__
    res = self._callback(*self._args, **self._kwargs)
  File "/home/jlpkort/anaconda3/lib/python3.8/multiprocessing/util.py", line 133, in _remove_temp_dir
    rmtree(tempdir)
  File "/home/jlpkort/anaconda3/lib/python3.8/shutil.py", line 722, in rmtree
    onerror(os.rmdir, path, sys.exc_info())
  File "/home/jlpkort/anaconda3/lib/python3.8/shutil.py", line 720, in rmtree
    os.rmdir(path)
OSError: [Errno 39] Directory not empty: '/scratch/pymp-xor2p9pw'
I0904 15:06:54.505995 5956 trainer.py:117]  [Step: 4000/100000 (4.0%)] D Loss: -36365.08203125 M Loss: 1.2982052564620972 G Loss: -5488.3232421875 
Traceback (most recent call last):
  File "/home/jlpkort/anaconda3/lib/python3.8/multiprocessing/util.py", line 300, in _run_finalizers
    finalizer()
  File "/home/jlpkort/anaconda3/lib/python3.8/multiprocessing/util.py", line 224, in __call__
    res = self._callback(*self._args, **self._kwargs)
  File "/home/jlpkort/anaconda3/lib/python3.8/multiprocessing/util.py", line 133, in _remove_temp_dir
    rmtree(tempdir)
  File "/home/jlpkort/anaconda3/lib/python3.8/shutil.py", line 722, in rmtree
    onerror(os.rmdir, path, sys.exc_info())
  File "/home/jlpkort/anaconda3/lib/python3.8/shutil.py", line 720, in rmtree
    os.rmdir(path)
OSError: [Errno 39] Directory not empty: '/scratch/pymp-8s6zmigv'
Traceback (most recent call last):
  File "/home/jlpkort/anaconda3/lib/python3.8/multiprocessing/util.py", line 300, in _run_finalizers
    finalizer()
  File "/home/jlpkort/anaconda3/lib/python3.8/multiprocessing/util.py", line 224, in __call__
    res = self._callback(*self._args, **self._kwargs)
  File "/home/jlpkort/anaconda3/lib/python3.8/multiprocessing/util.py", line 133, in _remove_temp_dir
    rmtree(tempdir)
  File "/home/jlpkort/anaconda3/lib/python3.8/shutil.py", line 722, in rmtree
    onerror(os.rmdir, path, sys.exc_info())
  File "/home/jlpkort/anaconda3/lib/python3.8/shutil.py", line 720, in rmtree
    os.rmdir(path)
OSError: [Errno 39] Directory not empty: '/scratch/pymp-uihi0kxa'
Traceback (most recent call last):
  File "/home/jlpkort/anaconda3/lib/python3.8/multiprocessing/util.py", line 300, in _run_finalizers
    finalizer()
  File "/home/jlpkort/anaconda3/lib/python3.8/multiprocessing/util.py", line 224, in __call__
    res = self._callback(*self._args, **self._kwargs)
  File "/home/jlpkort/anaconda3/lib/python3.8/multiprocessing/util.py", line 133, in _remove_temp_dir
    rmtree(tempdir)
  File "/home/jlpkort/anaconda3/lib/python3.8/shutil.py", line 722, in rmtree
    onerror(os.rmdir, path, sys.exc_info())
  File "/home/jlpkort/anaconda3/lib/python3.8/shutil.py", line 720, in rmtree
    os.rmdir(path)
OSError: [Errno 39] Directory not empty: '/scratch/pymp-5glvr28e'
Traceback (most recent call last):
  File "/home/jlpkort/anaconda3/lib/python3.8/multiprocessing/util.py", line 300, in _run_finalizers
    finalizer()
  File "/home/jlpkort/anaconda3/lib/python3.8/multiprocessing/util.py", line 224, in __call__
    res = self._callback(*self._args, **self._kwargs)
  File "/home/jlpkort/anaconda3/lib/python3.8/multiprocessing/util.py", line 133, in _remove_temp_dir
    rmtree(tempdir)
  File "/home/jlpkort/anaconda3/lib/python3.8/shutil.py", line 722, in rmtree
    onerror(os.rmdir, path, sys.exc_info())
  File "/home/jlpkort/anaconda3/lib/python3.8/shutil.py", line 720, in rmtree
    os.rmdir(path)
OSError: [Errno 39] Directory not empty: '/scratch/pymp-rrji79wu'
Traceback (most recent call last):
  File "/home/jlpkort/anaconda3/lib/python3.8/multiprocessing/util.py", line 300, in _run_finalizers
    finalizer()
  File "/home/jlpkort/anaconda3/lib/python3.8/multiprocessing/util.py", line 224, in __call__
    res = self._callback(*self._args, **self._kwargs)
  File "/home/jlpkort/anaconda3/lib/python3.8/multiprocessing/util.py", line 133, in _remove_temp_dir
    rmtree(tempdir)
  File "/home/jlpkort/anaconda3/lib/python3.8/shutil.py", line 722, in rmtree
    onerror(os.rmdir, path, sys.exc_info())
  File "/home/jlpkort/anaconda3/lib/python3.8/shutil.py", line 720, in rmtree
    os.rmdir(path)
OSError: [Errno 39] Directory not empty: '/scratch/pymp-53irt55e'
Traceback (most recent call last):
  File "/home/jlpkort/anaconda3/lib/python3.8/multiprocessing/util.py", line 300, in _run_finalizers
    finalizer()
  File "/home/jlpkort/anaconda3/lib/python3.8/multiprocessing/util.py", line 224, in __call__
    res = self._callback(*self._args, **self._kwargs)
  File "/home/jlpkort/anaconda3/lib/python3.8/multiprocessing/util.py", line 133, in _remove_temp_dir
    rmtree(tempdir)
  File "/home/jlpkort/anaconda3/lib/python3.8/shutil.py", line 722, in rmtree
    onerror(os.rmdir, path, sys.exc_info())
  File "/home/jlpkort/anaconda3/lib/python3.8/shutil.py", line 720, in rmtree
    os.rmdir(path)
OSError: [Errno 39] Directory not empty: '/scratch/pymp-s3msko9q'
Traceback (most recent call last):
  File "/home/jlpkort/anaconda3/lib/python3.8/multiprocessing/util.py", line 300, in _run_finalizers
    finalizer()
  File "/home/jlpkort/anaconda3/lib/python3.8/multiprocessing/util.py", line 224, in __call__
    res = self._callback(*self._args, **self._kwargs)
  File "/home/jlpkort/anaconda3/lib/python3.8/multiprocessing/util.py", line 133, in _remove_temp_dir
    rmtree(tempdir)
  File "/home/jlpkort/anaconda3/lib/python3.8/shutil.py", line 722, in rmtree
    onerror(os.rmdir, path, sys.exc_info())
  File "/home/jlpkort/anaconda3/lib/python3.8/shutil.py", line 720, in rmtree
    os.rmdir(path)
OSError: [Errno 39] Directory not empty: '/scratch/pymp-vzjwsjkl'
I0904 16:27:22.835354 5956 trainer.py:117]  [Step: 5000/100000 (5.0%)] D Loss: -65198.16796875 M Loss: 1.0761562585830688 G Loss: -10405.125 
Traceback (most recent call last):
  File "/home/jlpkort/anaconda3/lib/python3.8/multiprocessing/util.py", line 300, in _run_finalizers
    finalizer()
  File "/home/jlpkort/anaconda3/lib/python3.8/multiprocessing/util.py", line 224, in __call__
    res = self._callback(*self._args, **self._kwargs)
  File "/home/jlpkort/anaconda3/lib/python3.8/multiprocessing/util.py", line 133, in _remove_temp_dir
    rmtree(tempdir)
  File "/home/jlpkort/anaconda3/lib/python3.8/shutil.py", line 722, in rmtree
    onerror(os.rmdir, path, sys.exc_info())
  File "/home/jlpkort/anaconda3/lib/python3.8/shutil.py", line 720, in rmtree
    os.rmdir(path)
OSError: [Errno 39] Directory not empty: '/scratch/pymp-5iijfn5b'
Traceback (most recent call last):
  File "/home/jlpkort/anaconda3/lib/python3.8/multiprocessing/util.py", line 300, in _run_finalizers
    finalizer()
  File "/home/jlpkort/anaconda3/lib/python3.8/multiprocessing/util.py", line 224, in __call__
    res = self._callback(*self._args, **self._kwargs)
  File "/home/jlpkort/anaconda3/lib/python3.8/multiprocessing/util.py", line 133, in _remove_temp_dir
    rmtree(tempdir)
  File "/home/jlpkort/anaconda3/lib/python3.8/shutil.py", line 722, in rmtree
    onerror(os.rmdir, path, sys.exc_info())
  File "/home/jlpkort/anaconda3/lib/python3.8/shutil.py", line 720, in rmtree
    os.rmdir(path)
OSError: [Errno 39] Directory not empty: '/scratch/pymp-44m247kx'
Traceback (most recent call last):
  File "/home/jlpkort/anaconda3/lib/python3.8/multiprocessing/util.py", line 300, in _run_finalizers
    finalizer()
  File "/home/jlpkort/anaconda3/lib/python3.8/multiprocessing/util.py", line 224, in __call__
    res = self._callback(*self._args, **self._kwargs)
  File "/home/jlpkort/anaconda3/lib/python3.8/multiprocessing/util.py", line 133, in _remove_temp_dir
    rmtree(tempdir)
  File "/home/jlpkort/anaconda3/lib/python3.8/shutil.py", line 722, in rmtree
    onerror(os.rmdir, path, sys.exc_info())
  File "/home/jlpkort/anaconda3/lib/python3.8/shutil.py", line 720, in rmtree
    os.rmdir(path)
OSError: [Errno 39] Directory not empty: '/scratch/pymp-vver1kxs'
Traceback (most recent call last):
  File "/home/jlpkort/anaconda3/lib/python3.8/multiprocessing/util.py", line 300, in _run_finalizers
    finalizer()
  File "/home/jlpkort/anaconda3/lib/python3.8/multiprocessing/util.py", line 224, in __call__
    res = self._callback(*self._args, **self._kwargs)
  File "/home/jlpkort/anaconda3/lib/python3.8/multiprocessing/util.py", line 133, in _remove_temp_dir
    rmtree(tempdir)
  File "/home/jlpkort/anaconda3/lib/python3.8/shutil.py", line 722, in rmtree
    onerror(os.rmdir, path, sys.exc_info())
  File "/home/jlpkort/anaconda3/lib/python3.8/shutil.py", line 720, in rmtree
    os.rmdir(path)
OSError: [Errno 39] Directory not empty: '/scratch/pymp-q2bv5ld9'
Traceback (most recent call last):
  File "/home/jlpkort/anaconda3/lib/python3.8/multiprocessing/util.py", line 300, in _run_finalizers
    finalizer()
  File "/home/jlpkort/anaconda3/lib/python3.8/multiprocessing/util.py", line 224, in __call__
    res = self._callback(*self._args, **self._kwargs)
  File "/home/jlpkort/anaconda3/lib/python3.8/multiprocessing/util.py", line 133, in _remove_temp_dir
    rmtree(tempdir)
  File "/home/jlpkort/anaconda3/lib/python3.8/shutil.py", line 722, in rmtree
    onerror(os.rmdir, path, sys.exc_info())
  File "/home/jlpkort/anaconda3/lib/python3.8/shutil.py", line 720, in rmtree
    os.rmdir(path)
OSError: [Errno 39] Directory not empty: '/scratch/pymp-kh4159_q'
Traceback (most recent call last):
  File "/home/jlpkort/anaconda3/lib/python3.8/multiprocessing/util.py", line 300, in _run_finalizers
    finalizer()
  File "/home/jlpkort/anaconda3/lib/python3.8/multiprocessing/util.py", line 224, in __call__
    res = self._callback(*self._args, **self._kwargs)
  File "/home/jlpkort/anaconda3/lib/python3.8/multiprocessing/util.py", line 133, in _remove_temp_dir
    rmtree(tempdir)
  File "/home/jlpkort/anaconda3/lib/python3.8/shutil.py", line 722, in rmtree
    onerror(os.rmdir, path, sys.exc_info())
  File "/home/jlpkort/anaconda3/lib/python3.8/shutil.py", line 720, in rmtree
    os.rmdir(path)
OSError: [Errno 39] Directory not empty: '/scratch/pymp-628v6f59'
Traceback (most recent call last):
  File "/home/jlpkort/anaconda3/lib/python3.8/multiprocessing/util.py", line 300, in _run_finalizers
    finalizer()
  File "/home/jlpkort/anaconda3/lib/python3.8/multiprocessing/util.py", line 224, in __call__
    res = self._callback(*self._args, **self._kwargs)
  File "/home/jlpkort/anaconda3/lib/python3.8/multiprocessing/util.py", line 133, in _remove_temp_dir
    rmtree(tempdir)
  File "/home/jlpkort/anaconda3/lib/python3.8/shutil.py", line 722, in rmtree
    onerror(os.rmdir, path, sys.exc_info())
  File "/home/jlpkort/anaconda3/lib/python3.8/shutil.py", line 720, in rmtree
    os.rmdir(path)
OSError: [Errno 39] Directory not empty: '/scratch/pymp-pyg1tfwp'
I0904 17:48:02.116267 5956 trainer.py:117]  [Step: 6000/100000 (6.0%)] D Loss: -83767.4453125 M Loss: 1.284934401512146 G Loss: -15323.4033203125 
Traceback (most recent call last):
  File "/home/jlpkort/anaconda3/lib/python3.8/multiprocessing/util.py", line 300, in _run_finalizers
    finalizer()
  File "/home/jlpkort/anaconda3/lib/python3.8/multiprocessing/util.py", line 224, in __call__
    res = self._callback(*self._args, **self._kwargs)
  File "/home/jlpkort/anaconda3/lib/python3.8/multiprocessing/util.py", line 133, in _remove_temp_dir
    rmtree(tempdir)
  File "/home/jlpkort/anaconda3/lib/python3.8/shutil.py", line 722, in rmtree
    onerror(os.rmdir, path, sys.exc_info())
  File "/home/jlpkort/anaconda3/lib/python3.8/shutil.py", line 720, in rmtree
    os.rmdir(path)
OSError: [Errno 39] Directory not empty: '/scratch/pymp-qlx_jw7u'
Traceback (most recent call last):
  File "/home/jlpkort/anaconda3/lib/python3.8/multiprocessing/util.py", line 300, in _run_finalizers
    finalizer()
  File "/home/jlpkort/anaconda3/lib/python3.8/multiprocessing/util.py", line 224, in __call__
    res = self._callback(*self._args, **self._kwargs)
  File "/home/jlpkort/anaconda3/lib/python3.8/multiprocessing/util.py", line 133, in _remove_temp_dir
    rmtree(tempdir)
  File "/home/jlpkort/anaconda3/lib/python3.8/shutil.py", line 722, in rmtree
    onerror(os.rmdir, path, sys.exc_info())
  File "/home/jlpkort/anaconda3/lib/python3.8/shutil.py", line 720, in rmtree
    os.rmdir(path)
OSError: [Errno 39] Directory not empty: '/scratch/pymp-momzqka6'
Traceback (most recent call last):
  File "/home/jlpkort/anaconda3/lib/python3.8/multiprocessing/util.py", line 300, in _run_finalizers
    finalizer()
  File "/home/jlpkort/anaconda3/lib/python3.8/multiprocessing/util.py", line 224, in __call__
    res = self._callback(*self._args, **self._kwargs)
  File "/home/jlpkort/anaconda3/lib/python3.8/multiprocessing/util.py", line 133, in _remove_temp_dir
    rmtree(tempdir)
  File "/home/jlpkort/anaconda3/lib/python3.8/shutil.py", line 722, in rmtree
    onerror(os.rmdir, path, sys.exc_info())
  File "/home/jlpkort/anaconda3/lib/python3.8/shutil.py", line 720, in rmtree
    os.rmdir(path)
OSError: [Errno 39] Directory not empty: '/scratch/pymp-eaz47w89'
Traceback (most recent call last):
  File "/home/jlpkort/anaconda3/lib/python3.8/multiprocessing/util.py", line 300, in _run_finalizers
    finalizer()
  File "/home/jlpkort/anaconda3/lib/python3.8/multiprocessing/util.py", line 224, in __call__
    res = self._callback(*self._args, **self._kwargs)
  File "/home/jlpkort/anaconda3/lib/python3.8/multiprocessing/util.py", line 133, in _remove_temp_dir
    rmtree(tempdir)
  File "/home/jlpkort/anaconda3/lib/python3.8/shutil.py", line 722, in rmtree
    onerror(os.rmdir, path, sys.exc_info())
  File "/home/jlpkort/anaconda3/lib/python3.8/shutil.py", line 720, in rmtree
    os.rmdir(path)
OSError: [Errno 39] Directory not empty: '/scratch/pymp-3n7sniqh'
Traceback (most recent call last):
  File "/home/jlpkort/anaconda3/lib/python3.8/multiprocessing/util.py", line 300, in _run_finalizers
    finalizer()
  File "/home/jlpkort/anaconda3/lib/python3.8/multiprocessing/util.py", line 224, in __call__
    res = self._callback(*self._args, **self._kwargs)
  File "/home/jlpkort/anaconda3/lib/python3.8/multiprocessing/util.py", line 133, in _remove_temp_dir
    rmtree(tempdir)
  File "/home/jlpkort/anaconda3/lib/python3.8/shutil.py", line 722, in rmtree
    onerror(os.rmdir, path, sys.exc_info())
  File "/home/jlpkort/anaconda3/lib/python3.8/shutil.py", line 720, in rmtree
    os.rmdir(path)
OSError: [Errno 39] Directory not empty: '/scratch/pymp-eb9mtpgb'
Traceback (most recent call last):
  File "/home/jlpkort/anaconda3/lib/python3.8/multiprocessing/util.py", line 300, in _run_finalizers
    finalizer()
  File "/home/jlpkort/anaconda3/lib/python3.8/multiprocessing/util.py", line 224, in __call__
    res = self._callback(*self._args, **self._kwargs)
  File "/home/jlpkort/anaconda3/lib/python3.8/multiprocessing/util.py", line 133, in _remove_temp_dir
    rmtree(tempdir)
  File "/home/jlpkort/anaconda3/lib/python3.8/shutil.py", line 722, in rmtree
    onerror(os.rmdir, path, sys.exc_info())
  File "/home/jlpkort/anaconda3/lib/python3.8/shutil.py", line 720, in rmtree
    os.rmdir(path)
OSError: [Errno 39] Directory not empty: '/scratch/pymp-r4si1wsf'
Traceback (most recent call last):
  File "/home/jlpkort/anaconda3/lib/python3.8/multiprocessing/util.py", line 300, in _run_finalizers
    finalizer()
  File "/home/jlpkort/anaconda3/lib/python3.8/multiprocessing/util.py", line 224, in __call__
    res = self._callback(*self._args, **self._kwargs)
  File "/home/jlpkort/anaconda3/lib/python3.8/multiprocessing/util.py", line 133, in _remove_temp_dir
    rmtree(tempdir)
  File "/home/jlpkort/anaconda3/lib/python3.8/shutil.py", line 722, in rmtree
    onerror(os.rmdir, path, sys.exc_info())
  File "/home/jlpkort/anaconda3/lib/python3.8/shutil.py", line 720, in rmtree
    os.rmdir(path)
OSError: [Errno 39] Directory not empty: '/scratch/pymp-ev9vxya0'
Traceback (most recent call last):
  File "/home/jlpkort/anaconda3/lib/python3.8/multiprocessing/util.py", line 300, in _run_finalizers
    finalizer()
  File "/home/jlpkort/anaconda3/lib/python3.8/multiprocessing/util.py", line 224, in __call__
    res = self._callback(*self._args, **self._kwargs)
  File "/home/jlpkort/anaconda3/lib/python3.8/multiprocessing/util.py", line 133, in _remove_temp_dir
    rmtree(tempdir)
  File "/home/jlpkort/anaconda3/lib/python3.8/shutil.py", line 722, in rmtree
    onerror(os.rmdir, path, sys.exc_info())
  File "/home/jlpkort/anaconda3/lib/python3.8/shutil.py", line 720, in rmtree
    os.rmdir(path)
OSError: [Errno 39] Directory not empty: '/scratch/pymp-9ld4yv3p'
Traceback (most recent call last):
  File "/home/jlpkort/anaconda3/lib/python3.8/multiprocessing/util.py", line 300, in _run_finalizers
    finalizer()
  File "/home/jlpkort/anaconda3/lib/python3.8/multiprocessing/util.py", line 224, in __call__
    res = self._callback(*self._args, **self._kwargs)
  File "/home/jlpkort/anaconda3/lib/python3.8/multiprocessing/util.py", line 133, in _remove_temp_dir
    rmtree(tempdir)
  File "/home/jlpkort/anaconda3/lib/python3.8/shutil.py", line 722, in rmtree
    onerror(os.rmdir, path, sys.exc_info())
  File "/home/jlpkort/anaconda3/lib/python3.8/shutil.py", line 720, in rmtree
    os.rmdir(path)
OSError: [Errno 39] Directory not empty: '/scratch/pymp-mjy_ol3h'
I0904 19:09:57.246591 5956 trainer.py:117]  [Step: 7000/100000 (7.0%)] D Loss: -120835.0859375 M Loss: 1.1857354640960693 G Loss: -326957.96875 
Traceback (most recent call last):
  File "/home/jlpkort/anaconda3/lib/python3.8/multiprocessing/util.py", line 300, in _run_finalizers
    finalizer()
  File "/home/jlpkort/anaconda3/lib/python3.8/multiprocessing/util.py", line 224, in __call__
    res = self._callback(*self._args, **self._kwargs)
  File "/home/jlpkort/anaconda3/lib/python3.8/multiprocessing/util.py", line 133, in _remove_temp_dir
    rmtree(tempdir)
  File "/home/jlpkort/anaconda3/lib/python3.8/shutil.py", line 722, in rmtree
    onerror(os.rmdir, path, sys.exc_info())
  File "/home/jlpkort/anaconda3/lib/python3.8/shutil.py", line 720, in rmtree
    os.rmdir(path)
OSError: [Errno 39] Directory not empty: '/scratch/pymp-532vwv3o'
Traceback (most recent call last):
  File "/home/jlpkort/anaconda3/lib/python3.8/multiprocessing/util.py", line 300, in _run_finalizers
    finalizer()
  File "/home/jlpkort/anaconda3/lib/python3.8/multiprocessing/util.py", line 224, in __call__
    res = self._callback(*self._args, **self._kwargs)
  File "/home/jlpkort/anaconda3/lib/python3.8/multiprocessing/util.py", line 133, in _remove_temp_dir
    rmtree(tempdir)
  File "/home/jlpkort/anaconda3/lib/python3.8/shutil.py", line 722, in rmtree
    onerror(os.rmdir, path, sys.exc_info())
  File "/home/jlpkort/anaconda3/lib/python3.8/shutil.py", line 720, in rmtree
    os.rmdir(path)
OSError: [Errno 39] Directory not empty: '/scratch/pymp-j8_qt37o'
Traceback (most recent call last):
  File "/home/jlpkort/anaconda3/lib/python3.8/multiprocessing/util.py", line 300, in _run_finalizers
    finalizer()
  File "/home/jlpkort/anaconda3/lib/python3.8/multiprocessing/util.py", line 224, in __call__
    res = self._callback(*self._args, **self._kwargs)
  File "/home/jlpkort/anaconda3/lib/python3.8/multiprocessing/util.py", line 133, in _remove_temp_dir
    rmtree(tempdir)
  File "/home/jlpkort/anaconda3/lib/python3.8/shutil.py", line 722, in rmtree
    onerror(os.rmdir, path, sys.exc_info())
  File "/home/jlpkort/anaconda3/lib/python3.8/shutil.py", line 720, in rmtree
    os.rmdir(path)
OSError: [Errno 39] Directory not empty: '/scratch/pymp-3egz2uk8'
Traceback (most recent call last):
  File "/home/jlpkort/anaconda3/lib/python3.8/multiprocessing/util.py", line 300, in _run_finalizers
    finalizer()
  File "/home/jlpkort/anaconda3/lib/python3.8/multiprocessing/util.py", line 224, in __call__
    res = self._callback(*self._args, **self._kwargs)
  File "/home/jlpkort/anaconda3/lib/python3.8/multiprocessing/util.py", line 133, in _remove_temp_dir
    rmtree(tempdir)
  File "/home/jlpkort/anaconda3/lib/python3.8/shutil.py", line 722, in rmtree
    onerror(os.rmdir, path, sys.exc_info())
  File "/home/jlpkort/anaconda3/lib/python3.8/shutil.py", line 720, in rmtree
    os.rmdir(path)
OSError: [Errno 39] Directory not empty: '/scratch/pymp-9iyrz77k'
Traceback (most recent call last):
  File "/home/jlpkort/anaconda3/lib/python3.8/multiprocessing/util.py", line 300, in _run_finalizers
    finalizer()
  File "/home/jlpkort/anaconda3/lib/python3.8/multiprocessing/util.py", line 224, in __call__
    res = self._callback(*self._args, **self._kwargs)
  File "/home/jlpkort/anaconda3/lib/python3.8/multiprocessing/util.py", line 133, in _remove_temp_dir
    rmtree(tempdir)
  File "/home/jlpkort/anaconda3/lib/python3.8/shutil.py", line 722, in rmtree
    onerror(os.rmdir, path, sys.exc_info())
  File "/home/jlpkort/anaconda3/lib/python3.8/shutil.py", line 720, in rmtree
    os.rmdir(path)
OSError: [Errno 39] Directory not empty: '/scratch/pymp-zsh9cb54'
Traceback (most recent call last):
  File "/home/jlpkort/anaconda3/lib/python3.8/multiprocessing/util.py", line 300, in _run_finalizers
    finalizer()
  File "/home/jlpkort/anaconda3/lib/python3.8/multiprocessing/util.py", line 224, in __call__
    res = self._callback(*self._args, **self._kwargs)
  File "/home/jlpkort/anaconda3/lib/python3.8/multiprocessing/util.py", line 133, in _remove_temp_dir
    rmtree(tempdir)
  File "/home/jlpkort/anaconda3/lib/python3.8/shutil.py", line 722, in rmtree
    onerror(os.rmdir, path, sys.exc_info())
  File "/home/jlpkort/anaconda3/lib/python3.8/shutil.py", line 720, in rmtree
    os.rmdir(path)
OSError: [Errno 39] Directory not empty: '/scratch/pymp-dyq02npg'
Traceback (most recent call last):
  File "/home/jlpkort/anaconda3/lib/python3.8/multiprocessing/util.py", line 300, in _run_finalizers
    finalizer()
  File "/home/jlpkort/anaconda3/lib/python3.8/multiprocessing/util.py", line 224, in __call__
    res = self._callback(*self._args, **self._kwargs)
  File "/home/jlpkort/anaconda3/lib/python3.8/multiprocessing/util.py", line 133, in _remove_temp_dir
    rmtree(tempdir)
  File "/home/jlpkort/anaconda3/lib/python3.8/shutil.py", line 722, in rmtree
    onerror(os.rmdir, path, sys.exc_info())
  File "/home/jlpkort/anaconda3/lib/python3.8/shutil.py", line 720, in rmtree
    os.rmdir(path)
OSError: [Errno 39] Directory not empty: '/scratch/pymp-gwo5p_bc'
Traceback (most recent call last):
  File "/home/jlpkort/anaconda3/lib/python3.8/multiprocessing/util.py", line 300, in _run_finalizers
    finalizer()
  File "/home/jlpkort/anaconda3/lib/python3.8/multiprocessing/util.py", line 224, in __call__
    res = self._callback(*self._args, **self._kwargs)
  File "/home/jlpkort/anaconda3/lib/python3.8/multiprocessing/util.py", line 133, in _remove_temp_dir
    rmtree(tempdir)
  File "/home/jlpkort/anaconda3/lib/python3.8/shutil.py", line 722, in rmtree
    onerror(os.rmdir, path, sys.exc_info())
  File "/home/jlpkort/anaconda3/lib/python3.8/shutil.py", line 720, in rmtree
    os.rmdir(path)
OSError: [Errno 39] Directory not empty: '/scratch/pymp-j1uedny6'
I0904 20:32:05.025508 5956 trainer.py:117]  [Step: 8000/100000 (8.0%)] D Loss: -318626.375 M Loss: 1.0670782327651978 G Loss: -683607.0 
Traceback (most recent call last):
  File "/home/jlpkort/anaconda3/lib/python3.8/multiprocessing/util.py", line 300, in _run_finalizers
    finalizer()
  File "/home/jlpkort/anaconda3/lib/python3.8/multiprocessing/util.py", line 224, in __call__
    res = self._callback(*self._args, **self._kwargs)
  File "/home/jlpkort/anaconda3/lib/python3.8/multiprocessing/util.py", line 133, in _remove_temp_dir
    rmtree(tempdir)
  File "/home/jlpkort/anaconda3/lib/python3.8/shutil.py", line 722, in rmtree
    onerror(os.rmdir, path, sys.exc_info())
  File "/home/jlpkort/anaconda3/lib/python3.8/shutil.py", line 720, in rmtree
    os.rmdir(path)
OSError: [Errno 39] Directory not empty: '/scratch/pymp-iq_6rmi0'
Traceback (most recent call last):
  File "/home/jlpkort/anaconda3/lib/python3.8/multiprocessing/util.py", line 300, in _run_finalizers
    finalizer()
  File "/home/jlpkort/anaconda3/lib/python3.8/multiprocessing/util.py", line 224, in __call__
    res = self._callback(*self._args, **self._kwargs)
  File "/home/jlpkort/anaconda3/lib/python3.8/multiprocessing/util.py", line 133, in _remove_temp_dir
    rmtree(tempdir)
  File "/home/jlpkort/anaconda3/lib/python3.8/shutil.py", line 722, in rmtree
    onerror(os.rmdir, path, sys.exc_info())
  File "/home/jlpkort/anaconda3/lib/python3.8/shutil.py", line 720, in rmtree
    os.rmdir(path)
OSError: [Errno 39] Directory not empty: '/scratch/pymp-f01mb2t4'
Traceback (most recent call last):
  File "/home/jlpkort/anaconda3/lib/python3.8/multiprocessing/util.py", line 300, in _run_finalizers
    finalizer()
  File "/home/jlpkort/anaconda3/lib/python3.8/multiprocessing/util.py", line 224, in __call__
    res = self._callback(*self._args, **self._kwargs)
  File "/home/jlpkort/anaconda3/lib/python3.8/multiprocessing/util.py", line 133, in _remove_temp_dir
    rmtree(tempdir)
  File "/home/jlpkort/anaconda3/lib/python3.8/shutil.py", line 722, in rmtree
    onerror(os.rmdir, path, sys.exc_info())
  File "/home/jlpkort/anaconda3/lib/python3.8/shutil.py", line 720, in rmtree
    os.rmdir(path)
OSError: [Errno 39] Directory not empty: '/scratch/pymp-zlqfwsbm'
Traceback (most recent call last):
  File "/home/jlpkort/anaconda3/lib/python3.8/multiprocessing/util.py", line 300, in _run_finalizers
    finalizer()
  File "/home/jlpkort/anaconda3/lib/python3.8/multiprocessing/util.py", line 224, in __call__
    res = self._callback(*self._args, **self._kwargs)
  File "/home/jlpkort/anaconda3/lib/python3.8/multiprocessing/util.py", line 133, in _remove_temp_dir
    rmtree(tempdir)
  File "/home/jlpkort/anaconda3/lib/python3.8/shutil.py", line 722, in rmtree
    onerror(os.rmdir, path, sys.exc_info())
  File "/home/jlpkort/anaconda3/lib/python3.8/shutil.py", line 720, in rmtree
    os.rmdir(path)
OSError: [Errno 39] Directory not empty: '/scratch/pymp-0l3g5cy_'
Traceback (most recent call last):
  File "/home/jlpkort/anaconda3/lib/python3.8/multiprocessing/util.py", line 300, in _run_finalizers
    finalizer()
  File "/home/jlpkort/anaconda3/lib/python3.8/multiprocessing/util.py", line 224, in __call__
    res = self._callback(*self._args, **self._kwargs)
  File "/home/jlpkort/anaconda3/lib/python3.8/multiprocessing/util.py", line 133, in _remove_temp_dir
    rmtree(tempdir)
  File "/home/jlpkort/anaconda3/lib/python3.8/shutil.py", line 722, in rmtree
    onerror(os.rmdir, path, sys.exc_info())
  File "/home/jlpkort/anaconda3/lib/python3.8/shutil.py", line 720, in rmtree
    os.rmdir(path)
OSError: [Errno 39] Directory not empty: '/scratch/pymp-f4xihce5'
Traceback (most recent call last):
  File "/home/jlpkort/anaconda3/lib/python3.8/multiprocessing/util.py", line 300, in _run_finalizers
    finalizer()
  File "/home/jlpkort/anaconda3/lib/python3.8/multiprocessing/util.py", line 224, in __call__
    res = self._callback(*self._args, **self._kwargs)
  File "/home/jlpkort/anaconda3/lib/python3.8/multiprocessing/util.py", line 133, in _remove_temp_dir
    rmtree(tempdir)
  File "/home/jlpkort/anaconda3/lib/python3.8/shutil.py", line 722, in rmtree
    onerror(os.rmdir, path, sys.exc_info())
  File "/home/jlpkort/anaconda3/lib/python3.8/shutil.py", line 720, in rmtree
    os.rmdir(path)
OSError: [Errno 39] Directory not empty: '/scratch/pymp-qdkb6y0x'
I0904 21:54:14.867515 5956 trainer.py:117]  [Step: 9000/100000 (9.0%)] D Loss: -522513.15625 M Loss: 1.019033432006836 G Loss: -1160581.75 
Traceback (most recent call last):
  File "/home/jlpkort/anaconda3/lib/python3.8/multiprocessing/util.py", line 300, in _run_finalizers
    finalizer()
  File "/home/jlpkort/anaconda3/lib/python3.8/multiprocessing/util.py", line 224, in __call__
    res = self._callback(*self._args, **self._kwargs)
  File "/home/jlpkort/anaconda3/lib/python3.8/multiprocessing/util.py", line 133, in _remove_temp_dir
    rmtree(tempdir)
  File "/home/jlpkort/anaconda3/lib/python3.8/shutil.py", line 722, in rmtree
    onerror(os.rmdir, path, sys.exc_info())
  File "/home/jlpkort/anaconda3/lib/python3.8/shutil.py", line 720, in rmtree
    os.rmdir(path)
OSError: [Errno 39] Directory not empty: '/scratch/pymp-i1f8b0pj'
Traceback (most recent call last):
  File "/home/jlpkort/anaconda3/lib/python3.8/multiprocessing/util.py", line 300, in _run_finalizers
    finalizer()
  File "/home/jlpkort/anaconda3/lib/python3.8/multiprocessing/util.py", line 224, in __call__
    res = self._callback(*self._args, **self._kwargs)
  File "/home/jlpkort/anaconda3/lib/python3.8/multiprocessing/util.py", line 133, in _remove_temp_dir
    rmtree(tempdir)
  File "/home/jlpkort/anaconda3/lib/python3.8/shutil.py", line 722, in rmtree
    onerror(os.rmdir, path, sys.exc_info())
  File "/home/jlpkort/anaconda3/lib/python3.8/shutil.py", line 720, in rmtree
    os.rmdir(path)
OSError: [Errno 39] Directory not empty: '/scratch/pymp-uhz_wji0'
Traceback (most recent call last):
  File "/home/jlpkort/anaconda3/lib/python3.8/multiprocessing/util.py", line 300, in _run_finalizers
    finalizer()
  File "/home/jlpkort/anaconda3/lib/python3.8/multiprocessing/util.py", line 224, in __call__
    res = self._callback(*self._args, **self._kwargs)
  File "/home/jlpkort/anaconda3/lib/python3.8/multiprocessing/util.py", line 133, in _remove_temp_dir
    rmtree(tempdir)
  File "/home/jlpkort/anaconda3/lib/python3.8/shutil.py", line 722, in rmtree
    onerror(os.rmdir, path, sys.exc_info())
  File "/home/jlpkort/anaconda3/lib/python3.8/shutil.py", line 720, in rmtree
    os.rmdir(path)
OSError: [Errno 39] Directory not empty: '/scratch/pymp-1o3j4lg9'
Traceback (most recent call last):
  File "/home/jlpkort/anaconda3/lib/python3.8/multiprocessing/util.py", line 300, in _run_finalizers
    finalizer()
  File "/home/jlpkort/anaconda3/lib/python3.8/multiprocessing/util.py", line 224, in __call__
    res = self._callback(*self._args, **self._kwargs)
  File "/home/jlpkort/anaconda3/lib/python3.8/multiprocessing/util.py", line 133, in _remove_temp_dir
    rmtree(tempdir)
  File "/home/jlpkort/anaconda3/lib/python3.8/shutil.py", line 722, in rmtree
    onerror(os.rmdir, path, sys.exc_info())
  File "/home/jlpkort/anaconda3/lib/python3.8/shutil.py", line 720, in rmtree
    os.rmdir(path)
OSError: [Errno 39] Directory not empty: '/scratch/pymp-r_t6vfnm'
Traceback (most recent call last):
  File "/home/jlpkort/anaconda3/lib/python3.8/multiprocessing/util.py", line 300, in _run_finalizers
    finalizer()
  File "/home/jlpkort/anaconda3/lib/python3.8/multiprocessing/util.py", line 224, in __call__
    res = self._callback(*self._args, **self._kwargs)
  File "/home/jlpkort/anaconda3/lib/python3.8/multiprocessing/util.py", line 133, in _remove_temp_dir
    rmtree(tempdir)
  File "/home/jlpkort/anaconda3/lib/python3.8/shutil.py", line 722, in rmtree
    onerror(os.rmdir, path, sys.exc_info())
  File "/home/jlpkort/anaconda3/lib/python3.8/shutil.py", line 720, in rmtree
    os.rmdir(path)
OSError: [Errno 39] Directory not empty: '/scratch/pymp-zj_k9hkj'
I0904 23:16:26.318618 5956 trainer.py:117]  [Step: 10000/100000 (10.0%)] D Loss: -676996.75 M Loss: 1.004859447479248 G Loss: -1851862.875 
Traceback (most recent call last):
  File "/home/jlpkort/anaconda3/lib/python3.8/multiprocessing/util.py", line 300, in _run_finalizers
    finalizer()
  File "/home/jlpkort/anaconda3/lib/python3.8/multiprocessing/util.py", line 224, in __call__
    res = self._callback(*self._args, **self._kwargs)
  File "/home/jlpkort/anaconda3/lib/python3.8/multiprocessing/util.py", line 133, in _remove_temp_dir
    rmtree(tempdir)
  File "/home/jlpkort/anaconda3/lib/python3.8/shutil.py", line 722, in rmtree
    onerror(os.rmdir, path, sys.exc_info())
  File "/home/jlpkort/anaconda3/lib/python3.8/shutil.py", line 720, in rmtree
    os.rmdir(path)
OSError: [Errno 39] Directory not empty: '/scratch/pymp-u_4vwnr4'
Traceback (most recent call last):
  File "/home/jlpkort/anaconda3/lib/python3.8/multiprocessing/util.py", line 300, in _run_finalizers
    finalizer()
  File "/home/jlpkort/anaconda3/lib/python3.8/multiprocessing/util.py", line 224, in __call__
    res = self._callback(*self._args, **self._kwargs)
  File "/home/jlpkort/anaconda3/lib/python3.8/multiprocessing/util.py", line 133, in _remove_temp_dir
    rmtree(tempdir)
  File "/home/jlpkort/anaconda3/lib/python3.8/shutil.py", line 722, in rmtree
    onerror(os.rmdir, path, sys.exc_info())
  File "/home/jlpkort/anaconda3/lib/python3.8/shutil.py", line 720, in rmtree
    os.rmdir(path)
OSError: [Errno 39] Directory not empty: '/scratch/pymp-96k48bsu'
Traceback (most recent call last):
  File "/home/jlpkort/anaconda3/lib/python3.8/multiprocessing/util.py", line 300, in _run_finalizers
    finalizer()
  File "/home/jlpkort/anaconda3/lib/python3.8/multiprocessing/util.py", line 224, in __call__
    res = self._callback(*self._args, **self._kwargs)
  File "/home/jlpkort/anaconda3/lib/python3.8/multiprocessing/util.py", line 133, in _remove_temp_dir
    rmtree(tempdir)
  File "/home/jlpkort/anaconda3/lib/python3.8/shutil.py", line 722, in rmtree
    onerror(os.rmdir, path, sys.exc_info())
  File "/home/jlpkort/anaconda3/lib/python3.8/shutil.py", line 720, in rmtree
    os.rmdir(path)
OSError: [Errno 39] Directory not empty: '/scratch/pymp-514srtof'
Traceback (most recent call last):
  File "/home/jlpkort/anaconda3/lib/python3.8/multiprocessing/util.py", line 300, in _run_finalizers
    finalizer()
  File "/home/jlpkort/anaconda3/lib/python3.8/multiprocessing/util.py", line 224, in __call__
    res = self._callback(*self._args, **self._kwargs)
  File "/home/jlpkort/anaconda3/lib/python3.8/multiprocessing/util.py", line 133, in _remove_temp_dir
    rmtree(tempdir)
  File "/home/jlpkort/anaconda3/lib/python3.8/shutil.py", line 722, in rmtree
    onerror(os.rmdir, path, sys.exc_info())
  File "/home/jlpkort/anaconda3/lib/python3.8/shutil.py", line 720, in rmtree
    os.rmdir(path)
OSError: [Errno 39] Directory not empty: '/scratch/pymp-q160afuu'
Traceback (most recent call last):
  File "/home/jlpkort/anaconda3/lib/python3.8/multiprocessing/util.py", line 300, in _run_finalizers
    finalizer()
  File "/home/jlpkort/anaconda3/lib/python3.8/multiprocessing/util.py", line 224, in __call__
    res = self._callback(*self._args, **self._kwargs)
  File "/home/jlpkort/anaconda3/lib/python3.8/multiprocessing/util.py", line 133, in _remove_temp_dir
    rmtree(tempdir)
  File "/home/jlpkort/anaconda3/lib/python3.8/shutil.py", line 722, in rmtree
    onerror(os.rmdir, path, sys.exc_info())
  File "/home/jlpkort/anaconda3/lib/python3.8/shutil.py", line 720, in rmtree
    os.rmdir(path)
OSError: [Errno 39] Directory not empty: '/scratch/pymp-vhbwtu1t'
I0905 00:38:41.352671 5956 trainer.py:117]  [Step: 11000/100000 (11.0%)] D Loss: -817807.875 M Loss: 1.0139696598052979 G Loss: -2517789.75 
Traceback (most recent call last):
  File "/home/jlpkort/anaconda3/lib/python3.8/multiprocessing/util.py", line 300, in _run_finalizers
    finalizer()
  File "/home/jlpkort/anaconda3/lib/python3.8/multiprocessing/util.py", line 224, in __call__
    res = self._callback(*self._args, **self._kwargs)
  File "/home/jlpkort/anaconda3/lib/python3.8/multiprocessing/util.py", line 133, in _remove_temp_dir
    rmtree(tempdir)
  File "/home/jlpkort/anaconda3/lib/python3.8/shutil.py", line 722, in rmtree
    onerror(os.rmdir, path, sys.exc_info())
  File "/home/jlpkort/anaconda3/lib/python3.8/shutil.py", line 720, in rmtree
    os.rmdir(path)
OSError: [Errno 39] Directory not empty: '/scratch/pymp-2yev84ib'
Traceback (most recent call last):
  File "/home/jlpkort/anaconda3/lib/python3.8/multiprocessing/util.py", line 300, in _run_finalizers
    finalizer()
  File "/home/jlpkort/anaconda3/lib/python3.8/multiprocessing/util.py", line 224, in __call__
    res = self._callback(*self._args, **self._kwargs)
  File "/home/jlpkort/anaconda3/lib/python3.8/multiprocessing/util.py", line 133, in _remove_temp_dir
    rmtree(tempdir)
  File "/home/jlpkort/anaconda3/lib/python3.8/shutil.py", line 722, in rmtree
    onerror(os.rmdir, path, sys.exc_info())
  File "/home/jlpkort/anaconda3/lib/python3.8/shutil.py", line 720, in rmtree
    os.rmdir(path)
OSError: [Errno 39] Directory not empty: '/scratch/pymp-e6wx0yao'
Traceback (most recent call last):
  File "/home/jlpkort/anaconda3/lib/python3.8/multiprocessing/util.py", line 300, in _run_finalizers
    finalizer()
  File "/home/jlpkort/anaconda3/lib/python3.8/multiprocessing/util.py", line 224, in __call__
    res = self._callback(*self._args, **self._kwargs)
  File "/home/jlpkort/anaconda3/lib/python3.8/multiprocessing/util.py", line 133, in _remove_temp_dir
    rmtree(tempdir)
  File "/home/jlpkort/anaconda3/lib/python3.8/shutil.py", line 722, in rmtree
    onerror(os.rmdir, path, sys.exc_info())
  File "/home/jlpkort/anaconda3/lib/python3.8/shutil.py", line 720, in rmtree
    os.rmdir(path)
OSError: [Errno 39] Directory not empty: '/scratch/pymp-1ng1uy_p'
Traceback (most recent call last):
  File "/home/jlpkort/anaconda3/lib/python3.8/multiprocessing/util.py", line 300, in _run_finalizers
    finalizer()
  File "/home/jlpkort/anaconda3/lib/python3.8/multiprocessing/util.py", line 224, in __call__
    res = self._callback(*self._args, **self._kwargs)
  File "/home/jlpkort/anaconda3/lib/python3.8/multiprocessing/util.py", line 133, in _remove_temp_dir
    rmtree(tempdir)
  File "/home/jlpkort/anaconda3/lib/python3.8/shutil.py", line 722, in rmtree
    onerror(os.rmdir, path, sys.exc_info())
  File "/home/jlpkort/anaconda3/lib/python3.8/shutil.py", line 720, in rmtree
    os.rmdir(path)
OSError: [Errno 39] Directory not empty: '/scratch/pymp-j1pr3hxo'
Traceback (most recent call last):
  File "/home/jlpkort/anaconda3/lib/python3.8/multiprocessing/util.py", line 300, in _run_finalizers
    finalizer()
  File "/home/jlpkort/anaconda3/lib/python3.8/multiprocessing/util.py", line 224, in __call__
    res = self._callback(*self._args, **self._kwargs)
  File "/home/jlpkort/anaconda3/lib/python3.8/multiprocessing/util.py", line 133, in _remove_temp_dir
    rmtree(tempdir)
  File "/home/jlpkort/anaconda3/lib/python3.8/shutil.py", line 722, in rmtree
    onerror(os.rmdir, path, sys.exc_info())
  File "/home/jlpkort/anaconda3/lib/python3.8/shutil.py", line 720, in rmtree
    os.rmdir(path)
OSError: [Errno 39] Directory not empty: '/scratch/pymp-xk16iz4f'
Traceback (most recent call last):
  File "/home/jlpkort/anaconda3/lib/python3.8/multiprocessing/util.py", line 300, in _run_finalizers
    finalizer()
  File "/home/jlpkort/anaconda3/lib/python3.8/multiprocessing/util.py", line 224, in __call__
    res = self._callback(*self._args, **self._kwargs)
  File "/home/jlpkort/anaconda3/lib/python3.8/multiprocessing/util.py", line 133, in _remove_temp_dir
    rmtree(tempdir)
  File "/home/jlpkort/anaconda3/lib/python3.8/shutil.py", line 722, in rmtree
    onerror(os.rmdir, path, sys.exc_info())
  File "/home/jlpkort/anaconda3/lib/python3.8/shutil.py", line 720, in rmtree
    os.rmdir(path)
OSError: [Errno 39] Directory not empty: '/scratch/pymp-qkf7ez3f'
I0905 01:59:52.498550 5956 trainer.py:117]  [Step: 12000/100000 (12.0%)] D Loss: -1274499.5 M Loss: 1.0024468898773193 G Loss: -3892207.75 
Traceback (most recent call last):
  File "/home/jlpkort/anaconda3/lib/python3.8/multiprocessing/util.py", line 300, in _run_finalizers
    finalizer()
  File "/home/jlpkort/anaconda3/lib/python3.8/multiprocessing/util.py", line 224, in __call__
    res = self._callback(*self._args, **self._kwargs)
  File "/home/jlpkort/anaconda3/lib/python3.8/multiprocessing/util.py", line 133, in _remove_temp_dir
    rmtree(tempdir)
  File "/home/jlpkort/anaconda3/lib/python3.8/shutil.py", line 722, in rmtree
    onerror(os.rmdir, path, sys.exc_info())
  File "/home/jlpkort/anaconda3/lib/python3.8/shutil.py", line 720, in rmtree
    os.rmdir(path)
OSError: [Errno 39] Directory not empty: '/scratch/pymp-6ve8v93a'
Traceback (most recent call last):
  File "/home/jlpkort/anaconda3/lib/python3.8/multiprocessing/util.py", line 300, in _run_finalizers
    finalizer()
  File "/home/jlpkort/anaconda3/lib/python3.8/multiprocessing/util.py", line 224, in __call__
    res = self._callback(*self._args, **self._kwargs)
  File "/home/jlpkort/anaconda3/lib/python3.8/multiprocessing/util.py", line 133, in _remove_temp_dir
    rmtree(tempdir)
  File "/home/jlpkort/anaconda3/lib/python3.8/shutil.py", line 722, in rmtree
    onerror(os.rmdir, path, sys.exc_info())
  File "/home/jlpkort/anaconda3/lib/python3.8/shutil.py", line 720, in rmtree
    os.rmdir(path)
OSError: [Errno 39] Directory not empty: '/scratch/pymp-d50x3hp9'
Traceback (most recent call last):
  File "/home/jlpkort/anaconda3/lib/python3.8/multiprocessing/util.py", line 300, in _run_finalizers
    finalizer()
  File "/home/jlpkort/anaconda3/lib/python3.8/multiprocessing/util.py", line 224, in __call__
    res = self._callback(*self._args, **self._kwargs)
  File "/home/jlpkort/anaconda3/lib/python3.8/multiprocessing/util.py", line 133, in _remove_temp_dir
    rmtree(tempdir)
  File "/home/jlpkort/anaconda3/lib/python3.8/shutil.py", line 722, in rmtree
    onerror(os.rmdir, path, sys.exc_info())
  File "/home/jlpkort/anaconda3/lib/python3.8/shutil.py", line 720, in rmtree
    os.rmdir(path)
OSError: [Errno 39] Directory not empty: '/scratch/pymp-nrna70cg'
Traceback (most recent call last):
  File "/home/jlpkort/anaconda3/lib/python3.8/multiprocessing/util.py", line 300, in _run_finalizers
    finalizer()
  File "/home/jlpkort/anaconda3/lib/python3.8/multiprocessing/util.py", line 224, in __call__
    res = self._callback(*self._args, **self._kwargs)
  File "/home/jlpkort/anaconda3/lib/python3.8/multiprocessing/util.py", line 133, in _remove_temp_dir
    rmtree(tempdir)
  File "/home/jlpkort/anaconda3/lib/python3.8/shutil.py", line 722, in rmtree
    onerror(os.rmdir, path, sys.exc_info())
  File "/home/jlpkort/anaconda3/lib/python3.8/shutil.py", line 720, in rmtree
    os.rmdir(path)
OSError: [Errno 39] Directory not empty: '/scratch/pymp-vvv5max8'
Traceback (most recent call last):
  File "/home/jlpkort/anaconda3/lib/python3.8/multiprocessing/util.py", line 300, in _run_finalizers
    finalizer()
  File "/home/jlpkort/anaconda3/lib/python3.8/multiprocessing/util.py", line 224, in __call__
    res = self._callback(*self._args, **self._kwargs)
  File "/home/jlpkort/anaconda3/lib/python3.8/multiprocessing/util.py", line 133, in _remove_temp_dir
    rmtree(tempdir)
  File "/home/jlpkort/anaconda3/lib/python3.8/shutil.py", line 722, in rmtree
    onerror(os.rmdir, path, sys.exc_info())
  File "/home/jlpkort/anaconda3/lib/python3.8/shutil.py", line 720, in rmtree
    os.rmdir(path)
OSError: [Errno 39] Directory not empty: '/scratch/pymp-bub0o8bl'
I0905 03:19:59.292156 5956 trainer.py:117]  [Step: 13000/100000 (13.0%)] D Loss: -1498710.875 M Loss: 0.9976702928543091 G Loss: -4954280.5 
Traceback (most recent call last):
  File "/home/jlpkort/anaconda3/lib/python3.8/multiprocessing/util.py", line 300, in _run_finalizers
    finalizer()
  File "/home/jlpkort/anaconda3/lib/python3.8/multiprocessing/util.py", line 224, in __call__
    res = self._callback(*self._args, **self._kwargs)
  File "/home/jlpkort/anaconda3/lib/python3.8/multiprocessing/util.py", line 133, in _remove_temp_dir
    rmtree(tempdir)
  File "/home/jlpkort/anaconda3/lib/python3.8/shutil.py", line 722, in rmtree
    onerror(os.rmdir, path, sys.exc_info())
  File "/home/jlpkort/anaconda3/lib/python3.8/shutil.py", line 720, in rmtree
    os.rmdir(path)
OSError: [Errno 39] Directory not empty: '/scratch/pymp-w9rwzzzt'
Traceback (most recent call last):
  File "/home/jlpkort/anaconda3/lib/python3.8/multiprocessing/util.py", line 300, in _run_finalizers
    finalizer()
  File "/home/jlpkort/anaconda3/lib/python3.8/multiprocessing/util.py", line 224, in __call__
    res = self._callback(*self._args, **self._kwargs)
  File "/home/jlpkort/anaconda3/lib/python3.8/multiprocessing/util.py", line 133, in _remove_temp_dir
    rmtree(tempdir)
  File "/home/jlpkort/anaconda3/lib/python3.8/shutil.py", line 722, in rmtree
    onerror(os.rmdir, path, sys.exc_info())
  File "/home/jlpkort/anaconda3/lib/python3.8/shutil.py", line 720, in rmtree
    os.rmdir(path)
OSError: [Errno 39] Directory not empty: '/scratch/pymp-0bnnn4he'
Traceback (most recent call last):
  File "/home/jlpkort/anaconda3/lib/python3.8/multiprocessing/util.py", line 300, in _run_finalizers
    finalizer()
  File "/home/jlpkort/anaconda3/lib/python3.8/multiprocessing/util.py", line 224, in __call__
    res = self._callback(*self._args, **self._kwargs)
  File "/home/jlpkort/anaconda3/lib/python3.8/multiprocessing/util.py", line 133, in _remove_temp_dir
    rmtree(tempdir)
  File "/home/jlpkort/anaconda3/lib/python3.8/shutil.py", line 722, in rmtree
    onerror(os.rmdir, path, sys.exc_info())
  File "/home/jlpkort/anaconda3/lib/python3.8/shutil.py", line 720, in rmtree
    os.rmdir(path)
OSError: [Errno 39] Directory not empty: '/scratch/pymp-4ad45nsv'
I0905 04:40:03.709772 5956 trainer.py:117]  [Step: 14000/100000 (14.0%)] D Loss: -1460048.625 M Loss: 1.015097975730896 G Loss: -5183668.5 
Traceback (most recent call last):
  File "/home/jlpkort/anaconda3/lib/python3.8/multiprocessing/util.py", line 300, in _run_finalizers
    finalizer()
  File "/home/jlpkort/anaconda3/lib/python3.8/multiprocessing/util.py", line 224, in __call__
    res = self._callback(*self._args, **self._kwargs)
  File "/home/jlpkort/anaconda3/lib/python3.8/multiprocessing/util.py", line 133, in _remove_temp_dir
    rmtree(tempdir)
  File "/home/jlpkort/anaconda3/lib/python3.8/shutil.py", line 722, in rmtree
    onerror(os.rmdir, path, sys.exc_info())
  File "/home/jlpkort/anaconda3/lib/python3.8/shutil.py", line 720, in rmtree
    os.rmdir(path)
OSError: [Errno 39] Directory not empty: '/scratch/pymp-ezam0fti'
Traceback (most recent call last):
  File "/home/jlpkort/anaconda3/lib/python3.8/multiprocessing/util.py", line 300, in _run_finalizers
    finalizer()
  File "/home/jlpkort/anaconda3/lib/python3.8/multiprocessing/util.py", line 224, in __call__
    res = self._callback(*self._args, **self._kwargs)
  File "/home/jlpkort/anaconda3/lib/python3.8/multiprocessing/util.py", line 133, in _remove_temp_dir
    rmtree(tempdir)
  File "/home/jlpkort/anaconda3/lib/python3.8/shutil.py", line 722, in rmtree
    onerror(os.rmdir, path, sys.exc_info())
  File "/home/jlpkort/anaconda3/lib/python3.8/shutil.py", line 720, in rmtree
    os.rmdir(path)
OSError: [Errno 39] Directory not empty: '/scratch/pymp-drtiwei4'
Traceback (most recent call last):
  File "/home/jlpkort/anaconda3/lib/python3.8/multiprocessing/util.py", line 300, in _run_finalizers
    finalizer()
  File "/home/jlpkort/anaconda3/lib/python3.8/multiprocessing/util.py", line 224, in __call__
    res = self._callback(*self._args, **self._kwargs)
  File "/home/jlpkort/anaconda3/lib/python3.8/multiprocessing/util.py", line 133, in _remove_temp_dir
    rmtree(tempdir)
  File "/home/jlpkort/anaconda3/lib/python3.8/shutil.py", line 722, in rmtree
    onerror(os.rmdir, path, sys.exc_info())
  File "/home/jlpkort/anaconda3/lib/python3.8/shutil.py", line 720, in rmtree
    os.rmdir(path)
OSError: [Errno 39] Directory not empty: '/scratch/pymp-q2y7wobm'
I0905 06:00:14.248594 5956 trainer.py:117]  [Step: 15000/100000 (15.0%)] D Loss: -1485548.5 M Loss: 0.9726064205169678 G Loss: -6365976.0 
Traceback (most recent call last):
  File "/home/jlpkort/anaconda3/lib/python3.8/multiprocessing/util.py", line 300, in _run_finalizers
    finalizer()
  File "/home/jlpkort/anaconda3/lib/python3.8/multiprocessing/util.py", line 224, in __call__
    res = self._callback(*self._args, **self._kwargs)
  File "/home/jlpkort/anaconda3/lib/python3.8/multiprocessing/util.py", line 133, in _remove_temp_dir
    rmtree(tempdir)
  File "/home/jlpkort/anaconda3/lib/python3.8/shutil.py", line 722, in rmtree
    onerror(os.rmdir, path, sys.exc_info())
  File "/home/jlpkort/anaconda3/lib/python3.8/shutil.py", line 720, in rmtree
    os.rmdir(path)
OSError: [Errno 39] Directory not empty: '/scratch/pymp-j35dzqe0'
Traceback (most recent call last):
  File "/home/jlpkort/anaconda3/lib/python3.8/multiprocessing/util.py", line 300, in _run_finalizers
    finalizer()
  File "/home/jlpkort/anaconda3/lib/python3.8/multiprocessing/util.py", line 224, in __call__
    res = self._callback(*self._args, **self._kwargs)
  File "/home/jlpkort/anaconda3/lib/python3.8/multiprocessing/util.py", line 133, in _remove_temp_dir
    rmtree(tempdir)
  File "/home/jlpkort/anaconda3/lib/python3.8/shutil.py", line 722, in rmtree
    onerror(os.rmdir, path, sys.exc_info())
  File "/home/jlpkort/anaconda3/lib/python3.8/shutil.py", line 720, in rmtree
    os.rmdir(path)
OSError: [Errno 39] Directory not empty: '/scratch/pymp-wjp5t1rx'
Traceback (most recent call last):
  File "/home/jlpkort/anaconda3/lib/python3.8/multiprocessing/util.py", line 300, in _run_finalizers
    finalizer()
  File "/home/jlpkort/anaconda3/lib/python3.8/multiprocessing/util.py", line 224, in __call__
    res = self._callback(*self._args, **self._kwargs)
  File "/home/jlpkort/anaconda3/lib/python3.8/multiprocessing/util.py", line 133, in _remove_temp_dir
    rmtree(tempdir)
  File "/home/jlpkort/anaconda3/lib/python3.8/shutil.py", line 722, in rmtree
    onerror(os.rmdir, path, sys.exc_info())
  File "/home/jlpkort/anaconda3/lib/python3.8/shutil.py", line 720, in rmtree
    os.rmdir(path)
OSError: [Errno 39] Directory not empty: '/scratch/pymp-k5cv1sg3'
Traceback (most recent call last):
  File "/home/jlpkort/anaconda3/lib/python3.8/multiprocessing/util.py", line 300, in _run_finalizers
    finalizer()
  File "/home/jlpkort/anaconda3/lib/python3.8/multiprocessing/util.py", line 224, in __call__
    res = self._callback(*self._args, **self._kwargs)
  File "/home/jlpkort/anaconda3/lib/python3.8/multiprocessing/util.py", line 133, in _remove_temp_dir
    rmtree(tempdir)
  File "/home/jlpkort/anaconda3/lib/python3.8/shutil.py", line 722, in rmtree
    onerror(os.rmdir, path, sys.exc_info())
  File "/home/jlpkort/anaconda3/lib/python3.8/shutil.py", line 720, in rmtree
    os.rmdir(path)
OSError: [Errno 39] Directory not empty: '/scratch/pymp-wa1w9_7s'
Traceback (most recent call last):
  File "/home/jlpkort/anaconda3/lib/python3.8/multiprocessing/util.py", line 300, in _run_finalizers
    finalizer()
  File "/home/jlpkort/anaconda3/lib/python3.8/multiprocessing/util.py", line 224, in __call__
    res = self._callback(*self._args, **self._kwargs)
  File "/home/jlpkort/anaconda3/lib/python3.8/multiprocessing/util.py", line 133, in _remove_temp_dir
    rmtree(tempdir)
  File "/home/jlpkort/anaconda3/lib/python3.8/shutil.py", line 722, in rmtree
    onerror(os.rmdir, path, sys.exc_info())
  File "/home/jlpkort/anaconda3/lib/python3.8/shutil.py", line 720, in rmtree
    os.rmdir(path)
OSError: [Errno 39] Directory not empty: '/scratch/pymp-pw_6llp4'
Traceback (most recent call last):
  File "/home/jlpkort/anaconda3/lib/python3.8/multiprocessing/util.py", line 300, in _run_finalizers
    finalizer()
  File "/home/jlpkort/anaconda3/lib/python3.8/multiprocessing/util.py", line 224, in __call__
    res = self._callback(*self._args, **self._kwargs)
  File "/home/jlpkort/anaconda3/lib/python3.8/multiprocessing/util.py", line 133, in _remove_temp_dir
    rmtree(tempdir)
  File "/home/jlpkort/anaconda3/lib/python3.8/shutil.py", line 722, in rmtree
    onerror(os.rmdir, path, sys.exc_info())
  File "/home/jlpkort/anaconda3/lib/python3.8/shutil.py", line 720, in rmtree
    os.rmdir(path)
OSError: [Errno 39] Directory not empty: '/scratch/pymp-2ct___gm'
I0905 07:20:31.978562 5956 trainer.py:117]  [Step: 16000/100000 (16.0%)] D Loss: -1604094.5 M Loss: 1.0094547271728516 G Loss: -7493190.5 
Traceback (most recent call last):
  File "/home/jlpkort/anaconda3/lib/python3.8/multiprocessing/util.py", line 300, in _run_finalizers
    finalizer()
  File "/home/jlpkort/anaconda3/lib/python3.8/multiprocessing/util.py", line 224, in __call__
    res = self._callback(*self._args, **self._kwargs)
  File "/home/jlpkort/anaconda3/lib/python3.8/multiprocessing/util.py", line 133, in _remove_temp_dir
    rmtree(tempdir)
  File "/home/jlpkort/anaconda3/lib/python3.8/shutil.py", line 722, in rmtree
    onerror(os.rmdir, path, sys.exc_info())
  File "/home/jlpkort/anaconda3/lib/python3.8/shutil.py", line 720, in rmtree
    os.rmdir(path)
OSError: [Errno 39] Directory not empty: '/scratch/pymp-1zo1h26k'
Traceback (most recent call last):
  File "/home/jlpkort/anaconda3/lib/python3.8/multiprocessing/util.py", line 300, in _run_finalizers
    finalizer()
  File "/home/jlpkort/anaconda3/lib/python3.8/multiprocessing/util.py", line 224, in __call__
    res = self._callback(*self._args, **self._kwargs)
  File "/home/jlpkort/anaconda3/lib/python3.8/multiprocessing/util.py", line 133, in _remove_temp_dir
    rmtree(tempdir)
  File "/home/jlpkort/anaconda3/lib/python3.8/shutil.py", line 722, in rmtree
    onerror(os.rmdir, path, sys.exc_info())
  File "/home/jlpkort/anaconda3/lib/python3.8/shutil.py", line 720, in rmtree
    os.rmdir(path)
OSError: [Errno 39] Directory not empty: '/scratch/pymp-wihrhyf0'
Traceback (most recent call last):
  File "/home/jlpkort/anaconda3/lib/python3.8/multiprocessing/util.py", line 300, in _run_finalizers
    finalizer()
  File "/home/jlpkort/anaconda3/lib/python3.8/multiprocessing/util.py", line 224, in __call__
    res = self._callback(*self._args, **self._kwargs)
  File "/home/jlpkort/anaconda3/lib/python3.8/multiprocessing/util.py", line 133, in _remove_temp_dir
    rmtree(tempdir)
  File "/home/jlpkort/anaconda3/lib/python3.8/shutil.py", line 722, in rmtree
    onerror(os.rmdir, path, sys.exc_info())
  File "/home/jlpkort/anaconda3/lib/python3.8/shutil.py", line 720, in rmtree
    os.rmdir(path)
OSError: [Errno 39] Directory not empty: '/scratch/pymp-ae3vts06'
Traceback (most recent call last):
  File "/home/jlpkort/anaconda3/lib/python3.8/multiprocessing/util.py", line 300, in _run_finalizers
    finalizer()
  File "/home/jlpkort/anaconda3/lib/python3.8/multiprocessing/util.py", line 224, in __call__
    res = self._callback(*self._args, **self._kwargs)
  File "/home/jlpkort/anaconda3/lib/python3.8/multiprocessing/util.py", line 133, in _remove_temp_dir
    rmtree(tempdir)
  File "/home/jlpkort/anaconda3/lib/python3.8/shutil.py", line 722, in rmtree
    onerror(os.rmdir, path, sys.exc_info())
  File "/home/jlpkort/anaconda3/lib/python3.8/shutil.py", line 720, in rmtree
    os.rmdir(path)
OSError: [Errno 39] Directory not empty: '/scratch/pymp-tekg0ho3'
Traceback (most recent call last):
  File "/home/jlpkort/anaconda3/lib/python3.8/multiprocessing/util.py", line 300, in _run_finalizers
    finalizer()
  File "/home/jlpkort/anaconda3/lib/python3.8/multiprocessing/util.py", line 224, in __call__
    res = self._callback(*self._args, **self._kwargs)
  File "/home/jlpkort/anaconda3/lib/python3.8/multiprocessing/util.py", line 133, in _remove_temp_dir
    rmtree(tempdir)
  File "/home/jlpkort/anaconda3/lib/python3.8/shutil.py", line 722, in rmtree
    onerror(os.rmdir, path, sys.exc_info())
  File "/home/jlpkort/anaconda3/lib/python3.8/shutil.py", line 720, in rmtree
    os.rmdir(path)
OSError: [Errno 39] Directory not empty: '/scratch/pymp-57uwo6nt'
Traceback (most recent call last):
  File "/home/jlpkort/anaconda3/lib/python3.8/multiprocessing/util.py", line 300, in _run_finalizers
    finalizer()
  File "/home/jlpkort/anaconda3/lib/python3.8/multiprocessing/util.py", line 224, in __call__
    res = self._callback(*self._args, **self._kwargs)
  File "/home/jlpkort/anaconda3/lib/python3.8/multiprocessing/util.py", line 133, in _remove_temp_dir
    rmtree(tempdir)
  File "/home/jlpkort/anaconda3/lib/python3.8/shutil.py", line 722, in rmtree
    onerror(os.rmdir, path, sys.exc_info())
  File "/home/jlpkort/anaconda3/lib/python3.8/shutil.py", line 720, in rmtree
    os.rmdir(path)
OSError: [Errno 39] Directory not empty: '/scratch/pymp-13hxe7y5'
Traceback (most recent call last):
  File "/home/jlpkort/anaconda3/lib/python3.8/multiprocessing/util.py", line 300, in _run_finalizers
    finalizer()
  File "/home/jlpkort/anaconda3/lib/python3.8/multiprocessing/util.py", line 224, in __call__
    res = self._callback(*self._args, **self._kwargs)
  File "/home/jlpkort/anaconda3/lib/python3.8/multiprocessing/util.py", line 133, in _remove_temp_dir
    rmtree(tempdir)
  File "/home/jlpkort/anaconda3/lib/python3.8/shutil.py", line 722, in rmtree
    onerror(os.rmdir, path, sys.exc_info())
  File "/home/jlpkort/anaconda3/lib/python3.8/shutil.py", line 720, in rmtree
    os.rmdir(path)
OSError: [Errno 39] Directory not empty: '/scratch/pymp-njfsr996'
I0905 08:40:53.130571 5956 trainer.py:117]  [Step: 17000/100000 (17.0%)] D Loss: -2175286.5 M Loss: 1.0282461643218994 G Loss: -9433822.0 
Traceback (most recent call last):
  File "/home/jlpkort/anaconda3/lib/python3.8/multiprocessing/util.py", line 300, in _run_finalizers
    finalizer()
  File "/home/jlpkort/anaconda3/lib/python3.8/multiprocessing/util.py", line 224, in __call__
    res = self._callback(*self._args, **self._kwargs)
  File "/home/jlpkort/anaconda3/lib/python3.8/multiprocessing/util.py", line 133, in _remove_temp_dir
    rmtree(tempdir)
  File "/home/jlpkort/anaconda3/lib/python3.8/shutil.py", line 722, in rmtree
    onerror(os.rmdir, path, sys.exc_info())
  File "/home/jlpkort/anaconda3/lib/python3.8/shutil.py", line 720, in rmtree
    os.rmdir(path)
OSError: [Errno 39] Directory not empty: '/scratch/pymp-40qc6lkj'
Traceback (most recent call last):
  File "/home/jlpkort/anaconda3/lib/python3.8/multiprocessing/util.py", line 300, in _run_finalizers
    finalizer()
  File "/home/jlpkort/anaconda3/lib/python3.8/multiprocessing/util.py", line 224, in __call__
    res = self._callback(*self._args, **self._kwargs)
  File "/home/jlpkort/anaconda3/lib/python3.8/multiprocessing/util.py", line 133, in _remove_temp_dir
    rmtree(tempdir)
  File "/home/jlpkort/anaconda3/lib/python3.8/shutil.py", line 722, in rmtree
    onerror(os.rmdir, path, sys.exc_info())
  File "/home/jlpkort/anaconda3/lib/python3.8/shutil.py", line 720, in rmtree
    os.rmdir(path)
OSError: [Errno 39] Directory not empty: '/scratch/pymp-p4o6kaa7'
Traceback (most recent call last):
  File "/home/jlpkort/anaconda3/lib/python3.8/multiprocessing/util.py", line 300, in _run_finalizers
    finalizer()
  File "/home/jlpkort/anaconda3/lib/python3.8/multiprocessing/util.py", line 224, in __call__
    res = self._callback(*self._args, **self._kwargs)
  File "/home/jlpkort/anaconda3/lib/python3.8/multiprocessing/util.py", line 133, in _remove_temp_dir
    rmtree(tempdir)
  File "/home/jlpkort/anaconda3/lib/python3.8/shutil.py", line 722, in rmtree
    onerror(os.rmdir, path, sys.exc_info())
  File "/home/jlpkort/anaconda3/lib/python3.8/shutil.py", line 720, in rmtree
    os.rmdir(path)
OSError: [Errno 39] Directory not empty: '/scratch/pymp-7ojrv904'
Traceback (most recent call last):
  File "/home/jlpkort/anaconda3/lib/python3.8/multiprocessing/util.py", line 300, in _run_finalizers
    finalizer()
  File "/home/jlpkort/anaconda3/lib/python3.8/multiprocessing/util.py", line 224, in __call__
    res = self._callback(*self._args, **self._kwargs)
  File "/home/jlpkort/anaconda3/lib/python3.8/multiprocessing/util.py", line 133, in _remove_temp_dir
    rmtree(tempdir)
  File "/home/jlpkort/anaconda3/lib/python3.8/shutil.py", line 722, in rmtree
    onerror(os.rmdir, path, sys.exc_info())
  File "/home/jlpkort/anaconda3/lib/python3.8/shutil.py", line 720, in rmtree
    os.rmdir(path)
OSError: [Errno 39] Directory not empty: '/scratch/pymp-oi0scr5p'
I0905 10:01:14.378541 5956 trainer.py:117]  [Step: 18000/100000 (18.0%)] D Loss: -1768096.25 M Loss: 1.0013911724090576 G Loss: -9827428.0 
Traceback (most recent call last):
  File "/home/jlpkort/anaconda3/lib/python3.8/multiprocessing/util.py", line 300, in _run_finalizers
    finalizer()
  File "/home/jlpkort/anaconda3/lib/python3.8/multiprocessing/util.py", line 224, in __call__
    res = self._callback(*self._args, **self._kwargs)
  File "/home/jlpkort/anaconda3/lib/python3.8/multiprocessing/util.py", line 133, in _remove_temp_dir
    rmtree(tempdir)
  File "/home/jlpkort/anaconda3/lib/python3.8/shutil.py", line 722, in rmtree
    onerror(os.rmdir, path, sys.exc_info())
  File "/home/jlpkort/anaconda3/lib/python3.8/shutil.py", line 720, in rmtree
    os.rmdir(path)
OSError: [Errno 39] Directory not empty: '/scratch/pymp-0nj585ff'
Traceback (most recent call last):
  File "/home/jlpkort/anaconda3/lib/python3.8/multiprocessing/util.py", line 300, in _run_finalizers
    finalizer()
  File "/home/jlpkort/anaconda3/lib/python3.8/multiprocessing/util.py", line 224, in __call__
    res = self._callback(*self._args, **self._kwargs)
  File "/home/jlpkort/anaconda3/lib/python3.8/multiprocessing/util.py", line 133, in _remove_temp_dir
    rmtree(tempdir)
  File "/home/jlpkort/anaconda3/lib/python3.8/shutil.py", line 722, in rmtree
    onerror(os.rmdir, path, sys.exc_info())
  File "/home/jlpkort/anaconda3/lib/python3.8/shutil.py", line 720, in rmtree
    os.rmdir(path)
OSError: [Errno 39] Directory not empty: '/scratch/pymp-6x9x1_vi'
Traceback (most recent call last):
  File "/home/jlpkort/anaconda3/lib/python3.8/multiprocessing/util.py", line 300, in _run_finalizers
    finalizer()
  File "/home/jlpkort/anaconda3/lib/python3.8/multiprocessing/util.py", line 224, in __call__
    res = self._callback(*self._args, **self._kwargs)
  File "/home/jlpkort/anaconda3/lib/python3.8/multiprocessing/util.py", line 133, in _remove_temp_dir
    rmtree(tempdir)
  File "/home/jlpkort/anaconda3/lib/python3.8/shutil.py", line 722, in rmtree
    onerror(os.rmdir, path, sys.exc_info())
  File "/home/jlpkort/anaconda3/lib/python3.8/shutil.py", line 720, in rmtree
    os.rmdir(path)
OSError: [Errno 39] Directory not empty: '/scratch/pymp-m1x7ka77'
Traceback (most recent call last):
  File "/home/jlpkort/anaconda3/lib/python3.8/multiprocessing/util.py", line 300, in _run_finalizers
    finalizer()
  File "/home/jlpkort/anaconda3/lib/python3.8/multiprocessing/util.py", line 224, in __call__
    res = self._callback(*self._args, **self._kwargs)
  File "/home/jlpkort/anaconda3/lib/python3.8/multiprocessing/util.py", line 133, in _remove_temp_dir
    rmtree(tempdir)
  File "/home/jlpkort/anaconda3/lib/python3.8/shutil.py", line 722, in rmtree
    onerror(os.rmdir, path, sys.exc_info())
  File "/home/jlpkort/anaconda3/lib/python3.8/shutil.py", line 720, in rmtree
    os.rmdir(path)
OSError: [Errno 39] Directory not empty: '/scratch/pymp-t_o8shw2'
Traceback (most recent call last):
  File "/home/jlpkort/anaconda3/lib/python3.8/multiprocessing/util.py", line 300, in _run_finalizers
    finalizer()
  File "/home/jlpkort/anaconda3/lib/python3.8/multiprocessing/util.py", line 224, in __call__
    res = self._callback(*self._args, **self._kwargs)
  File "/home/jlpkort/anaconda3/lib/python3.8/multiprocessing/util.py", line 133, in _remove_temp_dir
    rmtree(tempdir)
  File "/home/jlpkort/anaconda3/lib/python3.8/shutil.py", line 722, in rmtree
    onerror(os.rmdir, path, sys.exc_info())
  File "/home/jlpkort/anaconda3/lib/python3.8/shutil.py", line 720, in rmtree
    os.rmdir(path)
OSError: [Errno 39] Directory not empty: '/scratch/pymp-hszqstps'
Traceback (most recent call last):
  File "/home/jlpkort/anaconda3/lib/python3.8/multiprocessing/util.py", line 300, in _run_finalizers
    finalizer()
  File "/home/jlpkort/anaconda3/lib/python3.8/multiprocessing/util.py", line 224, in __call__
    res = self._callback(*self._args, **self._kwargs)
  File "/home/jlpkort/anaconda3/lib/python3.8/multiprocessing/util.py", line 133, in _remove_temp_dir
    rmtree(tempdir)
  File "/home/jlpkort/anaconda3/lib/python3.8/shutil.py", line 722, in rmtree
    onerror(os.rmdir, path, sys.exc_info())
  File "/home/jlpkort/anaconda3/lib/python3.8/shutil.py", line 720, in rmtree
    os.rmdir(path)
OSError: [Errno 39] Directory not empty: '/scratch/pymp-da57wkge'
I0905 11:21:46.457202 5956 trainer.py:117]  [Step: 19000/100000 (19.0%)] D Loss: -1723854.375 M Loss: 1.06582772731781 G Loss: -10860824.0 
Traceback (most recent call last):
  File "/home/jlpkort/anaconda3/lib/python3.8/multiprocessing/util.py", line 300, in _run_finalizers
    finalizer()
  File "/home/jlpkort/anaconda3/lib/python3.8/multiprocessing/util.py", line 224, in __call__
    res = self._callback(*self._args, **self._kwargs)
  File "/home/jlpkort/anaconda3/lib/python3.8/multiprocessing/util.py", line 133, in _remove_temp_dir
    rmtree(tempdir)
  File "/home/jlpkort/anaconda3/lib/python3.8/shutil.py", line 722, in rmtree
    onerror(os.rmdir, path, sys.exc_info())
  File "/home/jlpkort/anaconda3/lib/python3.8/shutil.py", line 720, in rmtree
    os.rmdir(path)
OSError: [Errno 39] Directory not empty: '/scratch/pymp-1xrhigg3'
Traceback (most recent call last):
  File "/home/jlpkort/anaconda3/lib/python3.8/multiprocessing/util.py", line 300, in _run_finalizers
    finalizer()
  File "/home/jlpkort/anaconda3/lib/python3.8/multiprocessing/util.py", line 224, in __call__
    res = self._callback(*self._args, **self._kwargs)
  File "/home/jlpkort/anaconda3/lib/python3.8/multiprocessing/util.py", line 133, in _remove_temp_dir
    rmtree(tempdir)
  File "/home/jlpkort/anaconda3/lib/python3.8/shutil.py", line 722, in rmtree
    onerror(os.rmdir, path, sys.exc_info())
  File "/home/jlpkort/anaconda3/lib/python3.8/shutil.py", line 720, in rmtree
    os.rmdir(path)
OSError: [Errno 39] Directory not empty: '/scratch/pymp-rh61vcrv'
Traceback (most recent call last):
  File "/home/jlpkort/anaconda3/lib/python3.8/multiprocessing/util.py", line 300, in _run_finalizers
    finalizer()
  File "/home/jlpkort/anaconda3/lib/python3.8/multiprocessing/util.py", line 224, in __call__
    res = self._callback(*self._args, **self._kwargs)
  File "/home/jlpkort/anaconda3/lib/python3.8/multiprocessing/util.py", line 133, in _remove_temp_dir
    rmtree(tempdir)
  File "/home/jlpkort/anaconda3/lib/python3.8/shutil.py", line 722, in rmtree
    onerror(os.rmdir, path, sys.exc_info())
  File "/home/jlpkort/anaconda3/lib/python3.8/shutil.py", line 720, in rmtree
    os.rmdir(path)
OSError: [Errno 39] Directory not empty: '/scratch/pymp-4f6ozpo2'
Traceback (most recent call last):
  File "/home/jlpkort/anaconda3/lib/python3.8/multiprocessing/util.py", line 300, in _run_finalizers
    finalizer()
  File "/home/jlpkort/anaconda3/lib/python3.8/multiprocessing/util.py", line 224, in __call__
    res = self._callback(*self._args, **self._kwargs)
  File "/home/jlpkort/anaconda3/lib/python3.8/multiprocessing/util.py", line 133, in _remove_temp_dir
    rmtree(tempdir)
  File "/home/jlpkort/anaconda3/lib/python3.8/shutil.py", line 722, in rmtree
    onerror(os.rmdir, path, sys.exc_info())
  File "/home/jlpkort/anaconda3/lib/python3.8/shutil.py", line 720, in rmtree
    os.rmdir(path)
OSError: [Errno 39] Directory not empty: '/scratch/pymp-4nxikk5l'
Traceback (most recent call last):
  File "/home/jlpkort/anaconda3/lib/python3.8/multiprocessing/util.py", line 300, in _run_finalizers
    finalizer()
  File "/home/jlpkort/anaconda3/lib/python3.8/multiprocessing/util.py", line 224, in __call__
    res = self._callback(*self._args, **self._kwargs)
  File "/home/jlpkort/anaconda3/lib/python3.8/multiprocessing/util.py", line 133, in _remove_temp_dir
    rmtree(tempdir)
  File "/home/jlpkort/anaconda3/lib/python3.8/shutil.py", line 722, in rmtree
    onerror(os.rmdir, path, sys.exc_info())
  File "/home/jlpkort/anaconda3/lib/python3.8/shutil.py", line 720, in rmtree
    os.rmdir(path)
OSError: [Errno 39] Directory not empty: '/scratch/pymp-vl2719e2'
Traceback (most recent call last):
  File "/home/jlpkort/anaconda3/lib/python3.8/multiprocessing/util.py", line 300, in _run_finalizers
    finalizer()
  File "/home/jlpkort/anaconda3/lib/python3.8/multiprocessing/util.py", line 224, in __call__
    res = self._callback(*self._args, **self._kwargs)
  File "/home/jlpkort/anaconda3/lib/python3.8/multiprocessing/util.py", line 133, in _remove_temp_dir
    rmtree(tempdir)
  File "/home/jlpkort/anaconda3/lib/python3.8/shutil.py", line 722, in rmtree
    onerror(os.rmdir, path, sys.exc_info())
  File "/home/jlpkort/anaconda3/lib/python3.8/shutil.py", line 720, in rmtree
    os.rmdir(path)
OSError: [Errno 39] Directory not empty: '/scratch/pymp-ry1dcpfd'
Traceback (most recent call last):
  File "/home/jlpkort/anaconda3/lib/python3.8/multiprocessing/util.py", line 300, in _run_finalizers
    finalizer()
  File "/home/jlpkort/anaconda3/lib/python3.8/multiprocessing/util.py", line 224, in __call__
    res = self._callback(*self._args, **self._kwargs)
  File "/home/jlpkort/anaconda3/lib/python3.8/multiprocessing/util.py", line 133, in _remove_temp_dir
    rmtree(tempdir)
  File "/home/jlpkort/anaconda3/lib/python3.8/shutil.py", line 722, in rmtree
    onerror(os.rmdir, path, sys.exc_info())
  File "/home/jlpkort/anaconda3/lib/python3.8/shutil.py", line 720, in rmtree
    os.rmdir(path)
OSError: [Errno 39] Directory not empty: '/scratch/pymp-66svjqd4'
I0905 12:42:23.006634 5956 trainer.py:117]  [Step: 20000/100000 (20.0%)] D Loss: -2800228.0 M Loss: 1.339292049407959 G Loss: -13117757.0 
Traceback (most recent call last):
  File "/home/jlpkort/anaconda3/lib/python3.8/multiprocessing/util.py", line 300, in _run_finalizers
    finalizer()
  File "/home/jlpkort/anaconda3/lib/python3.8/multiprocessing/util.py", line 224, in __call__
    res = self._callback(*self._args, **self._kwargs)
  File "/home/jlpkort/anaconda3/lib/python3.8/multiprocessing/util.py", line 133, in _remove_temp_dir
    rmtree(tempdir)
  File "/home/jlpkort/anaconda3/lib/python3.8/shutil.py", line 722, in rmtree
    onerror(os.rmdir, path, sys.exc_info())
  File "/home/jlpkort/anaconda3/lib/python3.8/shutil.py", line 720, in rmtree
    os.rmdir(path)
OSError: [Errno 39] Directory not empty: '/scratch/pymp-06u3u824'
Traceback (most recent call last):
  File "/home/jlpkort/anaconda3/lib/python3.8/multiprocessing/util.py", line 300, in _run_finalizers
    finalizer()
  File "/home/jlpkort/anaconda3/lib/python3.8/multiprocessing/util.py", line 224, in __call__
    res = self._callback(*self._args, **self._kwargs)
  File "/home/jlpkort/anaconda3/lib/python3.8/multiprocessing/util.py", line 133, in _remove_temp_dir
    rmtree(tempdir)
  File "/home/jlpkort/anaconda3/lib/python3.8/shutil.py", line 722, in rmtree
    onerror(os.rmdir, path, sys.exc_info())
  File "/home/jlpkort/anaconda3/lib/python3.8/shutil.py", line 720, in rmtree
    os.rmdir(path)
OSError: [Errno 39] Directory not empty: '/scratch/pymp-isg7rois'
Traceback (most recent call last):
  File "/home/jlpkort/anaconda3/lib/python3.8/multiprocessing/util.py", line 300, in _run_finalizers
    finalizer()
  File "/home/jlpkort/anaconda3/lib/python3.8/multiprocessing/util.py", line 224, in __call__
    res = self._callback(*self._args, **self._kwargs)
  File "/home/jlpkort/anaconda3/lib/python3.8/multiprocessing/util.py", line 133, in _remove_temp_dir
    rmtree(tempdir)
  File "/home/jlpkort/anaconda3/lib/python3.8/shutil.py", line 722, in rmtree
    onerror(os.rmdir, path, sys.exc_info())
  File "/home/jlpkort/anaconda3/lib/python3.8/shutil.py", line 720, in rmtree
    os.rmdir(path)
OSError: [Errno 39] Directory not empty: '/scratch/pymp-17ao2o5z'
Traceback (most recent call last):
  File "/home/jlpkort/anaconda3/lib/python3.8/multiprocessing/util.py", line 300, in _run_finalizers
    finalizer()
  File "/home/jlpkort/anaconda3/lib/python3.8/multiprocessing/util.py", line 224, in __call__
    res = self._callback(*self._args, **self._kwargs)
  File "/home/jlpkort/anaconda3/lib/python3.8/multiprocessing/util.py", line 133, in _remove_temp_dir
    rmtree(tempdir)
  File "/home/jlpkort/anaconda3/lib/python3.8/shutil.py", line 722, in rmtree
    onerror(os.rmdir, path, sys.exc_info())
  File "/home/jlpkort/anaconda3/lib/python3.8/shutil.py", line 720, in rmtree
    os.rmdir(path)
OSError: [Errno 39] Directory not empty: '/scratch/pymp-akhkaxsl'
I0905 14:03:01.143593 5956 trainer.py:117]  [Step: 21000/100000 (21.0%)] D Loss: -2775053.75 M Loss: 1.026960015296936 G Loss: -15498658.0 
Traceback (most recent call last):
  File "/home/jlpkort/anaconda3/lib/python3.8/multiprocessing/util.py", line 300, in _run_finalizers
    finalizer()
  File "/home/jlpkort/anaconda3/lib/python3.8/multiprocessing/util.py", line 224, in __call__
    res = self._callback(*self._args, **self._kwargs)
  File "/home/jlpkort/anaconda3/lib/python3.8/multiprocessing/util.py", line 133, in _remove_temp_dir
    rmtree(tempdir)
  File "/home/jlpkort/anaconda3/lib/python3.8/shutil.py", line 722, in rmtree
    onerror(os.rmdir, path, sys.exc_info())
  File "/home/jlpkort/anaconda3/lib/python3.8/shutil.py", line 720, in rmtree
    os.rmdir(path)
OSError: [Errno 39] Directory not empty: '/scratch/pymp-shuapuxj'
Traceback (most recent call last):
  File "/home/jlpkort/anaconda3/lib/python3.8/multiprocessing/util.py", line 300, in _run_finalizers
    finalizer()
  File "/home/jlpkort/anaconda3/lib/python3.8/multiprocessing/util.py", line 224, in __call__
    res = self._callback(*self._args, **self._kwargs)
  File "/home/jlpkort/anaconda3/lib/python3.8/multiprocessing/util.py", line 133, in _remove_temp_dir
    rmtree(tempdir)
  File "/home/jlpkort/anaconda3/lib/python3.8/shutil.py", line 722, in rmtree
    onerror(os.rmdir, path, sys.exc_info())
  File "/home/jlpkort/anaconda3/lib/python3.8/shutil.py", line 720, in rmtree
    os.rmdir(path)
OSError: [Errno 39] Directory not empty: '/scratch/pymp-wt2ekxin'
Traceback (most recent call last):
  File "/home/jlpkort/anaconda3/lib/python3.8/multiprocessing/util.py", line 300, in _run_finalizers
    finalizer()
  File "/home/jlpkort/anaconda3/lib/python3.8/multiprocessing/util.py", line 224, in __call__
    res = self._callback(*self._args, **self._kwargs)
  File "/home/jlpkort/anaconda3/lib/python3.8/multiprocessing/util.py", line 133, in _remove_temp_dir
    rmtree(tempdir)
  File "/home/jlpkort/anaconda3/lib/python3.8/shutil.py", line 722, in rmtree
    onerror(os.rmdir, path, sys.exc_info())
  File "/home/jlpkort/anaconda3/lib/python3.8/shutil.py", line 720, in rmtree
    os.rmdir(path)
OSError: [Errno 39] Directory not empty: '/scratch/pymp-2h93m8c3'
I0905 15:23:36.644794 5956 trainer.py:117]  [Step: 22000/100000 (22.0%)] D Loss: -3914554.0 M Loss: 1.2932696342468262 G Loss: -19249108.0 
Traceback (most recent call last):
  File "/home/jlpkort/anaconda3/lib/python3.8/multiprocessing/util.py", line 300, in _run_finalizers
    finalizer()
  File "/home/jlpkort/anaconda3/lib/python3.8/multiprocessing/util.py", line 224, in __call__
    res = self._callback(*self._args, **self._kwargs)
  File "/home/jlpkort/anaconda3/lib/python3.8/multiprocessing/util.py", line 133, in _remove_temp_dir
    rmtree(tempdir)
  File "/home/jlpkort/anaconda3/lib/python3.8/shutil.py", line 722, in rmtree
    onerror(os.rmdir, path, sys.exc_info())
  File "/home/jlpkort/anaconda3/lib/python3.8/shutil.py", line 720, in rmtree
    os.rmdir(path)
OSError: [Errno 39] Directory not empty: '/scratch/pymp-w3cqq1ti'
Traceback (most recent call last):
  File "/home/jlpkort/anaconda3/lib/python3.8/multiprocessing/util.py", line 300, in _run_finalizers
    finalizer()
  File "/home/jlpkort/anaconda3/lib/python3.8/multiprocessing/util.py", line 224, in __call__
    res = self._callback(*self._args, **self._kwargs)
  File "/home/jlpkort/anaconda3/lib/python3.8/multiprocessing/util.py", line 133, in _remove_temp_dir
    rmtree(tempdir)
  File "/home/jlpkort/anaconda3/lib/python3.8/shutil.py", line 722, in rmtree
    onerror(os.rmdir, path, sys.exc_info())
  File "/home/jlpkort/anaconda3/lib/python3.8/shutil.py", line 720, in rmtree
    os.rmdir(path)
OSError: [Errno 39] Directory not empty: '/scratch/pymp-c1vvux39'
Traceback (most recent call last):
  File "/home/jlpkort/anaconda3/lib/python3.8/multiprocessing/util.py", line 300, in _run_finalizers
    finalizer()
  File "/home/jlpkort/anaconda3/lib/python3.8/multiprocessing/util.py", line 224, in __call__
    res = self._callback(*self._args, **self._kwargs)
  File "/home/jlpkort/anaconda3/lib/python3.8/multiprocessing/util.py", line 133, in _remove_temp_dir
    rmtree(tempdir)
  File "/home/jlpkort/anaconda3/lib/python3.8/shutil.py", line 722, in rmtree
    onerror(os.rmdir, path, sys.exc_info())
  File "/home/jlpkort/anaconda3/lib/python3.8/shutil.py", line 720, in rmtree
    os.rmdir(path)
OSError: [Errno 39] Directory not empty: '/scratch/pymp-the31tyf'
I0905 16:44:14.769931 5956 trainer.py:117]  [Step: 23000/100000 (23.0%)] D Loss: -4066809.75 M Loss: 1.342972755432129 G Loss: -23525816.0 
Traceback (most recent call last):
  File "/home/jlpkort/anaconda3/lib/python3.8/multiprocessing/util.py", line 300, in _run_finalizers
    finalizer()
  File "/home/jlpkort/anaconda3/lib/python3.8/multiprocessing/util.py", line 224, in __call__
    res = self._callback(*self._args, **self._kwargs)
  File "/home/jlpkort/anaconda3/lib/python3.8/multiprocessing/util.py", line 133, in _remove_temp_dir
    rmtree(tempdir)
  File "/home/jlpkort/anaconda3/lib/python3.8/shutil.py", line 722, in rmtree
    onerror(os.rmdir, path, sys.exc_info())
  File "/home/jlpkort/anaconda3/lib/python3.8/shutil.py", line 720, in rmtree
    os.rmdir(path)
OSError: [Errno 39] Directory not empty: '/scratch/pymp-qdb74yzo'
Traceback (most recent call last):
  File "/home/jlpkort/anaconda3/lib/python3.8/multiprocessing/util.py", line 300, in _run_finalizers
    finalizer()
  File "/home/jlpkort/anaconda3/lib/python3.8/multiprocessing/util.py", line 224, in __call__
    res = self._callback(*self._args, **self._kwargs)
  File "/home/jlpkort/anaconda3/lib/python3.8/multiprocessing/util.py", line 133, in _remove_temp_dir
    rmtree(tempdir)
  File "/home/jlpkort/anaconda3/lib/python3.8/shutil.py", line 722, in rmtree
    onerror(os.rmdir, path, sys.exc_info())
  File "/home/jlpkort/anaconda3/lib/python3.8/shutil.py", line 720, in rmtree
    os.rmdir(path)
OSError: [Errno 39] Directory not empty: '/scratch/pymp-ax86cmn4'
Traceback (most recent call last):
  File "/home/jlpkort/anaconda3/lib/python3.8/multiprocessing/util.py", line 300, in _run_finalizers
    finalizer()
  File "/home/jlpkort/anaconda3/lib/python3.8/multiprocessing/util.py", line 224, in __call__
    res = self._callback(*self._args, **self._kwargs)
  File "/home/jlpkort/anaconda3/lib/python3.8/multiprocessing/util.py", line 133, in _remove_temp_dir
    rmtree(tempdir)
  File "/home/jlpkort/anaconda3/lib/python3.8/shutil.py", line 722, in rmtree
    onerror(os.rmdir, path, sys.exc_info())
  File "/home/jlpkort/anaconda3/lib/python3.8/shutil.py", line 720, in rmtree
    os.rmdir(path)
OSError: [Errno 39] Directory not empty: '/scratch/pymp-wo4wahp1'
Traceback (most recent call last):
  File "/home/jlpkort/anaconda3/lib/python3.8/multiprocessing/util.py", line 300, in _run_finalizers
    finalizer()
  File "/home/jlpkort/anaconda3/lib/python3.8/multiprocessing/util.py", line 224, in __call__
    res = self._callback(*self._args, **self._kwargs)
  File "/home/jlpkort/anaconda3/lib/python3.8/multiprocessing/util.py", line 133, in _remove_temp_dir
    rmtree(tempdir)
  File "/home/jlpkort/anaconda3/lib/python3.8/shutil.py", line 722, in rmtree
    onerror(os.rmdir, path, sys.exc_info())
  File "/home/jlpkort/anaconda3/lib/python3.8/shutil.py", line 720, in rmtree
    os.rmdir(path)
OSError: [Errno 39] Directory not empty: '/scratch/pymp-x28lm2vi'
Traceback (most recent call last):
  File "/home/jlpkort/anaconda3/lib/python3.8/multiprocessing/util.py", line 300, in _run_finalizers
    finalizer()
  File "/home/jlpkort/anaconda3/lib/python3.8/multiprocessing/util.py", line 224, in __call__
    res = self._callback(*self._args, **self._kwargs)
  File "/home/jlpkort/anaconda3/lib/python3.8/multiprocessing/util.py", line 133, in _remove_temp_dir
    rmtree(tempdir)
  File "/home/jlpkort/anaconda3/lib/python3.8/shutil.py", line 722, in rmtree
    onerror(os.rmdir, path, sys.exc_info())
  File "/home/jlpkort/anaconda3/lib/python3.8/shutil.py", line 720, in rmtree
    os.rmdir(path)
OSError: [Errno 39] Directory not empty: '/scratch/pymp-u0t89kjb'
I0905 18:05:04.137103 5956 trainer.py:117]  [Step: 24000/100000 (24.0%)] D Loss: -3844213.25 M Loss: 1.3619258403778076 G Loss: -24463288.0 
Traceback (most recent call last):
  File "/home/jlpkort/anaconda3/lib/python3.8/multiprocessing/util.py", line 300, in _run_finalizers
    finalizer()
  File "/home/jlpkort/anaconda3/lib/python3.8/multiprocessing/util.py", line 224, in __call__
    res = self._callback(*self._args, **self._kwargs)
  File "/home/jlpkort/anaconda3/lib/python3.8/multiprocessing/util.py", line 133, in _remove_temp_dir
    rmtree(tempdir)
  File "/home/jlpkort/anaconda3/lib/python3.8/shutil.py", line 722, in rmtree
    onerror(os.rmdir, path, sys.exc_info())
  File "/home/jlpkort/anaconda3/lib/python3.8/shutil.py", line 720, in rmtree
    os.rmdir(path)
OSError: [Errno 39] Directory not empty: '/scratch/pymp-zgx6mz2f'
Traceback (most recent call last):
  File "/home/jlpkort/anaconda3/lib/python3.8/multiprocessing/util.py", line 300, in _run_finalizers
    finalizer()
  File "/home/jlpkort/anaconda3/lib/python3.8/multiprocessing/util.py", line 224, in __call__
    res = self._callback(*self._args, **self._kwargs)
  File "/home/jlpkort/anaconda3/lib/python3.8/multiprocessing/util.py", line 133, in _remove_temp_dir
    rmtree(tempdir)
  File "/home/jlpkort/anaconda3/lib/python3.8/shutil.py", line 722, in rmtree
    onerror(os.rmdir, path, sys.exc_info())
  File "/home/jlpkort/anaconda3/lib/python3.8/shutil.py", line 720, in rmtree
    os.rmdir(path)
OSError: [Errno 39] Directory not empty: '/scratch/pymp-0fpx1cgo'
I0905 19:25:55.433457 5956 trainer.py:117]  [Step: 25000/100000 (25.0%)] D Loss: -4236440.5 M Loss: 1.33933424949646 G Loss: -28343782.0 
Traceback (most recent call last):
  File "/home/jlpkort/anaconda3/lib/python3.8/multiprocessing/util.py", line 300, in _run_finalizers
    finalizer()
  File "/home/jlpkort/anaconda3/lib/python3.8/multiprocessing/util.py", line 224, in __call__
    res = self._callback(*self._args, **self._kwargs)
  File "/home/jlpkort/anaconda3/lib/python3.8/multiprocessing/util.py", line 133, in _remove_temp_dir
    rmtree(tempdir)
  File "/home/jlpkort/anaconda3/lib/python3.8/shutil.py", line 722, in rmtree
    onerror(os.rmdir, path, sys.exc_info())
  File "/home/jlpkort/anaconda3/lib/python3.8/shutil.py", line 720, in rmtree
    os.rmdir(path)
OSError: [Errno 39] Directory not empty: '/scratch/pymp-7l0d3kcb'
Traceback (most recent call last):
  File "/home/jlpkort/anaconda3/lib/python3.8/multiprocessing/util.py", line 300, in _run_finalizers
    finalizer()
  File "/home/jlpkort/anaconda3/lib/python3.8/multiprocessing/util.py", line 224, in __call__
    res = self._callback(*self._args, **self._kwargs)
  File "/home/jlpkort/anaconda3/lib/python3.8/multiprocessing/util.py", line 133, in _remove_temp_dir
    rmtree(tempdir)
  File "/home/jlpkort/anaconda3/lib/python3.8/shutil.py", line 722, in rmtree
    onerror(os.rmdir, path, sys.exc_info())
  File "/home/jlpkort/anaconda3/lib/python3.8/shutil.py", line 720, in rmtree
    os.rmdir(path)
OSError: [Errno 39] Directory not empty: '/scratch/pymp-y00lonsd'
Traceback (most recent call last):
  File "/home/jlpkort/anaconda3/lib/python3.8/multiprocessing/util.py", line 300, in _run_finalizers
    finalizer()
  File "/home/jlpkort/anaconda3/lib/python3.8/multiprocessing/util.py", line 224, in __call__
    res = self._callback(*self._args, **self._kwargs)
  File "/home/jlpkort/anaconda3/lib/python3.8/multiprocessing/util.py", line 133, in _remove_temp_dir
    rmtree(tempdir)
  File "/home/jlpkort/anaconda3/lib/python3.8/shutil.py", line 722, in rmtree
    onerror(os.rmdir, path, sys.exc_info())
  File "/home/jlpkort/anaconda3/lib/python3.8/shutil.py", line 720, in rmtree
    os.rmdir(path)
OSError: [Errno 39] Directory not empty: '/scratch/pymp-puqxpvr9'
I0905 20:46:59.539606 5956 trainer.py:117]  [Step: 26000/100000 (26.0%)] D Loss: -4511385.5 M Loss: 1.1397137641906738 G Loss: -31642008.0 
Traceback (most recent call last):
  File "/home/jlpkort/anaconda3/lib/python3.8/multiprocessing/util.py", line 300, in _run_finalizers
    finalizer()
  File "/home/jlpkort/anaconda3/lib/python3.8/multiprocessing/util.py", line 224, in __call__
    res = self._callback(*self._args, **self._kwargs)
  File "/home/jlpkort/anaconda3/lib/python3.8/multiprocessing/util.py", line 133, in _remove_temp_dir
    rmtree(tempdir)
  File "/home/jlpkort/anaconda3/lib/python3.8/shutil.py", line 722, in rmtree
    onerror(os.rmdir, path, sys.exc_info())
  File "/home/jlpkort/anaconda3/lib/python3.8/shutil.py", line 720, in rmtree
    os.rmdir(path)
OSError: [Errno 39] Directory not empty: '/scratch/pymp-u8xpvpi8'
Traceback (most recent call last):
  File "/home/jlpkort/anaconda3/lib/python3.8/multiprocessing/util.py", line 300, in _run_finalizers
    finalizer()
  File "/home/jlpkort/anaconda3/lib/python3.8/multiprocessing/util.py", line 224, in __call__
    res = self._callback(*self._args, **self._kwargs)
  File "/home/jlpkort/anaconda3/lib/python3.8/multiprocessing/util.py", line 133, in _remove_temp_dir
    rmtree(tempdir)
  File "/home/jlpkort/anaconda3/lib/python3.8/shutil.py", line 722, in rmtree
    onerror(os.rmdir, path, sys.exc_info())
  File "/home/jlpkort/anaconda3/lib/python3.8/shutil.py", line 720, in rmtree
    os.rmdir(path)
OSError: [Errno 39] Directory not empty: '/scratch/pymp-nqc_ind5'
Traceback (most recent call last):
  File "/home/jlpkort/anaconda3/lib/python3.8/multiprocessing/util.py", line 300, in _run_finalizers
    finalizer()
  File "/home/jlpkort/anaconda3/lib/python3.8/multiprocessing/util.py", line 224, in __call__
    res = self._callback(*self._args, **self._kwargs)
  File "/home/jlpkort/anaconda3/lib/python3.8/multiprocessing/util.py", line 133, in _remove_temp_dir
    rmtree(tempdir)
  File "/home/jlpkort/anaconda3/lib/python3.8/shutil.py", line 722, in rmtree
    onerror(os.rmdir, path, sys.exc_info())
  File "/home/jlpkort/anaconda3/lib/python3.8/shutil.py", line 720, in rmtree
    os.rmdir(path)
OSError: [Errno 39] Directory not empty: '/scratch/pymp-xw0qirty'
Traceback (most recent call last):
  File "/home/jlpkort/anaconda3/lib/python3.8/multiprocessing/util.py", line 300, in _run_finalizers
    finalizer()
  File "/home/jlpkort/anaconda3/lib/python3.8/multiprocessing/util.py", line 224, in __call__
    res = self._callback(*self._args, **self._kwargs)
  File "/home/jlpkort/anaconda3/lib/python3.8/multiprocessing/util.py", line 133, in _remove_temp_dir
    rmtree(tempdir)
  File "/home/jlpkort/anaconda3/lib/python3.8/shutil.py", line 722, in rmtree
    onerror(os.rmdir, path, sys.exc_info())
  File "/home/jlpkort/anaconda3/lib/python3.8/shutil.py", line 720, in rmtree
    os.rmdir(path)
OSError: [Errno 39] Directory not empty: '/scratch/pymp-yv_n_vem'
I0905 22:08:13.791233 5956 trainer.py:117]  [Step: 27000/100000 (27.0%)] D Loss: -6105877.0 M Loss: 1.2694802284240723 G Loss: -40985652.0 
Traceback (most recent call last):
  File "/home/jlpkort/anaconda3/lib/python3.8/multiprocessing/util.py", line 300, in _run_finalizers
    finalizer()
  File "/home/jlpkort/anaconda3/lib/python3.8/multiprocessing/util.py", line 224, in __call__
    res = self._callback(*self._args, **self._kwargs)
  File "/home/jlpkort/anaconda3/lib/python3.8/multiprocessing/util.py", line 133, in _remove_temp_dir
    rmtree(tempdir)
  File "/home/jlpkort/anaconda3/lib/python3.8/shutil.py", line 722, in rmtree
    onerror(os.rmdir, path, sys.exc_info())
  File "/home/jlpkort/anaconda3/lib/python3.8/shutil.py", line 720, in rmtree
    os.rmdir(path)
OSError: [Errno 39] Directory not empty: '/scratch/pymp-a2blwu09'
Traceback (most recent call last):
  File "/home/jlpkort/anaconda3/lib/python3.8/multiprocessing/util.py", line 300, in _run_finalizers
    finalizer()
  File "/home/jlpkort/anaconda3/lib/python3.8/multiprocessing/util.py", line 224, in __call__
    res = self._callback(*self._args, **self._kwargs)
  File "/home/jlpkort/anaconda3/lib/python3.8/multiprocessing/util.py", line 133, in _remove_temp_dir
    rmtree(tempdir)
  File "/home/jlpkort/anaconda3/lib/python3.8/shutil.py", line 722, in rmtree
    onerror(os.rmdir, path, sys.exc_info())
  File "/home/jlpkort/anaconda3/lib/python3.8/shutil.py", line 720, in rmtree
    os.rmdir(path)
OSError: [Errno 39] Directory not empty: '/scratch/pymp-3evd4tpv'
Traceback (most recent call last):
  File "/home/jlpkort/anaconda3/lib/python3.8/multiprocessing/util.py", line 300, in _run_finalizers
    finalizer()
  File "/home/jlpkort/anaconda3/lib/python3.8/multiprocessing/util.py", line 224, in __call__
    res = self._callback(*self._args, **self._kwargs)
  File "/home/jlpkort/anaconda3/lib/python3.8/multiprocessing/util.py", line 133, in _remove_temp_dir
    rmtree(tempdir)
  File "/home/jlpkort/anaconda3/lib/python3.8/shutil.py", line 722, in rmtree
    onerror(os.rmdir, path, sys.exc_info())
  File "/home/jlpkort/anaconda3/lib/python3.8/shutil.py", line 720, in rmtree
    os.rmdir(path)
OSError: [Errno 39] Directory not empty: '/scratch/pymp-opsuo1o_'
Traceback (most recent call last):
  File "/home/jlpkort/anaconda3/lib/python3.8/multiprocessing/util.py", line 300, in _run_finalizers
    finalizer()
  File "/home/jlpkort/anaconda3/lib/python3.8/multiprocessing/util.py", line 224, in __call__
    res = self._callback(*self._args, **self._kwargs)
  File "/home/jlpkort/anaconda3/lib/python3.8/multiprocessing/util.py", line 133, in _remove_temp_dir
    rmtree(tempdir)
  File "/home/jlpkort/anaconda3/lib/python3.8/shutil.py", line 722, in rmtree
    onerror(os.rmdir, path, sys.exc_info())
  File "/home/jlpkort/anaconda3/lib/python3.8/shutil.py", line 720, in rmtree
    os.rmdir(path)
OSError: [Errno 39] Directory not empty: '/scratch/pymp-01fs4gom'
I0905 23:29:17.626789 5956 trainer.py:117]  [Step: 28000/100000 (28.0%)] D Loss: -6209237.5 M Loss: 1.3519606590270996 G Loss: -46826528.0 
I0906 00:50:29.758465 5956 trainer.py:117]  [Step: 29000/100000 (29.0%)] D Loss: -5632526.0 M Loss: 1.374413013458252 G Loss: -48791736.0 
Traceback (most recent call last):
  File "/home/jlpkort/anaconda3/lib/python3.8/multiprocessing/util.py", line 300, in _run_finalizers
    finalizer()
  File "/home/jlpkort/anaconda3/lib/python3.8/multiprocessing/util.py", line 224, in __call__
    res = self._callback(*self._args, **self._kwargs)
  File "/home/jlpkort/anaconda3/lib/python3.8/multiprocessing/util.py", line 133, in _remove_temp_dir
    rmtree(tempdir)
  File "/home/jlpkort/anaconda3/lib/python3.8/shutil.py", line 722, in rmtree
    onerror(os.rmdir, path, sys.exc_info())
  File "/home/jlpkort/anaconda3/lib/python3.8/shutil.py", line 720, in rmtree
    os.rmdir(path)
OSError: [Errno 39] Directory not empty: '/scratch/pymp-1ls2r8zw'
Traceback (most recent call last):
  File "/home/jlpkort/anaconda3/lib/python3.8/multiprocessing/util.py", line 300, in _run_finalizers
    finalizer()
  File "/home/jlpkort/anaconda3/lib/python3.8/multiprocessing/util.py", line 224, in __call__
    res = self._callback(*self._args, **self._kwargs)
  File "/home/jlpkort/anaconda3/lib/python3.8/multiprocessing/util.py", line 133, in _remove_temp_dir
    rmtree(tempdir)
  File "/home/jlpkort/anaconda3/lib/python3.8/shutil.py", line 722, in rmtree
    onerror(os.rmdir, path, sys.exc_info())
  File "/home/jlpkort/anaconda3/lib/python3.8/shutil.py", line 720, in rmtree
    os.rmdir(path)
OSError: [Errno 39] Directory not empty: '/scratch/pymp-l046y5yq'
Traceback (most recent call last):
  File "/home/jlpkort/anaconda3/lib/python3.8/multiprocessing/util.py", line 300, in _run_finalizers
    finalizer()
  File "/home/jlpkort/anaconda3/lib/python3.8/multiprocessing/util.py", line 224, in __call__
    res = self._callback(*self._args, **self._kwargs)
  File "/home/jlpkort/anaconda3/lib/python3.8/multiprocessing/util.py", line 133, in _remove_temp_dir
    rmtree(tempdir)
  File "/home/jlpkort/anaconda3/lib/python3.8/shutil.py", line 722, in rmtree
    onerror(os.rmdir, path, sys.exc_info())
  File "/home/jlpkort/anaconda3/lib/python3.8/shutil.py", line 720, in rmtree
    os.rmdir(path)
OSError: [Errno 39] Directory not empty: '/scratch/pymp-ri3gx2i2'
I0906 02:11:43.353374 5956 trainer.py:117]  [Step: 30000/100000 (30.0%)] D Loss: -6138994.0 M Loss: 1.3550299406051636 G Loss: -48781516.0 
Traceback (most recent call last):
  File "/home/jlpkort/anaconda3/lib/python3.8/multiprocessing/util.py", line 300, in _run_finalizers
    finalizer()
  File "/home/jlpkort/anaconda3/lib/python3.8/multiprocessing/util.py", line 224, in __call__
    res = self._callback(*self._args, **self._kwargs)
  File "/home/jlpkort/anaconda3/lib/python3.8/multiprocessing/util.py", line 133, in _remove_temp_dir
    rmtree(tempdir)
  File "/home/jlpkort/anaconda3/lib/python3.8/shutil.py", line 722, in rmtree
    onerror(os.rmdir, path, sys.exc_info())
  File "/home/jlpkort/anaconda3/lib/python3.8/shutil.py", line 720, in rmtree
    os.rmdir(path)
OSError: [Errno 39] Directory not empty: '/scratch/pymp-kyb9e9o1'
Traceback (most recent call last):
  File "/home/jlpkort/anaconda3/lib/python3.8/multiprocessing/util.py", line 300, in _run_finalizers
    finalizer()
  File "/home/jlpkort/anaconda3/lib/python3.8/multiprocessing/util.py", line 224, in __call__
    res = self._callback(*self._args, **self._kwargs)
  File "/home/jlpkort/anaconda3/lib/python3.8/multiprocessing/util.py", line 133, in _remove_temp_dir
    rmtree(tempdir)
  File "/home/jlpkort/anaconda3/lib/python3.8/shutil.py", line 722, in rmtree
    onerror(os.rmdir, path, sys.exc_info())
  File "/home/jlpkort/anaconda3/lib/python3.8/shutil.py", line 720, in rmtree
    os.rmdir(path)
OSError: [Errno 39] Directory not empty: '/scratch/pymp-chm4tduq'
I0906 03:32:55.319238 5956 trainer.py:117]  [Step: 31000/100000 (31.0%)] D Loss: -5746184.0 M Loss: 1.3424227237701416 G Loss: -53761320.0 
Traceback (most recent call last):
  File "/home/jlpkort/anaconda3/lib/python3.8/multiprocessing/util.py", line 300, in _run_finalizers
    finalizer()
  File "/home/jlpkort/anaconda3/lib/python3.8/multiprocessing/util.py", line 224, in __call__
    res = self._callback(*self._args, **self._kwargs)
  File "/home/jlpkort/anaconda3/lib/python3.8/multiprocessing/util.py", line 133, in _remove_temp_dir
    rmtree(tempdir)
  File "/home/jlpkort/anaconda3/lib/python3.8/shutil.py", line 722, in rmtree
    onerror(os.rmdir, path, sys.exc_info())
  File "/home/jlpkort/anaconda3/lib/python3.8/shutil.py", line 720, in rmtree
    os.rmdir(path)
OSError: [Errno 39] Directory not empty: '/scratch/pymp-bw7bha9v'
Traceback (most recent call last):
  File "/home/jlpkort/anaconda3/lib/python3.8/multiprocessing/util.py", line 300, in _run_finalizers
    finalizer()
  File "/home/jlpkort/anaconda3/lib/python3.8/multiprocessing/util.py", line 224, in __call__
    res = self._callback(*self._args, **self._kwargs)
  File "/home/jlpkort/anaconda3/lib/python3.8/multiprocessing/util.py", line 133, in _remove_temp_dir
    rmtree(tempdir)
  File "/home/jlpkort/anaconda3/lib/python3.8/shutil.py", line 722, in rmtree
    onerror(os.rmdir, path, sys.exc_info())
  File "/home/jlpkort/anaconda3/lib/python3.8/shutil.py", line 720, in rmtree
    os.rmdir(path)
OSError: [Errno 39] Directory not empty: '/scratch/pymp-dzi9i_6w'
I0906 04:54:13.684091 5956 trainer.py:117]  [Step: 32000/100000 (32.0%)] D Loss: -7347930.0 M Loss: 1.3494243621826172 G Loss: -64367316.0 
Traceback (most recent call last):
  File "/home/jlpkort/anaconda3/lib/python3.8/multiprocessing/util.py", line 300, in _run_finalizers
    finalizer()
  File "/home/jlpkort/anaconda3/lib/python3.8/multiprocessing/util.py", line 224, in __call__
    res = self._callback(*self._args, **self._kwargs)
  File "/home/jlpkort/anaconda3/lib/python3.8/multiprocessing/util.py", line 133, in _remove_temp_dir
    rmtree(tempdir)
  File "/home/jlpkort/anaconda3/lib/python3.8/shutil.py", line 722, in rmtree
    onerror(os.rmdir, path, sys.exc_info())
  File "/home/jlpkort/anaconda3/lib/python3.8/shutil.py", line 720, in rmtree
    os.rmdir(path)
OSError: [Errno 39] Directory not empty: '/scratch/pymp-ol3nznmv'
Traceback (most recent call last):
  File "/home/jlpkort/anaconda3/lib/python3.8/multiprocessing/util.py", line 300, in _run_finalizers
    finalizer()
  File "/home/jlpkort/anaconda3/lib/python3.8/multiprocessing/util.py", line 224, in __call__
    res = self._callback(*self._args, **self._kwargs)
  File "/home/jlpkort/anaconda3/lib/python3.8/multiprocessing/util.py", line 133, in _remove_temp_dir
    rmtree(tempdir)
  File "/home/jlpkort/anaconda3/lib/python3.8/shutil.py", line 722, in rmtree
    onerror(os.rmdir, path, sys.exc_info())
  File "/home/jlpkort/anaconda3/lib/python3.8/shutil.py", line 720, in rmtree
    os.rmdir(path)
OSError: [Errno 39] Directory not empty: '/scratch/pymp-ume3p7k0'
Traceback (most recent call last):
  File "/home/jlpkort/anaconda3/lib/python3.8/multiprocessing/util.py", line 300, in _run_finalizers
    finalizer()
  File "/home/jlpkort/anaconda3/lib/python3.8/multiprocessing/util.py", line 224, in __call__
    res = self._callback(*self._args, **self._kwargs)
  File "/home/jlpkort/anaconda3/lib/python3.8/multiprocessing/util.py", line 133, in _remove_temp_dir
    rmtree(tempdir)
  File "/home/jlpkort/anaconda3/lib/python3.8/shutil.py", line 722, in rmtree
    onerror(os.rmdir, path, sys.exc_info())
  File "/home/jlpkort/anaconda3/lib/python3.8/shutil.py", line 720, in rmtree
    os.rmdir(path)
OSError: [Errno 39] Directory not empty: '/scratch/pymp-39rkdg3j'
I0906 06:15:35.793735 5956 trainer.py:117]  [Step: 33000/100000 (33.0%)] D Loss: -6010514.0 M Loss: 1.338255524635315 G Loss: -65657188.0 
Traceback (most recent call last):
  File "/home/jlpkort/anaconda3/lib/python3.8/multiprocessing/util.py", line 300, in _run_finalizers
    finalizer()
  File "/home/jlpkort/anaconda3/lib/python3.8/multiprocessing/util.py", line 224, in __call__
    res = self._callback(*self._args, **self._kwargs)
  File "/home/jlpkort/anaconda3/lib/python3.8/multiprocessing/util.py", line 133, in _remove_temp_dir
    rmtree(tempdir)
  File "/home/jlpkort/anaconda3/lib/python3.8/shutil.py", line 722, in rmtree
    onerror(os.rmdir, path, sys.exc_info())
  File "/home/jlpkort/anaconda3/lib/python3.8/shutil.py", line 720, in rmtree
    os.rmdir(path)
OSError: [Errno 39] Directory not empty: '/scratch/pymp-68yly8ti'
Traceback (most recent call last):
  File "/home/jlpkort/anaconda3/lib/python3.8/multiprocessing/util.py", line 300, in _run_finalizers
    finalizer()
  File "/home/jlpkort/anaconda3/lib/python3.8/multiprocessing/util.py", line 224, in __call__
    res = self._callback(*self._args, **self._kwargs)
  File "/home/jlpkort/anaconda3/lib/python3.8/multiprocessing/util.py", line 133, in _remove_temp_dir
    rmtree(tempdir)
  File "/home/jlpkort/anaconda3/lib/python3.8/shutil.py", line 722, in rmtree
    onerror(os.rmdir, path, sys.exc_info())
  File "/home/jlpkort/anaconda3/lib/python3.8/shutil.py", line 720, in rmtree
    os.rmdir(path)
OSError: [Errno 39] Directory not empty: '/scratch/pymp-u509fqtj'
Traceback (most recent call last):
  File "/home/jlpkort/anaconda3/lib/python3.8/multiprocessing/util.py", line 300, in _run_finalizers
    finalizer()
  File "/home/jlpkort/anaconda3/lib/python3.8/multiprocessing/util.py", line 224, in __call__
    res = self._callback(*self._args, **self._kwargs)
  File "/home/jlpkort/anaconda3/lib/python3.8/multiprocessing/util.py", line 133, in _remove_temp_dir
    rmtree(tempdir)
  File "/home/jlpkort/anaconda3/lib/python3.8/shutil.py", line 722, in rmtree
    onerror(os.rmdir, path, sys.exc_info())
  File "/home/jlpkort/anaconda3/lib/python3.8/shutil.py", line 720, in rmtree
    os.rmdir(path)
OSError: [Errno 39] Directory not empty: '/scratch/pymp-1nznfvcs'
Traceback (most recent call last):
  File "/home/jlpkort/anaconda3/lib/python3.8/multiprocessing/util.py", line 300, in _run_finalizers
    finalizer()
  File "/home/jlpkort/anaconda3/lib/python3.8/multiprocessing/util.py", line 224, in __call__
    res = self._callback(*self._args, **self._kwargs)
  File "/home/jlpkort/anaconda3/lib/python3.8/multiprocessing/util.py", line 133, in _remove_temp_dir
    rmtree(tempdir)
  File "/home/jlpkort/anaconda3/lib/python3.8/shutil.py", line 722, in rmtree
    onerror(os.rmdir, path, sys.exc_info())
  File "/home/jlpkort/anaconda3/lib/python3.8/shutil.py", line 720, in rmtree
    os.rmdir(path)
OSError: [Errno 39] Directory not empty: '/scratch/pymp-ul5a46ta'
I0906 07:37:03.982535 5956 trainer.py:117]  [Step: 34000/100000 (34.0%)] D Loss: -7947043.0 M Loss: 1.350905179977417 G Loss: -68515088.0 
Traceback (most recent call last):
  File "/home/jlpkort/anaconda3/lib/python3.8/multiprocessing/util.py", line 300, in _run_finalizers
    finalizer()
  File "/home/jlpkort/anaconda3/lib/python3.8/multiprocessing/util.py", line 224, in __call__
    res = self._callback(*self._args, **self._kwargs)
  File "/home/jlpkort/anaconda3/lib/python3.8/multiprocessing/util.py", line 133, in _remove_temp_dir
    rmtree(tempdir)
  File "/home/jlpkort/anaconda3/lib/python3.8/shutil.py", line 722, in rmtree
    onerror(os.rmdir, path, sys.exc_info())
  File "/home/jlpkort/anaconda3/lib/python3.8/shutil.py", line 720, in rmtree
    os.rmdir(path)
OSError: [Errno 39] Directory not empty: '/scratch/pymp-wdrzbysw'
Traceback (most recent call last):
  File "/home/jlpkort/anaconda3/lib/python3.8/multiprocessing/util.py", line 300, in _run_finalizers
    finalizer()
  File "/home/jlpkort/anaconda3/lib/python3.8/multiprocessing/util.py", line 224, in __call__
    res = self._callback(*self._args, **self._kwargs)
  File "/home/jlpkort/anaconda3/lib/python3.8/multiprocessing/util.py", line 133, in _remove_temp_dir
    rmtree(tempdir)
  File "/home/jlpkort/anaconda3/lib/python3.8/shutil.py", line 722, in rmtree
    onerror(os.rmdir, path, sys.exc_info())
  File "/home/jlpkort/anaconda3/lib/python3.8/shutil.py", line 720, in rmtree
    os.rmdir(path)
OSError: [Errno 39] Directory not empty: '/scratch/pymp-ect877qd'
I0906 08:58:34.079513 5956 trainer.py:117]  [Step: 35000/100000 (35.0%)] D Loss: -7909066.0 M Loss: 1.3632797002792358 G Loss: -78092408.0 
I0906 10:20:03.312834 5956 trainer.py:117]  [Step: 36000/100000 (36.0%)] D Loss: -6599229.0 M Loss: 1.3207828998565674 G Loss: -81363816.0 
Traceback (most recent call last):
  File "/home/jlpkort/anaconda3/lib/python3.8/multiprocessing/util.py", line 300, in _run_finalizers
    finalizer()
  File "/home/jlpkort/anaconda3/lib/python3.8/multiprocessing/util.py", line 224, in __call__
    res = self._callback(*self._args, **self._kwargs)
  File "/home/jlpkort/anaconda3/lib/python3.8/multiprocessing/util.py", line 133, in _remove_temp_dir
    rmtree(tempdir)
  File "/home/jlpkort/anaconda3/lib/python3.8/shutil.py", line 722, in rmtree
    onerror(os.rmdir, path, sys.exc_info())
  File "/home/jlpkort/anaconda3/lib/python3.8/shutil.py", line 720, in rmtree
    os.rmdir(path)
OSError: [Errno 39] Directory not empty: '/scratch/pymp-887rk377'
Traceback (most recent call last):
  File "/home/jlpkort/anaconda3/lib/python3.8/multiprocessing/util.py", line 300, in _run_finalizers
    finalizer()
  File "/home/jlpkort/anaconda3/lib/python3.8/multiprocessing/util.py", line 224, in __call__
    res = self._callback(*self._args, **self._kwargs)
  File "/home/jlpkort/anaconda3/lib/python3.8/multiprocessing/util.py", line 133, in _remove_temp_dir
    rmtree(tempdir)
  File "/home/jlpkort/anaconda3/lib/python3.8/shutil.py", line 722, in rmtree
    onerror(os.rmdir, path, sys.exc_info())
  File "/home/jlpkort/anaconda3/lib/python3.8/shutil.py", line 720, in rmtree
    os.rmdir(path)
OSError: [Errno 39] Directory not empty: '/scratch/pymp-airxblgq'
Traceback (most recent call last):
  File "/home/jlpkort/anaconda3/lib/python3.8/multiprocessing/util.py", line 300, in _run_finalizers
    finalizer()
  File "/home/jlpkort/anaconda3/lib/python3.8/multiprocessing/util.py", line 224, in __call__
    res = self._callback(*self._args, **self._kwargs)
  File "/home/jlpkort/anaconda3/lib/python3.8/multiprocessing/util.py", line 133, in _remove_temp_dir
    rmtree(tempdir)
  File "/home/jlpkort/anaconda3/lib/python3.8/shutil.py", line 722, in rmtree
    onerror(os.rmdir, path, sys.exc_info())
  File "/home/jlpkort/anaconda3/lib/python3.8/shutil.py", line 720, in rmtree
    os.rmdir(path)
OSError: [Errno 39] Directory not empty: '/scratch/pymp-otzwd49k'
I0906 11:41:57.308642 5956 trainer.py:117]  [Step: 37000/100000 (37.0%)] D Loss: -6253586.0 M Loss: 1.3469940423965454 G Loss: -83967576.0 
Traceback (most recent call last):
  File "/home/jlpkort/anaconda3/lib/python3.8/multiprocessing/util.py", line 300, in _run_finalizers
    finalizer()
  File "/home/jlpkort/anaconda3/lib/python3.8/multiprocessing/util.py", line 224, in __call__
    res = self._callback(*self._args, **self._kwargs)
  File "/home/jlpkort/anaconda3/lib/python3.8/multiprocessing/util.py", line 133, in _remove_temp_dir
    rmtree(tempdir)
  File "/home/jlpkort/anaconda3/lib/python3.8/shutil.py", line 722, in rmtree
    onerror(os.rmdir, path, sys.exc_info())
  File "/home/jlpkort/anaconda3/lib/python3.8/shutil.py", line 720, in rmtree
    os.rmdir(path)
OSError: [Errno 39] Directory not empty: '/scratch/pymp-jvy3v7ik'
I0906 13:03:49.111302 5956 trainer.py:117]  [Step: 38000/100000 (38.0%)] D Loss: -5728336.0 M Loss: 1.3547972440719604 G Loss: -93294808.0 
Traceback (most recent call last):
  File "/home/jlpkort/anaconda3/lib/python3.8/multiprocessing/util.py", line 300, in _run_finalizers
    finalizer()
  File "/home/jlpkort/anaconda3/lib/python3.8/multiprocessing/util.py", line 224, in __call__
    res = self._callback(*self._args, **self._kwargs)
  File "/home/jlpkort/anaconda3/lib/python3.8/multiprocessing/util.py", line 133, in _remove_temp_dir
    rmtree(tempdir)
  File "/home/jlpkort/anaconda3/lib/python3.8/shutil.py", line 722, in rmtree
    onerror(os.rmdir, path, sys.exc_info())
  File "/home/jlpkort/anaconda3/lib/python3.8/shutil.py", line 720, in rmtree
    os.rmdir(path)
OSError: [Errno 39] Directory not empty: '/scratch/pymp-i2rgfp1u'
Traceback (most recent call last):
  File "/home/jlpkort/anaconda3/lib/python3.8/multiprocessing/util.py", line 300, in _run_finalizers
    finalizer()
  File "/home/jlpkort/anaconda3/lib/python3.8/multiprocessing/util.py", line 224, in __call__
    res = self._callback(*self._args, **self._kwargs)
  File "/home/jlpkort/anaconda3/lib/python3.8/multiprocessing/util.py", line 133, in _remove_temp_dir
    rmtree(tempdir)
  File "/home/jlpkort/anaconda3/lib/python3.8/shutil.py", line 722, in rmtree
    onerror(os.rmdir, path, sys.exc_info())
  File "/home/jlpkort/anaconda3/lib/python3.8/shutil.py", line 720, in rmtree
    os.rmdir(path)
OSError: [Errno 39] Directory not empty: '/scratch/pymp-8hxh1xju'
Traceback (most recent call last):
  File "/home/jlpkort/anaconda3/lib/python3.8/multiprocessing/util.py", line 300, in _run_finalizers
    finalizer()
  File "/home/jlpkort/anaconda3/lib/python3.8/multiprocessing/util.py", line 224, in __call__
    res = self._callback(*self._args, **self._kwargs)
  File "/home/jlpkort/anaconda3/lib/python3.8/multiprocessing/util.py", line 133, in _remove_temp_dir
    rmtree(tempdir)
  File "/home/jlpkort/anaconda3/lib/python3.8/shutil.py", line 722, in rmtree
    onerror(os.rmdir, path, sys.exc_info())
  File "/home/jlpkort/anaconda3/lib/python3.8/shutil.py", line 720, in rmtree
    os.rmdir(path)
OSError: [Errno 39] Directory not empty: '/scratch/pymp-7hipznsx'
Traceback (most recent call last):
  File "/home/jlpkort/anaconda3/lib/python3.8/multiprocessing/util.py", line 300, in _run_finalizers
    finalizer()
  File "/home/jlpkort/anaconda3/lib/python3.8/multiprocessing/util.py", line 224, in __call__
    res = self._callback(*self._args, **self._kwargs)
  File "/home/jlpkort/anaconda3/lib/python3.8/multiprocessing/util.py", line 133, in _remove_temp_dir
    rmtree(tempdir)
  File "/home/jlpkort/anaconda3/lib/python3.8/shutil.py", line 722, in rmtree
    onerror(os.rmdir, path, sys.exc_info())
  File "/home/jlpkort/anaconda3/lib/python3.8/shutil.py", line 720, in rmtree
    os.rmdir(path)
OSError: [Errno 39] Directory not empty: '/scratch/pymp-movjlzkj'
I0906 14:25:29.815063 5956 trainer.py:117]  [Step: 39000/100000 (39.0%)] D Loss: -6519721.5 M Loss: 1.358583688735962 G Loss: -106992024.0 
Traceback (most recent call last):
  File "/home/jlpkort/anaconda3/lib/python3.8/multiprocessing/util.py", line 300, in _run_finalizers
    finalizer()
  File "/home/jlpkort/anaconda3/lib/python3.8/multiprocessing/util.py", line 224, in __call__
    res = self._callback(*self._args, **self._kwargs)
  File "/home/jlpkort/anaconda3/lib/python3.8/multiprocessing/util.py", line 133, in _remove_temp_dir
    rmtree(tempdir)
  File "/home/jlpkort/anaconda3/lib/python3.8/shutil.py", line 722, in rmtree
    onerror(os.rmdir, path, sys.exc_info())
  File "/home/jlpkort/anaconda3/lib/python3.8/shutil.py", line 720, in rmtree
    os.rmdir(path)
OSError: [Errno 39] Directory not empty: '/scratch/pymp-6ojdmv4q'
I0906 15:47:21.421432 5956 trainer.py:117]  [Step: 40000/100000 (40.0%)] D Loss: -8700053.0 M Loss: 1.356722354888916 G Loss: -111260672.0 
I0906 17:09:11.997691 5956 trainer.py:117]  [Step: 41000/100000 (41.0%)] D Loss: -9605684.0 M Loss: 1.3492553234100342 G Loss: -121278368.0 
Traceback (most recent call last):
  File "/home/jlpkort/anaconda3/lib/python3.8/multiprocessing/util.py", line 300, in _run_finalizers
    finalizer()
  File "/home/jlpkort/anaconda3/lib/python3.8/multiprocessing/util.py", line 224, in __call__
    res = self._callback(*self._args, **self._kwargs)
  File "/home/jlpkort/anaconda3/lib/python3.8/multiprocessing/util.py", line 133, in _remove_temp_dir
    rmtree(tempdir)
  File "/home/jlpkort/anaconda3/lib/python3.8/shutil.py", line 722, in rmtree
    onerror(os.rmdir, path, sys.exc_info())
  File "/home/jlpkort/anaconda3/lib/python3.8/shutil.py", line 720, in rmtree
    os.rmdir(path)
OSError: [Errno 39] Directory not empty: '/scratch/pymp-l91hm3gp'
Traceback (most recent call last):
  File "/home/jlpkort/anaconda3/lib/python3.8/multiprocessing/util.py", line 300, in _run_finalizers
    finalizer()
  File "/home/jlpkort/anaconda3/lib/python3.8/multiprocessing/util.py", line 224, in __call__
    res = self._callback(*self._args, **self._kwargs)
  File "/home/jlpkort/anaconda3/lib/python3.8/multiprocessing/util.py", line 133, in _remove_temp_dir
    rmtree(tempdir)
  File "/home/jlpkort/anaconda3/lib/python3.8/shutil.py", line 722, in rmtree
    onerror(os.rmdir, path, sys.exc_info())
  File "/home/jlpkort/anaconda3/lib/python3.8/shutil.py", line 720, in rmtree
    os.rmdir(path)
OSError: [Errno 39] Directory not empty: '/scratch/pymp-7s7sfzx7'
Traceback (most recent call last):
  File "/home/jlpkort/anaconda3/lib/python3.8/multiprocessing/util.py", line 300, in _run_finalizers
    finalizer()
  File "/home/jlpkort/anaconda3/lib/python3.8/multiprocessing/util.py", line 224, in __call__
    res = self._callback(*self._args, **self._kwargs)
  File "/home/jlpkort/anaconda3/lib/python3.8/multiprocessing/util.py", line 133, in _remove_temp_dir
    rmtree(tempdir)
  File "/home/jlpkort/anaconda3/lib/python3.8/shutil.py", line 722, in rmtree
    onerror(os.rmdir, path, sys.exc_info())
  File "/home/jlpkort/anaconda3/lib/python3.8/shutil.py", line 720, in rmtree
    os.rmdir(path)
OSError: [Errno 39] Directory not empty: '/scratch/pymp-kmerphcb'
Traceback (most recent call last):
  File "/home/jlpkort/anaconda3/lib/python3.8/multiprocessing/util.py", line 300, in _run_finalizers
    finalizer()
  File "/home/jlpkort/anaconda3/lib/python3.8/multiprocessing/util.py", line 224, in __call__
    res = self._callback(*self._args, **self._kwargs)
  File "/home/jlpkort/anaconda3/lib/python3.8/multiprocessing/util.py", line 133, in _remove_temp_dir
    rmtree(tempdir)
  File "/home/jlpkort/anaconda3/lib/python3.8/shutil.py", line 722, in rmtree
    onerror(os.rmdir, path, sys.exc_info())
  File "/home/jlpkort/anaconda3/lib/python3.8/shutil.py", line 720, in rmtree
    os.rmdir(path)
OSError: [Errno 39] Directory not empty: '/scratch/pymp-phokeywo'
I0906 18:31:05.687728 5956 trainer.py:117]  [Step: 42000/100000 (42.0%)] D Loss: -8927438.0 M Loss: 1.3446013927459717 G Loss: -130388296.0 
Traceback (most recent call last):
  File "/home/jlpkort/anaconda3/lib/python3.8/multiprocessing/util.py", line 300, in _run_finalizers
    finalizer()
  File "/home/jlpkort/anaconda3/lib/python3.8/multiprocessing/util.py", line 224, in __call__
    res = self._callback(*self._args, **self._kwargs)
  File "/home/jlpkort/anaconda3/lib/python3.8/multiprocessing/util.py", line 133, in _remove_temp_dir
    rmtree(tempdir)
  File "/home/jlpkort/anaconda3/lib/python3.8/shutil.py", line 722, in rmtree
    onerror(os.rmdir, path, sys.exc_info())
  File "/home/jlpkort/anaconda3/lib/python3.8/shutil.py", line 720, in rmtree
    os.rmdir(path)
OSError: [Errno 39] Directory not empty: '/scratch/pymp-p08z_yu6'
Traceback (most recent call last):
  File "/home/jlpkort/anaconda3/lib/python3.8/multiprocessing/util.py", line 300, in _run_finalizers
    finalizer()
  File "/home/jlpkort/anaconda3/lib/python3.8/multiprocessing/util.py", line 224, in __call__
    res = self._callback(*self._args, **self._kwargs)
  File "/home/jlpkort/anaconda3/lib/python3.8/multiprocessing/util.py", line 133, in _remove_temp_dir
    rmtree(tempdir)
  File "/home/jlpkort/anaconda3/lib/python3.8/shutil.py", line 722, in rmtree
    onerror(os.rmdir, path, sys.exc_info())
  File "/home/jlpkort/anaconda3/lib/python3.8/shutil.py", line 720, in rmtree
    os.rmdir(path)
OSError: [Errno 39] Directory not empty: '/scratch/pymp-wejbv4im'
Traceback (most recent call last):
  File "/home/jlpkort/anaconda3/lib/python3.8/multiprocessing/util.py", line 300, in _run_finalizers
    finalizer()
  File "/home/jlpkort/anaconda3/lib/python3.8/multiprocessing/util.py", line 224, in __call__
    res = self._callback(*self._args, **self._kwargs)
  File "/home/jlpkort/anaconda3/lib/python3.8/multiprocessing/util.py", line 133, in _remove_temp_dir
    rmtree(tempdir)
  File "/home/jlpkort/anaconda3/lib/python3.8/shutil.py", line 722, in rmtree
    onerror(os.rmdir, path, sys.exc_info())
  File "/home/jlpkort/anaconda3/lib/python3.8/shutil.py", line 720, in rmtree
    os.rmdir(path)
OSError: [Errno 39] Directory not empty: '/scratch/pymp-lz5bphua'
I0906 19:53:15.390804 5956 trainer.py:117]  [Step: 43000/100000 (43.0%)] D Loss: -8734774.0 M Loss: 1.3613545894622803 G Loss: -137727824.0 
Traceback (most recent call last):
  File "/home/jlpkort/anaconda3/lib/python3.8/multiprocessing/util.py", line 300, in _run_finalizers
    finalizer()
  File "/home/jlpkort/anaconda3/lib/python3.8/multiprocessing/util.py", line 224, in __call__
    res = self._callback(*self._args, **self._kwargs)
  File "/home/jlpkort/anaconda3/lib/python3.8/multiprocessing/util.py", line 133, in _remove_temp_dir
    rmtree(tempdir)
  File "/home/jlpkort/anaconda3/lib/python3.8/shutil.py", line 722, in rmtree
    onerror(os.rmdir, path, sys.exc_info())
  File "/home/jlpkort/anaconda3/lib/python3.8/shutil.py", line 720, in rmtree
    os.rmdir(path)
OSError: [Errno 39] Directory not empty: '/scratch/pymp-t9p4qpbq'
I0906 21:15:18.662493 5956 trainer.py:117]  [Step: 44000/100000 (44.0%)] D Loss: -8016591.5 M Loss: 1.3655431270599365 G Loss: -140589104.0 
I0906 22:37:16.714024 5956 trainer.py:117]  [Step: 45000/100000 (45.0%)] D Loss: -10223312.0 M Loss: 1.3638296127319336 G Loss: -152085504.0 
Traceback (most recent call last):
  File "/home/jlpkort/anaconda3/lib/python3.8/multiprocessing/util.py", line 300, in _run_finalizers
    finalizer()
  File "/home/jlpkort/anaconda3/lib/python3.8/multiprocessing/util.py", line 224, in __call__
    res = self._callback(*self._args, **self._kwargs)
  File "/home/jlpkort/anaconda3/lib/python3.8/multiprocessing/util.py", line 133, in _remove_temp_dir
    rmtree(tempdir)
  File "/home/jlpkort/anaconda3/lib/python3.8/shutil.py", line 722, in rmtree
    onerror(os.rmdir, path, sys.exc_info())
  File "/home/jlpkort/anaconda3/lib/python3.8/shutil.py", line 720, in rmtree
    os.rmdir(path)
OSError: [Errno 39] Directory not empty: '/scratch/pymp-mehsch18'
Traceback (most recent call last):
  File "/home/jlpkort/anaconda3/lib/python3.8/multiprocessing/util.py", line 300, in _run_finalizers
    finalizer()
  File "/home/jlpkort/anaconda3/lib/python3.8/multiprocessing/util.py", line 224, in __call__
    res = self._callback(*self._args, **self._kwargs)
  File "/home/jlpkort/anaconda3/lib/python3.8/multiprocessing/util.py", line 133, in _remove_temp_dir
    rmtree(tempdir)
  File "/home/jlpkort/anaconda3/lib/python3.8/shutil.py", line 722, in rmtree
    onerror(os.rmdir, path, sys.exc_info())
  File "/home/jlpkort/anaconda3/lib/python3.8/shutil.py", line 720, in rmtree
    os.rmdir(path)
OSError: [Errno 39] Directory not empty: '/scratch/pymp-kf16g01u'
Traceback (most recent call last):
  File "/home/jlpkort/anaconda3/lib/python3.8/multiprocessing/util.py", line 300, in _run_finalizers
    finalizer()
  File "/home/jlpkort/anaconda3/lib/python3.8/multiprocessing/util.py", line 224, in __call__
    res = self._callback(*self._args, **self._kwargs)
  File "/home/jlpkort/anaconda3/lib/python3.8/multiprocessing/util.py", line 133, in _remove_temp_dir
    rmtree(tempdir)
  File "/home/jlpkort/anaconda3/lib/python3.8/shutil.py", line 722, in rmtree
    onerror(os.rmdir, path, sys.exc_info())
  File "/home/jlpkort/anaconda3/lib/python3.8/shutil.py", line 720, in rmtree
    os.rmdir(path)
OSError: [Errno 39] Directory not empty: '/scratch/pymp-aavp02qa'
I0906 23:59:12.036317 5956 trainer.py:117]  [Step: 46000/100000 (46.0%)] D Loss: -11333302.0 M Loss: 1.3707044124603271 G Loss: -161667824.0 
Traceback (most recent call last):
  File "/home/jlpkort/anaconda3/lib/python3.8/multiprocessing/util.py", line 300, in _run_finalizers
    finalizer()
  File "/home/jlpkort/anaconda3/lib/python3.8/multiprocessing/util.py", line 224, in __call__
    res = self._callback(*self._args, **self._kwargs)
  File "/home/jlpkort/anaconda3/lib/python3.8/multiprocessing/util.py", line 133, in _remove_temp_dir
    rmtree(tempdir)
  File "/home/jlpkort/anaconda3/lib/python3.8/shutil.py", line 722, in rmtree
    onerror(os.rmdir, path, sys.exc_info())
  File "/home/jlpkort/anaconda3/lib/python3.8/shutil.py", line 720, in rmtree
    os.rmdir(path)
OSError: [Errno 39] Directory not empty: '/scratch/pymp-qy1epfg8'
I0907 01:21:17.283109 5956 trainer.py:117]  [Step: 47000/100000 (47.0%)] D Loss: -10284407.0 M Loss: 1.3518569469451904 G Loss: -173607744.0 
Traceback (most recent call last):
  File "/home/jlpkort/anaconda3/lib/python3.8/multiprocessing/util.py", line 300, in _run_finalizers
    finalizer()
  File "/home/jlpkort/anaconda3/lib/python3.8/multiprocessing/util.py", line 224, in __call__
    res = self._callback(*self._args, **self._kwargs)
  File "/home/jlpkort/anaconda3/lib/python3.8/multiprocessing/util.py", line 133, in _remove_temp_dir
    rmtree(tempdir)
  File "/home/jlpkort/anaconda3/lib/python3.8/shutil.py", line 722, in rmtree
    onerror(os.rmdir, path, sys.exc_info())
  File "/home/jlpkort/anaconda3/lib/python3.8/shutil.py", line 720, in rmtree
    os.rmdir(path)
OSError: [Errno 39] Directory not empty: '/scratch/pymp-evnk9qwb'
I0907 02:43:27.928063 5956 trainer.py:117]  [Step: 48000/100000 (48.0%)] D Loss: -11944706.0 M Loss: 1.3207828998565674 G Loss: -184523760.0 
Traceback (most recent call last):
  File "/home/jlpkort/anaconda3/lib/python3.8/multiprocessing/util.py", line 300, in _run_finalizers
    finalizer()
  File "/home/jlpkort/anaconda3/lib/python3.8/multiprocessing/util.py", line 224, in __call__
    res = self._callback(*self._args, **self._kwargs)
  File "/home/jlpkort/anaconda3/lib/python3.8/multiprocessing/util.py", line 133, in _remove_temp_dir
    rmtree(tempdir)
  File "/home/jlpkort/anaconda3/lib/python3.8/shutil.py", line 722, in rmtree
    onerror(os.rmdir, path, sys.exc_info())
  File "/home/jlpkort/anaconda3/lib/python3.8/shutil.py", line 720, in rmtree
    os.rmdir(path)
OSError: [Errno 39] Directory not empty: '/scratch/pymp-2lnwqrbx'
Traceback (most recent call last):
  File "/home/jlpkort/anaconda3/lib/python3.8/multiprocessing/util.py", line 300, in _run_finalizers
    finalizer()
  File "/home/jlpkort/anaconda3/lib/python3.8/multiprocessing/util.py", line 224, in __call__
    res = self._callback(*self._args, **self._kwargs)
  File "/home/jlpkort/anaconda3/lib/python3.8/multiprocessing/util.py", line 133, in _remove_temp_dir
    rmtree(tempdir)
  File "/home/jlpkort/anaconda3/lib/python3.8/shutil.py", line 722, in rmtree
    onerror(os.rmdir, path, sys.exc_info())
  File "/home/jlpkort/anaconda3/lib/python3.8/shutil.py", line 720, in rmtree
    os.rmdir(path)
OSError: [Errno 39] Directory not empty: '/scratch/pymp-acyo0oxr'
Traceback (most recent call last):
  File "/home/jlpkort/anaconda3/lib/python3.8/multiprocessing/util.py", line 300, in _run_finalizers
    finalizer()
  File "/home/jlpkort/anaconda3/lib/python3.8/multiprocessing/util.py", line 224, in __call__
    res = self._callback(*self._args, **self._kwargs)
  File "/home/jlpkort/anaconda3/lib/python3.8/multiprocessing/util.py", line 133, in _remove_temp_dir
    rmtree(tempdir)
  File "/home/jlpkort/anaconda3/lib/python3.8/shutil.py", line 722, in rmtree
    onerror(os.rmdir, path, sys.exc_info())
  File "/home/jlpkort/anaconda3/lib/python3.8/shutil.py", line 720, in rmtree
    os.rmdir(path)
OSError: [Errno 39] Directory not empty: '/scratch/pymp-dcu48l5i'
I0907 04:05:38.948569 5956 trainer.py:117]  [Step: 49000/100000 (49.0%)] D Loss: -10781594.0 M Loss: 1.3223906755447388 G Loss: -187619840.0 
Traceback (most recent call last):
  File "/home/jlpkort/anaconda3/lib/python3.8/multiprocessing/util.py", line 300, in _run_finalizers
    finalizer()
  File "/home/jlpkort/anaconda3/lib/python3.8/multiprocessing/util.py", line 224, in __call__
    res = self._callback(*self._args, **self._kwargs)
  File "/home/jlpkort/anaconda3/lib/python3.8/multiprocessing/util.py", line 133, in _remove_temp_dir
    rmtree(tempdir)
  File "/home/jlpkort/anaconda3/lib/python3.8/shutil.py", line 722, in rmtree
    onerror(os.rmdir, path, sys.exc_info())
  File "/home/jlpkort/anaconda3/lib/python3.8/shutil.py", line 720, in rmtree
    os.rmdir(path)
OSError: [Errno 39] Directory not empty: '/scratch/pymp-xjy819fr'
I0907 05:27:56.177354 5956 trainer.py:117]  [Step: 50000/100000 (50.0%)] D Loss: -11261698.0 M Loss: 1.3584990501403809 G Loss: -194865888.0 
Traceback (most recent call last):
  File "/home/jlpkort/anaconda3/lib/python3.8/multiprocessing/util.py", line 300, in _run_finalizers
    finalizer()
  File "/home/jlpkort/anaconda3/lib/python3.8/multiprocessing/util.py", line 224, in __call__
    res = self._callback(*self._args, **self._kwargs)
  File "/home/jlpkort/anaconda3/lib/python3.8/multiprocessing/util.py", line 133, in _remove_temp_dir
    rmtree(tempdir)
  File "/home/jlpkort/anaconda3/lib/python3.8/shutil.py", line 722, in rmtree
    onerror(os.rmdir, path, sys.exc_info())
  File "/home/jlpkort/anaconda3/lib/python3.8/shutil.py", line 720, in rmtree
    os.rmdir(path)
OSError: [Errno 39] Directory not empty: '/scratch/pymp-h7nx06_v'
I0907 06:50:14.594493 5956 trainer.py:117]  [Step: 51000/100000 (51.0%)] D Loss: -15177173.0 M Loss: 1.2532196044921875 G Loss: -207194128.0 
I0907 08:12:27.587716 5956 trainer.py:117]  [Step: 52000/100000 (52.0%)] D Loss: -13031072.0 M Loss: 1.370556354522705 G Loss: -215705632.0 
Traceback (most recent call last):
  File "/home/jlpkort/anaconda3/lib/python3.8/multiprocessing/util.py", line 300, in _run_finalizers
    finalizer()
  File "/home/jlpkort/anaconda3/lib/python3.8/multiprocessing/util.py", line 224, in __call__
    res = self._callback(*self._args, **self._kwargs)
  File "/home/jlpkort/anaconda3/lib/python3.8/multiprocessing/util.py", line 133, in _remove_temp_dir
    rmtree(tempdir)
  File "/home/jlpkort/anaconda3/lib/python3.8/shutil.py", line 722, in rmtree
    onerror(os.rmdir, path, sys.exc_info())
  File "/home/jlpkort/anaconda3/lib/python3.8/shutil.py", line 720, in rmtree
    os.rmdir(path)
OSError: [Errno 39] Directory not empty: '/scratch/pymp-d4pxkmpu'
Traceback (most recent call last):
  File "/home/jlpkort/anaconda3/lib/python3.8/multiprocessing/util.py", line 300, in _run_finalizers
    finalizer()
  File "/home/jlpkort/anaconda3/lib/python3.8/multiprocessing/util.py", line 224, in __call__
    res = self._callback(*self._args, **self._kwargs)
  File "/home/jlpkort/anaconda3/lib/python3.8/multiprocessing/util.py", line 133, in _remove_temp_dir
    rmtree(tempdir)
  File "/home/jlpkort/anaconda3/lib/python3.8/shutil.py", line 722, in rmtree
    onerror(os.rmdir, path, sys.exc_info())
  File "/home/jlpkort/anaconda3/lib/python3.8/shutil.py", line 720, in rmtree
    os.rmdir(path)
OSError: [Errno 39] Directory not empty: '/scratch/pymp-h7_thtsv'
Traceback (most recent call last):
  File "/home/jlpkort/anaconda3/lib/python3.8/multiprocessing/util.py", line 300, in _run_finalizers
    finalizer()
  File "/home/jlpkort/anaconda3/lib/python3.8/multiprocessing/util.py", line 224, in __call__
    res = self._callback(*self._args, **self._kwargs)
  File "/home/jlpkort/anaconda3/lib/python3.8/multiprocessing/util.py", line 133, in _remove_temp_dir
    rmtree(tempdir)
  File "/home/jlpkort/anaconda3/lib/python3.8/shutil.py", line 722, in rmtree
    onerror(os.rmdir, path, sys.exc_info())
  File "/home/jlpkort/anaconda3/lib/python3.8/shutil.py", line 720, in rmtree
    os.rmdir(path)
OSError: [Errno 39] Directory not empty: '/scratch/pymp-s1wfnxz_'
Traceback (most recent call last):
  File "/home/jlpkort/anaconda3/lib/python3.8/multiprocessing/util.py", line 300, in _run_finalizers
    finalizer()
  File "/home/jlpkort/anaconda3/lib/python3.8/multiprocessing/util.py", line 224, in __call__
    res = self._callback(*self._args, **self._kwargs)
  File "/home/jlpkort/anaconda3/lib/python3.8/multiprocessing/util.py", line 133, in _remove_temp_dir
    rmtree(tempdir)
  File "/home/jlpkort/anaconda3/lib/python3.8/shutil.py", line 722, in rmtree
    onerror(os.rmdir, path, sys.exc_info())
  File "/home/jlpkort/anaconda3/lib/python3.8/shutil.py", line 720, in rmtree
    os.rmdir(path)
OSError: [Errno 39] Directory not empty: '/scratch/pymp-icvdjfq9'
I0907 09:34:49.720335 5956 trainer.py:117]  [Step: 53000/100000 (53.0%)] D Loss: -14482643.0 M Loss: 1.3671085834503174 G Loss: -219773824.0 
slurmstepd: error: *** JOB 8160059 ON r31n1 CANCELLED AT 2021-09-07T09:44:44 DUE TO TIME LIMIT ***
